Workbook

Sheet README
A1: FPS Player Model — CS2 + Valorant
A2: Kills and headshot projections built map by map: per-map KPR × the rounds you expect on that map.
A3: Slate 2026-10-16 · 281 board legs · 18 matches
A5: HOW TO USE
A6: 1. Matches tab: every match on the slate, one row each. The shaded columns are yours — Map 1, Map 2, Map 3 (dropdowns) and Rounds M1/M2/M3. They arrive prefilled: maps from PickFinder's Map Picks, rounds from Thunderpick's Total Rounds ladder for that map. Change any of them and every projection for that match recalculates.
A7: 2. Board tab: pick a match in the shaded cell B2. Both rosters load, ranked by projected Maps 1-2 kills, with the PrizePicks line, the model's P(over), Thunderpick's own kill-line median and PickFinder's L10 beside it.
A8: 3. Projections tab: every leg on the board (Maps 1-2, Map 1, Map 2 — kills and HS), filterable.
A9: 4. Log tab: the same projections frozen as values at default settings when the sheet was built. Type the result in Actual after settlement; Result fills itself. This is the forward record the model does not yet have.
A11: THE MODEL, IN FOUR LINES
A12: Per-map KPR = (n × map KPR + SHRINK_MAPS × overall KPR) ÷ (n + SHRINK_MAPS), n = maps the player has on that map in PickFinder's sample. A map he has never played uses his overall KPR.
A13: Kills on map k = per-map KPR × rounds on map k. Maps 1-2 = map 1 + map 2. Maps 1-3 = maps 1-2 + P(map 3) × map 3.
A14: HS on map k = kills on map k × per-map HS%, shrunk the same way. (CS2 only — PickFinder posts no Valorant HS%.)
... A36: Each slate is rebuilt from fresh captures and imported over this file (File → Import → Replace spreadsheet), so the link stays the same. Your shaded edits are per slate and are replaced on the next import.

Sheet Match_Intel
A1: Match Intel — 2026-10-16
A2: Recent form, margins, ranks, pistols, map pools and recent vetoes per match. Windows: HLTV 3 months to the day before the slate; vlr last 10 series. Bucket probabilities are the frozen v2 model (PAPER, not a pick). Margins are rounds: + won by, − lost by.
A4: VAL · VIT vs LOUD | 06:00 UTC | Bo3 | Win: VIT 47% – LOUD 53% | 2-0 24% · 2-1 23% · 1-2 26% · 0-2 27%
B5: Team Vitality (VIT) | C5: LOUD (LOUD)
A6: Rank (vlr) | B6: Current Rank 1 Europe · Rating 2052 · Record 31W 15L | C6: Current Rank 1 Brazil · Rating 2004 · Record 79W 48L
A7: Last 10 series: maps W-L | B7: 16-10 | C7: 18-10
A8: Avg margin in wins / losses | B8: +4.8 / -4.0 | C8: +5.7 / -4.3
A9: Stomps for / against (8+) | B9: 1 / 2 | C9: 5 / 2
A10: Pistols | B10: not available from vlr summary pages | C10: not available from vlr summary pages
A11: Kill share (last 10 series, all maps) | B11: 10 series · 26 maps · team 81.3 kills/map Derke 21.2% (17.3/map) Chronicle 20.9% (17.0/map) Jamppi 20.4% (16.6/map) Sayonara 20.1% (16.4/map) PROFEK 17.4% (14.1/map) | C11: 10 series · 28 maps · team 76.1 kills/map lukxo 25.2% (19.1/map) erde 22.2% (16.9/map) tkzin 20.8% (15.8/map) Darker 16.6% (12.6/map) DaviH 15.2% (11.6/map)
A12: Last 5 series | B12: 2026-10-10 G2 Esports vs Team Vitality Abyss:11-13:P,Split:4-13:P 2026-10-08 Team Vitality vs Nongshim RedForce Split:13-8:P,Abyss:4-13:P,Haven:14-12: 2026-09-30 Team Vitality vs LOUD Ascent:13-7:P,Summit:19-17:P 2026-09-26 Global Esports vs Team Vitality Abyss:10-13:P,Ascent:13-9:P,Summit:11-13: 2026-08-22 Team Vitality vs Fire Flux Esports Abyss:13-11:P,Ascent:11-13:P,Split:7-13: | C12: 2026-10-10 NRG vs LOUD Haven:9-13:P,Sunset:13-10:P,Summit:3-13: 2026-10-07 Paper Rex vs LOUD Split:9-13:P,Sunset:13-15:P 2026-10-04 LOUD vs Global Esports Split:13-8:P,Sunset:13-9:P 2026-09-30 Team Vitality vs LOUD Ascent:13-7:P,Summit:19-17:P 2026-09-26 LOUD vs EDward Gaming Lotus:13-8:P,Summit:13-5:P
A13: Recent vetoes (last 5) | B13: 2026-10-10 vs G2 Esports: G2 ban Summit; VIT ban Sunset; G2 pick Abyss; VIT pick Split; G2 ban Haven; VIT ban Lotus; Ascent remains 2026-10-08 vs Nongshim RedForce: NS ban Lotus; VIT ban Sunset; NS pick Split; VIT pick Abyss; NS ban Ascent; VIT ban Summit; Haven remains 2026-09-30 vs LOUD: VIT ban Sunset; LOUD ban Split; VIT pick Ascent; LOUD pick Summit; VIT ban Abyss; LOUD ban Haven; Lotus remains 2026-09-26 vs Global Esports: VIT ban Sunset; GE ban Split; VIT pick Abyss; GE pick Ascent; VIT ban Haven; GE ban Lotus; Summit remains 2026-08-22 vs Fire Flux Esports: FF ban Haven; VIT ban Sunset; FF pick Abyss; VIT pick Ascent; FF ban Summit; VIT ban Lotus; Split remains | C13: 2026-10-10 vs NRG: NRG ban Split; LOUD ban Lotus; NRG pick Haven; LOUD pick Sunset; NRG ban Abyss; LOUD ban Ascent; Summit remains 2026-10-07 vs Paper Rex: PRX ban Abyss; LOUD ban Ascent; PRX pick Split; LOUD pick Sunset; PRX ban Haven; LOUD ban Lotus; Summit remains 2026-10-04 vs Global Esports: GE ban Lotus; LOUD ban Ascent; GE pick Split; LOUD pick Sunset; GE ban Summit; LOUD ban Haven; Abyss remains 2026-09-30 vs Team Vitality: VIT ban Sunset; LOUD ban Split; VIT pick Ascent; LOUD pick Summit; VIT ban Abyss; LOUD ban Haven; Lotus remains 2026-09-26 vs EDward Gaming: EDG ban Ascent; LOUD ban Split; EDG pick Lotus; LOUD pick Summit; EDG ban Abyss; LOUD ban Haven; Sunset remains
A14: Map | B14: PF pick % | C14: A maps (3 mo) | D14: A ATK % | E14: A DEF % | I14: B maps (3 mo) | J14: B ATK % | K14: B DEF % | O14: A 8+ | A 3-7 | close/OT | B 3-7 | B 8+ | P14: E rounds
A15: Split | B15: 15% | C15: 7 | D15: 55% | E15: 62% | I15: 3 | J15: 84% | K15: 41%
A16: Haven | B16: 15% | C16: 5 | D16: 63% | E16: 40% | I16: 6 | J16: 46% | K16: 50%
A17: Summit | B17: 15% | C17: 3 | D17: 43% | E17: 69% | I17: 9 | J17: 62% | K17: 56%
A18: Breeze | C18: 1 | D18: 67% | E18: 71% | I18: 2 | J18: 39% | K18: 54%
A19: Lotus | C19: 2 | D19: 47% | E19: 47% | I19: 7 | J19: 58% | K19: 49%
A20: Abyss | C20: 5 | D20: 58% | E20: 39% | I20: 3 | J20: 74% | K20: 53%
A21: Ascent | C21: 4 | D21: 57% | E21: 48% | I21: 3 | J21: 30% | K21: 48%
A22: Sunset | C22: 2 | D22: 50% | E22: 55% | I22: 9 | J22: 57% | K22: 55%
A24: CS2 · EF vs BCA | 08:00 UTC | Bo3 | Win: EF 64% – BCA 36% | 2-0 34% · 2-1 30% · 1-2 19% · 0-2 17%
B25: Eternal Fire (EF) | C25: Apogee Esports (BCA)
A26: Rank | B26: HLTV: #38 · VRS: #34 | C26: HLTV: #71 · VRS: #55
A27: Last 10 maps (newest first) | B27: 6-4 L L W L W W W W W L | C27: 2-8 L L L W L L L L L W
A28: Last 10 maps, avg margin | B28: +1.6 | C28: -5.0
A29: 3 months: maps W-L | B29: 56-32 (64%) | C29: 23-22 (51%)
A30: Avg margin in wins / losses | B30: +5.3 / -4.7 | C30: +5.8 / -4.6
A31: Stomps for / against (8+) | B31: 11 / 6 | C31: 5 / 4
A32: Pistols (3 months) | B32: 52.8% (93-83) · R2 conv 82.8% · R2 break 16.9% | C32: not captured
A33: Kill share (last 6 series, all maps) | B33: 6 series · 12 maps · team 80.0 kills/map jottAAA 23.2% (18.6/map) soulfly 22.2% (17.8/map) Kvem 19.1% (15.2/map) regali 17.8% (14.2/map) MisteM 17.7% (14.2/map) | C33: 6 series · 15 maps · team 67.8 kills/map ultimate 22.1% (15.0/map) ex1st 21.5% (14.6/map) Demho 20.5% (13.9/map) Qlocuu 19.4% (13.1/map) Prism 16.5% (11.2/map)
A34: Last 5 series | B34: 0 - 2 Eternal Fire vs Ninjas in Pyjamas 2 - 1 Eternal Fire vs JiJieHao 2 - 0 Eternal Fire vs Sangal 2 - 1 Eternal Fire vs BASEMENT BOYS 13 - 4 Eternal Fire vs Anteiku | C34: 0 - 2 Betclic vs Sangal 1 - 2 Betclic vs Ninjas in Pyjamas 0 - 2 Betclic vs PRIVATE 1 - 2 Betclic vs Astralis 2 - 1 Betclic vs Eternal Fire
A35: Recent vetoes (last 5) | B35: First ban: Nuke×4, Anubis×1 First pick: Dust2×3, Cache×1 3rd of Octob Eternal Fire vs Ninjas in Pyjamas: us ban Nuke · opp ban Anubis · us pick Dust2 · opp pick Inferno · us ban Mirage · opp ban Ancient · left Cache 3rd of Octob Eternal Fire vs JiJieHao: us ban Nuke · opp ban Cache · us pick Dust2 · opp pick Mirage · us ban Inferno · opp ban Ancient · left Anubis 3rd of Octob Eternal Fire vs Sangal: us ban Nuke · opp ban Inferno · us pick Dust2 · opp pick Cache · us ban Anubis · opp ban Ancient · left Mirage 2nd of Octob Eternal Fire vs BASEMENT BOYS: opp ban Inferno · us ban Nuke · opp pick Mirage · us pick Cache · opp ban Anubis · us ban Dust2 · left Ancient 2nd of Octob Eternal Fire vs Anteiku: opp ban Nuke · us ban Anubis · opp ban Cache · us ban Inferno · opp ban Dust2 · us ban Mirage · left Ancient | C35: First ban: Inferno×3, Nuke×1 First pick: Anubis×2, Nuke×2 12th of Octo Betclic vs Sangal: opp ban Ancient · us ban Nuke · opp pick Mirage · us pick Anubis · opp ban Inferno · us ban Dust2 · left Cache 12th of Octo Betclic vs Ninjas in Pyjamas: us ban Inferno · opp ban Anubis · us pick Ancient · opp pick Cache · us ban Mirage · opp ban Dust2 · left Nuke 8th of Octob Betclic vs PRIVATE: opp ban Anubis · us ban Dust2 · opp pick Mirage · us pick Nuke · us ban Inferno · opp ban Cache · left Ancient 25th of Sept Betclic vs Astralis: us ban Inferno · opp ban Anubis · us pick Nuke · opp pick Ancient · us ban Mirage · opp ban Dust2 · left Cache 24th of Sept Betclic vs Eternal Fire: opp ban Nuke · us ban Inferno · opp pick Cache · us pick Anubis · opp ban Mirage · us ban Dust2 · left Ancient
A36: Map | B36: PF pick % | C36: A maps | D36: A W-L | E36: A avg ± | F36: A CT % | G36: A T % | H36: A pistol | I36: B maps | J36: B W-L | K36: B avg ± | L36: B CT % | M36: B T % | N36: B pistol | O36: A 8+ | A 3-7 | close/OT | B 3-7 | B 8+ | P36: E rounds
A37: Ancient | B37: 29% | C37: 17 | D37: 12-5 | E37: +2.6 | F37: 58.6% | G37: 53.5% | H37: 16/34 | I37: 8 | J37: 4-4 | K37: -0.4 | L37: 57.8% | M37: 41.3% | N37: 4/16 | O37: 10% | 37% | 29% | 20% | 4% | P37: 22.4
A38: Anubis | B38: 24% | C38: 10 | D38: 6-4 | E38: +0.4 | F38: 46.5% | G38: 55.2% | H38: 10/20 | I38: 11 | J38: 4-7 | K38: +0.6 | L38: 55.9% | M38: 45.8% | N38: 10/22 | O38: 6% | 29% | 30% | 29% | 6% | P38: 22.5
A39: Cache | B39: 22% | C39: 17 | D39: 11-6 | E39: +1.3 | F39: 56.0% | G39: 50.0% | H39: 19/34 | I39: 8 | J39: 5-3 | K39: +1.0 | L39: 62.2% | M39: 43.3% | N39: 10/16 | O39: 7% | 30% | 31% | 27% | 6% | P39: 22.5
A40: Mirage | B40: 7% | C40: 16 | D40: 8-8 | E40: -0.3 | F40: 50.0% | G40: 48.5% | H40: 17/32 | I40: 7 | J40: 3-4 | K40: -0.7 | L40: 47.6% | M40: 49.3% | N40: 7/14 | O40: 6% | 29% | 30% | 28% | 6% | P40: 22.5
A41: Nuke | B41: 6% | C41: 0 | I41: 9 | J41: 5-4 | K41: +1.1 | L41: 55.6% | M41: 48.8% | N41: 10/18 | O41: 5% | 26% | 30% | 31% | 7% | P41: 22.5
A42: Inferno | B42: 6% | C42: 11 | D42: 6-5 | E42: +2.4 | F42: 55.6% | G42: 57.7% | H42: 14/22 | I42: 0 | O42: 9% | 35% | 30% | 22% | 4% | P42: 22.4
...

Sheet Board
A1: Board
A2: Match: | B2: CS2 · EF vs BCA
A4: Teams | B4: {=IFERROR(IF(INDEX(Matches!$E$5:$E$22,MATCH($B$2,Matches!$A$5:$A$22,0))="","",INDEX(Matches!$E$5:$E$22,MATCH($B$2,Matches!$A$5:$A$22,0))),"")&" vs "&IFERROR(IF(INDEX(Matches!$F$5:$F$22,MATCH($B$2,Matches!$A$5:$A$22,0))="","",INDEX(Matches!$F$5:$F$22,MATCH($B$2,Matches!$A$5:$A$22,0))),"")} -> Eternal Fire (EF) vs Apogee Esports (BCA) | D4: Start (CT) | E4: {=IFERROR(IF(INDEX(Matches!$C$5:$C$22,MATCH($B$2,Matches!$A$5:$A$22,0))="","",INDEX(Matches!$C$5:$C$22,MATCH($B$2,Matches!$A$5:$A$22,0))),"")} -> Fri 03:00 | G4: Bo | H4: {=IFERROR(IF(INDEX(Matches!$D$5:$D$22,MATCH($B$2,Matches!$A$5:$A$22,0))="","",INDEX(Matches!$D$5:$D$22,MATCH($B$2,Matches!$A$5:$A$22,0))),"")} -> 3
A5: P(A wins) | B5: {=IFERROR(IF(INDEX(Matches!$G$5:$G$22,MATCH($B$2,Matches!$A$5:$A$22,0))="","",INDEX(Matches!$G$5:$G$22,MATCH($B$2,Matches!$A$5:$A$22,0))),"")} -> 0.64197531 | D5: P(A 2-0) | E5: {=IFERROR(IF(INDEX(Matches!$H$5:$H$22,MATCH($B$2,Matches!$A$5:$A$22,0))="","",INDEX(Matches!$H$5:$H$22,MATCH($B$2,Matches!$A$5:$A$22,0))),"")} -> 0.34126772 | G5: P(B 2-0) | H5: {=IFERROR(IF(INDEX(Matches!$I$5:$I$22,MATCH($B$2,Matches!$A$5:$A$22,0))="","",INDEX(Matches!$I$5:$I$22,MATCH($B$2,Matches!$A$5:$A$22,0))),"")} -> 0.17063386
A6: P(3 maps) | B6: {=IFERROR(IF(INDEX(Matches!$J$5:$J$22,MATCH($B$2,Matches!$A$5:$A$22,0))="","",INDEX(Matches!$J$5:$J$22,MATCH($B$2,Matches!$A$5:$A$22,0))),"")} -> 0.48809842 | D6: Map pick #1 | E6: {=IFERROR(IF(INDEX(Matches!$K$5:$K$22,MATCH($B$2,Matches!$A$5:$A$22,0))="","",INDEX(Matches!$K$5:$K$22,MATCH($B$2,Matches!$A$5:$A$22,0))),"")} -> Ancient 29% | G6: Map pick #2 | H6: {=IFERROR(IF(INDEX(Matches!$L$5:$L$22,MATCH($B$2,Matches!$A$5:$A$22,0))="","",INDEX(Matches!$L$5:$L$22,MATCH($B$2,Matches!$A$5:$A$22,0))),"")} -> Anubis 24%
A7: TP rounds M1 | B7: {=IFERROR(IF(INDEX(Matches!$O$5:$O$22,MATCH($B$2,Matches!$A$5:$A$22,0))="","",INDEX(Matches!$O$5:$O$22,MATCH($B$2,Matches!$A$5:$A$22,0))),"")} -> 21.423154 | D7: TP rounds M2 | E7: {=IFERROR(IF(INDEX(Matches!$P$5:$P$22,MATCH($B$2,Matches!$A$5:$A$22,0))="","",INDEX(Matches!$P$5:$P$22,MATCH($B$2,Matches!$A$5:$A$22,0))),"")} -> 21.312553 | G7: P(OT) M1 | H7: {=IFERROR(IF(INDEX(Matches!$R$5:$R$22,MATCH($B$2,Matches!$A$5:$A$22,0))="","",INDEX(Matches!$R$5:$R$22,MATCH($B$2,Matches!$A$5:$A$22,0))),"")} -> 0.15942029
A8: A margin M1 | B8: {=IFERROR(IF(INDEX(Matches!$S$5:$S$22,MATCH($B$2,Matches!$A$5:$A$22,0))="","",INDEX(Matches!$S$5:$S$22,MATCH($B$2,Matches!$A$5:$A$22,0))),"")} -> 1.7003949 | D8: A rounds M1 | E8: {=IFERROR(IF(INDEX(Matches!$T$5:$T$22,MATCH($B$2,Matches!$A$5:$A$22,0))="","",INDEX(Matches!$T$5:$T$22,MATCH($B$2,Matches!$A$5:$A$22,0))),"")} | G8: B rounds M1 | H8: {=IFERROR(IF(INDEX(Matches!$U$5:$U$22,MATCH($B$2,Matches!$A$5:$A$22,0))="","",INDEX(Matches!$U$5:$U$22,MATCH($B$2,Matches!$A$5:$A$22,0))),"")} -> 11.5
A9: HLTV rounds M1 | B9: {=IFERROR(IF(INDEX(Matches!$AN$5:$AN$22,MATCH($B$2,Matches!$A$5:$A$22,0))="","",INDEX(Matches!$AN$5:$AN$22,MATCH($B$2,Matches!$A$5:$A$22,0))),"")} -> 21.2764 | D9: HLTV A margin M1 | E9: {=IFERROR(IF(INDEX(Matches!$AO$5:$AO$22,MATCH($B$2,Matches!$A$5:$A$22,0))="","",INDEX(Matches!$AO$5:$AO$22,MATCH($B$2,Matches!$A$5:$A$22,0))),"")} -> 0.4116 | G9: Hist share A / B | H9: {=IF(IFERROR(IF(INDEX(Matches!$AI$5:$AI$22,MATCH($B$2,Matches!$A$5:$A$22,0))="","",INDEX(Matches!$AI$5:$AI$22,MATCH($B$2,Matches!$A$5:$A$22,0))),"")="","",TEXT(IFERROR(IF(INDEX(Matches!$AI$5:$AI$22,MATCH($B$2,Matches!$A$5:$A$22,0))="","",INDEX(Matches!$AI$5:$AI$22,MATCH($B$2,Matches!$A$5:$A$22,0))),""),"0%")&" / "&TEXT(IFERROR(IF(INDEX(Matches!$AJ$5:$AJ$22,MATCH($B$2,Matches!$A$5:$A$22,0))="","",INDEX(Matches!$AJ$5:$AJ$22,MATCH($B$2,Matches!$A$5:$A$22,0))),""),"0%"))} -> 53% / 53%
A10: IN USE | B10: {="Map 1: "&IFERROR(IF(INDEX(Matches!$W$5:$W$22,MATCH($B$2,Matches!$A$5:$A$22,0))="","",INDEX(Matches!$W$5:$W$22,MATCH($B$2,Matches!$A$5:$A$22,0))),"")&" · Map 2: "&IFERROR(IF(INDEX(Matches!$X$5:$X$22,MATCH($B$2,Matches!$A$5:$A$22,0))="","",INDEX(Matches!$X$5:$X$22,MATCH($B$2,Matches!$A$5:$A$22,0))),"")&IF(IFERROR(IF(INDEX(Matches!$Y$5:$Y$22,MATCH($B$2,Matches!$A$5:$A$22,0))="","",INDEX(Matches!$Y$5:$Y$22,MATCH($B$2,Matches!$A$5:$A$22,0))),"")="",""," · Map 3: "&IFERROR(IF(INDEX(Matches!$Y$5:$Y$22,MATCH($B$2,Matches!$A$5:$A$22,0))="","",INDEX(Matches!$Y$5:$Y$22,MATCH($B$2,Matches!$A$5:$A$22,0))),""))} -> Map 1: Ancient · Map 2: Anubis · Map 3: Cache
B11: {="Rounds: "&TEXT(IFERROR(IF(INDEX(Matches!$Z$5:$Z$22,MATCH($B$2,Matches!$A$5:$A$22,0))="","",INDEX(Matches!$Z$5:$Z$22,MATCH($B$2,Matches!$A$5:$A$22,0))),""),"0.0")&" / "&TEXT(IFERROR(IF(INDEX(Matches!$AA$5:$AA$22,MATCH($B$2,Matches!$A$5:$A$22,0))="","",INDEX(Matches!$AA$5:$AA$22,MATCH($B$2,Matches!$A$5:$A$22,0))),""),"0.0")&IF(IFERROR(IF(INDEX(Matches!$AB$5:$AB$22,MATCH($B$2,Matches!$A$5:$A$22,0))="","",INDEX(Matches!$AB$5:$AB$22,MATCH($B$2,Matches!$A$5:$A$22,0))),"")="",""," / "&TEXT(IFERROR(IF(INDEX(Matches!$AB$5:$AB$22,MATCH($B$2,Matches!$A$5:$A$22,0))="","",INDEX(Matches!$AB$5:$AB$22,MATCH($B$2,Matches!$A$5:$A$22,0))),""),"0.0"))&" · P(map 3) "&TEXT(IFERROR(IF(INDEX(Matches!$AC$5:$AC$22,MATCH($B$2,Matches!$A$5:$A$22,0))="","",INDEX(Matches!$AC$5:$AC$22,MATCH($B$2,Matches!$A$5:$A$22,0))),""),"0%")} -> Rounds: 21.4 / 21.3 / 21.4 · P(map 3) 49%
B12: ="Change maps or rounds on the Matches tab, row "&(MATCH($B$2,Matches!$A$5:$A$22,0)+4)&" (shaded cells)." -> Change maps or rounds on the Matches tab, row 5 (shaded cells).
A14: Team | B14: Player | C14: KPR M1 | D14: KPR M2 | E14: Kills M1 | F14: Kills M2 | G14: Kills 1-2 | H14: Diff mult | I14: Adj K 1-2 | J14: PP line | K14: P(over) | L14: Adj P(over) | M14: TP book | N14: PF L10 | O14: HS% 1-2 | P14: HS 1-2 | Q14: PP HS line | R14: P(over) HS | S14: Sample | T14: Flags | V14: row
A15: {=IF($V15="","",INDEX(Calc!$D$2:$D$157,$V15))} -> EF | B15: {=IF($V15="","",INDEX(Calc!$E$2:$E$157,$V15))} -> jottAAA | C15: {=IF($V15="","",INDEX(Calc!$T$2:$T$157,$V15))} -> 0.825 | D15: {=IF($V15="","",INDEX(Calc!$AA$2:$AA$157,$V15))} -> 0.79454545 | E15: {=IF($V15="","",INDEX(Calc!$V$2:$V$157,$V15))} -> 17.6715 | F15: {=IF($V15="","",INDEX(Calc!$AC$2:$AC$157,$V15))} -> 16.931764 | G15: {=IF($V15="","",INDEX(Calc!$AL$2:$AL$157,$V15))} -> 34.603264 | H15: {=IF($V15="","",INDEX(Calc!$BK$2:$BK$157,$V15))} -> 0.96621425 | I15: {=IF($V15="","",INDEX(Calc!$BD$2:$BD$157,$V15))} -> 33.434166 | J15: {=IF($V15="","",IFERROR(INDEX(Projections!$F$2:$F$282,MATCH(INDEX(Calc!$A$2:$A$157,$V15)&"|K12",Projections!$Y$2:$Y$282,0)),""))} -> 33.5 | K15: {=IF($V15="","",IFERROR(INDEX(Projections!$I$2:$I$282,MATCH(INDEX(Calc!$A$2:$A$157,$V15)&"|K12",Projections!$Y$2:$Y$282,0)),""))} -> 0.56297254 | L15: {=IF($V15="","",IFERROR(INDEX(Projections!$AB$2:$AB$282,MATCH(INDEX(Calc!$A$2:$A$157,$V15)&"|K12",Projections!$Y$2:$Y$282,0)),""))} -> 0.49616123 | M15: {=IF($V15="","",IFERROR(INDEX(Projections!$M$2:$M$282,MATCH(INDEX(Calc!$A$2:$A$157,$V15)&"|K12",Projections!$Y$2:$Y$282,0)),""))} | N15: {=IF($V15="","",IFERROR(INDEX(Projections!$P$2:$P$282,MATCH(INDEX(Calc!$A$2:$A$157,$V15)&"|K12",Projections!$Y$2:$Y$282,0)),""))} -> 0.5 | O15: {=IF($V15="","",INDEX(Calc!$AP$2:$AP$157,$V15))} -> 0.57848758 | P15: {=IF($V15="","",INDEX(Calc!$AN$2:$AN$157,$V15))} -> 20.017558 | Q15: {=IF($V15="","",IFERROR(INDEX(Projections!$F$2:$F$282,MATCH(INDEX(Calc!$A$2:$A$157,$V15)&"|H12",Projections!$Y$2:$Y$282,0)),""))} -> 19 | R15: {=IF($V15="","",IFERROR(INDEX(Projections!$I$2:$I$282,MATCH(INDEX(Calc!$A$2:$A$157,$V15)&"|H12",Projections!$Y$2:$Y$282,0)),""))} -> 0.54151252 | S15: {=IF($V15="","",INDEX(Calc!$N$2:$N$157,$V15))} -> 29 | T15: {=IF($V15="","",INDEX(Calc!$AQ$2:$AQ$157,$V15))} | V15: =IFERROR(MATCH(1,Calc!$AR$2:$AR$157,0),"") -> 49
A16: {=IF($V16="","",INDEX(Calc!$D$2:$D$157,$V16))} -> EF | B16: {=IF($V16="","",INDEX(Calc!$E$2:$E$157,$V16))} -> Soulfly | C16: {=IF($V16="","",INDEX(Calc!$T$2:$T$157,$V16))} -> 0.795 | D16: {=IF($V16="","",INDEX(Calc!$AA$2:$AA$157,$V16))} -> 0.74818182 | E16: {=IF($V16="","",INDEX(Calc!$V$2:$V$157,$V16))} -> 17.0289 | F16: {=IF($V16="","",INDEX(Calc!$AC$2:$AC$157,$V16))} -> 15.943755 | G16: {=IF($V16="","",INDEX(Calc!$AL$2:$AL$157,$V16))} -> 32.972655 | H16: {=IF($V16="","",INDEX(Calc!$BK$2:$BK$157,$V16))} -> 0.96639289 | I16: {=IF($V16="","",INDEX(Calc!$BD$2:$BD$157,$V16))} -> 31.864539 | J16: {=IF($V16="","",IFERROR(INDEX(Projections!$F$2:$F$282,MATCH(INDEX(Calc!$A$2:$A$157,$V16)&"|K12",Projections!$Y$2:$Y$282,0)),""))} -> 30.5 | K16: {=IF($V16="","",IFERROR(INDEX(Projections!$I$2:$I$282,MATCH(INDEX(Calc!$A$2:$A$157,$V16)&"|K12",Projections!$Y$2:$Y$282,0)),""))} -> 0.6420463 | L16: {=IF($V16="","",IFERROR(INDEX(Projections!$AB$2:$AB$282,MATCH(INDEX(Calc!$A$2:$A$157,$V16)&"|K12",Projections!$Y$2:$Y$282,0)),""))} -> 0.58094042 | M16: {=IF($V16="","",IFERROR(INDEX(Projections!$M$2:$M$282,MATCH(INDEX(Calc!$A$2:$A$157,$V16)&"|K12",Projections!$Y$2:$Y$282,0)),""))} | N16: {=IF($V16="","",IFERROR(INDEX(Projections!$P$2:$P$282,MATCH(INDEX(Calc!$A$2:$A$157,$V16)&"|K12",Projections!$Y$2:$Y$282,0)),""))} -> 0.8 | O16: {=IF($V16="","",INDEX(Calc!$AP$2:$AP$157,$V16))} -> 0.53814082 | P16: {=IF($V16="","",INDEX(Calc!$AN$2:$AN$157,$V16))} -> 17.743931 | Q16: {=IF($V16="","",IFERROR(INDEX(Projections!$F$2:$F$282,MATCH(INDEX(Calc!$A$2:$A$157,$V16)&"|H12",Projections!$Y$2:$Y$282,0)),""))} -> 16.5 | R16: {=IF($V16="","",IFERROR(INDEX(Projections!$I$2:$I$282,MATCH(INDEX(Calc!$A$2:$A$157,$V16)&"|H12",Projections!$Y$2:$Y$282,0)),""))} -> 0.6056035 | S16: {=IF($V16="","",INDEX(Calc!$N$2:$N$157,$V16))} -> 29 | T16: {=IF($V16="","",INDEX(Calc!$AQ$2:$AQ$157,$V16))} | V16: =IFERROR(MATCH(2,Calc!$AR$2:$AR$157,0),"") -> 53
A17: {=IF($V17="","",INDEX(Calc!$D$2:$D$157,$V17))} -> BCA | B17: {=IF($V17="","",INDEX(Calc!$E$2:$E$157,$V17))} -> Ex1st | C17: {=IF($V17="","",INDEX(Calc!$T$2:$T$157,$V17))} -> 0.79454545 | D17: {=IF($V17="","",INDEX(Calc!$AA$2:$AA$157,$V17))} -> 0.72153846 | E17: {=IF($V17="","",INDEX(Calc!$V$2:$V$157,$V17))} -> 17.019164 | F17: {=IF($V17="","",INDEX(Calc!$AC$2:$AC$157,$V17))} -> 15.375985 | G17: {=IF($V17="","",INDEX(Calc!$AL$2:$AL$157,$V17))} -> 32.395148 | H17: {=IF($V17="","",INDEX(Calc!$BK$2:$BK$157,$V17))} -> 0.97915312 | I17: {=IF($V17="","",INDEX(Calc!$BD$2:$BD$157,$V17))} -> 31.71981 | J17: {=IF($V17="","",IFERROR(INDEX(Projections!$F$2:$F$282,MATCH(INDEX(Calc!$A$2:$A$157,$V17)&"|K12",Projections!$Y$2:$Y$282,0)),""))} -> 29.5 | K17: {=IF($V17="","",IFERROR(INDEX(Projections!$I$2:$I$282,MATCH(INDEX(Calc!$A$2:$A$157,$V17)&"|K12",Projections!$Y$2:$Y$282,0)),""))} -> 0.66636558 | L17: {=IF($V17="","",IFERROR(INDEX(Projections!$AB$2:$AB$282,MATCH(INDEX(Calc!$A$2:$A$157,$V17)&"|K12",Projections!$Y$2:$Y$282,0)),""))} -> 0.63047406 | M17: {=IF($V17="","",IFERROR(INDEX(Projections!$M$2:$M$282,MATCH(INDEX(Calc!$A$2:$A$157,$V17)&"|K12",Projections!$Y$2:$Y$282,0)),""))} | N17: {=IF($V17="","",IFERROR(INDEX(Projections!$P$2:$P$282,MATCH(INDEX(Calc!$A$2:$A$157,$V17)&"|K12",Projections!$Y$2:$Y$282,0)),""))} -> 0.6 | O17: {=IF($V17="","",INDEX(Calc!$AP$2:$AP$157,$V17))} -> 0.50809844 | P17: {=IF($V17="","",INDEX(Calc!$AN$2:$AN$157,$V17))} -> 16.459924 | Q17: {=IF($V17="","",IFERROR(INDEX(Projections!$F$2:$F$282,MATCH(INDEX(Calc!$A$2:$A$157,$V17)&"|H12",Projections!$Y$2:$Y$282,0)),""))} -> 15.5 | R17: {=IF($V17="","",IFERROR(INDEX(Projections!$I$2:$I$282,MATCH(INDEX(Calc!$A$2:$A$157,$V17)&"|H12",Projections!$Y$2:$Y$282,0)),""))} -> 0.58538859 | S17: {=IF($V17="","",INDEX(Calc!$N$2:$N$157,$V17))} -> 34 | T17: {=IF($V17="","",INDEX(Calc!$AQ$2:$AQ$157,$V17))} | V17: =IFERROR(MATCH(3,Calc!$AR$2:$AR$157,0),"") -> 45
A18: {=IF($V18="","",INDEX(Calc!$D$2:$D$157,$V18))} -> EF | B18: {=IF($V18="","",INDEX(Calc!$E$2:$E$157,$V18))} -> Kvem | C18: {=IF($V18="","",INDEX(Calc!$T$2:$T$157,$V18))} -> 0.78 | D18: {=IF($V18="","",INDEX(Calc!$AA$2:$AA$157,$V18))} -> 0.69909091 | E18: {=IF($V18="","",INDEX(Calc!$V$2:$V$157,$V18))} -> 16.7076 | F18: {=IF($V18="","",INDEX(Calc!$AC$2:$AC$157,$V18))} -> 14.897627 | G18: {=IF($V18="","",INDEX(Calc!$AL$2:$AL$157,$V18))} -> 31.605227 | H18: {=IF($V18="","",INDEX(Calc!$BK$2:$BK$157,$V18))} -> 0.9667702 | I18: {=IF($V18="","",INDEX(Calc!$BD$2:$BD$157,$V18))} -> 30.554992 | J18: {=IF($V18="","",IFERROR(INDEX(Projections!$F$2:$F$282,MATCH(INDEX(Calc!$A$2:$A$157,$V18)&"|K12",Projections!$Y$2:$Y$282,0)),""))} -> 31.5 | K18: {=IF($V18="","",IFERROR(INDEX(Projections!$I$2:$I$282,MATCH(INDEX(Calc!$A$2:$A$157,$V18)&"|K12",Projections!$Y$2:$Y$282,0)),""))} -> 0.50631069 | L18: {=IF($V18="","",IFERROR(INDEX(Projections!$AB$2:$AB$282,MATCH(INDEX(Calc!$A$2:$A$157,$V18)&"|K12",Projections!$Y$2:$Y$282,0)),""))} -> 0.44255774 | M18: {=IF($V18="","",IFERROR(INDEX(Projections!$M$2:$M$282,MATCH(INDEX(Calc!$A$2:$A$157,$V18)&"|K12",Projections!$Y$2:$Y$282,0)),""))} | N18: {=IF($V18="","",IFERROR(INDEX(Projections!$P$2:$P$282,MATCH(INDEX(Calc!$A$2:$A$157,$V18)&"|K12",Projections!$Y$2:$Y$282,0)),""))} -> 0.6 | O18: {=IF($V18="","",INDEX(Calc!$AP$2:$AP$157,$V18))} -> 0.56407089 | P18: {=IF($V18="","",INDEX(Calc!$AN$2:$AN$157,$V18))} -> 17.827589 | Q18: {=IF($V18="","",IFERROR(INDEX(Projections!$F$2:$F$282,MATCH(INDEX(Calc!$A$2:$A$157,$V18)&"|H12",Projections!$Y$2:$Y$282,0)),""))} -> 18.5 | R18: {=IF($V18="","",IFERROR(INDEX(Projections!$I$2:$I$282,MATCH(INDEX(Calc!$A$2:$A$157,$V18)&"|H12",Projections!$Y$2:$Y$282,0)),""))} -> 0.44280952 | S18: {=IF($V18="","",INDEX(Calc!$N$2:$N$157,$V18))} -> 29 | T18: {=IF($V18="","",INDEX(Calc!$AQ$2:$AQ$157,$V18))} | V18: =IFERROR(MATCH(4,Calc!$AR$2:$AR$157,0),"") -> 50
A19: {=IF($V19="","",INDEX(Calc!$D$2:$D$157,$V19))} -> BCA | B19: {=IF($V19="","",INDEX(Calc!$E$2:$E$157,$V19))} -> Qlocuu | C19: {=IF($V19="","",INDEX(Calc!$T$2:$T$157,$V19))} -> 0.66545455 | D19: {=IF($V19="","",INDEX(Calc!$AA$2:$AA$157,$V19))} -> 0.72769231 | E19: {=IF($V19="","",INDEX(Calc!$V$2:$V$157,$V19))} -> 14.254036 | F19: {=IF($V19="","",INDEX(Calc!$AC$2:$AC$157,$V19))} -> 15.507123 | G19: {=IF($V19="","",INDEX(Calc!$AL$2:$AL$157,$V19))} -> 29.761159 | H19: {=IF($V19="","",INDEX(Calc!$BK$2:$BK$157,$V19))} -> 0.98059089 | I19: {=IF($V19="","",INDEX(Calc!$BD$2:$BD$157,$V19))} -> 29.183522 | J19: {=IF($V19="","",IFERROR(INDEX(Projections!$F$2:$F$282,MATCH(INDEX(Calc!$A$2:$A$157,$V19)&"|K12",Projections!$Y$2:$Y$282,0)),""))} -> 27.5 | K19: {=IF($V19="","",IFERROR(INDEX(Projections!$I$2:$I$282,MATCH(INDEX(Calc!$A$2:$A$157,$V19)&"|K12",Projections!$Y$2:$Y$282,0)),""))} -> 0.63694386 | L19: {=IF($V19="","",IFERROR(INDEX(Projections!$AB$2:$AB$282,MATCH(INDEX(Calc!$A$2:$A$157,$V19)&"|K12",Projections!$Y$2:$Y$282,0)),""))} -> 0.60387187 | M19: {=IF($V19="","",IFERROR(INDEX(Projections!$M$2:$M$282,MATCH(INDEX(Calc!$A$2:$A$157,$V19)&"|K12",Projections!$Y$2:$Y$282,0)),""))} | N19: {=IF($V19="","",IFERROR(INDEX(Projections!$P$2:$P$282,MATCH(INDEX(Calc!$A$2:$A$157,$V19)&"|K12",Projections!$Y$2:$Y$282,0)),""))} -> 0.7 | O19: {=IF($V19="","",INDEX(Calc!$AP$2:$AP$157,$V19))} -> 0.51596077 | P19: {=IF($V19="","",INDEX(Calc!$AN$2:$AN$157,$V19))} -> 15.355591 | Q19: {=IF($V19="","",IFERROR(INDEX(Projections!$F$2:$F$282,MATCH(INDEX(Calc!$A$2:$A$157,$V19)&"|H12",Projections!$Y$2:$Y$282,0)),""))} -> 14.5 | R19: {=IF($V19="","",IFERROR(INDEX(Projections!$I$2:$I$282,MATCH(INDEX(Calc!$A$2:$A$157,$V19)&"|H12",Projections!$Y$2:$Y$282,0)),""))} -> 0.57878567 | S19: {=IF($V19="","",INDEX(Calc!$N$2:$N$157,$V19))} -> 34 | T19: {=IF($V19="","",INDEX(Calc!$AQ$2:$AQ$157,$V19))} | V19: =IFERROR(MATCH(5,Calc!$AR$2:$AR$157,0),"") -> 47
A20: {=IF($V20="","",INDEX(Calc!$D$2:$D$157,$V20))} -> BCA | B20: {=IF($V20="","",INDEX(Calc!$E$2:$E$157,$V20))} -> ultimate | C20: {=IF($V20="","",INDEX(Calc!$T$2:$T$157,$V20))} -> 0.64909091 | D20: {=IF($V20="","",INDEX(Calc!$AA$2:$AA$157,$V20))} -> 0.60545455 | E20: {=IF($V20="","",INDEX(Calc!$V$2:$V$157,$V20))} -> 13.903527 | F20: {=IF($V20="","",INDEX(Calc!$AC$2:$AC$157,$V20))} -> 12.902236 | G20: {=IF($V20="","",INDEX(Calc!$AL$2:$AL$157,$V20))} -> 26.805764 | H20: {=IF($V20="","",INDEX(Calc!$BK$2:$BK$157,$V20))} -> 0.97936019 | I20: {=IF($V20="","",INDEX(Calc!$BD$2:$BD$157,$V20))} -> 26.252498 | J20: {=IF($V20="","",IFERROR(INDEX(Projections!$F$2:$F$282,MATCH(INDEX(Calc!$A$2:$A$157,$V20)&"|K12",Projections!$Y$2:$Y$282,0)),""))} -> 28.5 | K20: {=IF($V20="","",IFERROR(INDEX(Projections!$I$2:$I$282,MATCH(INDEX(Calc!$A$2:$A$157,$V20)&"|K12",Projections!$Y$2:$Y$282,0)),""))} -> 0.3910574 | L20: {=IF($V20="","",IFERROR(INDEX(Projections!$AB$2:$AB$282,MATCH(INDEX(Calc!$A$2:$A$157,$V20)&"|K12",Projections!$Y$2:$Y$282,0)),""))} -> 0.35542153 | M20: {=IF($V20="","",IFERROR(INDEX(Projections!$M$2:$M$282,MATCH(INDEX(Calc!$A$2:$A$157,$V20)&"|K12",Projections!$Y$2:$Y$282,0)),""))} | N20: {=IF($V20="","",IFERROR(INDEX(Projections!$P$2:$P$282,MATCH(INDEX(Calc!$A$2:$A$157,$V20)&"|K12",Projections!$Y$2:$Y$282,0)),""))} -> 0.6 | O20: {=IF($V20="","",INDEX(Calc!$AP$2:$AP$157,$V20))} -> 0.35421393 | P20: {=IF($V20="","",INDEX(Calc!$AN$2:$AN$157,$V20))} -> 9.494975 | Q20: {=IF($V20="","",IFERROR(INDEX(Projections!$F$2:$F$282,MATCH(INDEX(Calc!$A$2:$A$157,$V20)&"|H12",Projections!$Y$2:$Y$282,0)),""))} -> 11.5 | R20: {=IF($V20="","",IFERROR(INDEX(Projections!$I$2:$I$282,MATCH(INDEX(Calc!$A$2:$A$157,$V20)&"|H12",Projections!$Y$2:$Y$282,0)),""))} -> 0.27127043 | S20: {=IF($V20="","",INDEX(Calc!$N$2:$N$157,$V20))} -> 30 | T20: {=IF($V20="","",INDEX(Calc!$AQ$2:$AQ$157,$V20))} | V20: =IFERROR(MATCH(6,Calc!$AR$2:$AR$157,0),"") -> 48
A21: {=IF($V21="","",INDEX(Calc!$D$2:$D$157,$V21))} -> BCA | B21: {=IF($V21="","",INDEX(Calc!$E$2:$E$157,$V21))} -> Prism | C21: {=IF($V21="","",INDEX(Calc!$T$2:$T$157,$V21))} -> 0.62818182 | D21: {=IF($V21="","",INDEX(Calc!$AA$2:$AA$157,$V21))} -> 0.60692308 | E21: {=IF($V21="","",INDEX(Calc!$V$2:$V$157,$V21))} -> 13.455655 | F21: {=IF($V21="","",INDEX(Calc!$AC$2:$AC$157,$V21))} -> 12.933531 | G21: {=IF($V21="","",INDEX(Calc!$AL$2:$AL$157,$V21))} -> 26.389185 | H21: {=IF($V21="","",INDEX(Calc!$BK$2:$BK$157,$V21))} -> 0.9796323 | I21: {=IF($V21="","",INDEX(Calc!$BD$2:$BD$157,$V21))} -> 25.851698 | J21: {=IF($V21="","",IFERROR(INDEX(Projections!$F$2:$F$282,MATCH(INDEX(Calc!$A$2:$A$157,$V21)&"|K12",Projections!$Y$2:$Y$282,0)),""))} -> 26.5 | K21: {=IF($V21="","",IFERROR(INDEX(Projections!$I$2:$I$282,MATCH(INDEX(Calc!$A$2:$A$157,$V21)&"|K12",Projections!$Y$2:$Y$282,0)),""))} -> 0.49272712 | L21: {=IF($V21="","",IFERROR(INDEX(Projections!$AB$2:$AB$282,MATCH(INDEX(Calc!$A$2:$A$157,$V21)&"|K12",Projections!$Y$2:$Y$282,0)),""))} -> 0.45709194 | M21: {=IF($V21="","",IFERROR(INDEX(Projections!$M$2:$M$282,MATCH(INDEX(Calc!$A$2:$A$157,$V21)&"|K12",Projections!$Y$2:$Y$282,0)),""))} | N21: {=IF($V21="","",IFERROR(INDEX(Projections!$P$2:$P$282,MATCH(INDEX(Calc!$A$2:$A$157,$V21)&"|K12",Projections!$Y$2:$Y$282,0)),""))} -> 0.5 | O21: {=IF($V21="","",INDEX(Calc!$AP$2:$AP$157,$V21))} -> 0.48458577 | P21: {=IF($V21="","",INDEX(Calc!$AN$2:$AN$157,$V21))} -> 12.787824 | Q21: {=IF($V21="","",IFERROR(INDEX(Projections!$F$2:$F$282,MATCH(INDEX(Calc!$A$2:$A$157,$V21)&"|H12",Projections!$Y$2:$Y$282,0)),""))} -> 13.5 | R21: {=IF($V21="","",IFERROR(INDEX(Projections!$I$2:$I$282,MATCH(INDEX(Calc!$A$2:$A$157,$V21)&"|H12",Projections!$Y$2:$Y$282,0)),""))} -> 0.42768508 | S21: {=IF($V21="","",INDEX(Calc!$N$2:$N$157,$V21))} -> 34 | T21: {=IF($V21="","",INDEX(Calc!$AQ$2:$AQ$157,$V21))} | V21: =IFERROR(MATCH(7,Calc!$AR$2:$AR$157,0),"") -> 46
A22: {=IF($V22="","",INDEX(Calc!$D$2:$D$157,$V22))} -> EF | B22: {=IF($V22="","",INDEX(Calc!$E$2:$E$157,$V22))} -> regali | C22: {=IF($V22="","",INDEX(Calc!$T$2:$T$157,$V22))} -> 0.625 | D22: {=IF($V22="","",INDEX(Calc!$AA$2:$AA$157,$V22))} -> 0.58272727 | E22: {=IF($V22="","",INDEX(Calc!$V$2:$V$157,$V22))} -> 13.3875 | F22: {=IF($V22="","",INDEX(Calc!$AC$2:$AC$157,$V22))} -> 12.417918 | G22: {=IF($V22="","",INDEX(Calc!$AL$2:$AL$157,$V22))} -> 25.805418 | H22: {=IF($V22="","",INDEX(Calc!$BK$2:$BK$157,$V22))} -> 0.96646511 | I22: {=IF($V22="","",INDEX(Calc!$BD$2:$BD$157,$V22))} -> 24.940036 | J22: {=IF($V22="","",IFERROR(INDEX(Projections!$F$2:$F$282,MATCH(INDEX(Calc!$A$2:$A$157,$V22)&"|K12",Projections!$Y$2:$Y$282,0)),""))} -> 29.5 | K22: {=IF($V22="","",IFERROR(INDEX(Projections!$I$2:$I$282,MATCH(INDEX(Calc!$A$2:$A$157,$V22)&"|K12",Projections!$Y$2:$Y$282,0)),""))} -> 0.26938456 | L22: {=IF($V22="","",IFERROR(INDEX(Projections!$AB$2:$AB$282,MATCH(INDEX(Calc!$A$2:$A$157,$V22)&"|K12",Projections!$Y$2:$Y$282,0)),""))} -> 0.2201459 | M22: {=IF($V22="","",IFERROR(INDEX(Projections!$M$2:$M$282,MATCH(INDEX(Calc!$A$2:$A$157,$V22)&"|K12",Projections!$Y$2:$Y$282,0)),""))} | N22: {=IF($V22="","",IFERROR(INDEX(Projections!$P$2:$P$282,MATCH(INDEX(Calc!$A$2:$A$157,$V22)&"|K12",Projections!$Y$2:$Y$282,0)),""))} -> 0.4 | O22: {=IF($V22="","",INDEX(Calc!$AP$2:$AP$157,$V22))} -> 0.34538808 | P22: {=IF($V22="","",INDEX(Calc!$AN$2:$AN$157,$V22))} -> 8.9128837 | Q22: {=IF($V22="","",IFERROR(INDEX(Projections!$F$2:$F$282,MATCH(INDEX(Calc!$A$2:$A$157,$V22)&"|H12",Projections!$Y$2:$Y$282,0)),""))} -> 11.5 | R22: {=IF($V22="","",IFERROR(INDEX(Projections!$I$2:$I$282,MATCH(INDEX(Calc!$A$2:$A$157,$V22)&"|H12",Projections!$Y$2:$Y$282,0)),""))} -> 0.20831532 | S22: {=IF($V22="","",INDEX(Calc!$N$2:$N$157,$V22))} -> 29 | T22: {=IF($V22="","",INDEX(Calc!$AQ$2:$AQ$157,$V22))} | V22: =IFERROR(MATCH(8,Calc!$AR$2:$AR$157,0),"") -> 52
A23: {=IF($V23="","",INDEX(Calc!$D$2:$D$157,$V23))} -> BCA | B23: {=IF($V23="","",INDEX(Calc!$E$2:$E$157,$V23))} -> Demho | C23: {=IF($V23="","",INDEX(Calc!$T$2:$T$157,$V23))} -> 0.57818182 | D23: {=IF($V23="","",INDEX(Calc!$AA$2:$AA$157,$V23))} -> 0.61846154 | E23: {=IF($V23="","",INDEX(Calc!$V$2:$V$157,$V23))} -> 12.384655 | F23: {=IF($V23="","",INDEX(Calc!$AC$2:$AC$157,$V23))} -> 13.179415 | G23: {=IF($V23="","",INDEX(Calc!$AL$2:$AL$157,$V23))} -> 25.56407 | H23: {=IF($V23="","",INDEX(Calc!$BK$2:$BK$157,$V23))} -> 0.98042027 | I23: {=IF($V23="","",INDEX(Calc!$BD$2:$BD$157,$V23))} -> 25.063532 | J23: {=IF($V23="","",IFERROR(INDEX(Projections!$F$2:$F$282,MATCH(INDEX(Calc!$A$2:$A$157,$V23)&"|K12",Projections!$Y$2:$Y$282,0)),""))} -> 25.5 | K23: {=IF($V23="","",IFERROR(INDEX(Projections!$I$2:$I$282,MATCH(INDEX(Calc!$A$2:$A$157,$V23)&"|K12",Projections!$Y$2:$Y$282,0)),""))} -> 0.50427245 | L23: {=IF($V23="","",IFERROR(INDEX(Projections!$AB$2:$AB$282,MATCH(INDEX(Calc!$A$2:$A$157,$V23)&"|K12",Projections!$Y$2:$Y$282,0)),""))} -> 0.47063134 | M23: {=IF($V23="","",IFERROR(INDEX(Projections!$M$2:$M$282,MATCH(INDEX(Calc!$A$2:$A$157,$V23)&"|K12",Projections!$Y$2:$Y$282,0)),""))} | N23: {=IF($V23="","",IFERROR(INDEX(Projections!$P$2:$P$282,MATCH(INDEX(Calc!$A$2:$A$157,$V23)&"|K12",Projections!$Y$2:$Y$282,0)),""))} -> 0.6 | O23: {=IF($V23="","",INDEX(Calc!$AP$2:$AP$157,$V23))} -> 0.42125788 | P23: {=IF($V23="","",INDEX(Calc!$AN$2:$AN$157,$V23))} -> 10.769066 | Q23: {=IF($V23="","",IFERROR(INDEX(Projections!$F$2:$F$282,MATCH(INDEX(Calc!$A$2:$A$157,$V23)&"|H12",Projections!$Y$2:$Y$282,0)),""))} -> 11.5 | R23: {=IF($V23="","",IFERROR(INDEX(Projections!$I$2:$I$282,MATCH(INDEX(Calc!$A$2:$A$157,$V23)&"|H12",Projections!$Y$2:$Y$282,0)),""))} -> 0.41837562 | S23: {=IF($V23="","",INDEX(Calc!$N$2:$N$157,$V23))} -> 34 | T23: {=IF($V23="","",INDEX(Calc!$AQ$2:$AQ$157,$V23))} | V23: =IFERROR(MATCH(9,Calc!$AR$2:$AR$157,0),"") -> 44
A24: {=IF($V24="","",INDEX(Calc!$D$2:$D$157,$V24))} -> EF | B24: {=IF($V24="","",INDEX(Calc!$E$2:$E$157,$V24))} -> MisteM | C24: {=IF($V24="","",INDEX(Calc!$T$2:$T$157,$V24))} -> 0.57 | D24: {=IF($V24="","",INDEX(Calc!$AA$2:$AA$157,$V24))} -> 0.54363636 | E24: {=IF($V24="","",INDEX(Calc!$V$2:$V$157,$V24))} -> 12.2094 | F24: {=IF($V24="","",INDEX(Calc!$AC$2:$AC$157,$V24))} -> 11.584891 | G24: {=IF($V24="","",INDEX(Calc!$AL$2:$AL$157,$V24))} -> 23.794291 | H24: {=IF($V24="","",INDEX(Calc!$BK$2:$BK$157,$V24))} -> 0.96628966 | I24: {=IF($V24="","",INDEX(Calc!$BD$2:$BD$157,$V24))} -> 22.992177 | J24: {=IF($V24="","",IFERROR(INDEX(Projections!$F$2:$F$282,MATCH(INDEX(Calc!$A$2:$A$157,$V24)&"|K12",Projections!$Y$2:$Y$282,0)),""))} -> 25.5 | K24: {=IF($V24="","",IFERROR(INDEX(Projections!$I$2:$I$282,MATCH(INDEX(Calc!$A$2:$A$157,$V24)&"|K12",Projections!$Y$2:$Y$282,0)),""))} -> 0.38379374 | L24: {=IF($V24="","",IFERROR(INDEX(Projections!$AB$2:$AB$282,MATCH(INDEX(Calc!$A$2:$A$157,$V24)&"|K12",Projections!$Y$2:$Y$282,0)),""))} -> 0.32923706 | M24: {=IF($V24="","",IFERROR(INDEX(Projections!$M$2:$M$282,MATCH(INDEX(Calc!$A$2:$A$157,$V24)&"|K12",Projections!$Y$2:$Y$282,0)),""))} | N24: {=IF($V24="","",IFERROR(INDEX(Projections!$P$2:$P$282,MATCH(INDEX(Calc!$A$2:$A$157,$V24)&"|K12",Projections!$Y$2:$Y$282,0)),""))} -> 0.6 | O24: {=IF($V24="","",INDEX(Calc!$AP$2:$AP$157,$V24))} -> 0.55145985 | P24: {=IF($V24="","",INDEX(Calc!$AN$2:$AN$157,$V24))} -> 13.121596 | Q24: {=IF($V24="","",IFERROR(INDEX(Projections!$F$2:$F$282,MATCH(INDEX(Calc!$A$2:$A$157,$V24)&"|H12",Projections!$Y$2:$Y$282,0)),""))} -> 13.5 | R24: {=IF($V24="","",IFERROR(INDEX(Projections!$I$2:$I$282,MATCH(INDEX(Calc!$A$2:$A$157,$V24)&"|H12",Projections!$Y$2:$Y$282,0)),""))} -> 0.46233468 | S24: {=IF($V24="","",INDEX(Calc!$N$2:$N$157,$V24))} -> 29 | T24: {=IF($V24="","",INDEX(Calc!$AQ$2:$AQ$157,$V24))} | V24: =IFERROR(MATCH(10,Calc!$AR$2:$AR$157,0),"") -> 51
A25: {=IF($V25="","",INDEX(Calc!$D$2:$D$157,$V25))} | B25: {=IF($V25="","",INDEX(Calc!$E$2:$E$157,$V25))} | C25: {=IF($V25="","",INDEX(Calc!$T$2:$T$157,$V25))} | D25: {=IF($V25="","",INDEX(Calc!$AA$2:$AA$157,$V25))} | E25: {=IF($V25="","",INDEX(Calc!$V$2:$V$157,$V25))} | F25: {=IF($V25="","",INDEX(Calc!$AC$2:$AC$157,$V25))} | G25: {=IF($V25="","",INDEX(Calc!$AL$2:$AL$157,$V25))} | H25: {=IF($V25="","",INDEX(Calc!$BK$2:$BK$157,$V25))} | I25: {=IF($V25="","",INDEX(Calc!$BD$2:$BD$157,$V25))} | J25: {=IF($V25="","",IFERROR(INDEX(Projections!$F$2:$F$282,MATCH(INDEX(Calc!$A$2:$A$157,$V25)&"|K12",Projections!$Y$2:$Y$282,0)),""))} | K25: {=IF($V25="","",IFERROR(INDEX(Projections!$I$2:$I$282,MATCH(INDEX(Calc!$A$2:$A$157,$V25)&"|K12",Projections!$Y$2:$Y$282,0)),""))} | L25: {=IF($V25="","",IFERROR(INDEX(Projections!$AB$2:$AB$282,MATCH(INDEX(Calc!$A$2:$A$157,$V25)&"|K12",Projections!$Y$2:$Y$282,0)),""))} | M25: {=IF($V25="","",IFERROR(INDEX(Projections!$M$2:$M$282,MATCH(INDEX(Calc!$A$2:$A$157,$V25)&"|K12",Projections!$Y$2:$Y$282,0)),""))} | N25: {=IF($V25="","",IFERROR(INDEX(Projections!$P$2:$P$282,MATCH(INDEX(Calc!$A$2:$A$157,$V25)&"|K12",Projections!$Y$2:$Y$282,0)),""))} | O25: {=IF($V25="","",INDEX(Calc!$AP$2:$AP$157,$V25))} | P25: {=IF($V25="","",INDEX(Calc!$AN$2:$AN$157,$V25))} | Q25: {=IF($V25="","",IFERROR(INDEX(Projections!$F$2:$F$282,MATCH(INDEX(Calc!$A$2:$A$157,$V25)&"|H12",Projections!$Y$2:$Y$282,0)),""))} | R25: {=IF($V25="","",IFERROR(INDEX(Projections!$I$2:$I$282,MATCH(INDEX(Calc!$A$2:$A$157,$V25)&"|H12",Projections!$Y$2:$Y$282,0)),""))} | S25: {=IF($V25="","",INDEX(Calc!$N$2:$N$157,$V25))} | T25: {=IF($V25="","",INDEX(Calc!$AQ$2:$AQ$157,$V25))} | V25: =IFERROR(MATCH(11,Calc!$AR$2:$AR$157,0),"")
A26: {=IF($V26="","",INDEX(Calc!$D$2:$D$157,$V26))} | B26: {=IF($V26="","",INDEX(Calc!$E$2:$E$157,$V26))} | C26: {=IF($V26="","",INDEX(Calc!$T$2:$T$157,$V26))} | D26: {=IF($V26="","",INDEX(Calc!$AA$2:$AA$157,$V26))} | E26: {=IF($V26="","",INDEX(Calc!$V$2:$V$157,$V26))} | F26: {=IF($V26="","",INDEX(Calc!$AC$2:$AC$157,$V26))} | G26: {=IF($V26="","",INDEX(Calc!$AL$2:$AL$157,$V26))} | H26: {=IF($V26="","",INDEX(Calc!$BK$2:$BK$157,$V26))} | I26: {=IF($V26="","",INDEX(Calc!$BD$2:$BD$157,$V26))} | J26: {=IF($V26="","",IFERROR(INDEX(Projections!$F$2:$F$282,MATCH(INDEX(Calc!$A$2:$A$157,$V26)&"|K12",Projections!$Y$2:$Y$282,0)),""))} | K26: {=IF($V26="","",IFERROR(INDEX(Projections!$I$2:$I$282,MATCH(INDEX(Calc!$A$2:$A$157,$V26)&"|K12",Projections!$Y$2:$Y$282,0)),""))} | L26: {=IF($V26="","",IFERROR(INDEX(Projections!$AB$2:$AB$282,MATCH(INDEX(Calc!$A$2:$A$157,$V26)&"|K12",Projections!$Y$2:$Y$282,0)),""))} | M26: {=IF($V26="","",IFERROR(INDEX(Projections!$M$2:$M$282,MATCH(INDEX(Calc!$A$2:$A$157,$V26)&"|K12",Projections!$Y$2:$Y$282,0)),""))} | N26: {=IF($V26="","",IFERROR(INDEX(Projections!$P$2:$P$282,MATCH(INDEX(Calc!$A$2:$A$157,$V26)&"|K12",Projections!$Y$2:$Y$282,0)),""))} | O26: {=IF($V26="","",INDEX(Calc!$AP$2:$AP$157,$V26))} | P26: {=IF($V26="","",INDEX(Calc!$AN$2:$AN$157,$V26))} | Q26: {=IF($V26="","",IFERROR(INDEX(Projections!$F$2:$F$282,MATCH(INDEX(Calc!$A$2:$A$157,$V26)&"|H12",Projections!$Y$2:$Y$282,0)),""))} | R26: {=IF($V26="","",IFERROR(INDEX(Projections!$I$2:$I$282,MATCH(INDEX(Calc!$A$2:$A$157,$V26)&"|H12",Projections!$Y$2:$Y$282,0)),""))} | S26: {=IF($V26="","",INDEX(Calc!$N$2:$N$157,$V26))} | T26: {=IF($V26="","",INDEX(Calc!$AQ$2:$AQ$157,$V26))} | V26: =IFERROR(MATCH(12,Calc!$AR$2:$AR$157,0),"")
A28: Kills = Σ over the chosen maps of (per-map KPR, shrunk toward the player's overall KPR by SHRINK_MAPS) × rounds. HS = kills × per-map HS%, shrunk the same way. P(over) is a normal approximation with variance = KILLS_DISPERSION × projection.
A29: Adj = the round-differential layer (CS2): each map's kills × (a·s + b·(1−s)) ÷ (a·s_hist + b·(1−s_hist)), s = the team's expected round share on that map from HLTV conditional margins and Thunderpick map odds, s_hist = its round share over HLTV's 3-month sample. PAPER: neither column has a forward record.

Sheet Matches
A1: Matches — pick the maps and rounds for every match in the shaded columns
A2: Prefilled: maps from PickFinder Map Picks (#1, #2, #3), rounds from Thunderpick "Total Rounds - Map k" (devigged 50% crossing). Overwrite any shaded cell; Calc, Projections and Board follow instantly.
A4: Match | B4: Title | C4: Start (CT) | D4: Bo | E4: Team A | F4: Team B | G4: P(A wins) | H4: P(A 2-0) | I4: P(B 2-0) | J4: P(3 maps) | K4: Map pick #1 | L4: Map pick #2 | M4: Map pick #3 | N4: Picks from | O4: TP rounds M1 | P4: TP rounds M2 | Q4: TP rounds M3 | R4: P(OT) M1 | S4: A margin M1 | T4: A rounds M1 | U4: B rounds M1 | V4: TP markets | W4: Map 1 | X4: Map 2 | Y4: Map 3 | Z4: Rounds M1 | AA4: Rounds M2 | AB4: Rounds M3 | AC4: P(map 3) used | AD4: Tag A | AE4: Tag B | AF4: P(A map 1) | AG4: P(A map 2) | AH4: P(A map 3) | AI4: A hist share | AJ4: B hist share | AK4: HLTV cA M1 | AL4: HLTV cB M1 | AM4: HLTV src M1 | AN4: HLTV rounds M1 | AO4: HLTV A margin M1 | AP4: HLTV A share M1 | AQ4: HLTV cA M2 | AR4: HLTV cB M2 | AS4: HLTV src M2 | AT4: HLTV rounds M2 | AU4: HLTV A margin M2 | AV4: HLTV A share M2 | AW4: HLTV cA M3 | AX4: HLTV cB M3 | AY4: HLTV src M3 | AZ4: HLTV rounds M3 | BA4: HLTV A margin M3 | BB4: HLTV A share M3
A5: CS2 · EF vs BCA | B5: CS2 | C5: Fri 03:00 | D5: 3 | E5: Eternal Fire (EF) | F5: Apogee Esports (BCA) | G5: 0.64197531 | H5: 0.34126772 | I5: 0.17063386 | J5: 0.48809842 | K5: Ancient 29% | L5: Anubis 24% | M5: Cache 22% | N5: PF Map Picks | O5: 21.423154 | P5: 21.312553 | Q5: 21.378165 | R5: 0.15942029 | S5: 1.7003949 | U5: 11.5 | V5: 225 | W5: Ancient | X5: Anubis | Y5: Cache | Z5: 21.42 | AA5: 21.31 | AB5: 21.38 | AC5: 0.4881 | AD5: EF | AE5: BCA | AF5: 0.56 | AG5: 0.6281 | AH5: 0.6072 | AI5: {=IFERROR(INDEX(HLTV_Teams!$N$2:$N$33,MATCH($A5&"|A",HLTV_Teams!$A$2:$A$33,0)),"")} -> 0.53109601 | AJ5: {=IFERROR(INDEX(HLTV_Teams!$N$2:$N$33,MATCH($A5&"|B",HLTV_Teams!$A$2:$A$33,0)),"")} -> 0.53121911 | AK5: =IF($W5="","",IFERROR((SUMIFS(HLTV_Long!$B$2:$B$451,HLTV_Long!$A$2:$A$451,$A5&"|A|"&$W5&"|lw")+SUMIFS(HLTV_Long!$B$2:$B$451,HLTV_Long!$A$2:$A$451,$A5&"|B|"&$W5&"|wl"))/(COUNTIFS(HLTV_Long!$A$2:$A$451,$A5&"|A|"&$W5&"|lw")+COUNTIFS(HLTV_Long!$A$2:$A$451,$A5&"|B|"&$W5&"|wl")),IFERROR((SUMIFS(HLTV_Long!$B$2:$B$451,HLTV_Long!$A$2:$A$451,$A5&"|A|"&"ALL"&"|lw")+SUMIFS(HLTV_Long!$B$2:$B$451,HLTV_Long!$A$2:$A$451,$A5&"|B|"&"ALL"&"|wl"))/(COUNTIFS(HLTV_Long!$A$2:$A$451,$A5&"|A|"&"ALL"&"|lw")+COUNTIFS(HLTV_Long!$A$2:$A$451,$A5&"|B|"&"ALL"&"|wl")),""))) -> 8.415 | AL5: =IF($W5="","",IFERROR((SUMIFS(HLTV_Long!$B$2:$B$451,HLTV_Long!$A$2:$A$451,$A5&"|B|"&$W5&"|lw")+SUMIFS(HLTV_Long!$B$2:$B$451,HLTV_Long!$A$2:$A$451,$A5&"|A|"&$W5&"|wl"))/(COUNTIFS(HLTV_Long!$A$2:$A$451,$A5&"|B|"&$W5&"|lw")+COUNTIFS(HLTV_Long!$A$2:$A$451,$A5&"|A|"&$W5&"|wl")),IFERROR((SUMIFS(HLTV_Long!$B$2:$B$451,HLTV_Long!$A$2:$A$451,$A5&"|B|"&"ALL"&"|lw")+SUMIFS(HLTV_Long!$B$2:$B$451,HLTV_Long!$A$2:$A$451,$A5&"|A|"&"ALL"&"|wl"))/(COUNTIFS(HLTV_Long!$A$2:$A$451,$A5&"|B|"&"ALL"&"|lw")+COUNTIFS(HLTV_Long!$A$2:$A$451,$A5&"|A|"&"ALL"&"|wl")),""))) -> 8.1 | AM5: =IF($W5="","",COUNTIFS(HLTV_Long!$A$2:$A$451,$A5&"|A|"&$W5&"|lw")+COUNTIFS(HLTV_Long!$A$2:$A$451,$A5&"|B|"&$W5&"|wl")+COUNTIFS(HLTV_Long!$A$2:$A$451,$A5&"|B|"&$W5&"|lw")+COUNTIFS(HLTV_Long!$A$2:$A$451,$A5&"|A|"&$W5&"|wl")) -> 4 | AN5: =IF(OR($AK5="",$AL5="",$AF5=""),"",13+$AF5*$AK5+(1-$AF5)*$AL5) -> 21.2764 | AO5: =IF($AN5="","",$AF5*(13-$AK5)-(1-$AF5)*(13-$AL5)) -> 0.4116 | AP5: =IF($AN5="","",($AF5*13+(1-$AF5)*$AL5)/$AN5) -> 0.50967269 | AQ5: =IF($X5="","",IFERROR((SUMIFS(HLTV_Long!$B$2:$B$451,HLTV_Long!$A$2:$A$451,$A5&"|A|"&$X5&"|lw")+SUMIFS(HLTV_Long!$B$2:$B$451,HLTV_Long!$A$2:$A$451,$A5&"|B|"&$X5&"|wl"))/(COUNTIFS(HLTV_Long!$A$2:$A$451,$A5&"|A|"&$X5&"|lw")+COUNTIFS(HLTV_Long!$A$2:$A$451,$A5&"|B|"&$X5&"|wl")),IFERROR((SUMIFS(HLTV_Long!$B$2:$B$451,HLTV_Long!$A$2:$A$451,$A5&"|A|"&"ALL"&"|lw")+SUMIFS(HLTV_Long!$B$2:$B$451,HLTV_Long!$A$2:$A$451,$A5&"|B|"&"ALL"&"|wl"))/(COUNTIFS(HLTV_Long!$A$2:$A$451,$A5&"|A|"&"ALL"&"|lw")+COUNTIFS(HLTV_Long!$A$2:$A$451,$A5&"|B|"&"ALL"&"|wl")),""))) -> 11.785 | AR5: =IF($X5="","",IFERROR((SUMIFS(HLTV_Long!$B$2:$B$451,HLTV_Long!$A$2:$A$451,$A5&"|B|"&$X5&"|lw")+SUMIFS(HLTV_Long!$B$2:$B$451,HLTV_Long!$A$2:$A$451,$A5&"|A|"&$X5&"|wl"))/(COUNTIFS(HLTV_Long!$A$2:$A$451,$A5&"|B|"&$X5&"|lw")+COUNTIFS(HLTV_Long!$A$2:$A$451,$A5&"|A|"&$X5&"|wl")),IFERROR((SUMIFS(HLTV_Long!$B$2:$B$451,HLTV_Long!$A$2:$A$451,$A5&"|B|"&"ALL"&"|lw")+SUMIFS(HLTV_Long!$B$2:$B$451,HLTV_Long!$A$2:$A$451,$A5&"|A|"&"ALL"&"|wl"))/(COUNTIFS(HLTV_Long!$A$2:$A$451,$A5&"|B|"&"ALL"&"|lw")+COUNTIFS(HLTV_Long!$A$2:$A$451,$A5&"|A|"&"ALL"&"|wl")),""))) -> 7.7 | AS5: =IF($X5="","",COUNTIFS(HLTV_Long!$A$2:$A$451,$A5&"|A|"&$X5&"|lw")+COUNTIFS(HLTV_Long!$A$2:$A$451,$A5&"|B|"&$X5&"|wl")+COUNTIFS(HLTV_Long!$A$2:$A$451,$A5&"|B|"&$X5&"|lw")+COUNTIFS(HLTV_Long!$A$2:$A$451,$A5&"|A|"&$X5&"|wl")) -> 4 | AT5: =IF(OR($AQ5="",$AR5="",$AG5=""),"",13+$AG5*$AQ5+(1-$AG5)*$AR5) -> 23.265788 | AU5: =IF($AT5="","",$AG5*(13-$AQ5)-(1-$AG5)*(13-$AR5)) -> -1.2079285 | AV5: =IF($AT5="","",($AG5*13+(1-$AG5)*$AR5)/$AT5) -> 0.47404067 | AW5: =IF($Y5="","",IFERROR((SUMIFS(HLTV_Long!$B$2:$B$451,HLTV_Long!$A$2:$A$451,$A5&"|A|"&$Y5&"|lw")+SUMIFS(HLTV_Long!$B$2:$B$451,HLTV_Long!$A$2:$A$451,$A5&"|B|"&$Y5&"|wl"))/(COUNTIFS(HLTV_Long!$A$2:$A$451,$A5&"|A|"&$Y5&"|lw")+COUNTIFS(HLTV_Long!$A$2:$A$451,$A5&"|B|"&$Y5&"|wl")),IFERROR((SUMIFS(HLTV_Long!$B$2:$B$451,HLTV_Long!$A$2:$A$451,$A5&"|A|"&"ALL"&"|lw")+SUMIFS(HLTV_Long!$B$2:$B$451,HLTV_Long!$A$2:$A$451,$A5&"|B|"&"ALL"&"|wl"))/(COUNTIFS(HLTV_Long!$A$2:$A$451,$A5&"|A|"&"ALL"&"|lw")+COUNTIFS(HLTV_Long!$A$2:$A$451,$A5&"|B|"&"ALL"&"|wl")),""))) -> 8.475 | AX5: =IF($Y5="","",IFERROR((SUMIFS(HLTV_Long!$B$2:$B$451,HLTV_Long!$A$2:$A$451,$A5&"|B|"&$Y5&"|lw")+SUMIFS(HLTV_Long!$B$2:$B$451,HLTV_Long!$A$2:$A$451,$A5&"|A|"&$Y5&"|wl"))/(COUNTIFS(HLTV_Long!$A$2:$A$451,$A5&"|B|"&$Y5&"|lw")+COUNTIFS(HLTV_Long!$A$2:$A$451,$A5&"|A|"&$Y5&"|wl")),IFERROR((SUMIFS(HLTV_Long!$B$2:$B$451,HLTV_Long!$A$2:$A$451,$A5&"|B|"&"ALL"&"|lw")+SUMIFS(HLTV_Long!$B$2:$B$451,HLTV_Long!$A$2:$A$451,$A5&"|A|"&"ALL"&"|wl"))/(COUNTIFS(HLTV_Long!$A$2:$A$451,$A5&"|B|"&"ALL"&"|lw")+COUNTIFS(HLTV_Long!$A$2:$A$451,$A5&"|A|"&"ALL"&"|wl")),""))) -> 9.05 | AY5: =IF($Y5="","",COUNTIFS(HLTV_Long!$A$2:$A$451,$A5&"|A|"&$Y5&"|lw")+COUNTIFS(HLTV_Long!$A$2:$A$451,$A5&"|B|"&$Y5&"|wl")+COUNTIFS(HLTV_Long!$A$2:$A$451,$A5&"|B|"&$Y5&"|lw")+COUNTIFS(HLTV_Long!$A$2:$A$451,$A5&"|A|"&$Y5&"|wl")) -> 4 | AZ5: =IF(OR($AW5="",$AX5="",$AH5=""),"",13+$AH5*$AW5+(1-$AH5)*$AX5) -> 21.70086 | BA5: =IF($AZ5="","",$AH5*(13-$AW5)-(1-$AH5)*(13-$AX5)) -> 1.19602 | BB5: =IF($AZ5="","",($AH5*13+(1-$AH5)*$AX5)/$AZ5) -> 0.52755697
A6: CS2 · NIP vs TL | B6: CS2 | C6: Fri 03:00 | D6: 3 | E6: Ninjas in Pyjamas (NIP) | F6: Liquid (TL) | G6: 0.51891892 | H6: 0.27270634 | I6: 0.22247096 | J6: 0.5048227 | K6: Cache 36% | L6: Mirage 19% | M6: Nuke 14% | N6: PF Map Picks | O6: 21.5 | P6: 21.5 | Q6: 21.5 | R6: 0.15942029 | S6: 1.6291028 | U6: 11.5 | V6: 228 | W6: Cache | X6: Mirage | Y6: Nuke | Z6: 21.5 | AA6: 21.5 | AB6: 21.5 | AC6: 0.5048 | AD6: NIP | AE6: TL | AF6: 0.56 | AG6: 0.4865 | AH6: 0.5081 | AI6: {=IFERROR(INDEX(HLTV_Teams!$N$2:$N$33,MATCH($A6&"|A",HLTV_Teams!$A$2:$A$33,0)),"")} -> 0.52544584 | AJ6: {=IFERROR(INDEX(HLTV_Teams!$N$2:$N$33,MATCH($A6&"|B",HLTV_Teams!$A$2:$A$33,0)),"")} -> 0.55928537 | AK6: =IF($W6="","",IFERROR((SUMIFS(HLTV_Long!$B$2:$B$451,HLTV_Long!$A$2:$A$451,$A6&"|A|"&$W6&"|lw")+SUMIFS(HLTV_Long!$B$2:$B$451,HLTV_Long!$A$2:$A$451,$A6&"|B|"&$W6&"|wl"))/(COUNTIFS(HLTV_Long!$A$2:$A$451,$A6&"|A|"&$W6&"|lw")+COUNTIFS(HLTV_Long!$A$2:$A$451,$A6&"|B|"&$W6&"|wl")),IFERROR((SUMIFS(HLTV_Long!$B$2:$B$451,HLTV_Long!$A$2:$A$451,$A6&"|A|"&"ALL"&"|lw")+SUMIFS(HLTV_Long!$B$2:$B$451,HLTV_Long!$A$2:$A$451,$A6&"|B|"&"ALL"&"|wl"))/(COUNTIFS(HLTV_Long!$A$2:$A$451,$A6&"|A|"&"ALL"&"|lw")+COUNTIFS(HLTV_Long!$A$2:$A$451,$A6&"|B|"&"ALL"&"|wl")),""))) -> 8.5 | AL6: =IF($W6="","",IFERROR((SUMIFS(HLTV_Long!$B$2:$B$451,HLTV_Long!$A$2:$A$451,$A6&"|B|"&$W6&"|lw")+SUMIFS(HLTV_Long!$B$2:$B$451,HLTV_Long!$A$2:$A$451,$A6&"|A|"&$W6&"|wl"))/(COUNTIFS(HLTV_Long!$A$2:$A$451,$A6&"|B|"&$W6&"|lw")+COUNTIFS(HLTV_Long!$A$2:$A$451,$A6&"|A|"&$W6&"|wl")),IFERROR((SUMIFS(HLTV_Long!$B$2:$B$451,HLTV_Long!$A$2:$A$451,$A6&"|B|"&"ALL"&"|lw")+SUMIFS(HLTV_Long!$B$2:$B$451,HLTV_Long!$A$2:$A$451,$A6&"|A|"&"ALL"&"|wl"))/(COUNTIFS(HLTV_Long!$A$2:$A$451,$A6&"|B|"&"ALL"&"|lw")+COUNTIFS(HLTV_Long!$A$2:$A$451,$A6&"|A|"&"ALL"&"|wl")),""))) -> 8.57 | AM6: =IF($W6="","",COUNTIFS(HLTV_Long!$A$2:$A$451,$A6&"|A|"&$W6&"|lw")+COUNTIFS(HLTV_Long!$A$2:$A$451,$A6&"|B|"&$W6&"|wl")+COUNTIFS(HLTV_Long!$A$2:$A$451,$A6&"|B|"&$W6&"|lw")+COUNTIFS(HLTV_Long!$A$2:$A$451,$A6&"|A|"&$W6&"|wl")) -> 4 | AN6: =IF(OR($AK6="",$AL6="",$AF6=""),"",13+$AF6*$AK6+(1-$AF6)*$AL6) -> 21.5308 | AO6: =IF($AN6="","",$AF6*(13-$AK6)-(1-$AF6)*(13-$AL6)) -> 0.5708 | AP6: =IF($AN6="","",($AF6*13+(1-$AF6)*$AL6)/$AN6) -> 0.51325543 | AQ6: =IF($X6="","",IFERROR((SUMIFS(HLTV_Long!$B$2:$B$451,HLTV_Long!$A$2:$A$451,$A6&"|A|"&$X6&"|lw")+SUMIFS(HLTV_Long!$B$2:$B$451,HLTV_Long!$A$2:$A$451,$A6&"|B|"&$X6&"|wl"))/(COUNTIFS(HLTV_Long!$A$2:$A$451,$A6&"|A|"&$X6&"|lw")+COUNTIFS(HLTV_Long!$A$2:$A$451,$A6&"|B|"&$X6&"|wl")),IFERROR((SUMIFS(HLTV_Long!$B$2:$B$451,HLTV_Long!$A$2:$A$451,$A6&"|A|"&"ALL"&"|lw")+SUMIFS(HLTV_Long!$B$2:$B$451,HLTV_Long!$A$2:$A$451,$A6&"|B|"&"ALL"&"|wl"))/(COUNTIFS(HLTV_Long!$A$2:$A$451,$A6&"|A|"&"ALL"&"|lw")+COUNTIFS(HLTV_Long!$A$2:$A$451,$A6&"|B|"&"ALL"&"|wl")),""))) -> 8.5 | AR6: =IF($X6="","",IFERROR((SUMIFS(HLTV_Long!$B$2:$B$451,HLTV_Long!$A$2:$A$451,$A6&"|B|"&$X6&"|lw")+SUMIFS(HLTV_Long!$B$2:$B$451,HLTV_Long!$A$2:$A$451,$A6&"|A|"&$X6&"|wl"))/(COUNTIFS(HLTV_Long!$A$2:$A$451,$A6&"|B|"&$X6&"|lw")+COUNTIFS(HLTV_Long!$A$2:$A$451,$A6&"|A|"&$X6&"|wl")),IFERROR((SUMIFS(HLTV_Long!$B$2:$B$451,HLTV_Long!$A$2:$A$451,$A6&"|B|"&"ALL"&"|lw")+SUMIFS(HLTV_Long!$B$2:$B$451,HLTV_Long!$A$2:$A$451,$A6&"|A|"&"ALL"&"|wl"))/(COUNTIFS(HLTV_Long!$A$2:$A$451,$A6&"|B|"&"ALL"&"|lw")+COUNTIFS(HLTV_Long!$A$2:$A$451,$A6&"|A|"&"ALL"&"|wl")),""))) -> 8.87 | AS6: =IF($X6="","",COUNTIFS(HLTV_Long!$A$2:$A$451,$A6&"|A|"&$X6&"|lw")+COUNTIFS(HLTV_Long!$A$2:$A$451,$A6&"|B|"&$X6&"|wl")+COUNTIFS(HLTV_Long!$A$2:$A$451,$A6&"|B|"&$X6&"|lw")+COUNTIFS(HLTV_Long!$A$2:$A$451,$A6&"|A|"&$X6&"|wl")) -> 4 | AT6: =IF(OR($AQ6="",$AR6="",$AG6=""),"",13+$AG6*$AQ6+(1-$AG6)*$AR6) -> 21.689995 | AU6: =IF($AT6="","",$AG6*(13-$AQ6)-(1-$AG6)*(13-$AR6)) -> 0.068495 | AV6: =IF($AT6="","",($AG6*13+(1-$AG6)*$AR6)/$AT6) -> 0.50157895 | AW6: =IF($Y6="","",IFERROR((SUMIFS(HLTV_Long!$B$2:$B$451,HLTV_Long!$A$2:$A$451,$A6&"|A|"&$Y6&"|lw")+SUMIFS(HLTV_Long!$B$2:$B$451,HLTV_Long!$A$2:$A$451,$A6&"|B|"&$Y6&"|wl"))/(COUNTIFS(HLTV_Long!$A$2:$A$451,$A6&"|A|"&$Y6&"|lw")+COUNTIFS(HLTV_Long!$A$2:$A$451,$A6&"|B|"&$Y6&"|wl")),IFERROR((SUMIFS(HLTV_Long!$B$2:$B$451,HLTV_Long!$A$2:$A$451,$A6&"|A|"&"ALL"&"|lw")+SUMIFS(HLTV_Long!$B$2:$B$451,HLTV_Long!$A$2:$A$451,$A6&"|B|"&"ALL"&"|wl"))/(COUNTIFS(HLTV_Long!$A$2:$A$451,$A6&"|A|"&"ALL"&"|lw")+COUNTIFS(HLTV_Long!$A$2:$A$451,$A6&"|B|"&"ALL"&"|wl")),""))) -> 8.52 | AX6: =IF($Y6="","",IFERROR((SUMIFS(HLTV_Long!$B$2:$B$451,HLTV_Long!$A$2:$A$451,$A6&"|B|"&$Y6&"|lw")+SUMIFS(HLTV_Long!$B$2:$B$451,HLTV_Long!$A$2:$A$451,$A6&"|A|"&$Y6&"|wl"))/(COUNTIFS(HLTV_Long!$A$2:$A$451,$A6&"|B|"&$Y6&"|lw")+COUNTIFS(HLTV_Long!$A$2:$A$451,$A6&"|A|"&$Y6&"|wl")),IFERROR((SUMIFS(HLTV_Long!$B$2:$B$451,HLTV_Long!$A$2:$A$451,$A6&"|B|"&"ALL"&"|lw")+SUMIFS(HLTV_Long!$B$2:$B$451,HLTV_Long!$A$2:$A$451,$A6&"|A|"&"ALL"&"|wl"))/(COUNTIFS(HLTV_Long!$A$2:$A$451,$A6&"|B|"&"ALL"&"|lw")+COUNTIFS(HLTV_Long!$A$2:$A$451,$A6&"|A|"&"ALL"&"|wl")),""))) -> 5.585 | AY6: =IF($Y6="","",COUNTIFS(HLTV_Long!$A$2:$A$451,$A6&"|A|"&$Y6&"|lw")+COUNTIFS(HLTV_Long!$A$2:$A$451,$A6&"|B|"&$Y6&"|wl")+COUNTIFS(HLTV_Long!$A$2:$A$451,$A6&"|B|"&$Y6&"|lw")+COUNTIFS(HLTV_Long!$A$2:$A$451,$A6&"|A|"&$Y6&"|wl")) -> 4 | AZ6: =IF(OR($AW6="",$AX6="",$AH6=""),"",13+$AH6*$AW6+(1-$AH6)*$AX6) -> 20.076273 | BA6: =IF($AZ6="","",$AH6*(13-$AW6)-(1-$AH6)*(13-$AX6)) -> -1.3711505 | BB6: =IF($AZ6="","",($AH6*13+(1-$AH6)*$AX6)/$AZ6) -> 0.46585147
A7: CS2 · VOCA vs PHA | B7: CS2 | C7: Fri 03:00 | D7: 1 | E7: Voca (VOCA) | F7: Phantom Esports (PHA) | G7: 0.45040214 | J7: 0 | K7: Ancient 52% | L7: Nuke 15% | M7: Mirage 8% | N7: PF Map Picks | O7: 21.5 | R7: 0.15942029 | S7: -1.3648957 | T7: 12.5 | V7: 70 | W7: Ancient | X7: Nuke | Z7: 21.5 | AA7: =Config!$B$7 -> 21.5 | AC7: 0 | AD7: VOCA | AE7: PHA | AF7: 0.4504 | AG7: 0.4504 | AH7: 0.4504 | AI7: {=IFERROR(INDEX(HLTV_Teams!$N$2:$N$33,MATCH($A7&"|A",HLTV_Teams!$A$2:$A$33,0)),"")} -> 0.54643399 | AJ7: {=IFERROR(INDEX(HLTV_Teams!$N$2:$N$33,MATCH($A7&"|B",HLTV_Teams!$A$2:$A$33,0)),"")} -> 0.48628402 | AK7: =IF($W7="","",IFERROR((SUMIFS(HLTV_Long!$B$2:$B$451,HLTV_Long!$A$2:$A$451,$A7&"|A|"&$W7&"|lw")+SUMIFS(HLTV_Long!$B$2:$B$451,HLTV_Long!$A$2:$A$451,$A7&"|B|"&$W7&"|wl"))/(COUNTIFS(HLTV_Long!$A$2:$A$451,$A7&"|A|"&$W7&"|lw")+COUNTIFS(HLTV_Long!$A$2:$A$451,$A7&"|B|"&$W7&"|wl")),IFERROR((SUMIFS(HLTV_Long!$B$2:$B$451,HLTV_Long!$A$2:$A$451,$A7&"|A|"&"ALL"&"|lw")+SUMIFS(HLTV_Long!$B$2:$B$451,HLTV_Long!$A$2:$A$451,$A7&"|B|"&"ALL"&"|wl"))/(COUNTIFS(HLTV_Long!$A$2:$A$451,$A7&"|A|"&"ALL"&"|lw")+COUNTIFS(HLTV_Long!$A$2:$A$451,$A7&"|B|"&"ALL"&"|wl")),""))) -> 7.145 | AL7: =IF($W7="","",IFERROR((SUMIFS(HLTV_Long!$B$2:$B$451,HLTV_Long!$A$2:$A$451,$A7&"|B|"&$W7&"|lw")+SUMIFS(HLTV_Long!$B$2:$B$451,HLTV_Long!$A$2:$A$451,$A7&"|A|"&$W7&"|wl"))/(COUNTIFS(HLTV_Long!$A$2:$A$451,$A7&"|B|"&$W7&"|lw")+COUNTIFS(HLTV_Long!$A$2:$A$451,$A7&"|A|"&$W7&"|wl")),IFERROR((SUMIFS(HLTV_Long!$B$2:$B$451,HLTV_Long!$A$2:$A$451,$A7&"|B|"&"ALL"&"|lw")+SUMIFS(HLTV_Long!$B$2:$B$451,HLTV_Long!$A$2:$A$451,$A7&"|A|"&"ALL"&"|wl"))/(COUNTIFS(HLTV_Long!$A$2:$A$451,$A7&"|B|"&"ALL"&"|lw")+COUNTIFS(HLTV_Long!$A$2:$A$451,$A7&"|A|"&"ALL"&"|wl")),""))) -> 8.07 | AM7: =IF($W7="","",COUNTIFS(HLTV_Long!$A$2:$A$451,$A7&"|A|"&$W7&"|lw")+COUNTIFS(HLTV_Long!$A$2:$A$451,$A7&"|B|"&$W7&"|wl")+COUNTIFS(HLTV_Long!$A$2:$A$451,$A7&"|B|"&$W7&"|lw")+COUNTIFS(HLTV_Long!$A$2:$A$451,$A7&"|A|"&$W7&"|wl")) -> 4 | AN7: =IF(OR($AK7="",$AL7="",$AF7=""),"",13+$AF7*$AK7+(1-$AF7)*$AL7) -> 20.65338 | AO7: =IF($AN7="","",$AF7*(13-$AK7)-(1-$AF7)*(13-$AL7)) -> -0.072436 | AP7: =IF($AN7="","",($AF7*13+(1-$AF7)*$AL7)/$AN7) -> 0.49824639 | AQ7: =IF($X7="","",IFERROR((SUMIFS(HLTV_Long!$B$2:$B$451,HLTV_Long!$A$2:$A$451,$A7&"|A|"&$X7&"|lw")+SUMIFS(HLTV_Long!$B$2:$B$451,HLTV_Long!$A$2:$A$451,$A7&"|B|"&$X7&"|wl"))/(COUNTIFS(HLTV_Long!$A$2:$A$451,$A7&"|A|"&$X7&"|lw")+COUNTIFS(HLTV_Long!$A$2:$A$451,$A7&"|B|"&$X7&"|wl")),IFERROR((SUMIFS(HLTV_Long!$B$2:$B$451,HLTV_Long!$A$2:$A$451,$A7&"|A|"&"ALL"&"|lw")+SUMIFS(HLTV_Long!$B$2:$B$451,HLTV_Long!$A$2:$A$451,$A7&"|B|"&"ALL"&"|wl"))/(COUNTIFS(HLTV_Long!$A$2:$A$451,$A7&"|A|"&"ALL"&"|lw")+COUNTIFS(HLTV_Long!$A$2:$A$451,$A7&"|B|"&"ALL"&"|wl")),""))) -> 8.165 | AR7: =IF($X7="","",IFERROR((SUMIFS(HLTV_Long!$B$2:$B$451,HLTV_Long!$A$2:$A$451,$A7&"|B|"&$X7&"|lw")+SUMIFS(HLTV_Long!$B$2:$B$451,HLTV_Long!$A$2:$A$451,$A7&"|A|"&$X7&"|wl"))/(COUNTIFS(HLTV_Long!$A$2:$A$451,$A7&"|B|"&$X7&"|lw")+COUNTIFS(HLTV_Long!$A$2:$A$451,$A7&"|A|"&$X7&"|wl")),IFERROR((SUMIFS(HLTV_Long!$B$2:$B$451,HLTV_Long!$A$2:$A$451,$A7&"|B|"&"ALL"&"|lw")+SUMIFS(HLTV_Long!$B$2:$B$451,HLTV_Long!$A$2:$A$451,$A7&"|A|"&"ALL"&"|wl"))/(COUNTIFS(HLTV_Long!$A$2:$A$451,$A7&"|B|"&"ALL"&"|lw")+COUNTIFS(HLTV_Long!$A$2:$A$451,$A7&"|A|"&"ALL"&"|wl")),""))) -> 9.875 | AS7: =IF($X7="","",COUNTIFS(HLTV_Long!$A$2:$A$451,$A7&"|A|"&$X7&"|lw")+COUNTIFS(HLTV_Long!$A$2:$A$451,$A7&"|B|"&$X7&"|wl")+COUNTIFS(HLTV_Long!$A$2:$A$451,$A7&"|B|"&$X7&"|lw")+COUNTIFS(HLTV_Long!$A$2:$A$451,$A7&"|A|"&$X7&"|wl")) -> 4 | AT7: =IF(OR($AQ7="",$AR7="",$AG7=""),"",13+$AG7*$AQ7+(1-$AG7)*$AR7) -> 22.104816 | AU7: =IF($AT7="","",$AG7*(13-$AQ7)-(1-$AG7)*(13-$AR7)) -> 0.460184 | AV7: =IF($AT7="","",($AG7*13+(1-$AG7)*$AR7)/$AT7) -> 0.51040913 | AW7: =IF($Y7="","",IFERROR((SUMIFS(HLTV_Long!$B$2:$B$451,HLTV_Long!$A$2:$A$451,$A7&"|A|"&$Y7&"|lw")+SUMIFS(HLTV_Long!$B$2:$B$451,HLTV_Long!$A$2:$A$451,$A7&"|B|"&$Y7&"|wl"))/(COUNTIFS(HLTV_Long!$A$2:$A$451,$A7&"|A|"&$Y7&"|lw")+COUNTIFS(HLTV_Long!$A$2:$A$451,$A7&"|B|"&$Y7&"|wl")),IFERROR((SUMIFS(HLTV_Long!$B$2:$B$451,HLTV_Long!$A$2:$A$451,$A7&"|A|"&"ALL"&"|lw")+SUMIFS(HLTV_Long!$B$2:$B$451,HLTV_Long!$A$2:$A$451,$A7&"|B|"&"ALL"&"|wl"))/(COUNTIFS(HLTV_Long!$A$2:$A$451,$A7&"|A|"&"ALL"&"|lw")+COUNTIFS(HLTV_Long!$A$2:$A$451,$A7&"|B|"&"ALL"&"|wl")),""))) | AX7: =IF($Y7="","",IFERROR((SUMIFS(HLTV_Long!$B$2:$B$451,HLTV_Long!$A$2:$A$451,$A7&"|B|"&$Y7&"|lw")+SUMIFS(HLTV_Long!$B$2:$B$451,HLTV_Long!$A$2:$A$451,$A7&"|A|"&$Y7&"|wl"))/(COUNTIFS(HLTV_Long!$A$2:$A$451,$A7&"|B|"&$Y7&"|lw")+COUNTIFS(HLTV_Long!$A$2:$A$451,$A7&"|A|"&$Y7&"|wl")),IFERROR((SUMIFS(HLTV_Long!$B$2:$B$451,HLTV_Long!$A$2:$A$451,$A7&"|B|"&"ALL"&"|lw")+SUMIFS(HLTV_Long!$B$2:$B$451,HLTV_Long!$A$2:$A$451,$A7&"|A|"&"ALL"&"|wl"))/(COUNTIFS(HLTV_Long!$A$2:$A$451,$A7&"|B|"&"ALL"&"|lw")+COUNTIFS(HLTV_Long!$A$2:$A$451,$A7&"|A|"&"ALL"&"|wl")),""))) | AY7: =IF($Y7="","",COUNTIFS(HLTV_Long!$A$2:$A$451,$A7&"|A|"&$Y7&"|lw")+COUNTIFS(HLTV_Long!$A$2:$A$451,$A7&"|B|"&$Y7&"|wl")+COUNTIFS(HLTV_Long!$A$2:$A$451,$A7&"|B|"&$Y7&"|lw")+COUNTIFS(HLTV_Long!$A$2:$A$451,$A7&"|A|"&$Y7&"|wl")) | AZ7: =IF(OR($AW7="",$AX7="",$AH7=""),"",13+$AH7*$AW7+(1-$AH7)*$AX7) | BA7: =IF($AZ7="","",$AH7*(13-$AW7)-(1-$AH7)*(13-$AX7)) | BB7: =IF($AZ7="","",($AH7*13+(1-$AH7)*$AX7)/$AZ7)
