Workbook

Sheet README
A1: MOBA Player Model — LoL + Dota 2
A2: Kills projections built on the one effect the record measured cleanly in LoL: players score about twice as many kills in map wins as in losses (25 of 25 players, median 2.2×).
A3: Slate 2026-10-16 · 18 board legs · 2 matches
A5: HOW TO USE
A6: 1. Matches tab: one row per match. Shaded: P(A wins) for maps 1, 2 and 3, whether maps 2 and 3 get played, and a kill-environment multiplier. They arrive prefilled from Thunderpick (map-winner odds, devigged). Bo5 "Maps 1-3" props always play three maps; Bo1 props are Map 1 only.
A7: 2. Board tab: pick a match in B2. Both rosters, ranked by projected Map 1 kills, with the PrizePicks line, P(over), Thunderpick's own kill-line median and PickFinder's L10.
A8: 3. Projections: every leg. Naive proj = his plain average per map, for comparison. Exact-line landings counts how often his last 15 series finished exactly on a whole-number line — the push check.
A9: 4. Log: the projections frozen as values when the sheet was built. Type Actual after settlement.
A11: THE MODEL
A12: K̄ = his kills per map, q = his map win rate (both from PickFinder Player Stats, same sample). r = WL_RATIO.
A13: k_win = K̄·r ÷ (q·r + 1 − q), k_loss = K̄ ÷ (q·r + 1 − q). These reproduce K̄ exactly at his own win rate.
A14: Map kills = Kills env × (P(win)·k_win + (1 − P(win))·k_loss). Maps 1-3 = sum over maps × P(map played).
... A30: Rebuilt per slate from fresh captures and imported over this file (File → Import → Replace spreadsheet); the link stays the same.

Sheet Board
A1: Board
A2: Match: | B2: LOL · KC vs MVK
A4: Teams | B4: {=IFERROR(IF(INDEX(Matches!$E$5:$E$6,MATCH($B$2,Matches!$A$5:$A$6,0))="","",INDEX(Matches!$E$5:$E$6,MATCH($B$2,Matches!$A$5:$A$6,0))),"")&" vs "&IFERROR(IF(INDEX(Matches!$F$5:$F$6,MATCH($B$2,Matches!$A$5:$A$6,0))="","",INDEX(Matches!$F$5:$F$6,MATCH($B$2,Matches!$A$5:$A$6,0))),"")} -> Karmine Corp (KC) vs MVK Esports (MVK) | D4: Start (CT) | E4: {=IFERROR(IF(INDEX(Matches!$C$5:$C$6,MATCH($B$2,Matches!$A$5:$A$6,0))="","",INDEX(Matches!$C$5:$C$6,MATCH($B$2,Matches!$A$5:$A$6,0))),"")} -> Fri 13:00 | G4: Bo | H4: {=IFERROR(IF(INDEX(Matches!$D$5:$D$6,MATCH($B$2,Matches!$A$5:$A$6,0))="","",INDEX(Matches!$D$5:$D$6,MATCH($B$2,Matches!$A$5:$A$6,0))),"")} -> 5
A5: Event | B5: {=IFERROR(IF(INDEX(Matches!$B$5:$B$6,MATCH($B$2,Matches!$A$5:$A$6,0))="","",INDEX(Matches!$B$5:$B$6,MATCH($B$2,Matches!$A$5:$A$6,0))),"")} -> Worlds 2026 | D5: P(A wins) | E5: {=IFERROR(IF(INDEX(Matches!$G$5:$G$6,MATCH($B$2,Matches!$A$5:$A$6,0))="","",INDEX(Matches!$G$5:$G$6,MATCH($B$2,Matches!$A$5:$A$6,0))),"")} -> 0.75697211 | G5: P(A wins M1) | H5: {=IFERROR(IF(INDEX(Matches!$M$5:$M$6,MATCH($B$2,Matches!$A$5:$A$6,0))="","",INDEX(Matches!$M$5:$M$6,MATCH($B$2,Matches!$A$5:$A$6,0))),"")} -> 0.6699
A6: TP total kills M1 | B6: {=IFERROR(IF(INDEX(Matches!$H$5:$H$6,MATCH($B$2,Matches!$A$5:$A$6,0))="","",INDEX(Matches!$H$5:$H$6,MATCH($B$2,Matches!$A$5:$A$6,0))),"")} | D6: TP A / B kills M1 | E6: {=IF(IFERROR(IF(INDEX(Matches!$I$5:$I$6,MATCH($B$2,Matches!$A$5:$A$6,0))="","",INDEX(Matches!$I$5:$I$6,MATCH($B$2,Matches!$A$5:$A$6,0))),"")="","",TEXT(IFERROR(IF(INDEX(Matches!$I$5:$I$6,MATCH($B$2,Matches!$A$5:$A$6,0))="","",INDEX(Matches!$I$5:$I$6,MATCH($B$2,Matches!$A$5:$A$6,0))),""),"0.0")&" / "&TEXT(IFERROR(IF(INDEX(Matches!$J$5:$J$6,MATCH($B$2,Matches!$A$5:$A$6,0))="","",INDEX(Matches!$J$5:$J$6,MATCH($B$2,Matches!$A$5:$A$6,0))),""),"0.0"))} | G6: TP duration M1 | H6: {=IFERROR(IF(INDEX(Matches!$K$5:$K$6,MATCH($B$2,Matches!$A$5:$A$6,0))="","",INDEX(Matches!$K$5:$K$6,MATCH($B$2,Matches!$A$5:$A$6,0))),"")}
A7: Kills env × | B7: {=IFERROR(IF(INDEX(Matches!$R$5:$R$6,MATCH($B$2,Matches!$A$5:$A$6,0))="","",INDEX(Matches!$R$5:$R$6,MATCH($B$2,Matches!$A$5:$A$6,0))),"")} -> 1 | D7: P(M2 / M3 played) | E7: {=TEXT(IFERROR(IF(INDEX(Matches!$P$5:$P$6,MATCH($B$2,Matches!$A$5:$A$6,0))="","",INDEX(Matches!$P$5:$P$6,MATCH($B$2,Matches!$A$5:$A$6,0))),""),"0%")&" / "&TEXT(IFERROR(IF(INDEX(Matches!$Q$5:$Q$6,MATCH($B$2,Matches!$A$5:$A$6,0))="","",INDEX(Matches!$Q$5:$Q$6,MATCH($B$2,Matches!$A$5:$A$6,0))),""),"0%")} -> 100% / 100% | G7: TP A − B kills M1 | H7: {=IF(IFERROR(IF(INDEX(Matches!$I$5:$I$6,MATCH($B$2,Matches!$A$5:$A$6,0))="","",INDEX(Matches!$I$5:$I$6,MATCH($B$2,Matches!$A$5:$A$6,0))),"")="","",IFERROR(IF(INDEX(Matches!$I$5:$I$6,MATCH($B$2,Matches!$A$5:$A$6,0))="","",INDEX(Matches!$I$5:$I$6,MATCH($B$2,Matches!$A$5:$A$6,0))),"")-IFERROR(IF(INDEX(Matches!$J$5:$J$6,MATCH($B$2,Matches!$A$5:$A$6,0))="","",INDEX(Matches!$J$5:$J$6,MATCH($B$2,Matches!$A$5:$A$6,0))),""))}
B9: ="Change P(win), maps played or kill environment on the Matches tab, row "&(MATCH($B$2,Matches!$A$5:$A$6,0)+4)&"." -> Change P(win), maps played or kill environment on the Matches tab, row 5.
A11: Team | B11: Player | C11: Map win q | D11: K avg | E11: k win | F11: k loss | G11: P(win M1) | H11: Proj M1 | I11: Naive M1 | J11: Line M1 | K11: P(over) M1 | L11: Proj series | M11: Line series | N11: P(over) series | O11: TP book | P11: PF L10 | Q11: Sample | R11: Flags | T11: row
A12: {=IF($T12="","",INDEX(Calc!$C$2:$C$19,$T12))} -> KC | B12: {=IF($T12="","",INDEX(Calc!$D$2:$D$19,$T12))} -> Caliste | C12: {=IF($T12="","",INDEX(Calc!$H$2:$H$19,$T12))} -> 0.7 | D12: {=IF($T12="","",INDEX(Calc!$I$2:$I$19,$T12))} -> 5 | E12: {=IF($T12="","",INDEX(Calc!$J$2:$J$19,$T12))} -> 5.9826746 | F12: {=IF($T12="","",INDEX(Calc!$K$2:$K$19,$T12))} -> 2.7070926 | G12: {=IF($T12="","",INDEX(Calc!$M$2:$M$19,$T12))} -> 0.6699 | H12: {=IF($T12="","",INDEX(Calc!$Y$2:$Y$19,$T12))} -> 4.901405 | I12: {=IF($T12="","",INDEX(Calc!$AE$2:$AE$19,$T12))} -> 5 | J12: {=IF($T12="","",IFERROR(INDEX(Projections!$E$2:$E$19,MATCH(INDEX(Calc!$A$2:$A$19,$T12)&"|K1",Projections!$AA$2:$AA$19,0)),""))} | K12: {=IF($T12="","",IFERROR(INDEX(Projections!$H$2:$H$19,MATCH(INDEX(Calc!$A$2:$A$19,$T12)&"|K1",Projections!$AA$2:$AA$19,0)),""))} | L12: {=IF($T12="","",INDEX(Calc!$AK$2:$AK$19,$T12))} -> 14.704215 | M12: {=IF($T12="","",IFERROR(INDEX(Projections!$E$2:$E$19,MATCH(INDEX(Calc!$A$2:$A$19,$T12)&"|"&INDEX(Calc!$AJ$2:$AJ$19,$T12),Projections!$AA$2:$AA$19,0)),""))} -> 15.5 | N12: {=IF($T12="","",IFERROR(INDEX(Projections!$H$2:$H$19,MATCH(INDEX(Calc!$A$2:$A$19,$T12)&"|"&INDEX(Calc!$AJ$2:$AJ$19,$T12),Projections!$AA$2:$AA$19,0)),""))} -> 0.43826464 | O12: {=IF($T12="","",IFERROR(INDEX(Projections!$N$2:$N$19,MATCH(INDEX(Calc!$A$2:$A$19,$T12)&"|K1",Projections!$AA$2:$AA$19,0)),IFERROR(INDEX(Projections!$N$2:$N$19,MATCH(INDEX(Calc!$A$2:$A$19,$T12)&"|"&INDEX(Calc!$AJ$2:$AJ$19,$T12),Projections!$AA$2:$AA$19,0)),"")))} | P12: {=IF($T12="","",IFERROR(INDEX(Projections!$S$2:$S$19,MATCH(INDEX(Calc!$A$2:$A$19,$T12)&"|K1",Projections!$AA$2:$AA$19,0)),IFERROR(INDEX(Projections!$S$2:$S$19,MATCH(INDEX(Calc!$A$2:$A$19,$T12)&"|"&INDEX(Calc!$AJ$2:$AJ$19,$T12),Projections!$AA$2:$AA$19,0)),"")))} -> 0.3 | Q12: {=IF($T12="","",INDEX(Calc!$G$2:$G$19,$T12))} -> 30 | R12: {=IF($T12="","",INDEX(Calc!$AH$2:$AH$19,$T12))} -> new roster: 0% of his recent games with these teammates | T12: =IFERROR(MATCH(1,Calc!$AI$2:$AI$19,0),"") -> 10
A13: {=IF($T13="","",INDEX(Calc!$C$2:$C$19,$T13))} -> KC | B13: {=IF($T13="","",INDEX(Calc!$D$2:$D$19,$T13))} -> Yike | C13: {=IF($T13="","",INDEX(Calc!$H$2:$H$19,$T13))} -> 0.63 | D13: {=IF($T13="","",INDEX(Calc!$I$2:$I$19,$T13))} -> 3.9 | E13: {=IF($T13="","",INDEX(Calc!$J$2:$J$19,$T13))} -> 4.8907677 | F13: {=IF($T13="","",INDEX(Calc!$K$2:$K$19,$T13))} -> 2.2130171 | G13: {=IF($T13="","",INDEX(Calc!$M$2:$M$19,$T13))} -> 0.6699 | H13: {=IF($T13="","",INDEX(Calc!$Y$2:$Y$19,$T13))} -> 4.0068423 | I13: {=IF($T13="","",INDEX(Calc!$AE$2:$AE$19,$T13))} -> 3.9 | J13: {=IF($T13="","",IFERROR(INDEX(Projections!$E$2:$E$19,MATCH(INDEX(Calc!$A$2:$A$19,$T13)&"|K1",Projections!$AA$2:$AA$19,0)),""))} | K13: {=IF($T13="","",IFERROR(INDEX(Projections!$H$2:$H$19,MATCH(INDEX(Calc!$A$2:$A$19,$T13)&"|K1",Projections!$AA$2:$AA$19,0)),""))} | L13: {=IF($T13="","",INDEX(Calc!$AK$2:$AK$19,$T13))} -> 12.020527 | M13: {=IF($T13="","",IFERROR(INDEX(Projections!$E$2:$E$19,MATCH(INDEX(Calc!$A$2:$A$19,$T13)&"|"&INDEX(Calc!$AJ$2:$AJ$19,$T13),Projections!$AA$2:$AA$19,0)),""))} -> 12.5 | N13: {=IF($T13="","",IFERROR(INDEX(Projections!$H$2:$H$19,MATCH(INDEX(Calc!$A$2:$A$19,$T13)&"|"&INDEX(Calc!$AJ$2:$AJ$19,$T13),Projections!$AA$2:$AA$19,0)),""))} -> 0.4577118 | O13: {=IF($T13="","",IFERROR(INDEX(Projections!$N$2:$N$19,MATCH(INDEX(Calc!$A$2:$A$19,$T13)&"|K1",Projections!$AA$2:$AA$19,0)),IFERROR(INDEX(Projections!$N$2:$N$19,MATCH(INDEX(Calc!$A$2:$A$19,$T13)&"|"&INDEX(Calc!$AJ$2:$AJ$19,$T13),Projections!$AA$2:$AA$19,0)),"")))} | P13: {=IF($T13="","",IFERROR(INDEX(Projections!$S$2:$S$19,MATCH(INDEX(Calc!$A$2:$A$19,$T13)&"|K1",Projections!$AA$2:$AA$19,0)),IFERROR(INDEX(Projections!$S$2:$S$19,MATCH(INDEX(Calc!$A$2:$A$19,$T13)&"|"&INDEX(Calc!$AJ$2:$AJ$19,$T13),Projections!$AA$2:$AA$19,0)),"")))} -> 0.2 | Q13: {=IF($T13="","",INDEX(Calc!$G$2:$G$19,$T13))} -> 30 | R13: {=IF($T13="","",INDEX(Calc!$AH$2:$AH$19,$T13))} -> new roster: 0% of his recent games with these teammates | T13: =IFERROR(MATCH(2,Calc!$AI$2:$AI$19,0),"") -> 13
A14: {=IF($T14="","",INDEX(Calc!$C$2:$C$19,$T14))} -> MVK | B14: {=IF($T14="","",INDEX(Calc!$D$2:$D$19,$T14))} -> Chika | C14: {=IF($T14="","",INDEX(Calc!$H$2:$H$19,$T14))} -> 0.43 | D14: {=IF($T14="","",INDEX(Calc!$I$2:$I$19,$T14))} -> 3.8 | E14: {=IF($T14="","",INDEX(Calc!$J$2:$J$19,$T14))} -> 5.5239098 | F14: {=IF($T14="","",INDEX(Calc!$K$2:$K$19,$T14))} -> 2.4995067 | G14: {=IF($T14="","",INDEX(Calc!$M$2:$M$19,$T14))} -> 0.3301 | H14: {=IF($T14="","",INDEX(Calc!$Y$2:$Y$19,$T14))} -> 3.4978621 | I14: {=IF($T14="","",INDEX(Calc!$AE$2:$AE$19,$T14))} -> 3.8 | J14: {=IF($T14="","",IFERROR(INDEX(Projections!$E$2:$E$19,MATCH(INDEX(Calc!$A$2:$A$19,$T14)&"|K1",Projections!$AA$2:$AA$19,0)),""))} | K14: {=IF($T14="","",IFERROR(INDEX(Projections!$H$2:$H$19,MATCH(INDEX(Calc!$A$2:$A$19,$T14)&"|K1",Projections!$AA$2:$AA$19,0)),""))} | L14: {=IF($T14="","",INDEX(Calc!$AK$2:$AK$19,$T14))} -> 10.493586 | M14: {=IF($T14="","",IFERROR(INDEX(Projections!$E$2:$E$19,MATCH(INDEX(Calc!$A$2:$A$19,$T14)&"|"&INDEX(Calc!$AJ$2:$AJ$19,$T14),Projections!$AA$2:$AA$19,0)),""))} -> 8.5 | N14: {=IF($T14="","",IFERROR(INDEX(Projections!$H$2:$H$19,MATCH(INDEX(Calc!$A$2:$A$19,$T14)&"|"&INDEX(Calc!$AJ$2:$AJ$19,$T14),Projections!$AA$2:$AA$19,0)),""))} -> 0.67330189 | O14: {=IF($T14="","",IFERROR(INDEX(Projections!$N$2:$N$19,MATCH(INDEX(Calc!$A$2:$A$19,$T14)&"|K1",Projections!$AA$2:$AA$19,0)),IFERROR(INDEX(Projections!$N$2:$N$19,MATCH(INDEX(Calc!$A$2:$A$19,$T14)&"|"&INDEX(Calc!$AJ$2:$AJ$19,$T14),Projections!$AA$2:$AA$19,0)),"")))} | P14: {=IF($T14="","",IFERROR(INDEX(Projections!$S$2:$S$19,MATCH(INDEX(Calc!$A$2:$A$19,$T14)&"|K1",Projections!$AA$2:$AA$19,0)),IFERROR(INDEX(Projections!$S$2:$S$19,MATCH(INDEX(Calc!$A$2:$A$19,$T14)&"|"&INDEX(Calc!$AJ$2:$AJ$19,$T14),Projections!$AA$2:$AA$19,0)),"")))} -> 0.8 | Q14: {=IF($T14="","",INDEX(Calc!$G$2:$G$19,$T14))} -> 30 | R14: {=IF($T14="","",INDEX(Calc!$AH$2:$AH$19,$T14))} -> new roster: 0% of his recent games with these teammates | T14: =IFERROR(MATCH(3,Calc!$AI$2:$AI$19,0),"") -> 14
A15: {=IF($T15="","",INDEX(Calc!$C$2:$C$19,$T15))} -> KC | B15: {=IF($T15="","",INDEX(Calc!$D$2:$D$19,$T15))} -> Canna | C15: {=IF($T15="","",INDEX(Calc!$H$2:$H$19,$T15))} -> 0.63 | D15: {=IF($T15="","",INDEX(Calc!$I$2:$I$19,$T15))} -> 3.4 | E15: {=IF($T15="","",INDEX(Calc!$J$2:$J$19,$T15))} -> 4.2637462 | F15: {=IF($T15="","",INDEX(Calc!$K$2:$K$19,$T15))} -> 1.9292969 | G15: {=IF($T15="","",INDEX(Calc!$M$2:$M$19,$T15))} -> 0.6699 | H15: {=IF($T15="","",INDEX(Calc!$Y$2:$Y$19,$T15))} -> 3.4931445 | I15: {=IF($T15="","",INDEX(Calc!$AE$2:$AE$19,$T15))} -> 3.4 | J15: {=IF($T15="","",IFERROR(INDEX(Projections!$E$2:$E$19,MATCH(INDEX(Calc!$A$2:$A$19,$T15)&"|K1",Projections!$AA$2:$AA$19,0)),""))} | K15: {=IF($T15="","",IFERROR(INDEX(Projections!$H$2:$H$19,MATCH(INDEX(Calc!$A$2:$A$19,$T15)&"|K1",Projections!$AA$2:$AA$19,0)),""))} | L15: {=IF($T15="","",INDEX(Calc!$AK$2:$AK$19,$T15))} -> 10.479434 | M15: {=IF($T15="","",IFERROR(INDEX(Projections!$E$2:$E$19,MATCH(INDEX(Calc!$A$2:$A$19,$T15)&"|"&INDEX(Calc!$AJ$2:$AJ$19,$T15),Projections!$AA$2:$AA$19,0)),""))} -> 9.5 | N15: {=IF($T15="","",IFERROR(INDEX(Projections!$H$2:$H$19,MATCH(INDEX(Calc!$A$2:$A$19,$T15)&"|"&INDEX(Calc!$AJ$2:$AJ$19,$T15),Projections!$AA$2:$AA$19,0)),""))} -> 0.5932441 | O15: {=IF($T15="","",IFERROR(INDEX(Projections!$N$2:$N$19,MATCH(INDEX(Calc!$A$2:$A$19,$T15)&"|K1",Projections!$AA$2:$AA$19,0)),IFERROR(INDEX(Projections!$N$2:$N$19,MATCH(INDEX(Calc!$A$2:$A$19,$T15)&"|"&INDEX(Calc!$AJ$2:$AJ$19,$T15),Projections!$AA$2:$AA$19,0)),"")))} | P15: {=IF($T15="","",IFERROR(INDEX(Projections!$S$2:$S$19,MATCH(INDEX(Calc!$A$2:$A$19,$T15)&"|K1",Projections!$AA$2:$AA$19,0)),IFERROR(INDEX(Projections!$S$2:$S$19,MATCH(INDEX(Calc!$A$2:$A$19,$T15)&"|"&INDEX(Calc!$AJ$2:$AJ$19,$T15),Projections!$AA$2:$AA$19,0)),"")))} -> 0.4 | Q15: {=IF($T15="","",INDEX(Calc!$G$2:$G$19,$T15))} -> 30 | R15: {=IF($T15="","",INDEX(Calc!$AH$2:$AH$19,$T15))} -> new roster: 0% of his recent games with these teammates | T15: =IFERROR(MATCH(4,Calc!$AI$2:$AI$19,0),"") -> 11
A16: {=IF($T16="","",INDEX(Calc!$C$2:$C$19,$T16))} -> MVK | B16: {=IF($T16="","",INDEX(Calc!$D$2:$D$19,$T16))} -> Harky | C16: {=IF($T16="","",INDEX(Calc!$H$2:$H$19,$T16))} -> 0.5 | D16: {=IF($T16="","",INDEX(Calc!$I$2:$I$19,$T16))} -> 3.4 | E16: {=IF($T16="","",INDEX(Calc!$J$2:$J$19,$T16))} -> 4.6816199 | F16: {=IF($T16="","",INDEX(Calc!$K$2:$K$19,$T16))} -> 2.1183801 | G16: {=IF($T16="","",INDEX(Calc!$M$2:$M$19,$T16))} -> 0.3301 | H16: {=IF($T16="","",INDEX(Calc!$Y$2:$Y$19,$T16))} -> 2.9645055 | I16: {=IF($T16="","",INDEX(Calc!$AE$2:$AE$19,$T16))} -> 3.4 | J16: {=IF($T16="","",IFERROR(INDEX(Projections!$E$2:$E$19,MATCH(INDEX(Calc!$A$2:$A$19,$T16)&"|K1",Projections!$AA$2:$AA$19,0)),""))} | K16: {=IF($T16="","",IFERROR(INDEX(Projections!$H$2:$H$19,MATCH(INDEX(Calc!$A$2:$A$19,$T16)&"|K1",Projections!$AA$2:$AA$19,0)),""))} | L16: {=IF($T16="","",INDEX(Calc!$AK$2:$AK$19,$T16))} -> 8.8935166 | M16: {=IF($T16="","",IFERROR(INDEX(Projections!$E$2:$E$19,MATCH(INDEX(Calc!$A$2:$A$19,$T16)&"|"&INDEX(Calc!$AJ$2:$AJ$19,$T16),Projections!$AA$2:$AA$19,0)),""))} -> 9 | N16: {=IF($T16="","",IFERROR(INDEX(Projections!$H$2:$H$19,MATCH(INDEX(Calc!$A$2:$A$19,$T16)&"|"&INDEX(Calc!$AJ$2:$AJ$19,$T16),Projections!$AA$2:$AA$19,0)),""))} -> 0.43959343 | O16: {=IF($T16="","",IFERROR(INDEX(Projections!$N$2:$N$19,MATCH(INDEX(Calc!$A$2:$A$19,$T16)&"|K1",Projections!$AA$2:$AA$19,0)),IFERROR(INDEX(Projections!$N$2:$N$19,MATCH(INDEX(Calc!$A$2:$A$19,$T16)&"|"&INDEX(Calc!$AJ$2:$AJ$19,$T16),Projections!$AA$2:$AA$19,0)),"")))} | P16: {=IF($T16="","",IFERROR(INDEX(Projections!$S$2:$S$19,MATCH(INDEX(Calc!$A$2:$A$19,$T16)&"|K1",Projections!$AA$2:$AA$19,0)),IFERROR(INDEX(Projections!$S$2:$S$19,MATCH(INDEX(Calc!$A$2:$A$19,$T16)&"|"&INDEX(Calc!$AJ$2:$AJ$19,$T16),Projections!$AA$2:$AA$19,0)),"")))} -> 0.7 | Q16: {=IF($T16="","",INDEX(Calc!$G$2:$G$19,$T16))} -> 30 | R16: {=IF($T16="","",INDEX(Calc!$AH$2:$AH$19,$T16))} -> new roster: 0% of his recent games with these teammates | T16: =IFERROR(MATCH(5,Calc!$AI$2:$AI$19,0),"") -> 16
A17: {=IF($T17="","",INDEX(Calc!$C$2:$C$19,$T17))} -> MVK | B17: {=IF($T17="","",INDEX(Calc!$D$2:$D$19,$T17))} -> Kratos | C17: {=IF($T17="","",INDEX(Calc!$H$2:$H$19,$T17))} -> 0.43 | D17: {=IF($T17="","",INDEX(Calc!$I$2:$I$19,$T17))} -> 2.7 | E17: {=IF($T17="","",INDEX(Calc!$J$2:$J$19,$T17))} -> 3.9248832 | F17: {=IF($T17="","",INDEX(Calc!$K$2:$K$19,$T17))} -> 1.7759653 | G17: {=IF($T17="","",INDEX(Calc!$M$2:$M$19,$T17))} -> 0.3301 | H17: {=IF($T17="","",INDEX(Calc!$Y$2:$Y$19,$T17))} -> 2.4853231 | I17: {=IF($T17="","",INDEX(Calc!$AE$2:$AE$19,$T17))} -> 2.7 | J17: {=IF($T17="","",IFERROR(INDEX(Projections!$E$2:$E$19,MATCH(INDEX(Calc!$A$2:$A$19,$T17)&"|K1",Projections!$AA$2:$AA$19,0)),""))} | K17: {=IF($T17="","",IFERROR(INDEX(Projections!$H$2:$H$19,MATCH(INDEX(Calc!$A$2:$A$19,$T17)&"|K1",Projections!$AA$2:$AA$19,0)),""))} | L17: {=IF($T17="","",INDEX(Calc!$AK$2:$AK$19,$T17))} -> 7.4559693 | M17: {=IF($T17="","",IFERROR(INDEX(Projections!$E$2:$E$19,MATCH(INDEX(Calc!$A$2:$A$19,$T17)&"|"&INDEX(Calc!$AJ$2:$AJ$19,$T17),Projections!$AA$2:$AA$19,0)),""))} -> 6 | N17: {=IF($T17="","",IFERROR(INDEX(Projections!$H$2:$H$19,MATCH(INDEX(Calc!$A$2:$A$19,$T17)&"|"&INDEX(Calc!$AJ$2:$AJ$19,$T17),Projections!$AA$2:$AA$19,0)),""))} -> 0.60551923 | O17: {=IF($T17="","",IFERROR(INDEX(Projections!$N$2:$N$19,MATCH(INDEX(Calc!$A$2:$A$19,$T17)&"|K1",Projections!$AA$2:$AA$19,0)),IFERROR(INDEX(Projections!$N$2:$N$19,MATCH(INDEX(Calc!$A$2:$A$19,$T17)&"|"&INDEX(Calc!$AJ$2:$AJ$19,$T17),Projections!$AA$2:$AA$19,0)),"")))} | P17: {=IF($T17="","",IFERROR(INDEX(Projections!$S$2:$S$19,MATCH(INDEX(Calc!$A$2:$A$19,$T17)&"|K1",Projections!$AA$2:$AA$19,0)),IFERROR(INDEX(Projections!$S$2:$S$19,MATCH(INDEX(Calc!$A$2:$A$19,$T17)&"|"&INDEX(Calc!$AJ$2:$AJ$19,$T17),Projections!$AA$2:$AA$19,0)),"")))} -> 0.8 | Q17: {=IF($T17="","",INDEX(Calc!$G$2:$G$19,$T17))} -> 30 | R17: {=IF($T17="","",INDEX(Calc!$AH$2:$AH$19,$T17))} -> new roster: 0% of his recent games with these teammates | T17: =IFERROR(MATCH(6,Calc!$AI$2:$AI$19,0),"") -> 17
A18: {=IF($T18="","",INDEX(Calc!$C$2:$C$19,$T18))} -> KC | B18: {=IF($T18="","",INDEX(Calc!$D$2:$D$19,$T18))} -> Kyeahoo | C18: {=IF($T18="","",INDEX(Calc!$H$2:$H$19,$T18))} -> 0.63 | D18: {=IF($T18="","",INDEX(Calc!$I$2:$I$19,$T18))} -> 2.3 | E18: {=IF($T18="","",INDEX(Calc!$J$2:$J$19,$T18))} -> 2.8842989 | F18: {=IF($T18="","",INDEX(Calc!$K$2:$K$19,$T18))} -> 1.3051126 | G18: {=IF($T18="","",INDEX(Calc!$M$2:$M$19,$T18))} -> 0.6699 | H18: {=IF($T18="","",INDEX(Calc!$Y$2:$Y$19,$T18))} -> 2.3630095 | I18: {=IF($T18="","",INDEX(Calc!$AE$2:$AE$19,$T18))} -> 2.3 | J18: {=IF($T18="","",IFERROR(INDEX(Projections!$E$2:$E$19,MATCH(INDEX(Calc!$A$2:$A$19,$T18)&"|K1",Projections!$AA$2:$AA$19,0)),""))} | K18: {=IF($T18="","",IFERROR(INDEX(Projections!$H$2:$H$19,MATCH(INDEX(Calc!$A$2:$A$19,$T18)&"|K1",Projections!$AA$2:$AA$19,0)),""))} | L18: {=IF($T18="","",INDEX(Calc!$AK$2:$AK$19,$T18))} -> 7.0890286 | M18: {=IF($T18="","",IFERROR(INDEX(Projections!$E$2:$E$19,MATCH(INDEX(Calc!$A$2:$A$19,$T18)&"|"&INDEX(Calc!$AJ$2:$AJ$19,$T18),Projections!$AA$2:$AA$19,0)),""))} -> 11.5 | N18: {=IF($T18="","",IFERROR(INDEX(Projections!$H$2:$H$19,MATCH(INDEX(Calc!$A$2:$A$19,$T18)&"|"&INDEX(Calc!$AJ$2:$AJ$19,$T18),Projections!$AA$2:$AA$19,0)),""))} -> 0.090468109 | O18: {=IF($T18="","",IFERROR(INDEX(Projections!$N$2:$N$19,MATCH(INDEX(Calc!$A$2:$A$19,$T18)&"|K1",Projections!$AA$2:$AA$19,0)),IFERROR(INDEX(Projections!$N$2:$N$19,MATCH(INDEX(Calc!$A$2:$A$19,$T18)&"|"&INDEX(Calc!$AJ$2:$AJ$19,$T18),Projections!$AA$2:$AA$19,0)),"")))} | P18: {=IF($T18="","",IFERROR(INDEX(Projections!$S$2:$S$19,MATCH(INDEX(Calc!$A$2:$A$19,$T18)&"|K1",Projections!$AA$2:$AA$19,0)),IFERROR(INDEX(Projections!$S$2:$S$19,MATCH(INDEX(Calc!$A$2:$A$19,$T18)&"|"&INDEX(Calc!$AJ$2:$AJ$19,$T18),Projections!$AA$2:$AA$19,0)),"")))} -> 0 | Q18: {=IF($T18="","",INDEX(Calc!$G$2:$G$19,$T18))} -> 30 | R18: {=IF($T18="","",INDEX(Calc!$AH$2:$AH$19,$T18))} -> new roster: 0% of his recent games with these teammates | T18: =IFERROR(MATCH(7,Calc!$AI$2:$AI$19,0),"") -> 12
A19: {=IF($T19="","",INDEX(Calc!$C$2:$C$19,$T19))} -> MVK | B19: {=IF($T19="","",INDEX(Calc!$D$2:$D$19,$T19))} -> Gury | C19: {=IF($T19="","",INDEX(Calc!$H$2:$H$19,$T19))} -> 0.43 | D19: {=IF($T19="","",INDEX(Calc!$I$2:$I$19,$T19))} -> 2.1 | E19: {=IF($T19="","",INDEX(Calc!$J$2:$J$19,$T19))} -> 3.052687 | F19: {=IF($T19="","",INDEX(Calc!$K$2:$K$19,$T19))} -> 1.3813063 | G19: {=IF($T19="","",INDEX(Calc!$M$2:$M$19,$T19))} -> 0.3301 | H19: {=IF($T19="","",INDEX(Calc!$Y$2:$Y$19,$T19))} -> 1.9330291 | I19: {=IF($T19="","",INDEX(Calc!$AE$2:$AE$19,$T19))} -> 2.1 | J19: {=IF($T19="","",IFERROR(INDEX(Projections!$E$2:$E$19,MATCH(INDEX(Calc!$A$2:$A$19,$T19)&"|K1",Projections!$AA$2:$AA$19,0)),""))} | K19: {=IF($T19="","",IFERROR(INDEX(Projections!$H$2:$H$19,MATCH(INDEX(Calc!$A$2:$A$19,$T19)&"|K1",Projections!$AA$2:$AA$19,0)),""))} | L19: {=IF($T19="","",INDEX(Calc!$AK$2:$AK$19,$T19))} -> 5.7990872 | M19: {=IF($T19="","",IFERROR(INDEX(Projections!$E$2:$E$19,MATCH(INDEX(Calc!$A$2:$A$19,$T19)&"|"&INDEX(Calc!$AJ$2:$AJ$19,$T19),Projections!$AA$2:$AA$19,0)),""))} -> 7 | N19: {=IF($T19="","",IFERROR(INDEX(Projections!$H$2:$H$19,MATCH(INDEX(Calc!$A$2:$A$19,$T19)&"|"&INDEX(Calc!$AJ$2:$AJ$19,$T19),Projections!$AA$2:$AA$19,0)),""))} -> 0.28944331 | O19: {=IF($T19="","",IFERROR(INDEX(Projections!$N$2:$N$19,MATCH(INDEX(Calc!$A$2:$A$19,$T19)&"|K1",Projections!$AA$2:$AA$19,0)),IFERROR(INDEX(Projections!$N$2:$N$19,MATCH(INDEX(Calc!$A$2:$A$19,$T19)&"|"&INDEX(Calc!$AJ$2:$AJ$19,$T19),Projections!$AA$2:$AA$19,0)),"")))} | P19: {=IF($T19="","",IFERROR(INDEX(Projections!$S$2:$S$19,MATCH(INDEX(Calc!$A$2:$A$19,$T19)&"|K1",Projections!$AA$2:$AA$19,0)),IFERROR(INDEX(Projections!$S$2:$S$19,MATCH(INDEX(Calc!$A$2:$A$19,$T19)&"|"&INDEX(Calc!$AJ$2:$AJ$19,$T19),Projections!$AA$2:$AA$19,0)),"")))} -> 0.4 | Q19: {=IF($T19="","",INDEX(Calc!$G$2:$G$19,$T19))} -> 30 | R19: {=IF($T19="","",INDEX(Calc!$AH$2:$AH$19,$T19))} -> new roster: 0% of his recent games with these teammates | T19: =IFERROR(MATCH(8,Calc!$AI$2:$AI$19,0),"") -> 15
A20: {=IF($T20="","",INDEX(Calc!$C$2:$C$19,$T20))} -> MVK | B20: {=IF($T20="","",INDEX(Calc!$D$2:$D$19,$T20))} -> Siuloong | C20: {=IF($T20="","",INDEX(Calc!$H$2:$H$19,$T20))} -> 0.43 | D20: {=IF($T20="","",INDEX(Calc!$I$2:$I$19,$T20))} -> 0.7 | E20: {=IF($T20="","",INDEX(Calc!$J$2:$J$19,$T20))} -> 1.0175623 | F20: {=IF($T20="","",INDEX(Calc!$K$2:$K$19,$T20))} -> 0.46043544 | G20: {=IF($T20="","",INDEX(Calc!$M$2:$M$19,$T20))} -> 0.3301 | H20: {=IF($T20="","",INDEX(Calc!$Y$2:$Y$19,$T20))} -> 0.64434302 | I20: {=IF($T20="","",INDEX(Calc!$AE$2:$AE$19,$T20))} -> 0.7 | J20: {=IF($T20="","",IFERROR(INDEX(Projections!$E$2:$E$19,MATCH(INDEX(Calc!$A$2:$A$19,$T20)&"|K1",Projections!$AA$2:$AA$19,0)),""))} | K20: {=IF($T20="","",IFERROR(INDEX(Projections!$H$2:$H$19,MATCH(INDEX(Calc!$A$2:$A$19,$T20)&"|K1",Projections!$AA$2:$AA$19,0)),""))} | L20: {=IF($T20="","",INDEX(Calc!$AK$2:$AK$19,$T20))} -> 1.9330291 | M20: {=IF($T20="","",IFERROR(INDEX(Projections!$E$2:$E$19,MATCH(INDEX(Calc!$A$2:$A$19,$T20)&"|"&INDEX(Calc!$AJ$2:$AJ$19,$T20),Projections!$AA$2:$AA$19,0)),""))} -> 1.5 | N20: {=IF($T20="","",IFERROR(INDEX(Projections!$H$2:$H$19,MATCH(INDEX(Calc!$A$2:$A$19,$T20)&"|"&INDEX(Calc!$AJ$2:$AJ$19,$T20),Projections!$AA$2:$AA$19,0)),""))} -> 0.60357745 | O20: {=IF($T20="","",IFERROR(INDEX(Projections!$N$2:$N$19,MATCH(INDEX(Calc!$A$2:$A$19,$T20)&"|K1",Projections!$AA$2:$AA$19,0)),IFERROR(INDEX(Projections!$N$2:$N$19,MATCH(INDEX(Calc!$A$2:$A$19,$T20)&"|"&INDEX(Calc!$AJ$2:$AJ$19,$T20),Projections!$AA$2:$AA$19,0)),"")))} | P20: {=IF($T20="","",IFERROR(INDEX(Projections!$S$2:$S$19,MATCH(INDEX(Calc!$A$2:$A$19,$T20)&"|K1",Projections!$AA$2:$AA$19,0)),IFERROR(INDEX(Projections!$S$2:$S$19,MATCH(INDEX(Calc!$A$2:$A$19,$T20)&"|"&INDEX(Calc!$AJ$2:$AJ$19,$T20),Projections!$AA$2:$AA$19,0)),"")))} -> 0.8 | Q20: {=IF($T20="","",INDEX(Calc!$G$2:$G$19,$T20))} -> 30 | R20: {=IF($T20="","",INDEX(Calc!$AH$2:$AH$19,$T20))} -> new roster: 0% of his recent games with these teammates | T20: =IFERROR(MATCH(9,Calc!$AI$2:$AI$19,0),"") -> 18
A21: {=IF($T21="","",INDEX(Calc!$C$2:$C$19,$T21))} | B21: {=IF($T21="","",INDEX(Calc!$D$2:$D$19,$T21))} | C21: {=IF($T21="","",INDEX(Calc!$H$2:$H$19,$T21))} | D21: {=IF($T21="","",INDEX(Calc!$I$2:$I$19,$T21))} | E21: {=IF($T21="","",INDEX(Calc!$J$2:$J$19,$T21))} | F21: {=IF($T21="","",INDEX(Calc!$K$2:$K$19,$T21))} | G21: {=IF($T21="","",INDEX(Calc!$M$2:$M$19,$T21))} | H21: {=IF($T21="","",INDEX(Calc!$Y$2:$Y$19,$T21))} | I21: {=IF($T21="","",INDEX(Calc!$AE$2:$AE$19,$T21))} | J21: {=IF($T21="","",IFERROR(INDEX(Projections!$E$2:$E$19,MATCH(INDEX(Calc!$A$2:$A$19,$T21)&"|K1",Projections!$AA$2:$AA$19,0)),""))} | K21: {=IF($T21="","",IFERROR(INDEX(Projections!$H$2:$H$19,MATCH(INDEX(Calc!$A$2:$A$19,$T21)&"|K1",Projections!$AA$2:$AA$19,0)),""))} | L21: {=IF($T21="","",INDEX(Calc!$AK$2:$AK$19,$T21))} | M21: {=IF($T21="","",IFERROR(INDEX(Projections!$E$2:$E$19,MATCH(INDEX(Calc!$A$2:$A$19,$T21)&"|"&INDEX(Calc!$AJ$2:$AJ$19,$T21),Projections!$AA$2:$AA$19,0)),""))} | N21: {=IF($T21="","",IFERROR(INDEX(Projections!$H$2:$H$19,MATCH(INDEX(Calc!$A$2:$A$19,$T21)&"|"&INDEX(Calc!$AJ$2:$AJ$19,$T21),Projections!$AA$2:$AA$19,0)),""))} | O21: {=IF($T21="","",IFERROR(INDEX(Projections!$N$2:$N$19,MATCH(INDEX(Calc!$A$2:$A$19,$T21)&"|K1",Projections!$AA$2:$AA$19,0)),IFERROR(INDEX(Projections!$N$2:$N$19,MATCH(INDEX(Calc!$A$2:$A$19,$T21)&"|"&INDEX(Calc!$AJ$2:$AJ$19,$T21),Projections!$AA$2:$AA$19,0)),"")))} | P21: {=IF($T21="","",IFERROR(INDEX(Projections!$S$2:$S$19,MATCH(INDEX(Calc!$A$2:$A$19,$T21)&"|K1",Projections!$AA$2:$AA$19,0)),IFERROR(INDEX(Projections!$S$2:$S$19,MATCH(INDEX(Calc!$A$2:$A$19,$T21)&"|"&INDEX(Calc!$AJ$2:$AJ$19,$T21),Projections!$AA$2:$AA$19,0)),"")))} | Q21: {=IF($T21="","",INDEX(Calc!$G$2:$G$19,$T21))} | R21: {=IF($T21="","",INDEX(Calc!$AH$2:$AH$19,$T21))} | T21: =IFERROR(MATCH(10,Calc!$AI$2:$AI$19,0),"")
A22: {=IF($T22="","",INDEX(Calc!$C$2:$C$19,$T22))} | B22: {=IF($T22="","",INDEX(Calc!$D$2:$D$19,$T22))} | C22: {=IF($T22="","",INDEX(Calc!$H$2:$H$19,$T22))} | D22: {=IF($T22="","",INDEX(Calc!$I$2:$I$19,$T22))} | E22: {=IF($T22="","",INDEX(Calc!$J$2:$J$19,$T22))} | F22: {=IF($T22="","",INDEX(Calc!$K$2:$K$19,$T22))} | G22: {=IF($T22="","",INDEX(Calc!$M$2:$M$19,$T22))} | H22: {=IF($T22="","",INDEX(Calc!$Y$2:$Y$19,$T22))} | I22: {=IF($T22="","",INDEX(Calc!$AE$2:$AE$19,$T22))} | J22: {=IF($T22="","",IFERROR(INDEX(Projections!$E$2:$E$19,MATCH(INDEX(Calc!$A$2:$A$19,$T22)&"|K1",Projections!$AA$2:$AA$19,0)),""))} | K22: {=IF($T22="","",IFERROR(INDEX(Projections!$H$2:$H$19,MATCH(INDEX(Calc!$A$2:$A$19,$T22)&"|K1",Projections!$AA$2:$AA$19,0)),""))} | L22: {=IF($T22="","",INDEX(Calc!$AK$2:$AK$19,$T22))} | M22: {=IF($T22="","",IFERROR(INDEX(Projections!$E$2:$E$19,MATCH(INDEX(Calc!$A$2:$A$19,$T22)&"|"&INDEX(Calc!$AJ$2:$AJ$19,$T22),Projections!$AA$2:$AA$19,0)),""))} | N22: {=IF($T22="","",IFERROR(INDEX(Projections!$H$2:$H$19,MATCH(INDEX(Calc!$A$2:$A$19,$T22)&"|"&INDEX(Calc!$AJ$2:$AJ$19,$T22),Projections!$AA$2:$AA$19,0)),""))} | O22: {=IF($T22="","",IFERROR(INDEX(Projections!$N$2:$N$19,MATCH(INDEX(Calc!$A$2:$A$19,$T22)&"|K1",Projections!$AA$2:$AA$19,0)),IFERROR(INDEX(Projections!$N$2:$N$19,MATCH(INDEX(Calc!$A$2:$A$19,$T22)&"|"&INDEX(Calc!$AJ$2:$AJ$19,$T22),Projections!$AA$2:$AA$19,0)),"")))} | P22: {=IF($T22="","",IFERROR(INDEX(Projections!$S$2:$S$19,MATCH(INDEX(Calc!$A$2:$A$19,$T22)&"|K1",Projections!$AA$2:$AA$19,0)),IFERROR(INDEX(Projections!$S$2:$S$19,MATCH(INDEX(Calc!$A$2:$A$19,$T22)&"|"&INDEX(Calc!$AJ$2:$AJ$19,$T22),Projections!$AA$2:$AA$19,0)),"")))} | Q22: {=IF($T22="","",INDEX(Calc!$G$2:$G$19,$T22))} | R22: {=IF($T22="","",INDEX(Calc!$AH$2:$AH$19,$T22))} | T22: =IFERROR(MATCH(11,Calc!$AI$2:$AI$19,0),"")
A23: {=IF($T23="","",INDEX(Calc!$C$2:$C$19,$T23))} | B23: {=IF($T23="","",INDEX(Calc!$D$2:$D$19,$T23))} | C23: {=IF($T23="","",INDEX(Calc!$H$2:$H$19,$T23))} | D23: {=IF($T23="","",INDEX(Calc!$I$2:$I$19,$T23))} | E23: {=IF($T23="","",INDEX(Calc!$J$2:$J$19,$T23))} | F23: {=IF($T23="","",INDEX(Calc!$K$2:$K$19,$T23))} | G23: {=IF($T23="","",INDEX(Calc!$M$2:$M$19,$T23))} | H23: {=IF($T23="","",INDEX(Calc!$Y$2:$Y$19,$T23))} | I23: {=IF($T23="","",INDEX(Calc!$AE$2:$AE$19,$T23))} | J23: {=IF($T23="","",IFERROR(INDEX(Projections!$E$2:$E$19,MATCH(INDEX(Calc!$A$2:$A$19,$T23)&"|K1",Projections!$AA$2:$AA$19,0)),""))} | K23: {=IF($T23="","",IFERROR(INDEX(Projections!$H$2:$H$19,MATCH(INDEX(Calc!$A$2:$A$19,$T23)&"|K1",Projections!$AA$2:$AA$19,0)),""))} | L23: {=IF($T23="","",INDEX(Calc!$AK$2:$AK$19,$T23))} | M23: {=IF($T23="","",IFERROR(INDEX(Projections!$E$2:$E$19,MATCH(INDEX(Calc!$A$2:$A$19,$T23)&"|"&INDEX(Calc!$AJ$2:$AJ$19,$T23),Projections!$AA$2:$AA$19,0)),""))} | N23: {=IF($T23="","",IFERROR(INDEX(Projections!$H$2:$H$19,MATCH(INDEX(Calc!$A$2:$A$19,$T23)&"|"&INDEX(Calc!$AJ$2:$AJ$19,$T23),Projections!$AA$2:$AA$19,0)),""))} | O23: {=IF($T23="","",IFERROR(INDEX(Projections!$N$2:$N$19,MATCH(INDEX(Calc!$A$2:$A$19,$T23)&"|K1",Projections!$AA$2:$AA$19,0)),IFERROR(INDEX(Projections!$N$2:$N$19,MATCH(INDEX(Calc!$A$2:$A$19,$T23)&"|"&INDEX(Calc!$AJ$2:$AJ$19,$T23),Projections!$AA$2:$AA$19,0)),"")))} | P23: {=IF($T23="","",IFERROR(INDEX(Projections!$S$2:$S$19,MATCH(INDEX(Calc!$A$2:$A$19,$T23)&"|K1",Projections!$AA$2:$AA$19,0)),IFERROR(INDEX(Projections!$S$2:$S$19,MATCH(INDEX(Calc!$A$2:$A$19,$T23)&"|"&INDEX(Calc!$AJ$2:$AJ$19,$T23),Projections!$AA$2:$AA$19,0)),"")))} | Q23: {=IF($T23="","",INDEX(Calc!$G$2:$G$19,$T23))} | R23: {=IF($T23="","",INDEX(Calc!$AH$2:$AH$19,$T23))} | T23: =IFERROR(MATCH(12,Calc!$AI$2:$AI$19,0),"")
A25: Proj = Σ maps of P(win map)·k_win + P(lose)·k_loss, with k_win = K̄·r/(q·r+1−q), k_loss = K̄/(q·r+1−q), r = WL_RATIO, q = his map win rate over PickFinder's sample. Naive = K̄ per map. At P(win) = q the two agree exactly. PAPER: no forward record.

Sheet Matches
A1: Matches — the shaded columns are yours: P(win) for each map, which maps get played, and the kill environment
A2: Prefilled from Thunderpick, devigged: P(A wins map k) from Map k Winner (Bo1: Match Winner). Kills env × scales every projection in the match (1 = the players' own history; 1.10 = a game 10% bloodier).
A4: Match | B4: Event | C4: Start (CT) | D4: Bo | E4: Team A | F4: Team B | G4: P(A wins) | H4: TP total kills M1 | I4: TP A kills M1 | J4: TP B kills M1 | K4: TP duration M1 | L4: TP markets | M4: P(A wins M1) | N4: P(A wins M2) | O4: P(A wins M3) | P4: P(M2 played) | Q4: P(M3 played) | R4: Kills env × | S4: Tag A | T4: Tag B
A5: LOL · KC vs MVK | B5: Worlds 2026 | C5: Fri 13:00 | D5: 5 | E5: Karmine Corp (KC) | F5: MVK Esports (MVK) | G5: 0.75697211 | L5: 315 | M5: 0.6699 | N5: 0.6699 | O5: 0.6699 | P5: 1 | Q5: 1 | R5: 1 | S5: KC | T5: MVK
A6: LOL · C9 vs FUR | B6: Worlds 2026 | C6: Fri 18:00 | D6: 5 | E6: Cloud9 (C9) | F6: FURIA Esports (FUR) | G6: 0.80672269 | L6: 315 | M6: 0.7014 | N6: 0.7014 | O6: 0.7014 | P6: 1 | Q6: 1 | R6: 1 | S6: C9 | T6: FUR

Sheet Projections
A1: Match | B1: Player | C1: Team | D1: Market | E1: Line | F1: Proj | G1: Sigma | H1: P(over) | I1: P(under) | J1: P(push) | K1: Model side (paper) | L1: Naive proj | M1: P(over) naive | N1: TP book median | O1: Map win rate q | P1: P(win M1) | Q1: PF Avg L10 | R1: PF L5 | S1: PF L10 | T1: PF L15 | U1: PF H2H | V1: PF streak | W1: Exact-line landings (15) | X1: Flags | Y1: Calc key | Z1: Code | AA1: Lookup
A2: LOL · C9 vs FUR | B2: Blaber | C2: C9 | D2: Maps 1-3 Kills | E2: 10.5 | F2: {=IFERROR(INDEX(CHOOSE(MATCH($Z2,{"K1","K12","K13"},0),Calc!$Y$2:$Y$19,Calc!$AA$2:$AA$19,Calc!$AC$2:$AC$19),MATCH($Y2,Calc!$A$2:$A$19,0)),"")} -> 9.6397717 | G2: {=IFERROR(SQRT(INDEX(CHOOSE(MATCH($Z2,{"K1","K12","K13"},0),Calc!$Z$2:$Z$19,Calc!$AB$2:$AB$19,Calc!$AD$2:$AD$19),MATCH($Y2,Calc!$A$2:$A$19,0))),"")} -> 3.9129057 | H2: =IF(OR($E2="",$F2="",N($G2)<=0),"",1-NORMDIST(FLOOR($E2,1)+0.5,$F2,$G2,TRUE())) -> 0.41299638 | I2: =IF($H2="","",NORMDIST(CEILING($E2,1)-0.5,$F2,$G2,TRUE())) -> 0.58700362 | J2: =IF($H2="","",MAX(0,1-$H2-$I2)) -> 0 | K2: =IF($H2="","",IF($H2>=0.5+Config!$B$8,"OVER",IF($I2>=0.5+Config!$B$8,"UNDER","—"))) -> UNDER | L2: {=IFERROR(INDEX(CHOOSE(MATCH($Z2,{"K1","K12","K13"},0),Calc!$AE$2:$AE$19,Calc!$AF$2:$AF$19,Calc!$AG$2:$AG$19),MATCH($Y2,Calc!$A$2:$A$19,0)),"")} -> 9 | M2: =IF(OR($E2="",$L2="",N($G2)<=0),"",1-NORMDIST(FLOOR($E2,1)+0.5,$L2,$G2*SQRT($L2/$F2),TRUE())) -> 0.34578027 | O2: {=IFERROR(INDEX(Calc!$H$2:$H$19,MATCH($Y2,Calc!$A$2:$A$19,0)),"")} -> 0.6 | P2: {=IFERROR(INDEX(Calc!$M$2:$M$19,MATCH($Y2,Calc!$A$2:$A$19,0)),"")} -> 0.7014 | Q2: 8.8 | R2: 0.4 | S2: 0.4 | T2: 0.33 | U2: 0%/0/1 | V2: 2 | X2: {=IFERROR(INDEX(Calc!$AH$2:$AH$19,MATCH($Y2,Calc!$A$2:$A$19,0)),"")} -> new roster: 0% of his recent games with these teammates | Y2: 8c0cdne5gb1xf15|LOL · C9 vs FUR | Z2: K13 | AA2: =Y2&"|"&Z2 -> 8c0cdne5gb1xf15|LOL · C9 vs FUR|K13
A3: LOL · C9 vs FUR | B3: Loki | C3: C9 | D3: Maps 1-3 Kills | E3: 14.5 | F3: {=IFERROR(INDEX(CHOOSE(MATCH($Z3,{"K1","K12","K13"},0),Calc!$Y$2:$Y$19,Calc!$AA$2:$AA$19,Calc!$AC$2:$AC$19),MATCH($Y3,Calc!$A$2:$A$19,0)),"")} -> 15.098525 | G3: {=IFERROR(SQRT(INDEX(CHOOSE(MATCH($Z3,{"K1","K12","K13"},0),Calc!$Z$2:$Z$19,Calc!$AB$2:$AB$19,Calc!$AD$2:$AD$19),MATCH($Y3,Calc!$A$2:$A$19,0))),"")} -> 5.1425556 | H3: =IF(OR($E3="",$F3="",N($G3)<=0),"",1-NORMDIST(FLOOR($E3,1)+0.5,$F3,$G3,TRUE())) -> 0.54632693 | I3: =IF($H3="","",NORMDIST(CEILING($E3,1)-0.5,$F3,$G3,TRUE())) -> 0.45367307 | J3: =IF($H3="","",MAX(0,1-$H3-$I3)) -> 0 | K3: =IF($H3="","",IF($H3>=0.5+Config!$B$8,"OVER",IF($I3>=0.5+Config!$B$8,"UNDER","—"))) -> OVER | L3: {=IFERROR(INDEX(CHOOSE(MATCH($Z3,{"K1","K12","K13"},0),Calc!$AE$2:$AE$19,Calc!$AF$2:$AF$19,Calc!$AG$2:$AG$19),MATCH($Y3,Calc!$A$2:$A$19,0)),"")} -> 13.8 | M3: =IF(OR($E3="",$L3="",N($G3)<=0),"",1-NORMDIST(FLOOR($E3,1)+0.5,$L3,$G3*SQRT($L3/$F3),TRUE())) -> 0.44339022 | O3: {=IFERROR(INDEX(Calc!$H$2:$H$19,MATCH($Y3,Calc!$A$2:$A$19,0)),"")} -> 0.57 | P3: {=IFERROR(INDEX(Calc!$M$2:$M$19,MATCH($Y3,Calc!$A$2:$A$19,0)),"")} -> 0.7014 | Q3: 13.2 | R3: 0.4 | S3: 0.6 | T3: 0.53 | U3: - | V3: 1 | X3: {=IFERROR(INDEX(Calc!$AH$2:$AH$19,MATCH($Y3,Calc!$A$2:$A$19,0)),"")} -> new roster: 0% of his recent games with these teammates | Y3: dzriszc5pnz15ca|LOL · C9 vs FUR | Z3: K13 | AA3: =Y3&"|"&Z3 -> dzriszc5pnz15ca|LOL · C9 vs FUR|K13
A4: LOL · C9 vs FUR | B4: Tactical | C4: C9 | D4: Maps 1-3 Kills | E4: 13.5 | F4: {=IFERROR(INDEX(CHOOSE(MATCH($Z4,{"K1","K12","K13"},0),Calc!$Y$2:$Y$19,Calc!$AA$2:$AA$19,Calc!$AC$2:$AC$19),MATCH($Y4,Calc!$A$2:$A$19,0)),"")} -> 11.159779 | G4: {=IFERROR(SQRT(INDEX(CHOOSE(MATCH($Z4,{"K1","K12","K13"},0),Calc!$Z$2:$Z$19,Calc!$AB$2:$AB$19,Calc!$AD$2:$AD$19),MATCH($Y4,Calc!$A$2:$A$19,0))),"")} -> 4.2699378 | H4: =IF(OR($E4="",$F4="",N($G4)<=0),"",1-NORMDIST(FLOOR($E4,1)+0.5,$F4,$G4,TRUE())) -> 0.29182224 | I4: =IF($H4="","",NORMDIST(CEILING($E4,1)-0.5,$F4,$G4,TRUE())) -> 0.70817776 | J4: =IF($H4="","",MAX(0,1-$H4-$I4)) -> 0 | K4: =IF($H4="","",IF($H4>=0.5+Config!$B$8,"OVER",IF($I4>=0.5+Config!$B$8,"UNDER","—"))) -> UNDER | L4: {=IFERROR(INDEX(CHOOSE(MATCH($Z4,{"K1","K12","K13"},0),Calc!$AE$2:$AE$19,Calc!$AF$2:$AF$19,Calc!$AG$2:$AG$19),MATCH($Y4,Calc!$A$2:$A$19,0)),"")} -> 10.2 | M4: =IF(OR($E4="",$L4="",N($G4)<=0),"",1-NORMDIST(FLOOR($E4,1)+0.5,$L4,$G4*SQRT($L4/$F4),TRUE())) -> 0.2094335 | O4: {=IFERROR(INDEX(Calc!$H$2:$H$19,MATCH($Y4,Calc!$A$2:$A$19,0)),"")} -> 0.57 | P4: {=IFERROR(INDEX(Calc!$M$2:$M$19,MATCH($Y4,Calc!$A$2:$A$19,0)),"")} -> 0.7014 | Q4: 11.4 | R4: 0.4 | S4: 0.4 | T4: 0.53 | U4: - | V4: 1 | X4: {=IFERROR(INDEX(Calc!$AH$2:$AH$19,MATCH($Y4,Calc!$A$2:$A$19,0)),"")} -> new roster: 0% of his recent games with these teammates | Y4: m04u1esa2a4edat|LOL · C9 vs FUR | Z4: K13 | AA4: =Y4&"|"&Z4 -> m04u1esa2a4edat|LOL · C9 vs FUR|K13
A5: LOL · C9 vs FUR | B5: Thanatos | C5: C9 | D5: Maps 1-3 Kills | E5: 9.5 | F5: {=IFERROR(INDEX(CHOOSE(MATCH($Z5,{"K1","K12","K13"},0),Calc!$Y$2:$Y$19,Calc!$AA$2:$AA$19,Calc!$AC$2:$AC$19),MATCH($Y5,Calc!$A$2:$A$19,0)),"")} -> 10.925075 | G5: {=IFERROR(SQRT(INDEX(CHOOSE(MATCH($Z5,{"K1","K12","K13"},0),Calc!$Z$2:$Z$19,Calc!$AB$2:$AB$19,Calc!$AD$2:$AD$19),MATCH($Y5,Calc!$A$2:$A$19,0))),"")} -> 4.2157125 | H5: =IF(OR($E5="",$F5="",N($G5)<=0),"",1-NORMDIST(FLOOR($E5,1)+0.5,$F5,$G5,TRUE())) -> 0.63233305 | I5: =IF($H5="","",NORMDIST(CEILING($E5,1)-0.5,$F5,$G5,TRUE())) -> 0.36766695 | J5: =IF($H5="","",MAX(0,1-$H5-$I5)) -> 0 | K5: =IF($H5="","",IF($H5>=0.5+Config!$B$8,"OVER",IF($I5>=0.5+Config!$B$8,"UNDER","—"))) -> OVER | L5: {=IFERROR(INDEX(CHOOSE(MATCH($Z5,{"K1","K12","K13"},0),Calc!$AE$2:$AE$19,Calc!$AF$2:$AF$19,Calc!$AG$2:$AG$19),MATCH($Y5,Calc!$A$2:$A$19,0)),"")} -> 10.2 | M5: =IF(OR($E5="",$L5="",N($G5)<=0),"",1-NORMDIST(FLOOR($E5,1)+0.5,$L5,$G5*SQRT($L5/$F5),TRUE())) -> 0.56822066 | O5: {=IFERROR(INDEX(Calc!$H$2:$H$19,MATCH($Y5,Calc!$A$2:$A$19,0)),"")} -> 0.6 | P5: {=IFERROR(INDEX(Calc!$M$2:$M$19,MATCH($Y5,Calc!$A$2:$A$19,0)),"")} -> 0.7014 | Q5: 9.2 | R5: 0.6 | S5: 0.5 | T5: 0.47 | U5: 0%/0/1 | V5: 1 | X5: {=IFERROR(INDEX(Calc!$AH$2:$AH$19,MATCH($Y5,Calc!$A$2:$A$19,0)),"")} -> new roster: 0% of his recent games with these teammates | Y5: j7y9h08j24nae95|LOL · C9 vs FUR | Z5: K13 | AA5: =Y5&"|"&Z5 -> j7y9h08j24nae95|LOL · C9 vs FUR|K13
A6: LOL · C9 vs FUR | B6: Ayu | C6: FUR | D6: Maps 1-3 Kills | E6: 9.5 | F6: {=IFERROR(INDEX(CHOOSE(MATCH($Z6,{"K1","K12","K13"},0),Calc!$Y$2:$Y$19,Calc!$AA$2:$AA$19,Calc!$AC$2:$AC$19),MATCH($Y6,Calc!$A$2:$A$19,0)),"")} -> 10.647527 | G6: {=IFERROR(SQRT(INDEX(CHOOSE(MATCH($Z6,{"K1","K12","K13"},0),Calc!$Z$2:$Z$19,Calc!$AB$2:$AB$19,Calc!$AD$2:$AD$19),MATCH($Y6,Calc!$A$2:$A$19,0))),"")} -> 4.4827248 | H6: =IF(OR($E6="",$F6="",N($G6)<=0),"",1-NORMDIST(FLOOR($E6,1)+0.5,$F6,$G6,TRUE())) -> 0.6010202 | I6: =IF($H6="","",NORMDIST(CEILING($E6,1)-0.5,$F6,$G6,TRUE())) -> 0.3989798 | J6: =IF($H6="","",MAX(0,1-$H6-$I6)) -> 0 | K6: =IF($H6="","",IF($H6>=0.5+Config!$B$8,"OVER",IF($I6>=0.5+Config!$B$8,"UNDER","—"))) -> OVER | L6: {=IFERROR(INDEX(CHOOSE(MATCH($Z6,{"K1","K12","K13"},0),Calc!$AE$2:$AE$19,Calc!$AF$2:$AF$19,Calc!$AG$2:$AG$19),MATCH($Y6,Calc!$A$2:$A$19,0)),"")} -> 13.5 | M6: =IF(OR($E6="",$L6="",N($G6)<=0),"",1-NORMDIST(FLOOR($E6,1)+0.5,$L6,$G6*SQRT($L6/$F6),TRUE())) -> 0.78595271 | O6: {=IFERROR(INDEX(Calc!$H$2:$H$19,MATCH($Y6,Calc!$A$2:$A$19,0)),"")} -> 0.6 | P6: {=IFERROR(INDEX(Calc!$M$2:$M$19,MATCH($Y6,Calc!$A$2:$A$19,0)),"")} -> 0.2986 | Q6: 13.3 | R6: 1 | S6: 0.8 | T6: 0.87 | U6: 100%/1/1 | V6: 5 | X6: {=IFERROR(INDEX(Calc!$AH$2:$AH$19,MATCH($Y6,Calc!$A$2:$A$19,0)),"")} -> new roster: 0% of his recent games with these teammates | Y6: e7oayaesoqb0bhf|LOL · C9 vs FUR | Z6: K13 | AA6: =Y6&"|"&Z6 -> e7oayaesoqb0bhf|LOL · C9 vs FUR|K13
A7: LOL · C9 vs FUR | B7: GUIGO | C7: FUR | D7: Maps 1-3 Kills | E7: 6 | F7: {=IFERROR(INDEX(CHOOSE(MATCH($Z7,{"K1","K12","K13"},0),Calc!$Y$2:$Y$19,Calc!$AA$2:$AA$19,Calc!$AC$2:$AC$19),MATCH($Y7,Calc!$A$2:$A$19,0)),"")} -> 7.51777 | G7: {=IFERROR(SQRT(INDEX(CHOOSE(MATCH($Z7,{"K1","K12","K13"},0),Calc!$Z$2:$Z$19,Calc!$AB$2:$AB$19,Calc!$AD$2:$AD$19),MATCH($Y7,Calc!$A$2:$A$19,0))),"")} -> 3.5903135 | H7: =IF(OR($E7="",$F7="",N($G7)<=0),"",1-NORMDIST(FLOOR($E7,1)+0.5,$F7,$G7,TRUE())) -> 0.61159426 | I7: =IF($H7="","",NORMDIST(CEILING($E7,1)-0.5,$F7,$G7,TRUE())) -> 0.2870567 | J7: =IF($H7="","",MAX(0,1-$H7-$I7)) -> 0.10134905 | K7: =IF($H7="","",IF($H7>=0.5+Config!$B$8,"OVER",IF($I7>=0.5+Config!$B$8,"UNDER","—"))) -> OVER | L7: {=IFERROR(INDEX(CHOOSE(MATCH($Z7,{"K1","K12","K13"},0),Calc!$AE$2:$AE$19,Calc!$AF$2:$AF$19,Calc!$AG$2:$AG$19),MATCH($Y7,Calc!$A$2:$A$19,0)),"")} -> 10.2 | M7: =IF(OR($E7="",$L7="",N($G7)<=0),"",1-NORMDIST(FLOOR($E7,1)+0.5,$L7,$G7*SQRT($L7/$F7),TRUE())) -> 0.81185053 | O7: {=IFERROR(INDEX(Calc!$H$2:$H$19,MATCH($Y7,Calc!$A$2:$A$19,0)),"")} -> 0.7 | P7: {=IFERROR(INDEX(Calc!$M$2:$M$19,MATCH($Y7,Calc!$A$2:$A$19,0)),"")} -> 0.2986 | Q7: 9.1 | R7: 0.8 | S7: 0.7 | T7: 0.8 | U7: 100%/1/1 | V7: -1 | W7: 1 | X7: {=IFERROR(INDEX(Calc!$AH$2:$AH$19,MATCH($Y7,Calc!$A$2:$A$19,0)),"")} -> new roster: 0% of his recent games with these teammates | Y7: yfeamupxfsjv1hs|LOL · C9 vs FUR | Z7: K13 | AA7: =Y7&"|"&Z7 -> yfeamupxfsjv1hs|LOL · C9 vs FUR|K13
A8: LOL · C9 vs FUR | B8: Jojo | C8: FUR | D8: Maps 1-3 Kills | E8: 1.5 | F8: {=IFERROR(INDEX(CHOOSE(MATCH($Z8,{"K1","K12","K13"},0),Calc!$Y$2:$Y$19,Calc!$AA$2:$AA$19,Calc!$AC$2:$AC$19),MATCH($Y8,Calc!$A$2:$A$19,0)),"")} -> 1.6562819 | G8: {=IFERROR(SQRT(INDEX(CHOOSE(MATCH($Z8,{"K1","K12","K13"},0),Calc!$Z$2:$Z$19,Calc!$AB$2:$AB$19,Calc!$AD$2:$AD$19),MATCH($Y8,Calc!$A$2:$A$19,0))),"")} -> 1.5180496 | H8: =IF(OR($E8="",$F8="",N($G8)<=0),"",1-NORMDIST(FLOOR($E8,1)+0.5,$F8,$G8,TRUE())) -> 0.54099834 | I8: =IF($H8="","",NORMDIST(CEILING($E8,1)-0.5,$F8,$G8,TRUE())) -> 0.45900166 | J8: =IF($H8="","",MAX(0,1-$H8-$I8)) -> 0 | K8: =IF($H8="","",IF($H8>=0.5+Config!$B$8,"OVER",IF($I8>=0.5+Config!$B$8,"UNDER","—"))) -> OVER | L8: {=IFERROR(INDEX(CHOOSE(MATCH($Z8,{"K1","K12","K13"},0),Calc!$AE$2:$AE$19,Calc!$AF$2:$AF$19,Calc!$AG$2:$AG$19),MATCH($Y8,Calc!$A$2:$A$19,0)),"")} -> 2.1 | M8: =IF(OR($E8="",$L8="",N($G8)<=0),"",1-NORMDIST(FLOOR($E8,1)+0.5,$L8,$G8*SQRT($L8/$F8),TRUE())) -> 0.63721057 | O8: {=IFERROR(INDEX(Calc!$H$2:$H$19,MATCH($Y8,Calc!$A$2:$A$19,0)),"")} -> 0.6 | P8: {=IFERROR(INDEX(Calc!$M$2:$M$19,MATCH($Y8,Calc!$A$2:$A$19,0)),"")} -> 0.2986 | Q8: 2.1 | R8: 0.6 | S8: 0.6 | T8: 0.53 | U8: 100%/1/1 | V8: -2 | X8: {=IFERROR(INDEX(Calc!$AH$2:$AH$19,MATCH($Y8,Calc!$A$2:$A$19,0)),"")} -> new roster: 0% of his recent games with these teammates | Y8: 0puc7tc09n5mldx|LOL · C9 vs FUR | Z8: K13 | AA8: =Y8&"|"&Z8 -> 0puc7tc09n5mldx|LOL · C9 vs FUR|K13
A9: LOL · C9 vs FUR | B9: Tatu | C9: FUR | D9: Maps 1-3 Kills | E9: 7 | F9: {=IFERROR(INDEX(CHOOSE(MATCH($Z9,{"K1","K12","K13"},0),Calc!$Y$2:$Y$19,Calc!$AA$2:$AA$19,Calc!$AC$2:$AC$19),MATCH($Y9,Calc!$A$2:$A$19,0)),"")} -> 6.1911047 | G9: {=IFERROR(SQRT(INDEX(CHOOSE(MATCH($Z9,{"K1","K12","K13"},0),Calc!$Z$2:$Z$19,Calc!$AB$2:$AB$19,Calc!$AD$2:$AD$19),MATCH($Y9,Calc!$A$2:$A$19,0))),"")} -> 3.1878766 | H9: =IF(OR($E9="",$F9="",N($G9)<=0),"",1-NORMDIST(FLOOR($E9,1)+0.5,$F9,$G9,TRUE())) -> 0.34068832 | I9: =IF($H9="","",NORMDIST(CEILING($E9,1)-0.5,$F9,$G9,TRUE())) -> 0.53859586 | J9: =IF($H9="","",MAX(0,1-$H9-$I9)) -> 0.12071582 | K9: =IF($H9="","",IF($H9>=0.5+Config!$B$8,"OVER",IF($I9>=0.5+Config!$B$8,"UNDER","—"))) -> — | L9: {=IFERROR(INDEX(CHOOSE(MATCH($Z9,{"K1","K12","K13"},0),Calc!$AE$2:$AE$19,Calc!$AF$2:$AF$19,Calc!$AG$2:$AG$19),MATCH($Y9,Calc!$A$2:$A$19,0)),"")} -> 8.4 | M9: =IF(OR($E9="",$L9="",N($G9)<=0),"",1-NORMDIST(FLOOR($E9,1)+0.5,$L9,$G9*SQRT($L9/$F9),TRUE())) -> 0.59575468 | O9: {=IFERROR(INDEX(Calc!$H$2:$H$19,MATCH($Y9,Calc!$A$2:$A$19,0)),"")} -> 0.7 | P9: {=IFERROR(INDEX(Calc!$M$2:$M$19,MATCH($Y9,Calc!$A$2:$A$19,0)),"")} -> 0.2986 | Q9: 11.8 | R9: 0.8 | S9: 0.9 | T9: 0.93 | U9: 100%/1/1 | V9: 3 | W9: 1 | X9: {=IFERROR(INDEX(Calc!$AH$2:$AH$19,MATCH($Y9,Calc!$A$2:$A$19,0)),"")} -> new roster: 0% of his recent games with these teammates | Y9: bfa7dj819gxo5o8|LOL · C9 vs FUR | Z9: K13 | AA9: =Y9&"|"&Z9 -> bfa7dj819gxo5o8|LOL · C9 vs FUR|K13
A10: LOL · C9 vs FUR | B10: Tutsz | C10: FUR | D10: Maps 1-3 Kills | E10: 8.5 | F10: {=IFERROR(INDEX(CHOOSE(MATCH($Z10,{"K1","K12","K13"},0),Calc!$Y$2:$Y$19,Calc!$AA$2:$AA$19,Calc!$AC$2:$AC$19),MATCH($Y10,Calc!$A$2:$A$19,0)),"")} -> 7.9599918 | G10: {=IFERROR(SQRT(INDEX(CHOOSE(MATCH($Z10,{"K1","K12","K13"},0),Calc!$Z$2:$Z$19,Calc!$AB$2:$AB$19,Calc!$AD$2:$AD$19),MATCH($Y10,Calc!$A$2:$A$19,0))),"")} -> 3.7205861 | H10: =IF(OR($E10="",$F10="",N($G10)<=0),"",1-NORMDIST(FLOOR($E10,1)+0.5,$F10,$G10,TRUE())) -> 0.44229992 | I10: =IF($H10="","",NORMDIST(CEILING($E10,1)-0.5,$F10,$G10,TRUE())) -> 0.55770008 | J10: =IF($H10="","",MAX(0,1-$H10-$I10)) -> 0 | K10: =IF($H10="","",IF($H10>=0.5+Config!$B$8,"OVER",IF($I10>=0.5+Config!$B$8,"UNDER","—"))) -> UNDER | L10: {=IFERROR(INDEX(CHOOSE(MATCH($Z10,{"K1","K12","K13"},0),Calc!$AE$2:$AE$19,Calc!$AF$2:$AF$19,Calc!$AG$2:$AG$19),MATCH($Y10,Calc!$A$2:$A$19,0)),"")} -> 10.8 | M10: =IF(OR($E10="",$L10="",N($G10)<=0),"",1-NORMDIST(FLOOR($E10,1)+0.5,$L10,$G10*SQRT($L10/$F10),TRUE())) -> 0.70219166 | O10: {=IFERROR(INDEX(Calc!$H$2:$H$19,MATCH($Y10,Calc!$A$2:$A$19,0)),"")} -> 0.7 | P10: {=IFERROR(INDEX(Calc!$M$2:$M$19,MATCH($Y10,Calc!$A$2:$A$19,0)),"")} -> 0.2986 | Q10: 9.3 | R10: 0.4 | S10: 0.5 | T10: 0.47 | U10: 100%/1/1 | V10: -3 | X10: {=IFERROR(INDEX(Calc!$AH$2:$AH$19,MATCH($Y10,Calc!$A$2:$A$19,0)),"")} -> new roster: 0% of his recent games with these teammates | Y10: vx8t2exqb0pxqzs|LOL · C9 vs FUR | Z10: K13 | AA10: =Y10&"|"&Z10 -> vx8t2exqb0pxqzs|LOL · C9 vs FUR|K13
A11: LOL · KC vs MVK | B11: Caliste | C11: KC | D11: Maps 1-3 Kills | E11: 15.5 | F11: {=IFERROR(INDEX(CHOOSE(MATCH($Z11,{"K1","K12","K13"},0),Calc!$Y$2:$Y$19,Calc!$AA$2:$AA$19,Calc!$AC$2:$AC$19),MATCH($Y11,Calc!$A$2:$A$19,0)),"")} -> 14.704215 | G11: {=IFERROR(SQRT(INDEX(CHOOSE(MATCH($Z11,{"K1","K12","K13"},0),Calc!$Z$2:$Z$19,Calc!$AB$2:$AB$19,Calc!$AD$2:$AD$19),MATCH($Y11,Calc!$A$2:$A$19,0))),"")} -> 5.1218561 | H11: =IF(OR($E11="",$F11="",N($G11)<=0),"",1-NORMDIST(FLOOR($E11,1)+0.5,$F11,$G11,TRUE())) -> 0.43826464 | I11: =IF($H11="","",NORMDIST(CEILING($E11,1)-0.5,$F11,$G11,TRUE())) -> 0.56173536 | J11: =IF($H11="","",MAX(0,1-$H11-$I11)) -> 0 | K11: =IF($H11="","",IF($H11>=0.5+Config!$B$8,"OVER",IF($I11>=0.5+Config!$B$8,"UNDER","—"))) -> UNDER | L11: {=IFERROR(INDEX(CHOOSE(MATCH($Z11,{"K1","K12","K13"},0),Calc!$AE$2:$AE$19,Calc!$AF$2:$AF$19,Calc!$AG$2:$AG$19),MATCH($Y11,Calc!$A$2:$A$19,0)),"")} -> 15 | M11: =IF(OR($E11="",$L11="",N($G11)<=0),"",1-NORMDIST(FLOOR($E11,1)+0.5,$L11,$G11*SQRT($L11/$F11),TRUE())) -> 0.46150075 | O11: {=IFERROR(INDEX(Calc!$H$2:$H$19,MATCH($Y11,Calc!$A$2:$A$19,0)),"")} -> 0.7 | P11: {=IFERROR(INDEX(Calc!$M$2:$M$19,MATCH($Y11,Calc!$A$2:$A$19,0)),"")} -> 0.6699 | Q11: 12.3 | R11: 0.2 | S11: 0.3 | T11: 0.33 | U11: - | V11: -4 | X11: {=IFERROR(INDEX(Calc!$AH$2:$AH$19,MATCH($Y11,Calc!$A$2:$A$19,0)),"")} -> new roster: 0% of his recent games with these teammates | Y11: 60n3jocjohvthia|LOL · KC vs MVK | Z11: K13 | AA11: =Y11&"|"&Z11 -> 60n3jocjohvthia|LOL · KC vs MVK|K13
A12: LOL · KC vs MVK | B12: Canna | C12: KC | D12: Maps 1-3 Kills | E12: 9.5 | F12: {=IFERROR(INDEX(CHOOSE(MATCH($Z12,{"K1","K12","K13"},0),Calc!$Y$2:$Y$19,Calc!$AA$2:$AA$19,Calc!$AC$2:$AC$19),MATCH($Y12,Calc!$A$2:$A$19,0)),"")} -> 10.479434 | G12: {=IFERROR(SQRT(INDEX(CHOOSE(MATCH($Z12,{"K1","K12","K13"},0),Calc!$Z$2:$Z$19,Calc!$AB$2:$AB$19,Calc!$AD$2:$AD$19),MATCH($Y12,Calc!$A$2:$A$19,0))),"")} -> 4.1519362 | H12: =IF(OR($E12="",$F12="",N($G12)<=0),"",1-NORMDIST(FLOOR($E12,1)+0.5,$F12,$G12,TRUE())) -> 0.5932441 | I12: =IF($H12="","",NORMDIST(CEILING($E12,1)-0.5,$F12,$G12,TRUE())) -> 0.4067559 | J12: =IF($H12="","",MAX(0,1-$H12-$I12)) -> 0 | K12: =IF($H12="","",IF($H12>=0.5+Config!$B$8,"OVER",IF($I12>=0.5+Config!$B$8,"UNDER","—"))) -> OVER | L12: {=IFERROR(INDEX(CHOOSE(MATCH($Z12,{"K1","K12","K13"},0),Calc!$AE$2:$AE$19,Calc!$AF$2:$AF$19,Calc!$AG$2:$AG$19),MATCH($Y12,Calc!$A$2:$A$19,0)),"")} -> 10.2 | M12: =IF(OR($E12="",$L12="",N($G12)<=0),"",1-NORMDIST(FLOOR($E12,1)+0.5,$L12,$G12*SQRT($L12/$F12),TRUE())) -> 0.5678448 | O12: {=IFERROR(INDEX(Calc!$H$2:$H$19,MATCH($Y12,Calc!$A$2:$A$19,0)),"")} -> 0.63 | P12: {=IFERROR(INDEX(Calc!$M$2:$M$19,MATCH($Y12,Calc!$A$2:$A$19,0)),"")} -> 0.6699 | Q12: 8.9 | R12: 0.4 | S12: 0.4 | T12: 0.47 | U12: - | V12: -3 | X12: {=IFERROR(INDEX(Calc!$AH$2:$AH$19,MATCH($Y12,Calc!$A$2:$A$19,0)),"")} -> new roster: 0% of his recent games with these teammates | Y12: 5h8ktthuwylbro2|LOL · KC vs MVK | Z12: K13 | AA12: =Y12&"|"&Z12 -> 5h8ktthuwylbro2|LOL · KC vs MVK|K13
A13: LOL · KC vs MVK | B13: Kyeahoo | C13: KC | D13: Maps 1-3 Kills | E13: 11.5 | F13: {=IFERROR(INDEX(CHOOSE(MATCH($Z13,{"K1","K12","K13"},0),Calc!$Y$2:$Y$19,Calc!$AA$2:$AA$19,Calc!$AC$2:$AC$19),MATCH($Y13,Calc!$A$2:$A$19,0)),"")} -> 7.0890286 | G13: {=IFERROR(SQRT(INDEX(CHOOSE(MATCH($Z13,{"K1","K12","K13"},0),Calc!$Z$2:$Z$19,Calc!$AB$2:$AB$19,Calc!$AD$2:$AD$19),MATCH($Y13,Calc!$A$2:$A$19,0))),"")} -> 3.2969908 | H13: =IF(OR($E13="",$F13="",N($G13)<=0),"",1-NORMDIST(FLOOR($E13,1)+0.5,$F13,$G13,TRUE())) -> 0.090468109 | I13: =IF($H13="","",NORMDIST(CEILING($E13,1)-0.5,$F13,$G13,TRUE())) -> 0.90953189 | J13: =IF($H13="","",MAX(0,1-$H13-$I13)) -> 0 | K13: =IF($H13="","",IF($H13>=0.5+Config!$B$8,"OVER",IF($I13>=0.5+Config!$B$8,"UNDER","—"))) -> UNDER | L13: {=IFERROR(INDEX(CHOOSE(MATCH($Z13,{"K1","K12","K13"},0),Calc!$AE$2:$AE$19,Calc!$AF$2:$AF$19,Calc!$AG$2:$AG$19),MATCH($Y13,Calc!$A$2:$A$19,0)),"")} -> 6.9 | M13: =IF(OR($E13="",$L13="",N($G13)<=0),"",1-NORMDIST(FLOOR($E13,1)+0.5,$L13,$G13*SQRT($L13/$F13),TRUE())) -> 0.078652512 | O13: {=IFERROR(INDEX(Calc!$H$2:$H$19,MATCH($Y13,Calc!$A$2:$A$19,0)),"")} -> 0.63 | P13: {=IFERROR(INDEX(Calc!$M$2:$M$19,MATCH($Y13,Calc!$A$2:$A$19,0)),"")} -> 0.6699 | Q13: 7 | R13: 0 | S13: 0 | T13: 0.13 | U13: - | V13: -11 | X13: {=IFERROR(INDEX(Calc!$AH$2:$AH$19,MATCH($Y13,Calc!$A$2:$A$19,0)),"")} -> new roster: 0% of his recent games with these teammates | Y13: cp4ibkwui10xeyj|LOL · KC vs MVK | Z13: K13 | AA13: =Y13&"|"&Z13 -> cp4ibkwui10xeyj|LOL · KC vs MVK|K13
A14: LOL · KC vs MVK | B14: Yike | C14: KC | D14: Maps 1-3 Kills | E14: 12.5 | F14: {=IFERROR(INDEX(CHOOSE(MATCH($Z14,{"K1","K12","K13"},0),Calc!$Y$2:$Y$19,Calc!$AA$2:$AA$19,Calc!$AC$2:$AC$19),MATCH($Y14,Calc!$A$2:$A$19,0)),"")} -> 12.020527 | G14: {=IFERROR(SQRT(INDEX(CHOOSE(MATCH($Z14,{"K1","K12","K13"},0),Calc!$Z$2:$Z$19,Calc!$AB$2:$AB$19,Calc!$AD$2:$AD$19),MATCH($Y14,Calc!$A$2:$A$19,0))),"")} -> 4.5148099 | H14: =IF(OR($E14="",$F14="",N($G14)<=0),"",1-NORMDIST(FLOOR($E14,1)+0.5,$F14,$G14,TRUE())) -> 0.4577118 | I14: =IF($H14="","",NORMDIST(CEILING($E14,1)-0.5,$F14,$G14,TRUE())) -> 0.5422882 | J14: =IF($H14="","",MAX(0,1-$H14-$I14)) -> 0 | K14: =IF($H14="","",IF($H14>=0.5+Config!$B$8,"OVER",IF($I14>=0.5+Config!$B$8,"UNDER","—"))) -> UNDER | L14: {=IFERROR(INDEX(CHOOSE(MATCH($Z14,{"K1","K12","K13"},0),Calc!$AE$2:$AE$19,Calc!$AF$2:$AF$19,Calc!$AG$2:$AG$19),MATCH($Y14,Calc!$A$2:$A$19,0)),"")} -> 11.7 | M14: =IF(OR($E14="",$L14="",N($G14)<=0),"",1-NORMDIST(FLOOR($E14,1)+0.5,$L14,$G14*SQRT($L14/$F14),TRUE())) -> 0.42873119 | O14: {=IFERROR(INDEX(Calc!$H$2:$H$19,MATCH($Y14,Calc!$A$2:$A$19,0)),"")} -> 0.63 | P14: {=IFERROR(INDEX(Calc!$M$2:$M$19,MATCH($Y14,Calc!$A$2:$A$19,0)),"")} -> 0.6699 | Q14: 9.1 | R14: 0.2 | S14: 0.2 | T14: 0.27 | U14: - | V14: -4 | X14: {=IFERROR(INDEX(Calc!$AH$2:$AH$19,MATCH($Y14,Calc!$A$2:$A$19,0)),"")} -> new roster: 0% of his recent games with these teammates | Y14: rfespsq7mcurckt|LOL · KC vs MVK | Z14: K13 | AA14: =Y14&"|"&Z14 -> rfespsq7mcurckt|LOL · KC vs MVK|K13
A15: LOL · KC vs MVK | B15: Chika | C15: MVK | D15: Maps 1-3 Kills | E15: 8.5 | F15: {=IFERROR(INDEX(CHOOSE(MATCH($Z15,{"K1","K12","K13"},0),Calc!$Y$2:$Y$19,Calc!$AA$2:$AA$19,Calc!$AC$2:$AC$19),MATCH($Y15,Calc!$A$2:$A$19,0)),"")} -> 10.493586 | G15: {=IFERROR(SQRT(INDEX(CHOOSE(MATCH($Z15,{"K1","K12","K13"},0),Calc!$Z$2:$Z$19,Calc!$AB$2:$AB$19,Calc!$AD$2:$AD$19),MATCH($Y15,Calc!$A$2:$A$19,0))),"")} -> 4.4395731 | H15: =IF(OR($E15="",$F15="",N($G15)<=0),"",1-NORMDIST(FLOOR($E15,1)+0.5,$F15,$G15,TRUE())) -> 0.67330189 | I15: =IF($H15="","",NORMDIST(CEILING($E15,1)-0.5,$F15,$G15,TRUE())) -> 0.32669811 | J15: =IF($H15="","",MAX(0,1-$H15-$I15)) -> 0 | K15: =IF($H15="","",IF($H15>=0.5+Config!$B$8,"OVER",IF($I15>=0.5+Config!$B$8,"UNDER","—"))) -> OVER | L15: {=IFERROR(INDEX(CHOOSE(MATCH($Z15,{"K1","K12","K13"},0),Calc!$AE$2:$AE$19,Calc!$AF$2:$AF$19,Calc!$AG$2:$AG$19),MATCH($Y15,Calc!$A$2:$A$19,0)),"")} -> 11.4 | M15: =IF(OR($E15="",$L15="",N($G15)<=0),"",1-NORMDIST(FLOOR($E15,1)+0.5,$L15,$G15*SQRT($L15/$F15),TRUE())) -> 0.73457519 | O15: {=IFERROR(INDEX(Calc!$H$2:$H$19,MATCH($Y15,Calc!$A$2:$A$19,0)),"")} -> 0.43 | P15: {=IFERROR(INDEX(Calc!$M$2:$M$19,MATCH($Y15,Calc!$A$2:$A$19,0)),"")} -> 0.3301 | Q15: 12.1 | R15: 0.8 | S15: 0.8 | U15: - | V15: 1 | X15: {=IFERROR(INDEX(Calc!$AH$2:$AH$19,MATCH($Y15,Calc!$A$2:$A$19,0)),"")} -> new roster: 0% of his recent games with these teammates | Y15: r22pe1iajr6mhdp|LOL · KC vs MVK | Z15: K13 | AA15: =Y15&"|"&Z15 -> r22pe1iajr6mhdp|LOL · KC vs MVK|K13
A16: LOL · KC vs MVK | B16: Gury | C16: MVK | D16: Maps 1-3 Kills | E16: 7 | F16: {=IFERROR(INDEX(CHOOSE(MATCH($Z16,{"K1","K12","K13"},0),Calc!$Y$2:$Y$19,Calc!$AA$2:$AA$19,Calc!$AC$2:$AC$19),MATCH($Y16,Calc!$A$2:$A$19,0)),"")} -> 5.7990872 | G16: {=IFERROR(SQRT(INDEX(CHOOSE(MATCH($Z16,{"K1","K12","K13"},0),Calc!$Z$2:$Z$19,Calc!$AB$2:$AB$19,Calc!$AD$2:$AD$19),MATCH($Y16,Calc!$A$2:$A$19,0))),"")} -> 3.0646428 | H16: =IF(OR($E16="",$F16="",N($G16)<=0),"",1-NORMDIST(FLOOR($E16,1)+0.5,$F16,$G16,TRUE())) -> 0.28944331 | I16: =IF($H16="","",NORMDIST(CEILING($E16,1)-0.5,$F16,$G16,TRUE())) -> 0.59045263 | J16: =IF($H16="","",MAX(0,1-$H16-$I16)) -> 0.12010406 | K16: =IF($H16="","",IF($H16>=0.5+Config!$B$8,"OVER",IF($I16>=0.5+Config!$B$8,"UNDER","—"))) -> UNDER | L16: {=IFERROR(INDEX(CHOOSE(MATCH($Z16,{"K1","K12","K13"},0),Calc!$AE$2:$AE$19,Calc!$AF$2:$AF$19,Calc!$AG$2:$AG$19),MATCH($Y16,Calc!$A$2:$A$19,0)),"")} -> 6.3 | M16: =IF(OR($E16="",$L16="",N($G16)<=0),"",1-NORMDIST(FLOOR($E16,1)+0.5,$L16,$G16*SQRT($L16/$F16),TRUE())) -> 0.3535797 | O16: {=IFERROR(INDEX(Calc!$H$2:$H$19,MATCH($Y16,Calc!$A$2:$A$19,0)),"")} -> 0.43 | P16: {=IFERROR(INDEX(Calc!$M$2:$M$19,MATCH($Y16,Calc!$A$2:$A$19,0)),"")} -> 0.3301 | Q16: 7.5 | R16: 0.4 | S16: 0.4 | T16: 0.33 | U16: - | V16: -2 | W16: 1 | X16: {=IFERROR(INDEX(Calc!$AH$2:$AH$19,MATCH($Y16,Calc!$A$2:$A$19,0)),"")} -> new roster: 0% of his recent games with these teammates | Y16: jr80asvwieexg6m|LOL · KC vs MVK | Z16: K13 | AA16: =Y16&"|"&Z16 -> jr80asvwieexg6m|LOL · KC vs MVK|K13
A17: LOL · KC vs MVK | B17: Harky | C17: MVK | D17: Maps 1-3 Kills | E17: 9 | F17: {=IFERROR(INDEX(CHOOSE(MATCH($Z17,{"K1","K12","K13"},0),Calc!$Y$2:$Y$19,Calc!$AA$2:$AA$19,Calc!$AC$2:$AC$19),MATCH($Y17,Calc!$A$2:$A$19,0)),"")} -> 8.8935166 | G17: {=IFERROR(SQRT(INDEX(CHOOSE(MATCH($Z17,{"K1","K12","K13"},0),Calc!$Z$2:$Z$19,Calc!$AB$2:$AB$19,Calc!$AD$2:$AD$19),MATCH($Y17,Calc!$A$2:$A$19,0))),"")} -> 3.9900193 | H17: =IF(OR($E17="",$F17="",N($G17)<=0),"",1-NORMDIST(FLOOR($E17,1)+0.5,$F17,$G17,TRUE())) -> 0.43959343 | I17: =IF($H17="","",NORMDIST(CEILING($E17,1)-0.5,$F17,$G17,TRUE())) -> 0.46071791 | J17: =IF($H17="","",MAX(0,1-$H17-$I17)) -> 0.099688662 | K17: =IF($H17="","",IF($H17>=0.5+Config!$B$8,"OVER",IF($I17>=0.5+Config!$B$8,"UNDER","—"))) -> — | L17: {=IFERROR(INDEX(CHOOSE(MATCH($Z17,{"K1","K12","K13"},0),Calc!$AE$2:$AE$19,Calc!$AF$2:$AF$19,Calc!$AG$2:$AG$19),MATCH($Y17,Calc!$A$2:$A$19,0)),"")} -> 10.2 | M17: =IF(OR($E17="",$L17="",N($G17)<=0),"",1-NORMDIST(FLOOR($E17,1)+0.5,$L17,$G17*SQRT($L17/$F17),TRUE())) -> 0.56506251 | O17: {=IFERROR(INDEX(Calc!$H$2:$H$19,MATCH($Y17,Calc!$A$2:$A$19,0)),"")} -> 0.5 | P17: {=IFERROR(INDEX(Calc!$M$2:$M$19,MATCH($Y17,Calc!$A$2:$A$19,0)),"")} -> 0.3301 | Q17: 9.7 | R17: 0.8 | S17: 0.7 | T17: 0.73 | U17: - | V17: 2 | W17: 3 | X17: {=IFERROR(INDEX(Calc!$AH$2:$AH$19,MATCH($Y17,Calc!$A$2:$A$19,0)),"")} -> new roster: 0% of his recent games with these teammates | Y17: tuhm132yvf0f8gg|LOL · KC vs MVK | Z17: K13 | AA17: =Y17&"|"&Z17 -> tuhm132yvf0f8gg|LOL · KC vs MVK|K13
A18: LOL · KC vs MVK | B18: Kratos | C18: MVK | D18: Maps 1-3 Kills | E18: 6 | F18: {=IFERROR(INDEX(CHOOSE(MATCH($Z18,{"K1","K12","K13"},0),Calc!$Y$2:$Y$19,Calc!$AA$2:$AA$19,Calc!$AC$2:$AC$19),MATCH($Y18,Calc!$A$2:$A$19,0)),"")} -> 7.4559693 | G18: {=IFERROR(SQRT(INDEX(CHOOSE(MATCH($Z18,{"K1","K12","K13"},0),Calc!$Z$2:$Z$19,Calc!$AB$2:$AB$19,Calc!$AD$2:$AD$19),MATCH($Y18,Calc!$A$2:$A$19,0))),"")} -> 3.5715893 | H18: =IF(OR($E18="",$F18="",N($G18)<=0),"",1-NORMDIST(FLOOR($E18,1)+0.5,$F18,$G18,TRUE())) -> 0.60551923 | I18: =IF($H18="","",NORMDIST(CEILING($E18,1)-0.5,$F18,$G18,TRUE())) -> 0.29196724 | J18: =IF($H18="","",MAX(0,1-$H18-$I18)) -> 0.10251353 | K18: =IF($H18="","",IF($H18>=0.5+Config!$B$8,"OVER",IF($I18>=0.5+Config!$B$8,"UNDER","—"))) -> OVER | L18: {=IFERROR(INDEX(CHOOSE(MATCH($Z18,{"K1","K12","K13"},0),Calc!$AE$2:$AE$19,Calc!$AF$2:$AF$19,Calc!$AG$2:$AG$19),MATCH($Y18,Calc!$A$2:$A$19,0)),"")} -> 8.1 | M18: =IF(OR($E18="",$L18="",N($G18)<=0),"",1-NORMDIST(FLOOR($E18,1)+0.5,$L18,$G18*SQRT($L18/$F18),TRUE())) -> 0.66633001 | O18: {=IFERROR(INDEX(Calc!$H$2:$H$19,MATCH($Y18,Calc!$A$2:$A$19,0)),"")} -> 0.43 | P18: {=IFERROR(INDEX(Calc!$M$2:$M$19,MATCH($Y18,Calc!$A$2:$A$19,0)),"")} -> 0.3301 | Q18: 7.6 | R18: 1 | S18: 0.8 | T18: 0.67 | U18: - | V18: 5 | W18: 2 | X18: {=IFERROR(INDEX(Calc!$AH$2:$AH$19,MATCH($Y18,Calc!$A$2:$A$19,0)),"")} -> new roster: 0% of his recent games with these teammates | Y18: zzsjtlvrbi44rqp|LOL · KC vs MVK | Z18: K13 | AA18: =Y18&"|"&Z18 -> zzsjtlvrbi44rqp|LOL · KC vs MVK|K13
A19: LOL · KC vs MVK | B19: Siuloong | C19: MVK | D19: Maps 1-3 Kills | E19: 1.5 | F19: {=IFERROR(INDEX(CHOOSE(MATCH($Z19,{"K1","K12","K13"},0),Calc!$Y$2:$Y$19,Calc!$AA$2:$AA$19,Calc!$AC$2:$AC$19),MATCH($Y19,Calc!$A$2:$A$19,0)),"")} -> 1.9330291 | G19: {=IFERROR(SQRT(INDEX(CHOOSE(MATCH($Z19,{"K1","K12","K13"},0),Calc!$Z$2:$Z$19,Calc!$AB$2:$AB$19,Calc!$AD$2:$AD$19),MATCH($Y19,Calc!$A$2:$A$19,0))),"")} -> 1.648894 | H19: =IF(OR($E19="",$F19="",N($G19)<=0),"",1-NORMDIST(FLOOR($E19,1)+0.5,$F19,$G19,TRUE())) -> 0.60357745 | I19: =IF($H19="","",NORMDIST(CEILING($E19,1)-0.5,$F19,$G19,TRUE())) -> 0.39642255 | J19: =IF($H19="","",MAX(0,1-$H19-$I19)) -> 0 | K19: =IF($H19="","",IF($H19>=0.5+Config!$B$8,"OVER",IF($I19>=0.5+Config!$B$8,"UNDER","—"))) -> OVER | L19: {=IFERROR(INDEX(CHOOSE(MATCH($Z19,{"K1","K12","K13"},0),Calc!$AE$2:$AE$19,Calc!$AF$2:$AF$19,Calc!$AG$2:$AG$19),MATCH($Y19,Calc!$A$2:$A$19,0)),"")} -> 2.1 | M19: =IF(OR($E19="",$L19="",N($G19)<=0),"",1-NORMDIST(FLOOR($E19,1)+0.5,$L19,$G19*SQRT($L19/$F19),TRUE())) -> 0.63649838 | O19: {=IFERROR(INDEX(Calc!$H$2:$H$19,MATCH($Y19,Calc!$A$2:$A$19,0)),"")} -> 0.43 | P19: {=IFERROR(INDEX(Calc!$M$2:$M$19,MATCH($Y19,Calc!$A$2:$A$19,0)),"")} -> 0.3301 | Q19: 2.5 | R19: 0.6 | S19: 0.8 | T19: 0.8 | U19: - | V19: 2 | X19: {=IFERROR(INDEX(Calc!$AH$2:$AH$19,MATCH($Y19,Calc!$A$2:$A$19,0)),"")} -> new roster: 0% of his recent games with these teammates | Y19: 16tiv29rhyefoti|LOL · KC vs MVK | Z19: K13 | AA19: =Y19&"|"&Z19 -> 16tiv29rhyefoti|LOL · KC vs MVK|K13

Sheet Calc
A1: Key | B1: Match | C1: Team | D1: Player | E1: PID | F1: Side | G1: Maps n | H1: Win rate q | I1: K avg | J1: k win | K1: k loss | L1: Env | M1: M1 p win | N1: M1 p played | O1: M1 mean | P1: M1 var | Q1: M2 p win | R1: M2 p played | S1: M2 mean | T1: M2 var | U1: M3 p win | V1: M3 p played | W1: M3 mean | X1: M3 var | Y1: K1 | Z1: K1 var | AA1: K12 | AB1: K12 var | AC1: K13 | AD1: K13 var | AE1: Naive K1 | AF1: Naive K12 | AG1: Naive K13 | AH1: Flags | AI1: Board rank | AJ1: Series code | AK1: Series proj
