Workbook

Sheet README
A1: FPS Player Model — CS2 + Valorant
A2: Kills and headshot projections built map by map: per-map KPR × the rounds you expect on that map.
A3: Slate 2026-10-29 · 260 board legs · 19 matches
A5: HOW TO USE
A6: 1. Matches tab: every match on the slate, one row each. The shaded columns are yours — Map 1, Map 2, Map 3 (dropdowns) and Rounds M1/M2/M3. They arrive prefilled: maps from PickFinder's Map Picks, rounds from Thunderpick's Total Rounds ladder for that map. Change any of them and every projection for that match recalculates.
A7: 2. Board tab: pick a match in the shaded cell B2. Both rosters load, ranked by projected Maps 1-2 kills, with the PrizePicks line, the model's P(over), Thunderpick's own kill-line median and PickFinder's L10 beside it.
A8: 3. Projections tab: every leg on the board (Maps 1-2, Map 1, Map 2 — kills and HS), filterable.
A9: 4. Log tab: the same projections frozen as values at default settings when the sheet was built. Type the result in Actual after settlement; Result fills itself. This is the forward record the model does not yet have.
A11: THE MODEL, IN FOUR LINES
A12: Per-map KPR = (n × map KPR + SHRINK_MAPS × overall KPR) ÷ (n + SHRINK_MAPS), n = maps the player has on that map in PickFinder's sample. A map he has never played uses his overall KPR.
A13: Kills on map k = per-map KPR × rounds on map k. Maps 1-2 = map 1 + map 2. Maps 1-3 = maps 1-2 + P(map 3) × map 3.
A14: HS on map k = kills on map k × per-map HS%, shrunk the same way. (CS2 only — PickFinder posts no Valorant HS%.)
... A36: Each slate is rebuilt from fresh captures and imported over this file (File → Import → Replace spreadsheet), so the link stays the same. Your shaded edits are per slate and are replaced on the next import.

Sheet Match_Intel
A1: Match Intel — 2026-10-29
A2: Recent form, margins, ranks, pistols, map pools and recent vetoes per match. Windows: HLTV 3 months to the day before the slate; vlr last 10 series. Bucket probabilities are the frozen v2 model (PAPER, not a pick). Margins are rounds: + won by, − lost by.
A4: CS2 · FUT vs NEMI | 08:00 UTC | Bo3 | Win: FUT 72% – NEMI 28% | 2-0 43% · 2-1 29% · 1-2 14% · 0-2 14%
B5: FUT Esports (FUT) | C5: Nemiga (NEMI)
A6: Rank | B6: HLTV: #7 · VRS: #8 | C6: HLTV: #21 · VRS: #17
A7: Last 10 maps (newest first) | B7: 7-3 W W L W W W W L L W | C7: 6-4 W W W W L L L L W W
A8: Last 10 maps, avg margin | B8: +2.2 | C8: +1.3
A9: 3 months: maps W-L | B9: 20-12 (62%) | C9: 80-38 (68%)
A10: Avg margin in wins / losses | B10: +5.0 / -4.2 | C10: +5.2 / -4.6
A11: Stomps for / against (8+) | B11: 3 / 1 | C11: 18 / 6
A12: Pistols (3 months) | B12: not captured | C12: 55.9% (132-104) · R2 conv 82.6% · R2 break 13.5%
A13: Kill share (last 6 series, all maps) | B13: 6 series · 14 maps · team 70.9 kills/map dem0n 23.9% (16.9/map) Krabeni 21.1% (14.9/map) xfl0ud 18.8% (13.3/map) dziugss 16.2% (11.5/map) SunPayus 11.6% (16.4/map) cmtry 8.5% (12.0/map) | C13: 6 series · 12 maps · team 86.7 kills/map syph0 22.8% (19.8/map) KaiR0N- 21.8% (18.9/map) khaN 19.7% (17.1/map) Xant3r 18.2% (15.8/map) robo 17.5% (15.2/map)
A14: Last 5 series | B14: 2 - 1 FUT vs Vitality 2 - 0 FUT vs Liquid 2 - 0 FUT vs TYLOO 0 - 2 FUT vs Vitality 2 - 0 FUT vs Inner Circle | C14: 0 - 2 The MongolZ vs Nemiga 2 - 0 Nemiga vs The MongolZ 2 - 0 Nemiga vs DENDELE 0 - 2 Nemiga vs Aurora 0 - 2 Nemiga vs BETBOOM
A15: Recent vetoes (last 5) | B15: First ban: Inferno×4, Dust2×1 First pick: Mirage×2, Dust2×1 26th of Octo FUT vs Vitality: us ban Inferno · opp ban Ancient · us pick Mirage · opp pick Dust2 · opp ban Nuke · us ban Cache · left Anubis 25th of Octo FUT vs Liquid: opp ban Ancient · us ban Inferno · opp pick Cache · us pick Dust2 · us ban Anubis · opp ban Nuke · left Mirage 24th of Octo FUT vs TYLOO: opp ban Dust2 · us ban Inferno · opp pick Nuke · us pick Ancient · us ban Cache · opp ban Anubis · left Mirage 31st of Augu FUT vs Vitality: us ban Inferno · opp ban Ancient · us pick Anubis · opp pick Dust2 · us ban Nuke · opp ban Mirage · left Cache 30th of Augu FUT vs Inner Circle: us ban Dust2 · opp ban Ancient · us pick Mirage · opp pick Nuke · us ban Cache · opp ban Inferno · left Anubis | C15: First ban: Inferno×4, Nuke×1 First pick: Cache×2, Ancient×1 28th of Octo The MongolZ vs Nemiga: us ban Inferno · opp ban Anubis · us pick Cache · opp pick Dust2 · opp ban Nuke · us ban Ancient · left Mirage 28th of Octo Nemiga vs The MongolZ: us ban Inferno · opp ban Anubis · us pick Cache · opp pick Dust2 · opp ban Nuke · us ban Ancient · left Mirage 27th of Octo Nemiga vs DENDELE: opp ban Dust2 · us ban Inferno · opp pick Nuke · us pick Ancient · us ban Anubis · opp ban Cache · left Mirage 26th of Octo Nemiga vs Aurora: us ban Inferno · opp ban Ancient · us pick Mirage · opp pick Anubis · opp ban Dust2 · us ban Cache · left Nuke 25th of Octo Nemiga vs BETBOOM: us ban Nuke · opp ban Cache · us pick Anubis · opp pick Mirage · opp ban Inferno · us ban Dust2 · left Ancient
A16: Map | B16: PF pick % | C16: A maps | D16: A W-L | E16: A avg ± | F16: A CT % | G16: A T % | H16: A pistol | I16: B maps | J16: B W-L | K16: B avg ± | L16: B CT % | M16: B T % | N16: B pistol | O16: A 8+ | A 3-7 | close/OT | B 3-7 | B 8+ | P16: E rounds
A17: Ancient | B17: 23% | C17: 8 | D17: 5-3 | E17: +2.6 | F17: 53.7% | G17: 58.1% | H17: 9/16 | I17: 26 | J17: 17-9 | K17: +1.8 | L17: 50.3% | M17: 57.2% | N17: 27/52 | O17: 6% | 28% | 31% | 29% | 6% | P17: 22.5
A18: Dust2 | B18: 19% | C18: 7 | D18: 4-3 | E18: +0.6 | F18: 44.7% | G18: 57.6% | H18: 7/14 | I18: 21 | J18: 13-8 | K18: +1.5 | L18: 52.4% | M18: 54.8% | N18: 23/42 | O18: 5% | 25% | 30% | 33% | 8% | P18: 22.5
A19: Mirage | B19: 16% | C19: 5 | D19: 4-1 | E19: +2.0 | F19: 66.1% | G19: 42.9% | H19: 7/10 | I19: 19 | J19: 13-6 | K19: +1.9 | L19: 63.1% | M19: 44.8% | N19: 24/38 | O19: 6% | 26% | 31% | 30% | 8% | P19: 22.5
A20: Anubis | C20: 5 | D20: 3-2 | E20: +2.0 | F20: 54.0% | G20: 55.2% | H20: 7/10 | I20: 17 | J20: 12-5 | K20: +2.2 | L20: 58.1% | M20: 51.3% | N20: 21/34 | O20: 5% | 26% | 30% | 32% | 7% | P20: 22.5
A21: Cache | C21: 2 | D21: 2-0 | E21: +5.5 | F21: 69.6% | G21: 55.6% | H21: 2/4 | I21: 17 | J21: 12-5 | K21: +2.7 | L21: 59.8% | M21: 53.0% | N21: 15/34 | O21: 5% | 25% | 30% | 33% | 8% | P21: 22.5
A22: Inferno | C22: 0 | I22: 1 | J22: 1-0 | K22: +6.0 | L22: 75.0% | M22: 58.3% | N22: 1/2 | O22: 5% | 26% | 30% | 32% | 7% | P22: 22.5
A23: Nuke | C23: 5 | D23: 2-3 | E23: -1.6 | F23: 45.9% | G23: 46.7% | H23: 6/10 | I23: 17 | J23: 12-5 | K23: +2.2 | L23: 60.8% | M23: 49.2% | N23: 21/34 | O23: 3% | 20% | 29% | 38% | 10% | P23: 22.3
A25: CS2 · B8 vs HOTU | 09:00 UTC | Bo3 | Win: B8 56% – HOTU 44% | 2-0 29% · 2-1 27% · 1-2 22% · 0-2 22%
B26: B8 (B8) | C26: HOTU (HOTU)
A27: Rank | B27: HLTV: #22 · VRS: #24 | C27: HLTV: #43 · VRS: #30
A28: Last 10 maps (newest first) | B28: 5-5 W W L W W L L L W L | C28: 6-4 W W W W L L L L W W
A29: Last 10 maps, avg margin | B29: -0.2 | C29: +0.5
A30: 3 months: maps W-L | B30: 29-20 (59%) | C30: 61-35 (64%)
A31: Avg margin in wins / losses | B31: +5.1 / -4.5 | C31: +6.0 / -5.4
A32: Stomps for / against (8+) | B32: 9 / 2 | C32: 19 / 9
A33: Pistols (3 months) | B33: not captured | C33: 59.4% (114-78) · R2 conv 87.5% · R2 break 7.7%
A34: Kill share (last 6 series, all maps) | B34: 6 series · 15 maps · team 68.2 kills/map esenthial 21.4% (14.6/map) npl 21.3% (14.5/map) s1zzi 19.6% (13.4/map) kensizor 19.6% (13.3/map) alex666 18.1% (12.3/map) | C34: 6 series · 14 maps · team 70.6 kills/map n0rb3r7 23.0% (16.2/map) frontales 22.7% (16.0/map) mizu 20.0% (14.1/map) dwushka 18.6% (13.1/map) kade0 15.7% (11.1/map)
A35: Last 5 series | B35: 2 - 1 B8 vs K27 2 - 1 B8 vs Alliance 1 - 2 B8 vs K27 0 - 2 B8 vs fnatic 0 - 2 B8 vs Luminosity | C35: 2 - 0 HOTU vs GamerLegion 2 - 0 HOTU vs Luminosity 0 - 2 HOTU vs fnatic 1 - 2 HOTU vs Astralis 2 - 0 HOTU vs fnatic
A36: Recent vetoes (last 5) | B36: First ban: Anubis×4, Nuke×1 First pick: Mirage×3, Dust2×2 28th of Octo B8 vs K27: opp ban Inferno · us ban Anubis · opp pick Nuke · us pick Dust2 · opp ban Ancient · us ban Cache · left Mirage 28th of Octo B8 vs Alliance: opp ban Cache · us ban Anubis · opp pick Inferno · us pick Mirage · opp ban Dust2 · us ban Nuke · left Ancient 27th of Octo B8 vs K27: opp ban Inferno · us ban Anubis · opp pick Mirage · us pick Dust2 · opp ban Ancient · us ban Cache · left Nuke 2nd of Octob B8 vs fnatic: opp ban Nuke · us ban Anubis · opp pick Cache · us pick Mirage · us ban Inferno · opp ban Dust2 · left Ancient 1st of Octob B8 vs Luminosity: opp ban Cache · us ban Nuke · opp pick Inferno · us pick Mirage · us ban Dust2 · opp ban Anubis · left Ancient | C36: First ban: Inferno×4, Anubis×1 First pick: Dust2×4, Mirage×1 28th of Octo HOTU vs GamerLegion: opp ban Anubis · us ban Inferno · opp pick Cache · us pick Dust2 · opp ban Mirage · us ban Nuke · left Ancient 27th of Octo HOTU vs Luminosity: us ban Anubis · opp ban Cache · us pick Mirage · opp pick Ancient · us ban Nuke · opp ban Dust2 · left Inferno 14th of Octo HOTU vs fnatic: opp ban Nuke · us ban Inferno · opp pick Ancient · us pick Dust2 · opp ban Mirage · us ban Anubis · left Cache 14th of Octo HOTU vs Astralis: us ban Inferno · opp ban Anubis · us pick Dust2 · opp pick Ancient · us ban Mirage · opp ban Cache · left Nuke 14th of Octo HOTU vs fnatic: opp ban Nuke · us ban Inferno · opp pick Ancient · us pick Dust2 · opp ban Mirage · us ban Anubis · left Cache
A37: Map | B37: PF pick % | C37: A maps | D37: A W-L | E37: A avg ± | F37: A CT % | G37: A T % | H37: A pistol | I37: B maps | J37: B W-L | K37: B avg ± | L37: B CT % | M37: B T % | N37: B pistol | O37: A 8+ | A 3-7 | close/OT | B 3-7 | B 8+ | P37: E rounds
A38: Dust2 | B38: 26% | C38: 10 | D38: 7-3 | E38: +1.2 | F38: 56.5% | G38: 48.3% | H38: 8/20 | I38: 22 | J38: 15-7 | K38: +3.5 | L38: 55.3% | M38: 61.2% | N38: 27/44 | O38: 3% | 20% | 29% | 38% | 10% | P38: 22.3
A39: Cache | B39: 21% | C39: 5 | D39: 3-2 | E39: +1.6 | F39: 60.0% | G39: 45.8% | H39: 6/10 | I39: 21 | J39: 14-7 | K39: +2.0 | L39: 62.6% | M39: 47.2% | N39: 19/42 | O39: 5% | 24% | 30% | 33% | 8% | P39: 22.5
A40: Mirage | B40: 21% | C40: 15 | D40: 8-7 | E40: +1.4 | F40: 55.6% | G40: 51.4% | H40: 21/30 | I40: 10 | J40: 8-2 | K40: +3.3 | L40: 63.6% | M40: 50.5% | N40: 15/20 | O40: 5% | 26% | 30% | 32% | 7% | P40: 22.5
A41: Ancient | C41: 8 | D41: 6-2 | E41: +3.5 | F41: 61.3% | G41: 54.0% | H41: 9/16 | I41: 14 | J41: 8-6 | K41: +1.1 | L41: 57.4% | M41: 45.7% | N41: 18/28 | O41: 8% | 34% | 30% | 23% | 4% | P41: 22.5
A42: Anubis | C42: 0 | I42: 16 | J42: 9-7 | K42: +0.2 | L42: 46.6% | M42: 53.5% | N42: 20/32 | O42: 6% | 29% | 30% | 29% | 6% | P42: 22.5
...

Sheet Board
A1: Board
A2: Match: | B2: CS2 · FUT vs NEMI
A4: Teams | B4: =IFERROR(IF(INDEX(Matches!$E$5:$E$23,MATCH($B$2,Matches!$A$5:$A$23,0))="","",INDEX(Matches!$E$5:$E$23,MATCH($B$2,Matches!$A$5:$A$23,0))),"")&" vs "&IFERROR(IF(INDEX(Matches!$F$5:$F$23,MATCH($B$2,Matches!$A$5:$A$23,0))="","",INDEX(Matches!$F$5:$F$23,MATCH($B$2,Matches!$A$5:$A$23,0))),"") -> FUT Esports (FUT) vs Nemiga (NEMI) | D4: Start (CT) | E4: =IFERROR(IF(INDEX(Matches!$C$5:$C$23,MATCH($B$2,Matches!$A$5:$A$23,0))="","",INDEX(Matches!$C$5:$C$23,MATCH($B$2,Matches!$A$5:$A$23,0))),"") -> Thu 03:00 | G4: Bo | H4: =IFERROR(IF(INDEX(Matches!$D$5:$D$23,MATCH($B$2,Matches!$A$5:$A$23,0))="","",INDEX(Matches!$D$5:$D$23,MATCH($B$2,Matches!$A$5:$A$23,0))),"") -> 3
A5: P(A wins) | B5: =IFERROR(IF(INDEX(Matches!$G$5:$G$23,MATCH($B$2,Matches!$A$5:$A$23,0))="","",INDEX(Matches!$G$5:$G$23,MATCH($B$2,Matches!$A$5:$A$23,0))),"") -> 0.72052402 | D5: P(A 2-0) | E5: =IFERROR(IF(INDEX(Matches!$H$5:$H$23,MATCH($B$2,Matches!$A$5:$A$23,0))="","",INDEX(Matches!$H$5:$H$23,MATCH($B$2,Matches!$A$5:$A$23,0))),"") -> 0.42735406 | G5: P(B 2-0) | H5: =IFERROR(IF(INDEX(Matches!$I$5:$I$23,MATCH($B$2,Matches!$A$5:$A$23,0))="","",INDEX(Matches!$I$5:$I$23,MATCH($B$2,Matches!$A$5:$A$23,0))),"") -> 0.13566796
A6: P(3 maps) | B6: =IFERROR(IF(INDEX(Matches!$J$5:$J$23,MATCH($B$2,Matches!$A$5:$A$23,0))="","",INDEX(Matches!$J$5:$J$23,MATCH($B$2,Matches!$A$5:$A$23,0))),"") -> 0.43697798 | D6: Map pick #1 | E6: =IFERROR(IF(INDEX(Matches!$K$5:$K$23,MATCH($B$2,Matches!$A$5:$A$23,0))="","",INDEX(Matches!$K$5:$K$23,MATCH($B$2,Matches!$A$5:$A$23,0))),"") -> Ancient 23% | G6: Map pick #2 | H6: =IFERROR(IF(INDEX(Matches!$L$5:$L$23,MATCH($B$2,Matches!$A$5:$A$23,0))="","",INDEX(Matches!$L$5:$L$23,MATCH($B$2,Matches!$A$5:$A$23,0))),"") -> Dust2 19%
A7: TP rounds M1 | B7: =IFERROR(IF(INDEX(Matches!$O$5:$O$23,MATCH($B$2,Matches!$A$5:$A$23,0))="","",INDEX(Matches!$O$5:$O$23,MATCH($B$2,Matches!$A$5:$A$23,0))),"") -> 21.312553 | D7: TP rounds M2 | E7: =IFERROR(IF(INDEX(Matches!$P$5:$P$23,MATCH($B$2,Matches!$A$5:$A$23,0))="","",INDEX(Matches!$P$5:$P$23,MATCH($B$2,Matches!$A$5:$A$23,0))),"") -> 21.114537 | G7: P(OT) M1 | H7: =IFERROR(IF(INDEX(Matches!$R$5:$R$23,MATCH($B$2,Matches!$A$5:$A$23,0))="","",INDEX(Matches!$R$5:$R$23,MATCH($B$2,Matches!$A$5:$A$23,0))),"") -> 0.14634146
A8: A margin M1 | B8: =IFERROR(IF(INDEX(Matches!$S$5:$S$23,MATCH($B$2,Matches!$A$5:$A$23,0))="","",INDEX(Matches!$S$5:$S$23,MATCH($B$2,Matches!$A$5:$A$23,0))),"") -> 2.9314276 | D8: A rounds M1 | E8: =IFERROR(IF(INDEX(Matches!$T$5:$T$23,MATCH($B$2,Matches!$A$5:$A$23,0))="","",INDEX(Matches!$T$5:$T$23,MATCH($B$2,Matches!$A$5:$A$23,0))),"") | G8: B rounds M1 | H8: =IFERROR(IF(INDEX(Matches!$U$5:$U$23,MATCH($B$2,Matches!$A$5:$A$23,0))="","",INDEX(Matches!$U$5:$U$23,MATCH($B$2,Matches!$A$5:$A$23,0))),"") -> 10.5
A9: HLTV rounds M1 | B9: =IFERROR(IF(INDEX(Matches!$AN$5:$AN$23,MATCH($B$2,Matches!$A$5:$A$23,0))="","",INDEX(Matches!$AN$5:$AN$23,MATCH($B$2,Matches!$A$5:$A$23,0))),"") -> 21.636239 | D9: HLTV A margin M1 | E9: =IFERROR(IF(INDEX(Matches!$AO$5:$AO$23,MATCH($B$2,Matches!$A$5:$A$23,0))="","",INDEX(Matches!$AO$5:$AO$23,MATCH($B$2,Matches!$A$5:$A$23,0))),"") -> 1.496412 | G9: Hist share A / B | H9: =IF(IFERROR(IF(INDEX(Matches!$AI$5:$AI$23,MATCH($B$2,Matches!$A$5:$A$23,0))="","",INDEX(Matches!$AI$5:$AI$23,MATCH($B$2,Matches!$A$5:$A$23,0))),"")="","",TEXT(IFERROR(IF(INDEX(Matches!$AI$5:$AI$23,MATCH($B$2,Matches!$A$5:$A$23,0))="","",INDEX(Matches!$AI$5:$AI$23,MATCH($B$2,Matches!$A$5:$A$23,0))),""),"0%")&" / "&TEXT(IFERROR(IF(INDEX(Matches!$AJ$5:$AJ$23,MATCH($B$2,Matches!$A$5:$A$23,0))="","",INDEX(Matches!$AJ$5:$AJ$23,MATCH($B$2,Matches!$A$5:$A$23,0))),""),"0%")) -> 54% / 53%
A10: IN USE | B10: ="Map 1: "&IFERROR(IF(INDEX(Matches!$W$5:$W$23,MATCH($B$2,Matches!$A$5:$A$23,0))="","",INDEX(Matches!$W$5:$W$23,MATCH($B$2,Matches!$A$5:$A$23,0))),"")&" · Map 2: "&IFERROR(IF(INDEX(Matches!$X$5:$X$23,MATCH($B$2,Matches!$A$5:$A$23,0))="","",INDEX(Matches!$X$5:$X$23,MATCH($B$2,Matches!$A$5:$A$23,0))),"")&IF(IFERROR(IF(INDEX(Matches!$Y$5:$Y$23,MATCH($B$2,Matches!$A$5:$A$23,0))="","",INDEX(Matches!$Y$5:$Y$23,MATCH($B$2,Matches!$A$5:$A$23,0))),"")="",""," · Map 3: "&IFERROR(IF(INDEX(Matches!$Y$5:$Y$23,MATCH($B$2,Matches!$A$5:$A$23,0))="","",INDEX(Matches!$Y$5:$Y$23,MATCH($B$2,Matches!$A$5:$A$23,0))),"")) -> Map 1: Ancient · Map 2: Dust2 · Map 3: Mirage
B11: ="Rounds: "&TEXT(IFERROR(IF(INDEX(Matches!$Z$5:$Z$23,MATCH($B$2,Matches!$A$5:$A$23,0))="","",INDEX(Matches!$Z$5:$Z$23,MATCH($B$2,Matches!$A$5:$A$23,0))),""),"0.0")&" / "&TEXT(IFERROR(IF(INDEX(Matches!$AA$5:$AA$23,MATCH($B$2,Matches!$A$5:$A$23,0))="","",INDEX(Matches!$AA$5:$AA$23,MATCH($B$2,Matches!$A$5:$A$23,0))),""),"0.0")&IF(IFERROR(IF(INDEX(Matches!$AB$5:$AB$23,MATCH($B$2,Matches!$A$5:$A$23,0))="","",INDEX(Matches!$AB$5:$AB$23,MATCH($B$2,Matches!$A$5:$A$23,0))),"")="",""," / "&TEXT(IFERROR(IF(INDEX(Matches!$AB$5:$AB$23,MATCH($B$2,Matches!$A$5:$A$23,0))="","",INDEX(Matches!$AB$5:$AB$23,MATCH($B$2,Matches!$A$5:$A$23,0))),""),"0.0"))&" · P(map 3) "&TEXT(IFERROR(IF(INDEX(Matches!$AC$5:$AC$23,MATCH($B$2,Matches!$A$5:$A$23,0))="","",INDEX(Matches!$AC$5:$AC$23,MATCH($B$2,Matches!$A$5:$A$23,0))),""),"0%") -> Rounds: 21.3 / 21.1 / 21.2 · P(map 3) 44%
B12: ="Change maps or rounds on the Matches tab, row "&(MATCH($B$2,Matches!$A$5:$A$23,0)+4)&" (shaded cells)." -> Change maps or rounds on the Matches tab, row 5 (shaded cells).
A14: Team | B14: Player | C14: KPR M1 | D14: KPR M2 | E14: Kills M1 | F14: Kills M2 | G14: Kills 1-2 | H14: Diff mult | I14: Adj K 1-2 | J14: PP line | K14: P(over) | L14: Adj P(over) | M14: TP book | N14: PF L10 | O14: HS% 1-2 | P14: HS 1-2 | Q14: PP HS line | R14: P(over) HS | S14: Sample | T14: Flags | V14: row
A15: =IF($V15="","",INDEX(Calc!$D$2:$D$137,$V15)) -> FUT | B15: =IF($V15="","",INDEX(Calc!$E$2:$E$137,$V15)) -> Dem0N | C15: =IF($V15="","",INDEX(Calc!$T$2:$T$137,$V15)) -> 0.77333333 | D15: =IF($V15="","",INDEX(Calc!$AA$2:$AA$137,$V15)) -> 0.74714286 | E15: =IF($V15="","",INDEX(Calc!$V$2:$V$137,$V15)) -> 16.479733 | F15: =IF($V15="","",INDEX(Calc!$AC$2:$AC$137,$V15)) -> 15.772186 | G15: =IF($V15="","",INDEX(Calc!$AL$2:$AL$137,$V15)) -> 32.251919 | H15: =IF($V15="","",INDEX(Calc!$BK$2:$BK$137,$V15)) -> 0.98966019 | I15: =IF($V15="","",INDEX(Calc!$BD$2:$BD$137,$V15)) -> 31.91844 | J15: =IF($V15="","",IFERROR(INDEX(Projections!$F$2:$F$261,MATCH(INDEX(Calc!$A$2:$A$137,$V15)&"|K12",Projections!$Y$2:$Y$261,0)),"")) -> 32.5 | K15: =IF($V15="","",IFERROR(INDEX(Projections!$I$2:$I$261,MATCH(INDEX(Calc!$A$2:$A$137,$V15)&"|K12",Projections!$Y$2:$Y$261,0)),"")) -> 0.48527474 | L15: =IF($V15="","",IFERROR(INDEX(Projections!$AB$2:$AB$261,MATCH(INDEX(Calc!$A$2:$A$137,$V15)&"|K12",Projections!$Y$2:$Y$261,0)),"")) -> 0.46533655 | M15: =IF($V15="","",IFERROR(INDEX(Projections!$M$2:$M$261,MATCH(INDEX(Calc!$A$2:$A$137,$V15)&"|K12",Projections!$Y$2:$Y$261,0)),"")) -> 33.18 | N15: =IF($V15="","",IFERROR(INDEX(Projections!$P$2:$P$261,MATCH(INDEX(Calc!$A$2:$A$137,$V15)&"|K12",Projections!$Y$2:$Y$261,0)),"")) -> 0.6 | O15: =IF($V15="","",INDEX(Calc!$AP$2:$AP$137,$V15)) -> 0.68186894 | P15: =IF($V15="","",INDEX(Calc!$AN$2:$AN$137,$V15)) -> 21.991582 | Q15: =IF($V15="","",IFERROR(INDEX(Projections!$F$2:$F$261,MATCH(INDEX(Calc!$A$2:$A$137,$V15)&"|H12",Projections!$Y$2:$Y$261,0)),"")) -> 20.5 | R15: =IF($V15="","",IFERROR(INDEX(Projections!$I$2:$I$261,MATCH(INDEX(Calc!$A$2:$A$137,$V15)&"|H12",Projections!$Y$2:$Y$261,0)),"")) -> 0.611003 | S15: =IF($V15="","",INDEX(Calc!$N$2:$N$137,$V15)) -> 37 | T15: =IF($V15="","",INDEX(Calc!$AQ$2:$AQ$137,$V15)) | V15: =IFERROR(MATCH(1,Calc!$AR$2:$AR$137,0),"") -> 64
A16: =IF($V16="","",INDEX(Calc!$D$2:$D$137,$V16)) -> NEMI | B16: =IF($V16="","",INDEX(Calc!$E$2:$E$137,$V16)) -> KaiR0N | C16: =IF($V16="","",INDEX(Calc!$T$2:$T$137,$V16)) -> 0.69818182 | D16: =IF($V16="","",INDEX(Calc!$AA$2:$AA$137,$V16)) -> 0.755 | E16: =IF($V16="","",INDEX(Calc!$V$2:$V$137,$V16)) -> 14.878255 | F16: =IF($V16="","",INDEX(Calc!$AC$2:$AC$137,$V16)) -> 15.93805 | G16: =IF($V16="","",INDEX(Calc!$AL$2:$AL$137,$V16)) -> 30.816305 | H16: =IF($V16="","",INDEX(Calc!$BK$2:$BK$137,$V16)) -> 0.94165783 | I16: =IF($V16="","",INDEX(Calc!$BD$2:$BD$137,$V16)) -> 29.018414 | J16: =IF($V16="","",IFERROR(INDEX(Projections!$F$2:$F$261,MATCH(INDEX(Calc!$A$2:$A$137,$V16)&"|K12",Projections!$Y$2:$Y$261,0)),"")) -> 29.5 | K16: =IF($V16="","",IFERROR(INDEX(Projections!$I$2:$I$261,MATCH(INDEX(Calc!$A$2:$A$137,$V16)&"|K12",Projections!$Y$2:$Y$261,0)),"")) -> 0.57941691 | L16: =IF($V16="","",IFERROR(INDEX(Projections!$AB$2:$AB$261,MATCH(INDEX(Calc!$A$2:$A$137,$V16)&"|K12",Projections!$Y$2:$Y$261,0)),"")) -> 0.46988591 | M16: =IF($V16="","",IFERROR(INDEX(Projections!$M$2:$M$261,MATCH(INDEX(Calc!$A$2:$A$137,$V16)&"|K12",Projections!$Y$2:$Y$261,0)),"")) -> 0 | N16: =IF($V16="","",IFERROR(INDEX(Projections!$P$2:$P$261,MATCH(INDEX(Calc!$A$2:$A$137,$V16)&"|K12",Projections!$Y$2:$Y$261,0)),"")) -> 0.6 | O16: =IF($V16="","",INDEX(Calc!$AP$2:$AP$137,$V16)) -> 0.60270637 | P16: =IF($V16="","",INDEX(Calc!$AN$2:$AN$137,$V16)) -> 18.573183 | Q16: =IF($V16="","",IFERROR(INDEX(Projections!$F$2:$F$261,MATCH(INDEX(Calc!$A$2:$A$137,$V16)&"|H12",Projections!$Y$2:$Y$261,0)),"")) -> 18 | R16: =IF($V16="","",IFERROR(INDEX(Projections!$I$2:$I$261,MATCH(INDEX(Calc!$A$2:$A$137,$V16)&"|H12",Projections!$Y$2:$Y$261,0)),"")) -> 0.5060808 | S16: =IF($V16="","",INDEX(Calc!$N$2:$N$137,$V16)) -> 35 | T16: =IF($V16="","",INDEX(Calc!$AQ$2:$AQ$137,$V16)) | V16: =IFERROR(MATCH(2,Calc!$AR$2:$AR$137,0),"") -> 69
A17: =IF($V17="","",INDEX(Calc!$D$2:$D$137,$V17)) -> FUT | B17: =IF($V17="","",INDEX(Calc!$E$2:$E$137,$V17)) -> Krabeni | C17: =IF($V17="","",INDEX(Calc!$T$2:$T$137,$V17)) -> 0.74333333 | D17: =IF($V17="","",INDEX(Calc!$AA$2:$AA$137,$V17)) -> 0.69714286 | E17: =IF($V17="","",INDEX(Calc!$V$2:$V$137,$V17)) -> 15.840433 | F17: =IF($V17="","",INDEX(Calc!$AC$2:$AC$137,$V17)) -> 14.716686 | G17: =IF($V17="","",INDEX(Calc!$AL$2:$AL$137,$V17)) -> 30.557119 | H17: =IF($V17="","",INDEX(Calc!$BK$2:$BK$137,$V17)) -> 0.98968433 | I17: =IF($V17="","",INDEX(Calc!$BD$2:$BD$137,$V17)) -> 30.241902 | J17: =IF($V17="","",IFERROR(INDEX(Projections!$F$2:$F$261,MATCH(INDEX(Calc!$A$2:$A$137,$V17)&"|K12",Projections!$Y$2:$Y$261,0)),"")) -> 30.5 | K17: =IF($V17="","",IFERROR(INDEX(Projections!$I$2:$I$261,MATCH(INDEX(Calc!$A$2:$A$137,$V17)&"|K12",Projections!$Y$2:$Y$261,0)),"")) -> 0.5034839 | L17: =IF($V17="","",IFERROR(INDEX(Projections!$AB$2:$AB$261,MATCH(INDEX(Calc!$A$2:$A$137,$V17)&"|K12",Projections!$Y$2:$Y$261,0)),"")) -> 0.48417978 | M17: =IF($V17="","",IFERROR(INDEX(Projections!$M$2:$M$261,MATCH(INDEX(Calc!$A$2:$A$137,$V17)&"|K12",Projections!$Y$2:$Y$261,0)),"")) -> 30.94 | N17: =IF($V17="","",IFERROR(INDEX(Projections!$P$2:$P$261,MATCH(INDEX(Calc!$A$2:$A$137,$V17)&"|K12",Projections!$Y$2:$Y$261,0)),"")) -> 0.4 | O17: =IF($V17="","",INDEX(Calc!$AP$2:$AP$137,$V17)) -> 0.55600828 | P17: =IF($V17="","",INDEX(Calc!$AN$2:$AN$137,$V17)) -> 16.990011 | Q17: =IF($V17="","",IFERROR(INDEX(Projections!$F$2:$F$261,MATCH(INDEX(Calc!$A$2:$A$137,$V17)&"|H12",Projections!$Y$2:$Y$261,0)),"")) -> 17.5 | R17: =IF($V17="","",IFERROR(INDEX(Projections!$I$2:$I$261,MATCH(INDEX(Calc!$A$2:$A$137,$V17)&"|H12",Projections!$Y$2:$Y$261,0)),"")) -> 0.45544865 | S17: =IF($V17="","",INDEX(Calc!$N$2:$N$137,$V17)) -> 37 | T17: =IF($V17="","",INDEX(Calc!$AQ$2:$AQ$137,$V17)) | V17: =IFERROR(MATCH(3,Calc!$AR$2:$AR$137,0),"") -> 66
A18: =IF($V18="","",INDEX(Calc!$D$2:$D$137,$V18)) -> NEMI | B18: =IF($V18="","",INDEX(Calc!$E$2:$E$137,$V18)) -> Xant3r | C18: =IF($V18="","",INDEX(Calc!$T$2:$T$137,$V18)) -> 0.71090909 | D18: =IF($V18="","",INDEX(Calc!$AA$2:$AA$137,$V18)) -> 0.72333333 | E18: =IF($V18="","",INDEX(Calc!$V$2:$V$137,$V18)) -> 15.149473 | F18: =IF($V18="","",INDEX(Calc!$AC$2:$AC$137,$V18)) -> 15.269567 | G18: =IF($V18="","",INDEX(Calc!$AL$2:$AL$137,$V18)) -> 30.419039 | H18: =IF($V18="","",INDEX(Calc!$BK$2:$BK$137,$V18)) -> 0.94160788 | I18: =IF($V18="","",INDEX(Calc!$BD$2:$BD$137,$V18)) -> 28.642807 | J18: =IF($V18="","",IFERROR(INDEX(Projections!$F$2:$F$261,MATCH(INDEX(Calc!$A$2:$A$137,$V18)&"|K12",Projections!$Y$2:$Y$261,0)),"")) -> 27 | K18: =IF($V18="","",IFERROR(INDEX(Projections!$I$2:$I$261,MATCH(INDEX(Calc!$A$2:$A$137,$V18)&"|K12",Projections!$Y$2:$Y$261,0)),"")) -> 0.67267236 | L18: =IF($V18="","",IFERROR(INDEX(Projections!$AB$2:$AB$261,MATCH(INDEX(Calc!$A$2:$A$137,$V18)&"|K12",Projections!$Y$2:$Y$261,0)),"")) -> 0.57160757 | M18: =IF($V18="","",IFERROR(INDEX(Projections!$M$2:$M$261,MATCH(INDEX(Calc!$A$2:$A$137,$V18)&"|K12",Projections!$Y$2:$Y$261,0)),"")) -> 26.72 | N18: =IF($V18="","",IFERROR(INDEX(Projections!$P$2:$P$261,MATCH(INDEX(Calc!$A$2:$A$137,$V18)&"|K12",Projections!$Y$2:$Y$261,0)),"")) -> 0.8 | O18: =IF($V18="","",INDEX(Calc!$AP$2:$AP$137,$V18)) -> 0.54161697 | P18: =IF($V18="","",INDEX(Calc!$AN$2:$AN$137,$V18)) -> 16.475468 | Q18: =IF($V18="","",IFERROR(INDEX(Projections!$F$2:$F$261,MATCH(INDEX(Calc!$A$2:$A$137,$V18)&"|H12",Projections!$Y$2:$Y$261,0)),"")) -> 15.5 | R18: =IF($V18="","",IFERROR(INDEX(Projections!$I$2:$I$261,MATCH(INDEX(Calc!$A$2:$A$137,$V18)&"|H12",Projections!$Y$2:$Y$261,0)),"")) -> 0.58623761 | S18: =IF($V18="","",INDEX(Calc!$N$2:$N$137,$V18)) -> 35 | T18: =IF($V18="","",INDEX(Calc!$AQ$2:$AQ$137,$V18)) | V18: =IFERROR(MATCH(4,Calc!$AR$2:$AR$137,0),"") -> 73
A19: =IF($V19="","",INDEX(Calc!$D$2:$D$137,$V19)) -> NEMI | B19: =IF($V19="","",INDEX(Calc!$E$2:$E$137,$V19)) -> syph0 | C19: =IF($V19="","",INDEX(Calc!$T$2:$T$137,$V19)) -> 0.72727273 | D19: =IF($V19="","",INDEX(Calc!$AA$2:$AA$137,$V19)) -> 0.70583333 | E19: =IF($V19="","",INDEX(Calc!$V$2:$V$137,$V19)) -> 15.498182 | F19: =IF($V19="","",INDEX(Calc!$AC$2:$AC$137,$V19)) -> 14.900142 | G19: =IF($V19="","",INDEX(Calc!$AL$2:$AL$137,$V19)) -> 30.398323 | H19: =IF($V19="","",INDEX(Calc!$BK$2:$BK$137,$V19)) -> 0.94156913 | I19: =IF($V19="","",INDEX(Calc!$BD$2:$BD$137,$V19)) -> 28.622123 | J19: =IF($V19="","",IFERROR(INDEX(Projections!$F$2:$F$261,MATCH(INDEX(Calc!$A$2:$A$137,$V19)&"|K12",Projections!$Y$2:$Y$261,0)),"")) -> 27.5 | K19: =IF($V19="","",IFERROR(INDEX(Projections!$I$2:$I$261,MATCH(INDEX(Calc!$A$2:$A$137,$V19)&"|K12",Projections!$Y$2:$Y$261,0)),"")) -> 0.67158039 | L19: =IF($V19="","",IFERROR(INDEX(Projections!$AB$2:$AB$261,MATCH(INDEX(Calc!$A$2:$A$137,$V19)&"|K12",Projections!$Y$2:$Y$261,0)),"")) -> 0.57035028 | M19: =IF($V19="","",IFERROR(INDEX(Projections!$M$2:$M$261,MATCH(INDEX(Calc!$A$2:$A$137,$V19)&"|K12",Projections!$Y$2:$Y$261,0)),"")) -> 27.12 | N19: =IF($V19="","",IFERROR(INDEX(Projections!$P$2:$P$261,MATCH(INDEX(Calc!$A$2:$A$137,$V19)&"|K12",Projections!$Y$2:$Y$261,0)),"")) -> 0.8 | O19: =IF($V19="","",INDEX(Calc!$AP$2:$AP$137,$V19)) -> 0.55406769 | P19: =IF($V19="","",INDEX(Calc!$AN$2:$AN$137,$V19)) -> 16.842729 | Q19: =IF($V19="","",IFERROR(INDEX(Projections!$F$2:$F$261,MATCH(INDEX(Calc!$A$2:$A$137,$V19)&"|H12",Projections!$Y$2:$Y$261,0)),"")) -> 15.5 | R19: =IF($V19="","",IFERROR(INDEX(Projections!$I$2:$I$261,MATCH(INDEX(Calc!$A$2:$A$137,$V19)&"|H12",Projections!$Y$2:$Y$261,0)),"")) -> 0.61639044 | S19: =IF($V19="","",INDEX(Calc!$N$2:$N$137,$V19)) -> 35 | T19: =IF($V19="","",INDEX(Calc!$AQ$2:$AQ$137,$V19)) | V19: =IFERROR(MATCH(5,Calc!$AR$2:$AR$137,0),"") -> 72
A20: =IF($V20="","",INDEX(Calc!$D$2:$D$137,$V20)) -> NEMI | B20: =IF($V20="","",INDEX(Calc!$E$2:$E$137,$V20)) -> robo | C20: =IF($V20="","",INDEX(Calc!$T$2:$T$137,$V20)) -> 0.70818182 | D20: =IF($V20="","",INDEX(Calc!$AA$2:$AA$137,$V20)) -> 0.6875 | E20: =IF($V20="","",INDEX(Calc!$V$2:$V$137,$V20)) -> 15.091355 | F20: =IF($V20="","",INDEX(Calc!$AC$2:$AC$137,$V20)) -> 14.513125 | G20: =IF($V20="","",INDEX(Calc!$AL$2:$AL$137,$V20)) -> 29.60448 | H20: =IF($V20="","",INDEX(Calc!$BK$2:$BK$137,$V20)) -> 0.94156936 | I20: =IF($V20="","",INDEX(Calc!$BD$2:$BD$137,$V20)) -> 27.874671 | J20: =IF($V20="","",IFERROR(INDEX(Projections!$F$2:$F$261,MATCH(INDEX(Calc!$A$2:$A$137,$V20)&"|K12",Projections!$Y$2:$Y$261,0)),"")) -> 25.5 | K20: =IF($V20="","",IFERROR(INDEX(Projections!$I$2:$I$261,MATCH(INDEX(Calc!$A$2:$A$137,$V20)&"|K12",Projections!$Y$2:$Y$261,0)),"")) -> 0.73811721 | L20: =IF($V20="","",IFERROR(INDEX(Projections!$AB$2:$AB$261,MATCH(INDEX(Calc!$A$2:$A$137,$V20)&"|K12",Projections!$Y$2:$Y$261,0)),"")) -> 0.64807631 | M20: =IF($V20="","",IFERROR(INDEX(Projections!$M$2:$M$261,MATCH(INDEX(Calc!$A$2:$A$137,$V20)&"|K12",Projections!$Y$2:$Y$261,0)),"")) -> 26 | N20: =IF($V20="","",IFERROR(INDEX(Projections!$P$2:$P$261,MATCH(INDEX(Calc!$A$2:$A$137,$V20)&"|K12",Projections!$Y$2:$Y$261,0)),"")) -> 0.7 | O20: =IF($V20="","",INDEX(Calc!$AP$2:$AP$137,$V20)) -> 0.5230693 | P20: =IF($V20="","",INDEX(Calc!$AN$2:$AN$137,$V20)) -> 15.485194 | Q20: =IF($V20="","",IFERROR(INDEX(Projections!$F$2:$F$261,MATCH(INDEX(Calc!$A$2:$A$137,$V20)&"|H12",Projections!$Y$2:$Y$261,0)),"")) -> 13.5 | R20: =IF($V20="","",IFERROR(INDEX(Projections!$I$2:$I$261,MATCH(INDEX(Calc!$A$2:$A$137,$V20)&"|H12",Projections!$Y$2:$Y$261,0)),"")) -> 0.67679869 | S20: =IF($V20="","",INDEX(Calc!$N$2:$N$137,$V20)) -> 35 | T20: =IF($V20="","",INDEX(Calc!$AQ$2:$AQ$137,$V20)) | V20: =IFERROR(MATCH(6,Calc!$AR$2:$AR$137,0),"") -> 71
A21: =IF($V21="","",INDEX(Calc!$D$2:$D$137,$V21)) -> NEMI | B21: =IF($V21="","",INDEX(Calc!$E$2:$E$137,$V21)) -> khaN | C21: =IF($V21="","",INDEX(Calc!$T$2:$T$137,$V21)) -> 0.64181818 | D21: =IF($V21="","",INDEX(Calc!$AA$2:$AA$137,$V21)) -> 0.715 | E21: =IF($V21="","",INDEX(Calc!$V$2:$V$137,$V21)) -> 13.677145 | F21: =IF($V21="","",INDEX(Calc!$AC$2:$AC$137,$V21)) -> 15.09365 | G21: =IF($V21="","",INDEX(Calc!$AL$2:$AL$137,$V21)) -> 28.770795 | H21: =IF($V21="","",INDEX(Calc!$BK$2:$BK$137,$V21)) -> 0.94168218 | I21: =IF($V21="","",INDEX(Calc!$BD$2:$BD$137,$V21)) -> 27.092945 | J21: =IF($V21="","",IFERROR(INDEX(Projections!$F$2:$F$261,MATCH(INDEX(Calc!$A$2:$A$137,$V21)&"|K12",Projections!$Y$2:$Y$261,0)),"")) -> 28.5 | K21: =IF($V21="","",IFERROR(INDEX(Projections!$I$2:$I$261,MATCH(INDEX(Calc!$A$2:$A$137,$V21)&"|K12",Projections!$Y$2:$Y$261,0)),"")) -> 0.51701687 | L21: =IF($V21="","",IFERROR(INDEX(Projections!$AB$2:$AB$261,MATCH(INDEX(Calc!$A$2:$A$137,$V21)&"|K12",Projections!$Y$2:$Y$261,0)),"")) -> 0.40964255 | M21: =IF($V21="","",IFERROR(INDEX(Projections!$M$2:$M$261,MATCH(INDEX(Calc!$A$2:$A$137,$V21)&"|K12",Projections!$Y$2:$Y$261,0)),"")) -> 28.72 | N21: =IF($V21="","",IFERROR(INDEX(Projections!$P$2:$P$261,MATCH(INDEX(Calc!$A$2:$A$137,$V21)&"|K12",Projections!$Y$2:$Y$261,0)),"")) -> 0.5 | O21: =IF($V21="","",INDEX(Calc!$AP$2:$AP$137,$V21)) -> 0.34778351 | P21: =IF($V21="","",INDEX(Calc!$AN$2:$AN$137,$V21)) -> 10.006008 | Q21: =IF($V21="","",IFERROR(INDEX(Projections!$F$2:$F$261,MATCH(INDEX(Calc!$A$2:$A$137,$V21)&"|H12",Projections!$Y$2:$Y$261,0)),"")) -> 9.5 | R21: =IF($V21="","",IFERROR(INDEX(Projections!$I$2:$I$261,MATCH(INDEX(Calc!$A$2:$A$137,$V21)&"|H12",Projections!$Y$2:$Y$261,0)),"")) -> 0.55957034 | S21: =IF($V21="","",INDEX(Calc!$N$2:$N$137,$V21)) -> 35 | T21: =IF($V21="","",INDEX(Calc!$AQ$2:$AQ$137,$V21)) | V21: =IFERROR(MATCH(7,Calc!$AR$2:$AR$137,0),"") -> 70
A22: =IF($V22="","",INDEX(Calc!$D$2:$D$137,$V22)) -> FUT | B22: =IF($V22="","",INDEX(Calc!$E$2:$E$137,$V22)) -> xfl0ud | C22: =IF($V22="","",INDEX(Calc!$T$2:$T$137,$V22)) -> 0.7 | D22: =IF($V22="","",INDEX(Calc!$AA$2:$AA$137,$V22)) -> 0.64785714 | E22: =IF($V22="","",INDEX(Calc!$V$2:$V$137,$V22)) -> 14.917 | F22: =IF($V22="","",INDEX(Calc!$AC$2:$AC$137,$V22)) -> 13.676264 | G22: =IF($V22="","",INDEX(Calc!$AL$2:$AL$137,$V22)) -> 28.593264 | H22: =IF($V22="","",INDEX(Calc!$BK$2:$BK$137,$V22)) -> 0.98969509 | I22: =IF($V22="","",INDEX(Calc!$BD$2:$BD$137,$V22)) -> 28.298613 | J22: =IF($V22="","",IFERROR(INDEX(Projections!$F$2:$F$261,MATCH(INDEX(Calc!$A$2:$A$137,$V22)&"|K12",Projections!$Y$2:$Y$261,0)),"")) -> 28.5 | K22: =IF($V22="","",IFERROR(INDEX(Projections!$I$2:$I$261,MATCH(INDEX(Calc!$A$2:$A$137,$V22)&"|K12",Projections!$Y$2:$Y$261,0)),"")) -> 0.50588049 | L22: =IF($V22="","",IFERROR(INDEX(Projections!$AB$2:$AB$261,MATCH(INDEX(Calc!$A$2:$A$137,$V22)&"|K12",Projections!$Y$2:$Y$261,0)),"")) -> 0.48723795 | M22: =IF($V22="","",IFERROR(INDEX(Projections!$M$2:$M$261,MATCH(INDEX(Calc!$A$2:$A$137,$V22)&"|K12",Projections!$Y$2:$Y$261,0)),"")) -> 29.02 | N22: =IF($V22="","",IFERROR(INDEX(Projections!$P$2:$P$261,MATCH(INDEX(Calc!$A$2:$A$137,$V22)&"|K12",Projections!$Y$2:$Y$261,0)),"")) -> 0.6 | O22: =IF($V22="","",INDEX(Calc!$AP$2:$AP$137,$V22)) -> 0.56066549 | P22: =IF($V22="","",INDEX(Calc!$AN$2:$AN$137,$V22)) -> 16.031257 | Q22: =IF($V22="","",IFERROR(INDEX(Projections!$F$2:$F$261,MATCH(INDEX(Calc!$A$2:$A$137,$V22)&"|H12",Projections!$Y$2:$Y$261,0)),"")) -> 16.5 | R22: =IF($V22="","",IFERROR(INDEX(Projections!$I$2:$I$261,MATCH(INDEX(Calc!$A$2:$A$137,$V22)&"|H12",Projections!$Y$2:$Y$261,0)),"")) -> 0.45786783 | S22: =IF($V22="","",INDEX(Calc!$N$2:$N$137,$V22)) -> 37 | T22: =IF($V22="","",INDEX(Calc!$AQ$2:$AQ$137,$V22)) | V22: =IFERROR(MATCH(8,Calc!$AR$2:$AR$137,0),"") -> 68
A23: =IF($V23="","",INDEX(Calc!$D$2:$D$137,$V23)) -> FUT | B23: =IF($V23="","",INDEX(Calc!$E$2:$E$137,$V23)) -> SunPayus | C23: =IF($V23="","",INDEX(Calc!$T$2:$T$137,$V23)) -> 0.67909091 | D23: =IF($V23="","",INDEX(Calc!$AA$2:$AA$137,$V23)) -> 0.66538462 | E23: =IF($V23="","",INDEX(Calc!$V$2:$V$137,$V23)) -> 14.471427 | F23: =IF($V23="","",INDEX(Calc!$AC$2:$AC$137,$V23)) -> 14.046269 | G23: =IF($V23="","",INDEX(Calc!$AL$2:$AL$137,$V23)) -> 28.517697 | H23: =IF($V23="","",INDEX(Calc!$BK$2:$BK$137,$V23)) -> 0.98964876 | I23: =IF($V23="","",INDEX(Calc!$BD$2:$BD$137,$V23)) -> 28.222503 | J23: =IF($V23="","",IFERROR(INDEX(Projections!$F$2:$F$261,MATCH(INDEX(Calc!$A$2:$A$137,$V23)&"|K12",Projections!$Y$2:$Y$261,0)),"")) -> 31.5 | K23: =IF($V23="","",IFERROR(INDEX(Projections!$I$2:$I$261,MATCH(INDEX(Calc!$A$2:$A$137,$V23)&"|K12",Projections!$Y$2:$Y$261,0)),"")) -> 0.31846782 | L23: =IF($V23="","",IFERROR(INDEX(Projections!$AB$2:$AB$261,MATCH(INDEX(Calc!$A$2:$A$137,$V23)&"|K12",Projections!$Y$2:$Y$261,0)),"")) -> 0.30104011 | M23: =IF($V23="","",IFERROR(INDEX(Projections!$M$2:$M$261,MATCH(INDEX(Calc!$A$2:$A$137,$V23)&"|K12",Projections!$Y$2:$Y$261,0)),"")) -> 30.46 | N23: =IF($V23="","",IFERROR(INDEX(Projections!$P$2:$P$261,MATCH(INDEX(Calc!$A$2:$A$137,$V23)&"|K12",Projections!$Y$2:$Y$261,0)),"")) -> 0.5 | O23: =IF($V23="","",INDEX(Calc!$AP$2:$AP$137,$V23)) -> 0.34116488 | P23: =IF($V23="","",INDEX(Calc!$AN$2:$AN$137,$V23)) -> 9.7292365 | Q23: =IF($V23="","",IFERROR(INDEX(Projections!$F$2:$F$261,MATCH(INDEX(Calc!$A$2:$A$137,$V23)&"|H12",Projections!$Y$2:$Y$261,0)),"")) -> 11.5 | R23: =IF($V23="","",IFERROR(INDEX(Projections!$I$2:$I$261,MATCH(INDEX(Calc!$A$2:$A$137,$V23)&"|H12",Projections!$Y$2:$Y$261,0)),"")) -> 0.29717996 | S23: =IF($V23="","",INDEX(Calc!$N$2:$N$137,$V23)) -> 34 | T23: =IF($V23="","",INDEX(Calc!$AQ$2:$AQ$137,$V23)) | V23: =IFERROR(MATCH(9,Calc!$AR$2:$AR$137,0),"") -> 67
A24: =IF($V24="","",INDEX(Calc!$D$2:$D$137,$V24)) -> FUT | B24: =IF($V24="","",INDEX(Calc!$E$2:$E$137,$V24)) -> dziugss | C24: =IF($V24="","",INDEX(Calc!$T$2:$T$137,$V24)) -> 0.62666667 | D24: =IF($V24="","",INDEX(Calc!$AA$2:$AA$137,$V24)) -> 0.58142857 | E24: =IF($V24="","",INDEX(Calc!$V$2:$V$137,$V24)) -> 13.354267 | F24: =IF($V24="","",INDEX(Calc!$AC$2:$AC$137,$V24)) -> 12.273957 | G24: =IF($V24="","",INDEX(Calc!$AL$2:$AL$137,$V24)) -> 25.628224 | H24: =IF($V24="","",INDEX(Calc!$BK$2:$BK$137,$V24)) -> 0.98969307 | I24: =IF($V24="","",INDEX(Calc!$BD$2:$BD$137,$V24)) -> 25.364076 | J24: =IF($V24="","",IFERROR(INDEX(Projections!$F$2:$F$261,MATCH(INDEX(Calc!$A$2:$A$137,$V24)&"|K12",Projections!$Y$2:$Y$261,0)),"")) -> 26.5 | K24: =IF($V24="","",IFERROR(INDEX(Projections!$I$2:$I$261,MATCH(INDEX(Calc!$A$2:$A$137,$V24)&"|K12",Projections!$Y$2:$Y$261,0)),"")) -> 0.44214235 | L24: =IF($V24="","",IFERROR(INDEX(Projections!$AB$2:$AB$261,MATCH(INDEX(Calc!$A$2:$A$137,$V24)&"|K12",Projections!$Y$2:$Y$261,0)),"")) -> 0.42441038 | M24: =IF($V24="","",IFERROR(INDEX(Projections!$M$2:$M$261,MATCH(INDEX(Calc!$A$2:$A$137,$V24)&"|K12",Projections!$Y$2:$Y$261,0)),"")) -> 26.82 | N24: =IF($V24="","",IFERROR(INDEX(Projections!$P$2:$P$261,MATCH(INDEX(Calc!$A$2:$A$137,$V24)&"|K12",Projections!$Y$2:$Y$261,0)),"")) -> 0.2 | O24: =IF($V24="","",INDEX(Calc!$AP$2:$AP$137,$V24)) -> 0.55826373 | P24: =IF($V24="","",INDEX(Calc!$AN$2:$AN$137,$V24)) -> 14.307308 | Q24: =IF($V24="","",IFERROR(INDEX(Projections!$F$2:$F$261,MATCH(INDEX(Calc!$A$2:$A$137,$V24)&"|H12",Projections!$Y$2:$Y$261,0)),"")) -> 15.5 | R24: =IF($V24="","",IFERROR(INDEX(Projections!$I$2:$I$261,MATCH(INDEX(Calc!$A$2:$A$137,$V24)&"|H12",Projections!$Y$2:$Y$261,0)),"")) -> 0.3877876 | S24: =IF($V24="","",INDEX(Calc!$N$2:$N$137,$V24)) -> 37 | T24: =IF($V24="","",INDEX(Calc!$AQ$2:$AQ$137,$V24)) | V24: =IFERROR(MATCH(10,Calc!$AR$2:$AR$137,0),"") -> 65
A25: =IF($V25="","",INDEX(Calc!$D$2:$D$137,$V25)) | B25: =IF($V25="","",INDEX(Calc!$E$2:$E$137,$V25)) | C25: =IF($V25="","",INDEX(Calc!$T$2:$T$137,$V25)) | D25: =IF($V25="","",INDEX(Calc!$AA$2:$AA$137,$V25)) | E25: =IF($V25="","",INDEX(Calc!$V$2:$V$137,$V25)) | F25: =IF($V25="","",INDEX(Calc!$AC$2:$AC$137,$V25)) | G25: =IF($V25="","",INDEX(Calc!$AL$2:$AL$137,$V25)) | H25: =IF($V25="","",INDEX(Calc!$BK$2:$BK$137,$V25)) | I25: =IF($V25="","",INDEX(Calc!$BD$2:$BD$137,$V25)) | J25: =IF($V25="","",IFERROR(INDEX(Projections!$F$2:$F$261,MATCH(INDEX(Calc!$A$2:$A$137,$V25)&"|K12",Projections!$Y$2:$Y$261,0)),"")) | K25: =IF($V25="","",IFERROR(INDEX(Projections!$I$2:$I$261,MATCH(INDEX(Calc!$A$2:$A$137,$V25)&"|K12",Projections!$Y$2:$Y$261,0)),"")) | L25: =IF($V25="","",IFERROR(INDEX(Projections!$AB$2:$AB$261,MATCH(INDEX(Calc!$A$2:$A$137,$V25)&"|K12",Projections!$Y$2:$Y$261,0)),"")) | M25: =IF($V25="","",IFERROR(INDEX(Projections!$M$2:$M$261,MATCH(INDEX(Calc!$A$2:$A$137,$V25)&"|K12",Projections!$Y$2:$Y$261,0)),"")) | N25: =IF($V25="","",IFERROR(INDEX(Projections!$P$2:$P$261,MATCH(INDEX(Calc!$A$2:$A$137,$V25)&"|K12",Projections!$Y$2:$Y$261,0)),"")) | O25: =IF($V25="","",INDEX(Calc!$AP$2:$AP$137,$V25)) | P25: =IF($V25="","",INDEX(Calc!$AN$2:$AN$137,$V25)) | Q25: =IF($V25="","",IFERROR(INDEX(Projections!$F$2:$F$261,MATCH(INDEX(Calc!$A$2:$A$137,$V25)&"|H12",Projections!$Y$2:$Y$261,0)),"")) | R25: =IF($V25="","",IFERROR(INDEX(Projections!$I$2:$I$261,MATCH(INDEX(Calc!$A$2:$A$137,$V25)&"|H12",Projections!$Y$2:$Y$261,0)),"")) | S25: =IF($V25="","",INDEX(Calc!$N$2:$N$137,$V25)) | T25: =IF($V25="","",INDEX(Calc!$AQ$2:$AQ$137,$V25)) | V25: =IFERROR(MATCH(11,Calc!$AR$2:$AR$137,0),"")
A26: =IF($V26="","",INDEX(Calc!$D$2:$D$137,$V26)) | B26: =IF($V26="","",INDEX(Calc!$E$2:$E$137,$V26)) | C26: =IF($V26="","",INDEX(Calc!$T$2:$T$137,$V26)) | D26: =IF($V26="","",INDEX(Calc!$AA$2:$AA$137,$V26)) | E26: =IF($V26="","",INDEX(Calc!$V$2:$V$137,$V26)) | F26: =IF($V26="","",INDEX(Calc!$AC$2:$AC$137,$V26)) | G26: =IF($V26="","",INDEX(Calc!$AL$2:$AL$137,$V26)) | H26: =IF($V26="","",INDEX(Calc!$BK$2:$BK$137,$V26)) | I26: =IF($V26="","",INDEX(Calc!$BD$2:$BD$137,$V26)) | J26: =IF($V26="","",IFERROR(INDEX(Projections!$F$2:$F$261,MATCH(INDEX(Calc!$A$2:$A$137,$V26)&"|K12",Projections!$Y$2:$Y$261,0)),"")) | K26: =IF($V26="","",IFERROR(INDEX(Projections!$I$2:$I$261,MATCH(INDEX(Calc!$A$2:$A$137,$V26)&"|K12",Projections!$Y$2:$Y$261,0)),"")) | L26: =IF($V26="","",IFERROR(INDEX(Projections!$AB$2:$AB$261,MATCH(INDEX(Calc!$A$2:$A$137,$V26)&"|K12",Projections!$Y$2:$Y$261,0)),"")) | M26: =IF($V26="","",IFERROR(INDEX(Projections!$M$2:$M$261,MATCH(INDEX(Calc!$A$2:$A$137,$V26)&"|K12",Projections!$Y$2:$Y$261,0)),"")) | N26: =IF($V26="","",IFERROR(INDEX(Projections!$P$2:$P$261,MATCH(INDEX(Calc!$A$2:$A$137,$V26)&"|K12",Projections!$Y$2:$Y$261,0)),"")) | O26: =IF($V26="","",INDEX(Calc!$AP$2:$AP$137,$V26)) | P26: =IF($V26="","",INDEX(Calc!$AN$2:$AN$137,$V26)) | Q26: =IF($V26="","",IFERROR(INDEX(Projections!$F$2:$F$261,MATCH(INDEX(Calc!$A$2:$A$137,$V26)&"|H12",Projections!$Y$2:$Y$261,0)),"")) | R26: =IF($V26="","",IFERROR(INDEX(Projections!$I$2:$I$261,MATCH(INDEX(Calc!$A$2:$A$137,$V26)&"|H12",Projections!$Y$2:$Y$261,0)),"")) | S26: =IF($V26="","",INDEX(Calc!$N$2:$N$137,$V26)) | T26: =IF($V26="","",INDEX(Calc!$AQ$2:$AQ$137,$V26)) | V26: =IFERROR(MATCH(12,Calc!$AR$2:$AR$137,0),"")
A28: Kills = Σ over the chosen maps of (per-map KPR, shrunk toward the player's overall KPR by SHRINK_MAPS) × rounds. HS = kills × per-map HS%, shrunk the same way. P(over) is a normal approximation with variance = KILLS_DISPERSION × projection.
A29: Adj = the round-differential layer (CS2): each map's kills × (a·s + b·(1−s)) ÷ (a·s_hist + b·(1−s_hist)), s = the team's expected round share on that map from HLTV conditional margins and Thunderpick map odds, s_hist = its round share over HLTV's 3-month sample. PAPER: neither column has a forward record.

Sheet Matches
A1: Matches — pick the maps and rounds for every match in the shaded columns
A2: Prefilled: maps from PickFinder Map Picks (#1, #2, #3), rounds from Thunderpick "Total Rounds - Map k" (devigged 50% crossing). Overwrite any shaded cell; Calc, Projections and Board follow instantly.
A4: Match | B4: Title | C4: Start (CT) | D4: Bo | E4: Team A | F4: Team B | G4: P(A wins) | H4: P(A 2-0) | I4: P(B 2-0) | J4: P(3 maps) | K4: Map pick #1 | L4: Map pick #2 | M4: Map pick #3 | N4: Picks from | O4: TP rounds M1 | P4: TP rounds M2 | Q4: TP rounds M3 | R4: P(OT) M1 | S4: A margin M1 | T4: A rounds M1 | U4: B rounds M1 | V4: TP markets | W4: Map 1 | X4: Map 2 | Y4: Map 3 | Z4: Rounds M1 | AA4: Rounds M2 | AB4: Rounds M3 | AC4: P(map 3) used | AD4: Tag A | AE4: Tag B | AF4: P(A map 1) | AG4: P(A map 2) | AH4: P(A map 3) | AI4: A hist share | AJ4: B hist share | AK4: HLTV cA M1 | AL4: HLTV cB M1 | AM4: HLTV src M1 | AN4: HLTV rounds M1 | AO4: HLTV A margin M1 | AP4: HLTV A share M1 | AQ4: HLTV cA M2 | AR4: HLTV cB M2 | AS4: HLTV src M2 | AT4: HLTV rounds M2 | AU4: HLTV A margin M2 | AV4: HLTV A share M2 | AW4: HLTV cA M3 | AX4: HLTV cB M3 | AY4: HLTV src M3 | AZ4: HLTV rounds M3 | BA4: HLTV A margin M3 | BB4: HLTV A share M3
A5: CS2 · FUT vs NEMI | B5: CS2 | C5: Thu 03:00 | D5: 3 | E5: FUT Esports (FUT) | F5: Nemiga (NEMI) | G5: 0.72052402 | H5: 0.42735406 | I5: 0.13566796 | J5: 0.43697798 | K5: Ancient 23% | L5: Dust2 19% | M5: Mirage 16% | N5: HLTV veto: played, minus first-bans (no Map Picks) | O5: 21.312553 | P5: 21.114537 | Q5: 21.222284 | R5: 0.14634146 | S5: 2.9314276 | U5: 10.5 | V5: 510 | W5: Ancient | X5: Dust2 | Y5: Mirage | Z5: 21.31 | AA5: 21.11 | AB5: 21.22 | AC5: 0.437 | AD5: FUT | AE5: NEMI | AF5: 0.6281 | AG5: 0.7014 | AH5: 0.6553 | AI5: =IFERROR(INDEX(HLTV_Teams!$N$2:$N$35,MATCH($A5&"|A",HLTV_Teams!$A$2:$A$35,0)),"") -> 0.54476338 | AJ5: =IFERROR(INDEX(HLTV_Teams!$N$2:$N$35,MATCH($A5&"|B",HLTV_Teams!$A$2:$A$35,0)),"") -> 0.53468828 | AK5: =IF($W5="","",IFERROR((SUMIFS(HLTV_Long!$B$2:$B$443,HLTV_Long!$A$2:$A$443,$A5&"|A|"&$W5&"|lw")+SUMIFS(HLTV_Long!$B$2:$B$443,HLTV_Long!$A$2:$A$443,$A5&"|B|"&$W5&"|wl"))/(COUNTIFS(HLTV_Long!$A$2:$A$443,$A5&"|A|"&$W5&"|lw")+COUNTIFS(HLTV_Long!$A$2:$A$443,$A5&"|B|"&$W5&"|wl")),IFERROR((SUMIFS(HLTV_Long!$B$2:$B$443,HLTV_Long!$A$2:$A$443,$A5&"|A|"&"ALL"&"|lw")+SUMIFS(HLTV_Long!$B$2:$B$443,HLTV_Long!$A$2:$A$443,$A5&"|B|"&"ALL"&"|wl"))/(COUNTIFS(HLTV_Long!$A$2:$A$443,$A5&"|A|"&"ALL"&"|lw")+COUNTIFS(HLTV_Long!$A$2:$A$443,$A5&"|B|"&"ALL"&"|wl")),""))) -> 8.335 | AL5: =IF($W5="","",IFERROR((SUMIFS(HLTV_Long!$B$2:$B$443,HLTV_Long!$A$2:$A$443,$A5&"|B|"&$W5&"|lw")+SUMIFS(HLTV_Long!$B$2:$B$443,HLTV_Long!$A$2:$A$443,$A5&"|A|"&$W5&"|wl"))/(COUNTIFS(HLTV_Long!$A$2:$A$443,$A5&"|B|"&$W5&"|lw")+COUNTIFS(HLTV_Long!$A$2:$A$443,$A5&"|A|"&$W5&"|wl")),IFERROR((SUMIFS(HLTV_Long!$B$2:$B$443,HLTV_Long!$A$2:$A$443,$A5&"|B|"&"ALL"&"|lw")+SUMIFS(HLTV_Long!$B$2:$B$443,HLTV_Long!$A$2:$A$443,$A5&"|A|"&"ALL"&"|wl"))/(COUNTIFS(HLTV_Long!$A$2:$A$443,$A5&"|B|"&"ALL"&"|lw")+COUNTIFS(HLTV_Long!$A$2:$A$443,$A5&"|A|"&"ALL"&"|wl")),""))) -> 9.145 | AM5: =IF($W5="","",COUNTIFS(HLTV_Long!$A$2:$A$443,$A5&"|A|"&$W5&"|lw")+COUNTIFS(HLTV_Long!$A$2:$A$443,$A5&"|B|"&$W5&"|wl")+COUNTIFS(HLTV_Long!$A$2:$A$443,$A5&"|B|"&$W5&"|lw")+COUNTIFS(HLTV_Long!$A$2:$A$443,$A5&"|A|"&$W5&"|wl")) -> 4 | AN5: =IF(OR($AK5="",$AL5="",$AF5=""),"",13+$AF5*$AK5+(1-$AF5)*$AL5) -> 21.636239 | AO5: =IF($AN5="","",$AF5*(13-$AK5)-(1-$AF5)*(13-$AL5)) -> 1.496412 | AP5: =IF($AN5="","",($AF5*13+(1-$AF5)*$AL5)/$AN5) -> 0.53458115 | AQ5: =IF($X5="","",IFERROR((SUMIFS(HLTV_Long!$B$2:$B$443,HLTV_Long!$A$2:$A$443,$A5&"|A|"&$X5&"|lw")+SUMIFS(HLTV_Long!$B$2:$B$443,HLTV_Long!$A$2:$A$443,$A5&"|B|"&$X5&"|wl"))/(COUNTIFS(HLTV_Long!$A$2:$A$443,$A5&"|A|"&$X5&"|lw")+COUNTIFS(HLTV_Long!$A$2:$A$443,$A5&"|B|"&$X5&"|wl")),IFERROR((SUMIFS(HLTV_Long!$B$2:$B$443,HLTV_Long!$A$2:$A$443,$A5&"|A|"&"ALL"&"|lw")+SUMIFS(HLTV_Long!$B$2:$B$443,HLTV_Long!$A$2:$A$443,$A5&"|B|"&"ALL"&"|wl"))/(COUNTIFS(HLTV_Long!$A$2:$A$443,$A5&"|A|"&"ALL"&"|lw")+COUNTIFS(HLTV_Long!$A$2:$A$443,$A5&"|B|"&"ALL"&"|wl")),""))) -> 9.25 | AR5: =IF($X5="","",IFERROR((SUMIFS(HLTV_Long!$B$2:$B$443,HLTV_Long!$A$2:$A$443,$A5&"|B|"&$X5&"|lw")+SUMIFS(HLTV_Long!$B$2:$B$443,HLTV_Long!$A$2:$A$443,$A5&"|A|"&$X5&"|wl"))/(COUNTIFS(HLTV_Long!$A$2:$A$443,$A5&"|B|"&$X5&"|lw")+COUNTIFS(HLTV_Long!$A$2:$A$443,$A5&"|A|"&$X5&"|wl")),IFERROR((SUMIFS(HLTV_Long!$B$2:$B$443,HLTV_Long!$A$2:$A$443,$A5&"|B|"&"ALL"&"|lw")+SUMIFS(HLTV_Long!$B$2:$B$443,HLTV_Long!$A$2:$A$443,$A5&"|A|"&"ALL"&"|wl"))/(COUNTIFS(HLTV_Long!$A$2:$A$443,$A5&"|B|"&"ALL"&"|lw")+COUNTIFS(HLTV_Long!$A$2:$A$443,$A5&"|A|"&"ALL"&"|wl")),""))) -> 8.75 | AS5: =IF($X5="","",COUNTIFS(HLTV_Long!$A$2:$A$443,$A5&"|A|"&$X5&"|lw")+COUNTIFS(HLTV_Long!$A$2:$A$443,$A5&"|B|"&$X5&"|wl")+COUNTIFS(HLTV_Long!$A$2:$A$443,$A5&"|B|"&$X5&"|lw")+COUNTIFS(HLTV_Long!$A$2:$A$443,$A5&"|A|"&$X5&"|wl")) -> 4 | AT5: =IF(OR($AQ5="",$AR5="",$AG5=""),"",13+$AG5*$AQ5+(1-$AG5)*$AR5) -> 22.1007 | AU5: =IF($AT5="","",$AG5*(13-$AQ5)-(1-$AG5)*(13-$AR5)) -> 1.3612 | AV5: =IF($AT5="","",($AG5*13+(1-$AG5)*$AR5)/$AT5) -> 0.5307954 | AW5: =IF($Y5="","",IFERROR((SUMIFS(HLTV_Long!$B$2:$B$443,HLTV_Long!$A$2:$A$443,$A5&"|A|"&$Y5&"|lw")+SUMIFS(HLTV_Long!$B$2:$B$443,HLTV_Long!$A$2:$A$443,$A5&"|B|"&$Y5&"|wl"))/(COUNTIFS(HLTV_Long!$A$2:$A$443,$A5&"|A|"&$Y5&"|lw")+COUNTIFS(HLTV_Long!$A$2:$A$443,$A5&"|B|"&$Y5&"|wl")),IFERROR((SUMIFS(HLTV_Long!$B$2:$B$443,HLTV_Long!$A$2:$A$443,$A5&"|A|"&"ALL"&"|lw")+SUMIFS(HLTV_Long!$B$2:$B$443,HLTV_Long!$A$2:$A$443,$A5&"|B|"&"ALL"&"|wl"))/(COUNTIFS(HLTV_Long!$A$2:$A$443,$A5&"|A|"&"ALL"&"|lw")+COUNTIFS(HLTV_Long!$A$2:$A$443,$A5&"|B|"&"ALL"&"|wl")),""))) -> 10.265 | AX5: =IF($Y5="","",IFERROR((SUMIFS(HLTV_Long!$B$2:$B$443,HLTV_Long!$A$2:$A$443,$A5&"|B|"&$Y5&"|lw")+SUMIFS(HLTV_Long!$B$2:$B$443,HLTV_Long!$A$2:$A$443,$A5&"|A|"&$Y5&"|wl"))/(COUNTIFS(HLTV_Long!$A$2:$A$443,$A5&"|B|"&$Y5&"|lw")+COUNTIFS(HLTV_Long!$A$2:$A$443,$A5&"|A|"&$Y5&"|wl")),IFERROR((SUMIFS(HLTV_Long!$B$2:$B$443,HLTV_Long!$A$2:$A$443,$A5&"|B|"&"ALL"&"|lw")+SUMIFS(HLTV_Long!$B$2:$B$443,HLTV_Long!$A$2:$A$443,$A5&"|A|"&"ALL"&"|wl"))/(COUNTIFS(HLTV_Long!$A$2:$A$443,$A5&"|B|"&"ALL"&"|lw")+COUNTIFS(HLTV_Long!$A$2:$A$443,$A5&"|A|"&"ALL"&"|wl")),""))) -> 10.09 | AY5: =IF($Y5="","",COUNTIFS(HLTV_Long!$A$2:$A$443,$A5&"|A|"&$Y5&"|lw")+COUNTIFS(HLTV_Long!$A$2:$A$443,$A5&"|B|"&$Y5&"|wl")+COUNTIFS(HLTV_Long!$A$2:$A$443,$A5&"|B|"&$Y5&"|lw")+COUNTIFS(HLTV_Long!$A$2:$A$443,$A5&"|A|"&$Y5&"|wl")) -> 4 | AZ5: =IF(OR($AW5="",$AX5="",$AH5=""),"",13+$AH5*$AW5+(1-$AH5)*$AX5) -> 23.204677 | BA5: =IF($AZ5="","",$AH5*(13-$AW5)-(1-$AH5)*(13-$AX5)) -> 0.7891685 | BB5: =IF($AZ5="","",($AH5*13+(1-$AH5)*$AX5)/$AZ5) -> 0.51700451
A6: CS2 · B8 vs HOTU | B6: CS2 | C6: Thu 04:00 | D6: 3 | E6: B8 (B8) | F6: HOTU (HOTU) | G6: 0.56 | H6: 0.29132726 | I6: 0.2223287 | J6: 0.48634403 | K6: Dust2 26% | L6: Cache 21% | M6: Mirage 21% | N6: HLTV veto: played, minus first-bans (no Map Picks) | O6: 21.5 | P6: 21.5 | Q6: 21.5 | R6: 0.15942029 | S6: 0.996875 | V6: 230 | W6: Dust2 | X6: Cache | Y6: Mirage | Z6: 21.5 | AA6: 21.5 | AB6: 21.5 | AC6: 0.4863 | AD6: B8 | AE6: HOTU | AF6: 0.5376 | AG6: 0.5376 | AH6: 0.5376 | AI6: =IFERROR(INDEX(HLTV_Teams!$N$2:$N$35,MATCH($A6&"|A",HLTV_Teams!$A$2:$A$35,0)),"") -> 0.53085098 | AJ6: =IFERROR(INDEX(HLTV_Teams!$N$2:$N$35,MATCH($A6&"|B",HLTV_Teams!$A$2:$A$35,0)),"") -> 0.54811927 | AK6: =IF($W6="","",IFERROR((SUMIFS(HLTV_Long!$B$2:$B$443,HLTV_Long!$A$2:$A$443,$A6&"|A|"&$W6&"|lw")+SUMIFS(HLTV_Long!$B$2:$B$443,HLTV_Long!$A$2:$A$443,$A6&"|B|"&$W6&"|wl"))/(COUNTIFS(HLTV_Long!$A$2:$A$443,$A6&"|A|"&$W6&"|lw")+COUNTIFS(HLTV_Long!$A$2:$A$443,$A6&"|B|"&$W6&"|wl")),IFERROR((SUMIFS(HLTV_Long!$B$2:$B$443,HLTV_Long!$A$2:$A$443,$A6&"|A|"&"ALL"&"|lw")+SUMIFS(HLTV_Long!$B$2:$B$443,HLTV_Long!$A$2:$A$443,$A6&"|B|"&"ALL"&"|wl"))/(COUNTIFS(HLTV_Long!$A$2:$A$443,$A6&"|A|"&"ALL"&"|lw")+COUNTIFS(HLTV_Long!$A$2:$A$443,$A6&"|B|"&"ALL"&"|wl")),""))) -> 8.42 | AL6: =IF($W6="","",IFERROR((SUMIFS(HLTV_Long!$B$2:$B$443,HLTV_Long!$A$2:$A$443,$A6&"|B|"&$W6&"|lw")+SUMIFS(HLTV_Long!$B$2:$B$443,HLTV_Long!$A$2:$A$443,$A6&"|A|"&$W6&"|wl"))/(COUNTIFS(HLTV_Long!$A$2:$A$443,$A6&"|B|"&$W6&"|lw")+COUNTIFS(HLTV_Long!$A$2:$A$443,$A6&"|A|"&$W6&"|wl")),IFERROR((SUMIFS(HLTV_Long!$B$2:$B$443,HLTV_Long!$A$2:$A$443,$A6&"|B|"&"ALL"&"|lw")+SUMIFS(HLTV_Long!$B$2:$B$443,HLTV_Long!$A$2:$A$443,$A6&"|A|"&"ALL"&"|wl"))/(COUNTIFS(HLTV_Long!$A$2:$A$443,$A6&"|B|"&"ALL"&"|lw")+COUNTIFS(HLTV_Long!$A$2:$A$443,$A6&"|A|"&"ALL"&"|wl")),""))) -> 5.935 | AM6: =IF($W6="","",COUNTIFS(HLTV_Long!$A$2:$A$443,$A6&"|A|"&$W6&"|lw")+COUNTIFS(HLTV_Long!$A$2:$A$443,$A6&"|B|"&$W6&"|wl")+COUNTIFS(HLTV_Long!$A$2:$A$443,$A6&"|B|"&$W6&"|lw")+COUNTIFS(HLTV_Long!$A$2:$A$443,$A6&"|A|"&$W6&"|wl")) -> 4 | AN6: =IF(OR($AK6="",$AL6="",$AF6=""),"",13+$AF6*$AK6+(1-$AF6)*$AL6) -> 20.270936 | AO6: =IF($AN6="","",$AF6*(13-$AK6)-(1-$AF6)*(13-$AL6)) -> -0.804648 | AP6: =IF($AN6="","",($AF6*13+(1-$AF6)*$AL6)/$AN6) -> 0.48015267 | AQ6: =IF($X6="","",IFERROR((SUMIFS(HLTV_Long!$B$2:$B$443,HLTV_Long!$A$2:$A$443,$A6&"|A|"&$X6&"|lw")+SUMIFS(HLTV_Long!$B$2:$B$443,HLTV_Long!$A$2:$A$443,$A6&"|B|"&$X6&"|wl"))/(COUNTIFS(HLTV_Long!$A$2:$A$443,$A6&"|A|"&$X6&"|lw")+COUNTIFS(HLTV_Long!$A$2:$A$443,$A6&"|B|"&$X6&"|wl")),IFERROR((SUMIFS(HLTV_Long!$B$2:$B$443,HLTV_Long!$A$2:$A$443,$A6&"|A|"&"ALL"&"|lw")+SUMIFS(HLTV_Long!$B$2:$B$443,HLTV_Long!$A$2:$A$443,$A6&"|B|"&"ALL"&"|wl"))/(COUNTIFS(HLTV_Long!$A$2:$A$443,$A6&"|A|"&"ALL"&"|lw")+COUNTIFS(HLTV_Long!$A$2:$A$443,$A6&"|B|"&"ALL"&"|wl")),""))) -> 6.645 | AR6: =IF($X6="","",IFERROR((SUMIFS(HLTV_Long!$B$2:$B$443,HLTV_Long!$A$2:$A$443,$A6&"|B|"&$X6&"|lw")+SUMIFS(HLTV_Long!$B$2:$B$443,HLTV_Long!$A$2:$A$443,$A6&"|A|"&$X6&"|wl"))/(COUNTIFS(HLTV_Long!$A$2:$A$443,$A6&"|B|"&$X6&"|lw")+COUNTIFS(HLTV_Long!$A$2:$A$443,$A6&"|A|"&$X6&"|wl")),IFERROR((SUMIFS(HLTV_Long!$B$2:$B$443,HLTV_Long!$A$2:$A$443,$A6&"|B|"&"ALL"&"|lw")+SUMIFS(HLTV_Long!$B$2:$B$443,HLTV_Long!$A$2:$A$443,$A6&"|A|"&"ALL"&"|wl"))/(COUNTIFS(HLTV_Long!$A$2:$A$443,$A6&"|B|"&"ALL"&"|lw")+COUNTIFS(HLTV_Long!$A$2:$A$443,$A6&"|A|"&"ALL"&"|wl")),""))) -> 8.32 | AS6: =IF($X6="","",COUNTIFS(HLTV_Long!$A$2:$A$443,$A6&"|A|"&$X6&"|lw")+COUNTIFS(HLTV_Long!$A$2:$A$443,$A6&"|B|"&$X6&"|wl")+COUNTIFS(HLTV_Long!$A$2:$A$443,$A6&"|B|"&$X6&"|lw")+COUNTIFS(HLTV_Long!$A$2:$A$443,$A6&"|A|"&$X6&"|wl")) -> 4 | AT6: =IF(OR($AQ6="",$AR6="",$AG6=""),"",13+$AG6*$AQ6+(1-$AG6)*$AR6) -> 20.41952 | AU6: =IF($AT6="","",$AG6*(13-$AQ6)-(1-$AG6)*(13-$AR6)) -> 1.252416 | AV6: =IF($AT6="","",($AG6*13+(1-$AG6)*$AR6)/$AT6) -> 0.53066713 | AW6: =IF($Y6="","",IFERROR((SUMIFS(HLTV_Long!$B$2:$B$443,HLTV_Long!$A$2:$A$443,$A6&"|A|"&$Y6&"|lw")+SUMIFS(HLTV_Long!$B$2:$B$443,HLTV_Long!$A$2:$A$443,$A6&"|B|"&$Y6&"|wl"))/(COUNTIFS(HLTV_Long!$A$2:$A$443,$A6&"|A|"&$Y6&"|lw")+COUNTIFS(HLTV_Long!$A$2:$A$443,$A6&"|B|"&$Y6&"|wl")),IFERROR((SUMIFS(HLTV_Long!$B$2:$B$443,HLTV_Long!$A$2:$A$443,$A6&"|A|"&"ALL"&"|lw")+SUMIFS(HLTV_Long!$B$2:$B$443,HLTV_Long!$A$2:$A$443,$A6&"|B|"&"ALL"&"|wl"))/(COUNTIFS(HLTV_Long!$A$2:$A$443,$A6&"|A|"&"ALL"&"|lw")+COUNTIFS(HLTV_Long!$A$2:$A$443,$A6&"|B|"&"ALL"&"|wl")),""))) -> 7.715 | AX6: =IF($Y6="","",IFERROR((SUMIFS(HLTV_Long!$B$2:$B$443,HLTV_Long!$A$2:$A$443,$A6&"|B|"&$Y6&"|lw")+SUMIFS(HLTV_Long!$B$2:$B$443,HLTV_Long!$A$2:$A$443,$A6&"|A|"&$Y6&"|wl"))/(COUNTIFS(HLTV_Long!$A$2:$A$443,$A6&"|B|"&$Y6&"|lw")+COUNTIFS(HLTV_Long!$A$2:$A$443,$A6&"|A|"&$Y6&"|wl")),IFERROR((SUMIFS(HLTV_Long!$B$2:$B$443,HLTV_Long!$A$2:$A$443,$A6&"|B|"&"ALL"&"|lw")+SUMIFS(HLTV_Long!$B$2:$B$443,HLTV_Long!$A$2:$A$443,$A6&"|A|"&"ALL"&"|wl"))/(COUNTIFS(HLTV_Long!$A$2:$A$443,$A6&"|B|"&"ALL"&"|lw")+COUNTIFS(HLTV_Long!$A$2:$A$443,$A6&"|A|"&"ALL"&"|wl")),""))) -> 8.855 | AY6: =IF($Y6="","",COUNTIFS(HLTV_Long!$A$2:$A$443,$A6&"|A|"&$Y6&"|lw")+COUNTIFS(HLTV_Long!$A$2:$A$443,$A6&"|B|"&$Y6&"|wl")+COUNTIFS(HLTV_Long!$A$2:$A$443,$A6&"|B|"&$Y6&"|lw")+COUNTIFS(HLTV_Long!$A$2:$A$443,$A6&"|A|"&$Y6&"|wl")) -> 4 | AZ6: =IF(OR($AW6="",$AX6="",$AH6=""),"",13+$AH6*$AW6+(1-$AH6)*$AX6) -> 21.242136 | BA6: =IF($AZ6="","",$AH6*(13-$AW6)-(1-$AH6)*(13-$AX6)) -> 0.924568 | BB6: =IF($AZ6="","",($AH6*13+(1-$AH6)*$AX6)/$AZ6) -> 0.52176259
A7: CS2 · EF vs BIG | B7: CS2 | C7: Thu 06:00 | D7: 3 | E7: Eternal Fire (EF) | F7: BIG (BIG) | G7: 0.44 | H7: 0.21176281 | I7: 0.29208663 | J7: 0.49615056 | K7: Cache 24% | L7: Ancient 20% | M7: Mirage 19% | N7: HLTV veto: played, minus first-bans (no Map Picks) | O7: 21.5 | P7: 21.423154 | Q7: 21.5 | R7: 0.15942029 | S7: -0.40417009 | V7: 228 | W7: Cache | X7: Ancient | Y7: Mirage | Z7: 21.5 | AA7: 21.42 | AB7: 21.5 | AC7: 0.4962 | AD7: EF | AE7: BIG | AF7: 0.5 | AG7: 0.418 | AH7: 0.4624 | AI7: =IFERROR(INDEX(HLTV_Teams!$N$2:$N$35,MATCH($A7&"|A",HLTV_Teams!$A$2:$A$35,0)),"") -> 0.51682331 | AJ7: =IFERROR(INDEX(HLTV_Teams!$N$2:$N$35,MATCH($A7&"|B",HLTV_Teams!$A$2:$A$35,0)),"") -> 0.50839175 | AK7: =IF($W7="","",IFERROR((SUMIFS(HLTV_Long!$B$2:$B$443,HLTV_Long!$A$2:$A$443,$A7&"|A|"&$W7&"|lw")+SUMIFS(HLTV_Long!$B$2:$B$443,HLTV_Long!$A$2:$A$443,$A7&"|B|"&$W7&"|wl"))/(COUNTIFS(HLTV_Long!$A$2:$A$443,$A7&"|A|"&$W7&"|lw")+COUNTIFS(HLTV_Long!$A$2:$A$443,$A7&"|B|"&$W7&"|wl")),IFERROR((SUMIFS(HLTV_Long!$B$2:$B$443,HLTV_Long!$A$2:$A$443,$A7&"|A|"&"ALL"&"|lw")+SUMIFS(HLTV_Long!$B$2:$B$443,HLTV_Long!$A$2:$A$443,$A7&"|B|"&"ALL"&"|wl"))/(COUNTIFS(HLTV_Long!$A$2:$A$443,$A7&"|A|"&"ALL"&"|lw")+COUNTIFS(HLTV_Long!$A$2:$A$443,$A7&"|B|"&"ALL"&"|wl")),""))) -> 8.81 | AL7: =IF($W7="","",IFERROR((SUMIFS(HLTV_Long!$B$2:$B$443,HLTV_Long!$A$2:$A$443,$A7&"|B|"&$W7&"|lw")+SUMIFS(HLTV_Long!$B$2:$B$443,HLTV_Long!$A$2:$A$443,$A7&"|A|"&$W7&"|wl"))/(COUNTIFS(HLTV_Long!$A$2:$A$443,$A7&"|B|"&$W7&"|lw")+COUNTIFS(HLTV_Long!$A$2:$A$443,$A7&"|A|"&$W7&"|wl")),IFERROR((SUMIFS(HLTV_Long!$B$2:$B$443,HLTV_Long!$A$2:$A$443,$A7&"|B|"&"ALL"&"|lw")+SUMIFS(HLTV_Long!$B$2:$B$443,HLTV_Long!$A$2:$A$443,$A7&"|A|"&"ALL"&"|wl"))/(COUNTIFS(HLTV_Long!$A$2:$A$443,$A7&"|B|"&"ALL"&"|lw")+COUNTIFS(HLTV_Long!$A$2:$A$443,$A7&"|A|"&"ALL"&"|wl")),""))) -> 8.555 | AM7: =IF($W7="","",COUNTIFS(HLTV_Long!$A$2:$A$443,$A7&"|A|"&$W7&"|lw")+COUNTIFS(HLTV_Long!$A$2:$A$443,$A7&"|B|"&$W7&"|wl")+COUNTIFS(HLTV_Long!$A$2:$A$443,$A7&"|B|"&$W7&"|lw")+COUNTIFS(HLTV_Long!$A$2:$A$443,$A7&"|A|"&$W7&"|wl")) -> 4 | AN7: =IF(OR($AK7="",$AL7="",$AF7=""),"",13+$AF7*$AK7+(1-$AF7)*$AL7) -> 21.6825 | AO7: =IF($AN7="","",$AF7*(13-$AK7)-(1-$AF7)*(13-$AL7)) -> -0.1275 | AP7: =IF($AN7="","",($AF7*13+(1-$AF7)*$AL7)/$AN7) -> 0.49705984 | AQ7: =IF($X7="","",IFERROR((SUMIFS(HLTV_Long!$B$2:$B$443,HLTV_Long!$A$2:$A$443,$A7&"|A|"&$X7&"|lw")+SUMIFS(HLTV_Long!$B$2:$B$443,HLTV_Long!$A$2:$A$443,$A7&"|B|"&$X7&"|wl"))/(COUNTIFS(HLTV_Long!$A$2:$A$443,$A7&"|A|"&$X7&"|lw")+COUNTIFS(HLTV_Long!$A$2:$A$443,$A7&"|B|"&$X7&"|wl")),IFERROR((SUMIFS(HLTV_Long!$B$2:$B$443,HLTV_Long!$A$2:$A$443,$A7&"|A|"&"ALL"&"|lw")+SUMIFS(HLTV_Long!$B$2:$B$443,HLTV_Long!$A$2:$A$443,$A7&"|B|"&"ALL"&"|wl"))/(COUNTIFS(HLTV_Long!$A$2:$A$443,$A7&"|A|"&"ALL"&"|lw")+COUNTIFS(HLTV_Long!$A$2:$A$443,$A7&"|B|"&"ALL"&"|wl")),""))) -> 9.335 | AR7: =IF($X7="","",IFERROR((SUMIFS(HLTV_Long!$B$2:$B$443,HLTV_Long!$A$2:$A$443,$A7&"|B|"&$X7&"|lw")+SUMIFS(HLTV_Long!$B$2:$B$443,HLTV_Long!$A$2:$A$443,$A7&"|A|"&$X7&"|wl"))/(COUNTIFS(HLTV_Long!$A$2:$A$443,$A7&"|B|"&$X7&"|lw")+COUNTIFS(HLTV_Long!$A$2:$A$443,$A7&"|A|"&$X7&"|wl")),IFERROR((SUMIFS(HLTV_Long!$B$2:$B$443,HLTV_Long!$A$2:$A$443,$A7&"|B|"&"ALL"&"|lw")+SUMIFS(HLTV_Long!$B$2:$B$443,HLTV_Long!$A$2:$A$443,$A7&"|A|"&"ALL"&"|wl"))/(COUNTIFS(HLTV_Long!$A$2:$A$443,$A7&"|B|"&"ALL"&"|lw")+COUNTIFS(HLTV_Long!$A$2:$A$443,$A7&"|A|"&"ALL"&"|wl")),""))) -> 8.665 | AS7: =IF($X7="","",COUNTIFS(HLTV_Long!$A$2:$A$443,$A7&"|A|"&$X7&"|lw")+COUNTIFS(HLTV_Long!$A$2:$A$443,$A7&"|B|"&$X7&"|wl")+COUNTIFS(HLTV_Long!$A$2:$A$443,$A7&"|B|"&$X7&"|lw")+COUNTIFS(HLTV_Long!$A$2:$A$443,$A7&"|A|"&$X7&"|wl")) -> 4 | AT7: =IF(OR($AQ7="",$AR7="",$AG7=""),"",13+$AG7*$AQ7+(1-$AG7)*$AR7) -> 21.94506 | AU7: =IF($AT7="","",$AG7*(13-$AQ7)-(1-$AG7)*(13-$AR7)) -> -0.991 | AV7: =IF($AT7="","",($AG7*13+(1-$AG7)*$AR7)/$AT7) -> 0.47742089 | AW7: =IF($Y7="","",IFERROR((SUMIFS(HLTV_Long!$B$2:$B$443,HLTV_Long!$A$2:$A$443,$A7&"|A|"&$Y7&"|lw")+SUMIFS(HLTV_Long!$B$2:$B$443,HLTV_Long!$A$2:$A$443,$A7&"|B|"&$Y7&"|wl"))/(COUNTIFS(HLTV_Long!$A$2:$A$443,$A7&"|A|"&$Y7&"|lw")+COUNTIFS(HLTV_Long!$A$2:$A$443,$A7&"|B|"&$Y7&"|wl")),IFERROR((SUMIFS(HLTV_Long!$B$2:$B$443,HLTV_Long!$A$2:$A$443,$A7&"|A|"&"ALL"&"|lw")+SUMIFS(HLTV_Long!$B$2:$B$443,HLTV_Long!$A$2:$A$443,$A7&"|B|"&"ALL"&"|wl"))/(COUNTIFS(HLTV_Long!$A$2:$A$443,$A7&"|A|"&"ALL"&"|lw")+COUNTIFS(HLTV_Long!$A$2:$A$443,$A7&"|B|"&"ALL"&"|wl")),""))) -> 8.55 | AX7: =IF($Y7="","",IFERROR((SUMIFS(HLTV_Long!$B$2:$B$443,HLTV_Long!$A$2:$A$443,$A7&"|B|"&$Y7&"|lw")+SUMIFS(HLTV_Long!$B$2:$B$443,HLTV_Long!$A$2:$A$443,$A7&"|A|"&$Y7&"|wl"))/(COUNTIFS(HLTV_Long!$A$2:$A$443,$A7&"|B|"&$Y7&"|lw")+COUNTIFS(HLTV_Long!$A$2:$A$443,$A7&"|A|"&$Y7&"|wl")),IFERROR((SUMIFS(HLTV_Long!$B$2:$B$443,HLTV_Long!$A$2:$A$443,$A7&"|B|"&"ALL"&"|lw")+SUMIFS(HLTV_Long!$B$2:$B$443,HLTV_Long!$A$2:$A$443,$A7&"|A|"&"ALL"&"|wl"))/(COUNTIFS(HLTV_Long!$A$2:$A$443,$A7&"|B|"&"ALL"&"|lw")+COUNTIFS(HLTV_Long!$A$2:$A$443,$A7&"|A|"&"ALL"&"|wl")),""))) -> 8.745 | AY7: =IF($Y7="","",COUNTIFS(HLTV_Long!$A$2:$A$443,$A7&"|A|"&$Y7&"|lw")+COUNTIFS(HLTV_Long!$A$2:$A$443,$A7&"|B|"&$Y7&"|wl")+COUNTIFS(HLTV_Long!$A$2:$A$443,$A7&"|B|"&$Y7&"|lw")+COUNTIFS(HLTV_Long!$A$2:$A$443,$A7&"|A|"&$Y7&"|wl")) -> 4 | AZ7: =IF(OR($AW7="",$AX7="",$AH7=""),"",13+$AH7*$AW7+(1-$AH7)*$AX7) -> 21.654832 | BA7: =IF($AZ7="","",$AH7*(13-$AW7)-(1-$AH7)*(13-$AX7)) -> -0.229808 | BB7: =IF($AZ7="","",($AH7*13+(1-$AH7)*$AX7)/$AZ7) -> 0.49469384
