Workbook

Sheet README
A1: MOBA Player Model — LoL + Dota 2
A2: Kills projections built on the one effect the record measured cleanly in LoL: players score about twice as many kills in map wins as in losses (25 of 25 players, median 2.2×).
A3: Slate 2026-10-18 · 10 board legs · 1 matches
A5: HOW TO USE
A6: 1. Matches tab: one row per match. Shaded: P(A wins) for maps 1, 2 and 3, whether maps 2 and 3 get played, and a kill-environment multiplier. They arrive prefilled from Thunderpick (map-winner odds, devigged). Bo5 "Maps 1-3" props always play three maps; Bo1 props are Map 1 only.
A7: 2. Board tab: pick a match in B2. Both rosters, ranked by projected Map 1 kills, with the PrizePicks line, P(over), Thunderpick's own kill-line median and PickFinder's L10.
A8: 3. Projections: every leg. Naive proj = his plain average per map, for comparison. Exact-line landings counts how often his last 15 series finished exactly on a whole-number line — the push check.
A9: 4. Log: the projections frozen as values when the sheet was built. Type Actual after settlement.
A11: THE MODEL
A12: K̄ = his kills per map, q = his map win rate (both from PickFinder Player Stats, same sample). r = WL_RATIO.
A13: k_win = K̄·r ÷ (q·r + 1 − q), k_loss = K̄ ÷ (q·r + 1 − q). These reproduce K̄ exactly at his own win rate.
A14: Map kills = Kills env × (P(win)·k_win + (1 − P(win))·k_loss). Maps 1-3 = sum over maps × P(map played).
... A30: Rebuilt per slate from fresh captures and imported over this file (File → Import → Replace spreadsheet); the link stays the same.

Sheet Board
A1: Board
A2: Match: | B2: LOL · KC vs MVK
A4: Teams | B4: =IFERROR(IF(INDEX(Matches!$E$5:$E$5,MATCH($B$2,Matches!$A$5:$A$5,0))="","",INDEX(Matches!$E$5:$E$5,MATCH($B$2,Matches!$A$5:$A$5,0))),"")&" vs "&IFERROR(IF(INDEX(Matches!$F$5:$F$5,MATCH($B$2,Matches!$A$5:$A$5,0))="","",INDEX(Matches!$F$5:$F$5,MATCH($B$2,Matches!$A$5:$A$5,0))),"") | D4: Start (CT) | E4: =IFERROR(IF(INDEX(Matches!$C$5:$C$5,MATCH($B$2,Matches!$A$5:$A$5,0))="","",INDEX(Matches!$C$5:$C$5,MATCH($B$2,Matches!$A$5:$A$5,0))),"") | G4: Bo | H4: =IFERROR(IF(INDEX(Matches!$D$5:$D$5,MATCH($B$2,Matches!$A$5:$A$5,0))="","",INDEX(Matches!$D$5:$D$5,MATCH($B$2,Matches!$A$5:$A$5,0))),"")
A5: Event | B5: =IFERROR(IF(INDEX(Matches!$B$5:$B$5,MATCH($B$2,Matches!$A$5:$A$5,0))="","",INDEX(Matches!$B$5:$B$5,MATCH($B$2,Matches!$A$5:$A$5,0))),"") | D5: P(A wins) | E5: =IFERROR(IF(INDEX(Matches!$G$5:$G$5,MATCH($B$2,Matches!$A$5:$A$5,0))="","",INDEX(Matches!$G$5:$G$5,MATCH($B$2,Matches!$A$5:$A$5,0))),"") | G5: P(A wins M1) | H5: =IFERROR(IF(INDEX(Matches!$M$5:$M$5,MATCH($B$2,Matches!$A$5:$A$5,0))="","",INDEX(Matches!$M$5:$M$5,MATCH($B$2,Matches!$A$5:$A$5,0))),"")
A6: TP total kills M1 | B6: =IFERROR(IF(INDEX(Matches!$H$5:$H$5,MATCH($B$2,Matches!$A$5:$A$5,0))="","",INDEX(Matches!$H$5:$H$5,MATCH($B$2,Matches!$A$5:$A$5,0))),"") | D6: TP A / B kills M1 | E6: =IF(IFERROR(IF(INDEX(Matches!$I$5:$I$5,MATCH($B$2,Matches!$A$5:$A$5,0))="","",INDEX(Matches!$I$5:$I$5,MATCH($B$2,Matches!$A$5:$A$5,0))),"")="","",TEXT(IFERROR(IF(INDEX(Matches!$I$5:$I$5,MATCH($B$2,Matches!$A$5:$A$5,0))="","",INDEX(Matches!$I$5:$I$5,MATCH($B$2,Matches!$A$5:$A$5,0))),""),"0.0")&" / "&TEXT(IFERROR(IF(INDEX(Matches!$J$5:$J$5,MATCH($B$2,Matches!$A$5:$A$5,0))="","",INDEX(Matches!$J$5:$J$5,MATCH($B$2,Matches!$A$5:$A$5,0))),""),"0.0")) | G6: TP duration M1 | H6: =IFERROR(IF(INDEX(Matches!$K$5:$K$5,MATCH($B$2,Matches!$A$5:$A$5,0))="","",INDEX(Matches!$K$5:$K$5,MATCH($B$2,Matches!$A$5:$A$5,0))),"")
A7: Kills env × | B7: =IFERROR(IF(INDEX(Matches!$R$5:$R$5,MATCH($B$2,Matches!$A$5:$A$5,0))="","",INDEX(Matches!$R$5:$R$5,MATCH($B$2,Matches!$A$5:$A$5,0))),"") | D7: P(M2 / M3 played) | E7: =TEXT(IFERROR(IF(INDEX(Matches!$P$5:$P$5,MATCH($B$2,Matches!$A$5:$A$5,0))="","",INDEX(Matches!$P$5:$P$5,MATCH($B$2,Matches!$A$5:$A$5,0))),""),"0%")&" / "&TEXT(IFERROR(IF(INDEX(Matches!$Q$5:$Q$5,MATCH($B$2,Matches!$A$5:$A$5,0))="","",INDEX(Matches!$Q$5:$Q$5,MATCH($B$2,Matches!$A$5:$A$5,0))),""),"0%") | G7: TP A − B kills M1 | H7: =IF(IFERROR(IF(INDEX(Matches!$I$5:$I$5,MATCH($B$2,Matches!$A$5:$A$5,0))="","",INDEX(Matches!$I$5:$I$5,MATCH($B$2,Matches!$A$5:$A$5,0))),"")="","",IFERROR(IF(INDEX(Matches!$I$5:$I$5,MATCH($B$2,Matches!$A$5:$A$5,0))="","",INDEX(Matches!$I$5:$I$5,MATCH($B$2,Matches!$A$5:$A$5,0))),"")-IFERROR(IF(INDEX(Matches!$J$5:$J$5,MATCH($B$2,Matches!$A$5:$A$5,0))="","",INDEX(Matches!$J$5:$J$5,MATCH($B$2,Matches!$A$5:$A$5,0))),""))
B9: ="Change P(win), maps played or kill environment on the Matches tab, row "&(MATCH($B$2,Matches!$A$5:$A$5,0)+4)&"."
A11: Team | B11: Player | C11: Map win q | D11: K avg | E11: k win | F11: k loss | G11: P(win M1) | H11: Proj M1 | I11: Naive M1 | J11: Line M1 | K11: P(over) M1 | L11: Proj series | M11: Line series | N11: P(over) series | O11: TP book | P11: PF L10 | Q11: Sample | R11: Flags | T11: row
A12: =IF($T12="","",INDEX(Calc!$C$2:$C$11,$T12)) | B12: =IF($T12="","",INDEX(Calc!$D$2:$D$11,$T12)) | C12: =IF($T12="","",INDEX(Calc!$H$2:$H$11,$T12)) | D12: =IF($T12="","",INDEX(Calc!$I$2:$I$11,$T12)) | E12: =IF($T12="","",INDEX(Calc!$J$2:$J$11,$T12)) | F12: =IF($T12="","",INDEX(Calc!$K$2:$K$11,$T12)) | G12: =IF($T12="","",INDEX(Calc!$M$2:$M$11,$T12)) | H12: =IF($T12="","",INDEX(Calc!$Y$2:$Y$11,$T12)) | I12: =IF($T12="","",INDEX(Calc!$AE$2:$AE$11,$T12)) | J12: =IF($T12="","",IFERROR(INDEX(Projections!$E$2:$E$11,MATCH(INDEX(Calc!$A$2:$A$11,$T12)&"|K1",Projections!$AA$2:$AA$11,0)),"")) | K12: =IF($T12="","",IFERROR(INDEX(Projections!$H$2:$H$11,MATCH(INDEX(Calc!$A$2:$A$11,$T12)&"|K1",Projections!$AA$2:$AA$11,0)),"")) | L12: =IF($T12="","",INDEX(Calc!$AK$2:$AK$11,$T12)) | M12: =IF($T12="","",IFERROR(INDEX(Projections!$E$2:$E$11,MATCH(INDEX(Calc!$A$2:$A$11,$T12)&"|"&INDEX(Calc!$AJ$2:$AJ$11,$T12),Projections!$AA$2:$AA$11,0)),"")) | N12: =IF($T12="","",IFERROR(INDEX(Projections!$H$2:$H$11,MATCH(INDEX(Calc!$A$2:$A$11,$T12)&"|"&INDEX(Calc!$AJ$2:$AJ$11,$T12),Projections!$AA$2:$AA$11,0)),"")) | O12: =IF($T12="","",IFERROR(INDEX(Projections!$N$2:$N$11,MATCH(INDEX(Calc!$A$2:$A$11,$T12)&"|K1",Projections!$AA$2:$AA$11,0)),IFERROR(INDEX(Projections!$N$2:$N$11,MATCH(INDEX(Calc!$A$2:$A$11,$T12)&"|"&INDEX(Calc!$AJ$2:$AJ$11,$T12),Projections!$AA$2:$AA$11,0)),""))) | P12: =IF($T12="","",IFERROR(INDEX(Projections!$S$2:$S$11,MATCH(INDEX(Calc!$A$2:$A$11,$T12)&"|K1",Projections!$AA$2:$AA$11,0)),IFERROR(INDEX(Projections!$S$2:$S$11,MATCH(INDEX(Calc!$A$2:$A$11,$T12)&"|"&INDEX(Calc!$AJ$2:$AJ$11,$T12),Projections!$AA$2:$AA$11,0)),""))) | Q12: =IF($T12="","",INDEX(Calc!$G$2:$G$11,$T12)) | R12: =IF($T12="","",INDEX(Calc!$AH$2:$AH$11,$T12)) | T12: =IFERROR(MATCH(1,Calc!$AI$2:$AI$11,0),"")
A13: =IF($T13="","",INDEX(Calc!$C$2:$C$11,$T13)) | B13: =IF($T13="","",INDEX(Calc!$D$2:$D$11,$T13)) | C13: =IF($T13="","",INDEX(Calc!$H$2:$H$11,$T13)) | D13: =IF($T13="","",INDEX(Calc!$I$2:$I$11,$T13)) | E13: =IF($T13="","",INDEX(Calc!$J$2:$J$11,$T13)) | F13: =IF($T13="","",INDEX(Calc!$K$2:$K$11,$T13)) | G13: =IF($T13="","",INDEX(Calc!$M$2:$M$11,$T13)) | H13: =IF($T13="","",INDEX(Calc!$Y$2:$Y$11,$T13)) | I13: =IF($T13="","",INDEX(Calc!$AE$2:$AE$11,$T13)) | J13: =IF($T13="","",IFERROR(INDEX(Projections!$E$2:$E$11,MATCH(INDEX(Calc!$A$2:$A$11,$T13)&"|K1",Projections!$AA$2:$AA$11,0)),"")) | K13: =IF($T13="","",IFERROR(INDEX(Projections!$H$2:$H$11,MATCH(INDEX(Calc!$A$2:$A$11,$T13)&"|K1",Projections!$AA$2:$AA$11,0)),"")) | L13: =IF($T13="","",INDEX(Calc!$AK$2:$AK$11,$T13)) | M13: =IF($T13="","",IFERROR(INDEX(Projections!$E$2:$E$11,MATCH(INDEX(Calc!$A$2:$A$11,$T13)&"|"&INDEX(Calc!$AJ$2:$AJ$11,$T13),Projections!$AA$2:$AA$11,0)),"")) | N13: =IF($T13="","",IFERROR(INDEX(Projections!$H$2:$H$11,MATCH(INDEX(Calc!$A$2:$A$11,$T13)&"|"&INDEX(Calc!$AJ$2:$AJ$11,$T13),Projections!$AA$2:$AA$11,0)),"")) | O13: =IF($T13="","",IFERROR(INDEX(Projections!$N$2:$N$11,MATCH(INDEX(Calc!$A$2:$A$11,$T13)&"|K1",Projections!$AA$2:$AA$11,0)),IFERROR(INDEX(Projections!$N$2:$N$11,MATCH(INDEX(Calc!$A$2:$A$11,$T13)&"|"&INDEX(Calc!$AJ$2:$AJ$11,$T13),Projections!$AA$2:$AA$11,0)),""))) | P13: =IF($T13="","",IFERROR(INDEX(Projections!$S$2:$S$11,MATCH(INDEX(Calc!$A$2:$A$11,$T13)&"|K1",Projections!$AA$2:$AA$11,0)),IFERROR(INDEX(Projections!$S$2:$S$11,MATCH(INDEX(Calc!$A$2:$A$11,$T13)&"|"&INDEX(Calc!$AJ$2:$AJ$11,$T13),Projections!$AA$2:$AA$11,0)),""))) | Q13: =IF($T13="","",INDEX(Calc!$G$2:$G$11,$T13)) | R13: =IF($T13="","",INDEX(Calc!$AH$2:$AH$11,$T13)) | T13: =IFERROR(MATCH(2,Calc!$AI$2:$AI$11,0),"")
A14: =IF($T14="","",INDEX(Calc!$C$2:$C$11,$T14)) | B14: =IF($T14="","",INDEX(Calc!$D$2:$D$11,$T14)) | C14: =IF($T14="","",INDEX(Calc!$H$2:$H$11,$T14)) | D14: =IF($T14="","",INDEX(Calc!$I$2:$I$11,$T14)) | E14: =IF($T14="","",INDEX(Calc!$J$2:$J$11,$T14)) | F14: =IF($T14="","",INDEX(Calc!$K$2:$K$11,$T14)) | G14: =IF($T14="","",INDEX(Calc!$M$2:$M$11,$T14)) | H14: =IF($T14="","",INDEX(Calc!$Y$2:$Y$11,$T14)) | I14: =IF($T14="","",INDEX(Calc!$AE$2:$AE$11,$T14)) | J14: =IF($T14="","",IFERROR(INDEX(Projections!$E$2:$E$11,MATCH(INDEX(Calc!$A$2:$A$11,$T14)&"|K1",Projections!$AA$2:$AA$11,0)),"")) | K14: =IF($T14="","",IFERROR(INDEX(Projections!$H$2:$H$11,MATCH(INDEX(Calc!$A$2:$A$11,$T14)&"|K1",Projections!$AA$2:$AA$11,0)),"")) | L14: =IF($T14="","",INDEX(Calc!$AK$2:$AK$11,$T14)) | M14: =IF($T14="","",IFERROR(INDEX(Projections!$E$2:$E$11,MATCH(INDEX(Calc!$A$2:$A$11,$T14)&"|"&INDEX(Calc!$AJ$2:$AJ$11,$T14),Projections!$AA$2:$AA$11,0)),"")) | N14: =IF($T14="","",IFERROR(INDEX(Projections!$H$2:$H$11,MATCH(INDEX(Calc!$A$2:$A$11,$T14)&"|"&INDEX(Calc!$AJ$2:$AJ$11,$T14),Projections!$AA$2:$AA$11,0)),"")) | O14: =IF($T14="","",IFERROR(INDEX(Projections!$N$2:$N$11,MATCH(INDEX(Calc!$A$2:$A$11,$T14)&"|K1",Projections!$AA$2:$AA$11,0)),IFERROR(INDEX(Projections!$N$2:$N$11,MATCH(INDEX(Calc!$A$2:$A$11,$T14)&"|"&INDEX(Calc!$AJ$2:$AJ$11,$T14),Projections!$AA$2:$AA$11,0)),""))) | P14: =IF($T14="","",IFERROR(INDEX(Projections!$S$2:$S$11,MATCH(INDEX(Calc!$A$2:$A$11,$T14)&"|K1",Projections!$AA$2:$AA$11,0)),IFERROR(INDEX(Projections!$S$2:$S$11,MATCH(INDEX(Calc!$A$2:$A$11,$T14)&"|"&INDEX(Calc!$AJ$2:$AJ$11,$T14),Projections!$AA$2:$AA$11,0)),""))) | Q14: =IF($T14="","",INDEX(Calc!$G$2:$G$11,$T14)) | R14: =IF($T14="","",INDEX(Calc!$AH$2:$AH$11,$T14)) | T14: =IFERROR(MATCH(3,Calc!$AI$2:$AI$11,0),"")
A15: =IF($T15="","",INDEX(Calc!$C$2:$C$11,$T15)) | B15: =IF($T15="","",INDEX(Calc!$D$2:$D$11,$T15)) | C15: =IF($T15="","",INDEX(Calc!$H$2:$H$11,$T15)) | D15: =IF($T15="","",INDEX(Calc!$I$2:$I$11,$T15)) | E15: =IF($T15="","",INDEX(Calc!$J$2:$J$11,$T15)) | F15: =IF($T15="","",INDEX(Calc!$K$2:$K$11,$T15)) | G15: =IF($T15="","",INDEX(Calc!$M$2:$M$11,$T15)) | H15: =IF($T15="","",INDEX(Calc!$Y$2:$Y$11,$T15)) | I15: =IF($T15="","",INDEX(Calc!$AE$2:$AE$11,$T15)) | J15: =IF($T15="","",IFERROR(INDEX(Projections!$E$2:$E$11,MATCH(INDEX(Calc!$A$2:$A$11,$T15)&"|K1",Projections!$AA$2:$AA$11,0)),"")) | K15: =IF($T15="","",IFERROR(INDEX(Projections!$H$2:$H$11,MATCH(INDEX(Calc!$A$2:$A$11,$T15)&"|K1",Projections!$AA$2:$AA$11,0)),"")) | L15: =IF($T15="","",INDEX(Calc!$AK$2:$AK$11,$T15)) | M15: =IF($T15="","",IFERROR(INDEX(Projections!$E$2:$E$11,MATCH(INDEX(Calc!$A$2:$A$11,$T15)&"|"&INDEX(Calc!$AJ$2:$AJ$11,$T15),Projections!$AA$2:$AA$11,0)),"")) | N15: =IF($T15="","",IFERROR(INDEX(Projections!$H$2:$H$11,MATCH(INDEX(Calc!$A$2:$A$11,$T15)&"|"&INDEX(Calc!$AJ$2:$AJ$11,$T15),Projections!$AA$2:$AA$11,0)),"")) | O15: =IF($T15="","",IFERROR(INDEX(Projections!$N$2:$N$11,MATCH(INDEX(Calc!$A$2:$A$11,$T15)&"|K1",Projections!$AA$2:$AA$11,0)),IFERROR(INDEX(Projections!$N$2:$N$11,MATCH(INDEX(Calc!$A$2:$A$11,$T15)&"|"&INDEX(Calc!$AJ$2:$AJ$11,$T15),Projections!$AA$2:$AA$11,0)),""))) | P15: =IF($T15="","",IFERROR(INDEX(Projections!$S$2:$S$11,MATCH(INDEX(Calc!$A$2:$A$11,$T15)&"|K1",Projections!$AA$2:$AA$11,0)),IFERROR(INDEX(Projections!$S$2:$S$11,MATCH(INDEX(Calc!$A$2:$A$11,$T15)&"|"&INDEX(Calc!$AJ$2:$AJ$11,$T15),Projections!$AA$2:$AA$11,0)),""))) | Q15: =IF($T15="","",INDEX(Calc!$G$2:$G$11,$T15)) | R15: =IF($T15="","",INDEX(Calc!$AH$2:$AH$11,$T15)) | T15: =IFERROR(MATCH(4,Calc!$AI$2:$AI$11,0),"")
A16: =IF($T16="","",INDEX(Calc!$C$2:$C$11,$T16)) | B16: =IF($T16="","",INDEX(Calc!$D$2:$D$11,$T16)) | C16: =IF($T16="","",INDEX(Calc!$H$2:$H$11,$T16)) | D16: =IF($T16="","",INDEX(Calc!$I$2:$I$11,$T16)) | E16: =IF($T16="","",INDEX(Calc!$J$2:$J$11,$T16)) | F16: =IF($T16="","",INDEX(Calc!$K$2:$K$11,$T16)) | G16: =IF($T16="","",INDEX(Calc!$M$2:$M$11,$T16)) | H16: =IF($T16="","",INDEX(Calc!$Y$2:$Y$11,$T16)) | I16: =IF($T16="","",INDEX(Calc!$AE$2:$AE$11,$T16)) | J16: =IF($T16="","",IFERROR(INDEX(Projections!$E$2:$E$11,MATCH(INDEX(Calc!$A$2:$A$11,$T16)&"|K1",Projections!$AA$2:$AA$11,0)),"")) | K16: =IF($T16="","",IFERROR(INDEX(Projections!$H$2:$H$11,MATCH(INDEX(Calc!$A$2:$A$11,$T16)&"|K1",Projections!$AA$2:$AA$11,0)),"")) | L16: =IF($T16="","",INDEX(Calc!$AK$2:$AK$11,$T16)) | M16: =IF($T16="","",IFERROR(INDEX(Projections!$E$2:$E$11,MATCH(INDEX(Calc!$A$2:$A$11,$T16)&"|"&INDEX(Calc!$AJ$2:$AJ$11,$T16),Projections!$AA$2:$AA$11,0)),"")) | N16: =IF($T16="","",IFERROR(INDEX(Projections!$H$2:$H$11,MATCH(INDEX(Calc!$A$2:$A$11,$T16)&"|"&INDEX(Calc!$AJ$2:$AJ$11,$T16),Projections!$AA$2:$AA$11,0)),"")) | O16: =IF($T16="","",IFERROR(INDEX(Projections!$N$2:$N$11,MATCH(INDEX(Calc!$A$2:$A$11,$T16)&"|K1",Projections!$AA$2:$AA$11,0)),IFERROR(INDEX(Projections!$N$2:$N$11,MATCH(INDEX(Calc!$A$2:$A$11,$T16)&"|"&INDEX(Calc!$AJ$2:$AJ$11,$T16),Projections!$AA$2:$AA$11,0)),""))) | P16: =IF($T16="","",IFERROR(INDEX(Projections!$S$2:$S$11,MATCH(INDEX(Calc!$A$2:$A$11,$T16)&"|K1",Projections!$AA$2:$AA$11,0)),IFERROR(INDEX(Projections!$S$2:$S$11,MATCH(INDEX(Calc!$A$2:$A$11,$T16)&"|"&INDEX(Calc!$AJ$2:$AJ$11,$T16),Projections!$AA$2:$AA$11,0)),""))) | Q16: =IF($T16="","",INDEX(Calc!$G$2:$G$11,$T16)) | R16: =IF($T16="","",INDEX(Calc!$AH$2:$AH$11,$T16)) | T16: =IFERROR(MATCH(5,Calc!$AI$2:$AI$11,0),"")
A17: =IF($T17="","",INDEX(Calc!$C$2:$C$11,$T17)) | B17: =IF($T17="","",INDEX(Calc!$D$2:$D$11,$T17)) | C17: =IF($T17="","",INDEX(Calc!$H$2:$H$11,$T17)) | D17: =IF($T17="","",INDEX(Calc!$I$2:$I$11,$T17)) | E17: =IF($T17="","",INDEX(Calc!$J$2:$J$11,$T17)) | F17: =IF($T17="","",INDEX(Calc!$K$2:$K$11,$T17)) | G17: =IF($T17="","",INDEX(Calc!$M$2:$M$11,$T17)) | H17: =IF($T17="","",INDEX(Calc!$Y$2:$Y$11,$T17)) | I17: =IF($T17="","",INDEX(Calc!$AE$2:$AE$11,$T17)) | J17: =IF($T17="","",IFERROR(INDEX(Projections!$E$2:$E$11,MATCH(INDEX(Calc!$A$2:$A$11,$T17)&"|K1",Projections!$AA$2:$AA$11,0)),"")) | K17: =IF($T17="","",IFERROR(INDEX(Projections!$H$2:$H$11,MATCH(INDEX(Calc!$A$2:$A$11,$T17)&"|K1",Projections!$AA$2:$AA$11,0)),"")) | L17: =IF($T17="","",INDEX(Calc!$AK$2:$AK$11,$T17)) | M17: =IF($T17="","",IFERROR(INDEX(Projections!$E$2:$E$11,MATCH(INDEX(Calc!$A$2:$A$11,$T17)&"|"&INDEX(Calc!$AJ$2:$AJ$11,$T17),Projections!$AA$2:$AA$11,0)),"")) | N17: =IF($T17="","",IFERROR(INDEX(Projections!$H$2:$H$11,MATCH(INDEX(Calc!$A$2:$A$11,$T17)&"|"&INDEX(Calc!$AJ$2:$AJ$11,$T17),Projections!$AA$2:$AA$11,0)),"")) | O17: =IF($T17="","",IFERROR(INDEX(Projections!$N$2:$N$11,MATCH(INDEX(Calc!$A$2:$A$11,$T17)&"|K1",Projections!$AA$2:$AA$11,0)),IFERROR(INDEX(Projections!$N$2:$N$11,MATCH(INDEX(Calc!$A$2:$A$11,$T17)&"|"&INDEX(Calc!$AJ$2:$AJ$11,$T17),Projections!$AA$2:$AA$11,0)),""))) | P17: =IF($T17="","",IFERROR(INDEX(Projections!$S$2:$S$11,MATCH(INDEX(Calc!$A$2:$A$11,$T17)&"|K1",Projections!$AA$2:$AA$11,0)),IFERROR(INDEX(Projections!$S$2:$S$11,MATCH(INDEX(Calc!$A$2:$A$11,$T17)&"|"&INDEX(Calc!$AJ$2:$AJ$11,$T17),Projections!$AA$2:$AA$11,0)),""))) | Q17: =IF($T17="","",INDEX(Calc!$G$2:$G$11,$T17)) | R17: =IF($T17="","",INDEX(Calc!$AH$2:$AH$11,$T17)) | T17: =IFERROR(MATCH(6,Calc!$AI$2:$AI$11,0),"")
A18: =IF($T18="","",INDEX(Calc!$C$2:$C$11,$T18)) | B18: =IF($T18="","",INDEX(Calc!$D$2:$D$11,$T18)) | C18: =IF($T18="","",INDEX(Calc!$H$2:$H$11,$T18)) | D18: =IF($T18="","",INDEX(Calc!$I$2:$I$11,$T18)) | E18: =IF($T18="","",INDEX(Calc!$J$2:$J$11,$T18)) | F18: =IF($T18="","",INDEX(Calc!$K$2:$K$11,$T18)) | G18: =IF($T18="","",INDEX(Calc!$M$2:$M$11,$T18)) | H18: =IF($T18="","",INDEX(Calc!$Y$2:$Y$11,$T18)) | I18: =IF($T18="","",INDEX(Calc!$AE$2:$AE$11,$T18)) | J18: =IF($T18="","",IFERROR(INDEX(Projections!$E$2:$E$11,MATCH(INDEX(Calc!$A$2:$A$11,$T18)&"|K1",Projections!$AA$2:$AA$11,0)),"")) | K18: =IF($T18="","",IFERROR(INDEX(Projections!$H$2:$H$11,MATCH(INDEX(Calc!$A$2:$A$11,$T18)&"|K1",Projections!$AA$2:$AA$11,0)),"")) | L18: =IF($T18="","",INDEX(Calc!$AK$2:$AK$11,$T18)) | M18: =IF($T18="","",IFERROR(INDEX(Projections!$E$2:$E$11,MATCH(INDEX(Calc!$A$2:$A$11,$T18)&"|"&INDEX(Calc!$AJ$2:$AJ$11,$T18),Projections!$AA$2:$AA$11,0)),"")) | N18: =IF($T18="","",IFERROR(INDEX(Projections!$H$2:$H$11,MATCH(INDEX(Calc!$A$2:$A$11,$T18)&"|"&INDEX(Calc!$AJ$2:$AJ$11,$T18),Projections!$AA$2:$AA$11,0)),"")) | O18: =IF($T18="","",IFERROR(INDEX(Projections!$N$2:$N$11,MATCH(INDEX(Calc!$A$2:$A$11,$T18)&"|K1",Projections!$AA$2:$AA$11,0)),IFERROR(INDEX(Projections!$N$2:$N$11,MATCH(INDEX(Calc!$A$2:$A$11,$T18)&"|"&INDEX(Calc!$AJ$2:$AJ$11,$T18),Projections!$AA$2:$AA$11,0)),""))) | P18: =IF($T18="","",IFERROR(INDEX(Projections!$S$2:$S$11,MATCH(INDEX(Calc!$A$2:$A$11,$T18)&"|K1",Projections!$AA$2:$AA$11,0)),IFERROR(INDEX(Projections!$S$2:$S$11,MATCH(INDEX(Calc!$A$2:$A$11,$T18)&"|"&INDEX(Calc!$AJ$2:$AJ$11,$T18),Projections!$AA$2:$AA$11,0)),""))) | Q18: =IF($T18="","",INDEX(Calc!$G$2:$G$11,$T18)) | R18: =IF($T18="","",INDEX(Calc!$AH$2:$AH$11,$T18)) | T18: =IFERROR(MATCH(7,Calc!$AI$2:$AI$11,0),"")
A19: =IF($T19="","",INDEX(Calc!$C$2:$C$11,$T19)) | B19: =IF($T19="","",INDEX(Calc!$D$2:$D$11,$T19)) | C19: =IF($T19="","",INDEX(Calc!$H$2:$H$11,$T19)) | D19: =IF($T19="","",INDEX(Calc!$I$2:$I$11,$T19)) | E19: =IF($T19="","",INDEX(Calc!$J$2:$J$11,$T19)) | F19: =IF($T19="","",INDEX(Calc!$K$2:$K$11,$T19)) | G19: =IF($T19="","",INDEX(Calc!$M$2:$M$11,$T19)) | H19: =IF($T19="","",INDEX(Calc!$Y$2:$Y$11,$T19)) | I19: =IF($T19="","",INDEX(Calc!$AE$2:$AE$11,$T19)) | J19: =IF($T19="","",IFERROR(INDEX(Projections!$E$2:$E$11,MATCH(INDEX(Calc!$A$2:$A$11,$T19)&"|K1",Projections!$AA$2:$AA$11,0)),"")) | K19: =IF($T19="","",IFERROR(INDEX(Projections!$H$2:$H$11,MATCH(INDEX(Calc!$A$2:$A$11,$T19)&"|K1",Projections!$AA$2:$AA$11,0)),"")) | L19: =IF($T19="","",INDEX(Calc!$AK$2:$AK$11,$T19)) | M19: =IF($T19="","",IFERROR(INDEX(Projections!$E$2:$E$11,MATCH(INDEX(Calc!$A$2:$A$11,$T19)&"|"&INDEX(Calc!$AJ$2:$AJ$11,$T19),Projections!$AA$2:$AA$11,0)),"")) | N19: =IF($T19="","",IFERROR(INDEX(Projections!$H$2:$H$11,MATCH(INDEX(Calc!$A$2:$A$11,$T19)&"|"&INDEX(Calc!$AJ$2:$AJ$11,$T19),Projections!$AA$2:$AA$11,0)),"")) | O19: =IF($T19="","",IFERROR(INDEX(Projections!$N$2:$N$11,MATCH(INDEX(Calc!$A$2:$A$11,$T19)&"|K1",Projections!$AA$2:$AA$11,0)),IFERROR(INDEX(Projections!$N$2:$N$11,MATCH(INDEX(Calc!$A$2:$A$11,$T19)&"|"&INDEX(Calc!$AJ$2:$AJ$11,$T19),Projections!$AA$2:$AA$11,0)),""))) | P19: =IF($T19="","",IFERROR(INDEX(Projections!$S$2:$S$11,MATCH(INDEX(Calc!$A$2:$A$11,$T19)&"|K1",Projections!$AA$2:$AA$11,0)),IFERROR(INDEX(Projections!$S$2:$S$11,MATCH(INDEX(Calc!$A$2:$A$11,$T19)&"|"&INDEX(Calc!$AJ$2:$AJ$11,$T19),Projections!$AA$2:$AA$11,0)),""))) | Q19: =IF($T19="","",INDEX(Calc!$G$2:$G$11,$T19)) | R19: =IF($T19="","",INDEX(Calc!$AH$2:$AH$11,$T19)) | T19: =IFERROR(MATCH(8,Calc!$AI$2:$AI$11,0),"")
A20: =IF($T20="","",INDEX(Calc!$C$2:$C$11,$T20)) | B20: =IF($T20="","",INDEX(Calc!$D$2:$D$11,$T20)) | C20: =IF($T20="","",INDEX(Calc!$H$2:$H$11,$T20)) | D20: =IF($T20="","",INDEX(Calc!$I$2:$I$11,$T20)) | E20: =IF($T20="","",INDEX(Calc!$J$2:$J$11,$T20)) | F20: =IF($T20="","",INDEX(Calc!$K$2:$K$11,$T20)) | G20: =IF($T20="","",INDEX(Calc!$M$2:$M$11,$T20)) | H20: =IF($T20="","",INDEX(Calc!$Y$2:$Y$11,$T20)) | I20: =IF($T20="","",INDEX(Calc!$AE$2:$AE$11,$T20)) | J20: =IF($T20="","",IFERROR(INDEX(Projections!$E$2:$E$11,MATCH(INDEX(Calc!$A$2:$A$11,$T20)&"|K1",Projections!$AA$2:$AA$11,0)),"")) | K20: =IF($T20="","",IFERROR(INDEX(Projections!$H$2:$H$11,MATCH(INDEX(Calc!$A$2:$A$11,$T20)&"|K1",Projections!$AA$2:$AA$11,0)),"")) | L20: =IF($T20="","",INDEX(Calc!$AK$2:$AK$11,$T20)) | M20: =IF($T20="","",IFERROR(INDEX(Projections!$E$2:$E$11,MATCH(INDEX(Calc!$A$2:$A$11,$T20)&"|"&INDEX(Calc!$AJ$2:$AJ$11,$T20),Projections!$AA$2:$AA$11,0)),"")) | N20: =IF($T20="","",IFERROR(INDEX(Projections!$H$2:$H$11,MATCH(INDEX(Calc!$A$2:$A$11,$T20)&"|"&INDEX(Calc!$AJ$2:$AJ$11,$T20),Projections!$AA$2:$AA$11,0)),"")) | O20: =IF($T20="","",IFERROR(INDEX(Projections!$N$2:$N$11,MATCH(INDEX(Calc!$A$2:$A$11,$T20)&"|K1",Projections!$AA$2:$AA$11,0)),IFERROR(INDEX(Projections!$N$2:$N$11,MATCH(INDEX(Calc!$A$2:$A$11,$T20)&"|"&INDEX(Calc!$AJ$2:$AJ$11,$T20),Projections!$AA$2:$AA$11,0)),""))) | P20: =IF($T20="","",IFERROR(INDEX(Projections!$S$2:$S$11,MATCH(INDEX(Calc!$A$2:$A$11,$T20)&"|K1",Projections!$AA$2:$AA$11,0)),IFERROR(INDEX(Projections!$S$2:$S$11,MATCH(INDEX(Calc!$A$2:$A$11,$T20)&"|"&INDEX(Calc!$AJ$2:$AJ$11,$T20),Projections!$AA$2:$AA$11,0)),""))) | Q20: =IF($T20="","",INDEX(Calc!$G$2:$G$11,$T20)) | R20: =IF($T20="","",INDEX(Calc!$AH$2:$AH$11,$T20)) | T20: =IFERROR(MATCH(9,Calc!$AI$2:$AI$11,0),"")
A21: =IF($T21="","",INDEX(Calc!$C$2:$C$11,$T21)) | B21: =IF($T21="","",INDEX(Calc!$D$2:$D$11,$T21)) | C21: =IF($T21="","",INDEX(Calc!$H$2:$H$11,$T21)) | D21: =IF($T21="","",INDEX(Calc!$I$2:$I$11,$T21)) | E21: =IF($T21="","",INDEX(Calc!$J$2:$J$11,$T21)) | F21: =IF($T21="","",INDEX(Calc!$K$2:$K$11,$T21)) | G21: =IF($T21="","",INDEX(Calc!$M$2:$M$11,$T21)) | H21: =IF($T21="","",INDEX(Calc!$Y$2:$Y$11,$T21)) | I21: =IF($T21="","",INDEX(Calc!$AE$2:$AE$11,$T21)) | J21: =IF($T21="","",IFERROR(INDEX(Projections!$E$2:$E$11,MATCH(INDEX(Calc!$A$2:$A$11,$T21)&"|K1",Projections!$AA$2:$AA$11,0)),"")) | K21: =IF($T21="","",IFERROR(INDEX(Projections!$H$2:$H$11,MATCH(INDEX(Calc!$A$2:$A$11,$T21)&"|K1",Projections!$AA$2:$AA$11,0)),"")) | L21: =IF($T21="","",INDEX(Calc!$AK$2:$AK$11,$T21)) | M21: =IF($T21="","",IFERROR(INDEX(Projections!$E$2:$E$11,MATCH(INDEX(Calc!$A$2:$A$11,$T21)&"|"&INDEX(Calc!$AJ$2:$AJ$11,$T21),Projections!$AA$2:$AA$11,0)),"")) | N21: =IF($T21="","",IFERROR(INDEX(Projections!$H$2:$H$11,MATCH(INDEX(Calc!$A$2:$A$11,$T21)&"|"&INDEX(Calc!$AJ$2:$AJ$11,$T21),Projections!$AA$2:$AA$11,0)),"")) | O21: =IF($T21="","",IFERROR(INDEX(Projections!$N$2:$N$11,MATCH(INDEX(Calc!$A$2:$A$11,$T21)&"|K1",Projections!$AA$2:$AA$11,0)),IFERROR(INDEX(Projections!$N$2:$N$11,MATCH(INDEX(Calc!$A$2:$A$11,$T21)&"|"&INDEX(Calc!$AJ$2:$AJ$11,$T21),Projections!$AA$2:$AA$11,0)),""))) | P21: =IF($T21="","",IFERROR(INDEX(Projections!$S$2:$S$11,MATCH(INDEX(Calc!$A$2:$A$11,$T21)&"|K1",Projections!$AA$2:$AA$11,0)),IFERROR(INDEX(Projections!$S$2:$S$11,MATCH(INDEX(Calc!$A$2:$A$11,$T21)&"|"&INDEX(Calc!$AJ$2:$AJ$11,$T21),Projections!$AA$2:$AA$11,0)),""))) | Q21: =IF($T21="","",INDEX(Calc!$G$2:$G$11,$T21)) | R21: =IF($T21="","",INDEX(Calc!$AH$2:$AH$11,$T21)) | T21: =IFERROR(MATCH(10,Calc!$AI$2:$AI$11,0),"")
A22: =IF($T22="","",INDEX(Calc!$C$2:$C$11,$T22)) | B22: =IF($T22="","",INDEX(Calc!$D$2:$D$11,$T22)) | C22: =IF($T22="","",INDEX(Calc!$H$2:$H$11,$T22)) | D22: =IF($T22="","",INDEX(Calc!$I$2:$I$11,$T22)) | E22: =IF($T22="","",INDEX(Calc!$J$2:$J$11,$T22)) | F22: =IF($T22="","",INDEX(Calc!$K$2:$K$11,$T22)) | G22: =IF($T22="","",INDEX(Calc!$M$2:$M$11,$T22)) | H22: =IF($T22="","",INDEX(Calc!$Y$2:$Y$11,$T22)) | I22: =IF($T22="","",INDEX(Calc!$AE$2:$AE$11,$T22)) | J22: =IF($T22="","",IFERROR(INDEX(Projections!$E$2:$E$11,MATCH(INDEX(Calc!$A$2:$A$11,$T22)&"|K1",Projections!$AA$2:$AA$11,0)),"")) | K22: =IF($T22="","",IFERROR(INDEX(Projections!$H$2:$H$11,MATCH(INDEX(Calc!$A$2:$A$11,$T22)&"|K1",Projections!$AA$2:$AA$11,0)),"")) | L22: =IF($T22="","",INDEX(Calc!$AK$2:$AK$11,$T22)) | M22: =IF($T22="","",IFERROR(INDEX(Projections!$E$2:$E$11,MATCH(INDEX(Calc!$A$2:$A$11,$T22)&"|"&INDEX(Calc!$AJ$2:$AJ$11,$T22),Projections!$AA$2:$AA$11,0)),"")) | N22: =IF($T22="","",IFERROR(INDEX(Projections!$H$2:$H$11,MATCH(INDEX(Calc!$A$2:$A$11,$T22)&"|"&INDEX(Calc!$AJ$2:$AJ$11,$T22),Projections!$AA$2:$AA$11,0)),"")) | O22: =IF($T22="","",IFERROR(INDEX(Projections!$N$2:$N$11,MATCH(INDEX(Calc!$A$2:$A$11,$T22)&"|K1",Projections!$AA$2:$AA$11,0)),IFERROR(INDEX(Projections!$N$2:$N$11,MATCH(INDEX(Calc!$A$2:$A$11,$T22)&"|"&INDEX(Calc!$AJ$2:$AJ$11,$T22),Projections!$AA$2:$AA$11,0)),""))) | P22: =IF($T22="","",IFERROR(INDEX(Projections!$S$2:$S$11,MATCH(INDEX(Calc!$A$2:$A$11,$T22)&"|K1",Projections!$AA$2:$AA$11,0)),IFERROR(INDEX(Projections!$S$2:$S$11,MATCH(INDEX(Calc!$A$2:$A$11,$T22)&"|"&INDEX(Calc!$AJ$2:$AJ$11,$T22),Projections!$AA$2:$AA$11,0)),""))) | Q22: =IF($T22="","",INDEX(Calc!$G$2:$G$11,$T22)) | R22: =IF($T22="","",INDEX(Calc!$AH$2:$AH$11,$T22)) | T22: =IFERROR(MATCH(11,Calc!$AI$2:$AI$11,0),"")
A23: =IF($T23="","",INDEX(Calc!$C$2:$C$11,$T23)) | B23: =IF($T23="","",INDEX(Calc!$D$2:$D$11,$T23)) | C23: =IF($T23="","",INDEX(Calc!$H$2:$H$11,$T23)) | D23: =IF($T23="","",INDEX(Calc!$I$2:$I$11,$T23)) | E23: =IF($T23="","",INDEX(Calc!$J$2:$J$11,$T23)) | F23: =IF($T23="","",INDEX(Calc!$K$2:$K$11,$T23)) | G23: =IF($T23="","",INDEX(Calc!$M$2:$M$11,$T23)) | H23: =IF($T23="","",INDEX(Calc!$Y$2:$Y$11,$T23)) | I23: =IF($T23="","",INDEX(Calc!$AE$2:$AE$11,$T23)) | J23: =IF($T23="","",IFERROR(INDEX(Projections!$E$2:$E$11,MATCH(INDEX(Calc!$A$2:$A$11,$T23)&"|K1",Projections!$AA$2:$AA$11,0)),"")) | K23: =IF($T23="","",IFERROR(INDEX(Projections!$H$2:$H$11,MATCH(INDEX(Calc!$A$2:$A$11,$T23)&"|K1",Projections!$AA$2:$AA$11,0)),"")) | L23: =IF($T23="","",INDEX(Calc!$AK$2:$AK$11,$T23)) | M23: =IF($T23="","",IFERROR(INDEX(Projections!$E$2:$E$11,MATCH(INDEX(Calc!$A$2:$A$11,$T23)&"|"&INDEX(Calc!$AJ$2:$AJ$11,$T23),Projections!$AA$2:$AA$11,0)),"")) | N23: =IF($T23="","",IFERROR(INDEX(Projections!$H$2:$H$11,MATCH(INDEX(Calc!$A$2:$A$11,$T23)&"|"&INDEX(Calc!$AJ$2:$AJ$11,$T23),Projections!$AA$2:$AA$11,0)),"")) | O23: =IF($T23="","",IFERROR(INDEX(Projections!$N$2:$N$11,MATCH(INDEX(Calc!$A$2:$A$11,$T23)&"|K1",Projections!$AA$2:$AA$11,0)),IFERROR(INDEX(Projections!$N$2:$N$11,MATCH(INDEX(Calc!$A$2:$A$11,$T23)&"|"&INDEX(Calc!$AJ$2:$AJ$11,$T23),Projections!$AA$2:$AA$11,0)),""))) | P23: =IF($T23="","",IFERROR(INDEX(Projections!$S$2:$S$11,MATCH(INDEX(Calc!$A$2:$A$11,$T23)&"|K1",Projections!$AA$2:$AA$11,0)),IFERROR(INDEX(Projections!$S$2:$S$11,MATCH(INDEX(Calc!$A$2:$A$11,$T23)&"|"&INDEX(Calc!$AJ$2:$AJ$11,$T23),Projections!$AA$2:$AA$11,0)),""))) | Q23: =IF($T23="","",INDEX(Calc!$G$2:$G$11,$T23)) | R23: =IF($T23="","",INDEX(Calc!$AH$2:$AH$11,$T23)) | T23: =IFERROR(MATCH(12,Calc!$AI$2:$AI$11,0),"")
A25: Proj = Σ maps of P(win map)·k_win + P(lose)·k_loss, with k_win = K̄·r/(q·r+1−q), k_loss = K̄/(q·r+1−q), r = WL_RATIO, q = his map win rate over PickFinder's sample. Naive = K̄ per map. At P(win) = q the two agree exactly. PAPER: no forward record.

Sheet Matches
A1: Matches — the shaded columns are yours: P(win) for each map, which maps get played, and the kill environment
A2: Prefilled from Thunderpick, devigged: P(A wins map k) from Map k Winner (Bo1: Match Winner). Kills env × scales every projection in the match (1 = the players' own history; 1.10 = a game 10% bloodier).
A4: Match | B4: Event | C4: Start (CT) | D4: Bo | E4: Team A | F4: Team B | G4: P(A wins) | H4: TP total kills M1 | I4: TP A kills M1 | J4: TP B kills M1 | K4: TP duration M1 | L4: TP markets | M4: P(A wins M1) | N4: P(A wins M2) | O4: P(A wins M3) | P4: P(M2 played) | Q4: P(M3 played) | R4: Kills env × | S4: Tag A | T4: Tag B
A5: LOL · KC vs MVK | B5: Worlds 2026 | C5: Sun 13:00 | D5: 5 | E5: Karmine Corp (KC) | F5: MVK Esports (MVK) | G5: 0.84057971 | L5: 315 | M5: 0.7111 | N5: 0.7111 | O5: 0.7111 | P5: 1 | Q5: 1 | R5: 1 | S5: KC | T5: MVK

Sheet Projections
A1: Match | B1: Player | C1: Team | D1: Market | E1: Line | F1: Proj | G1: Sigma | H1: P(over) | I1: P(under) | J1: P(push) | K1: Model side (paper) | L1: Naive proj | M1: P(over) naive | N1: TP book median | O1: Map win rate q | P1: P(win M1) | Q1: PF Avg L10 | R1: PF L5 | S1: PF L10 | T1: PF L15 | U1: PF H2H | V1: PF streak | W1: Exact-line landings (15) | X1: Flags | Y1: Calc key | Z1: Code | AA1: Lookup
A2: LOL · KC vs MVK | B2: Busio | C2: KC | D2: Maps 1-3 Kills | E2: 2.5 | F2: =IFERROR(INDEX(CHOOSE(MATCH($Z2,{"K1","K12","K13"},0),Calc!$Y$2:$Y$11,Calc!$AA$2:$AA$11,Calc!$AC$2:$AC$11),MATCH($Y2,Calc!$A$2:$A$11,0)),"") | G2: =IFERROR(SQRT(INDEX(CHOOSE(MATCH($Z2,{"K1","K12","K13"},0),Calc!$Z$2:$Z$11,Calc!$AB$2:$AB$11,Calc!$AD$2:$AD$11),MATCH($Y2,Calc!$A$2:$A$11,0))),"") | H2: =IF(OR($E2="",$F2="",N($G2)<=0),"",1-NORMDIST(FLOOR($E2,1)+0.5,$F2,$G2,TRUE)) | I2: =IF($H2="","",NORMDIST(CEILING($E2,1)-0.5,$F2,$G2,TRUE)) | J2: =IF($H2="","",MAX(0,1-$H2-$I2)) | K2: =IF($H2="","",IF($H2>=0.5+Config!$B$8,"OVER",IF($I2>=0.5+Config!$B$8,"UNDER","—"))) | L2: =IFERROR(INDEX(CHOOSE(MATCH($Z2,{"K1","K12","K13"},0),Calc!$AE$2:$AE$11,Calc!$AF$2:$AF$11,Calc!$AG$2:$AG$11),MATCH($Y2,Calc!$A$2:$A$11,0)),"") | M2: =IF(OR($E2="",$L2="",N($G2)<=0),"",1-NORMDIST(FLOOR($E2,1)+0.5,$L2,$G2*SQRT($L2/$F2),TRUE)) | O2: =IFERROR(INDEX(Calc!$H$2:$H$11,MATCH($Y2,Calc!$A$2:$A$11,0)),"") | P2: =IFERROR(INDEX(Calc!$M$2:$M$11,MATCH($Y2,Calc!$A$2:$A$11,0)),"") | Q2: 2.9 | R2: 0.2 | S2: 0.4 | T2: 0.47 | U2: 100%/1/1 | V2: 1 | X2: =IFERROR(INDEX(Calc!$AH$2:$AH$11,MATCH($Y2,Calc!$A$2:$A$11,0)),"") | Y2: s5zw84wcumkore8|LOL · KC vs MVK | Z2: K13 | AA2: =Y2&"|"&Z2
A3: LOL · KC vs MVK | B3: Caliste | C3: KC | D3: Maps 1-3 Kills | E3: 15.5 | F3: =IFERROR(INDEX(CHOOSE(MATCH($Z3,{"K1","K12","K13"},0),Calc!$Y$2:$Y$11,Calc!$AA$2:$AA$11,Calc!$AC$2:$AC$11),MATCH($Y3,Calc!$A$2:$A$11,0)),"") | G3: =IFERROR(SQRT(INDEX(CHOOSE(MATCH($Z3,{"K1","K12","K13"},0),Calc!$Z$2:$Z$11,Calc!$AB$2:$AB$11,Calc!$AD$2:$AD$11),MATCH($Y3,Calc!$A$2:$A$11,0))),"") | H3: =IF(OR($E3="",$F3="",N($G3)<=0),"",1-NORMDIST(FLOOR($E3,1)+0.5,$F3,$G3,TRUE)) | I3: =IF($H3="","",NORMDIST(CEILING($E3,1)-0.5,$F3,$G3,TRUE)) | J3: =IF($H3="","",MAX(0,1-$H3-$I3)) | K3: =IF($H3="","",IF($H3>=0.5+Config!$B$8,"OVER",IF($I3>=0.5+Config!$B$8,"UNDER","—"))) | L3: =IFERROR(INDEX(CHOOSE(MATCH($Z3,{"K1","K12","K13"},0),Calc!$AE$2:$AE$11,Calc!$AF$2:$AF$11,Calc!$AG$2:$AG$11),MATCH($Y3,Calc!$A$2:$A$11,0)),"") | M3: =IF(OR($E3="",$L3="",N($G3)<=0),"",1-NORMDIST(FLOOR($E3,1)+0.5,$L3,$G3*SQRT($L3/$F3),TRUE)) | O3: =IFERROR(INDEX(Calc!$H$2:$H$11,MATCH($Y3,Calc!$A$2:$A$11,0)),"") | P3: =IFERROR(INDEX(Calc!$M$2:$M$11,MATCH($Y3,Calc!$A$2:$A$11,0)),"") | Q3: 12.4 | R3: 0 | S3: 0.3 | T3: 0.27 | U3: 0%/0/1 | V3: -5 | X3: =IFERROR(INDEX(Calc!$AH$2:$AH$11,MATCH($Y3,Calc!$A$2:$A$11,0)),"") | Y3: 60n3jocjohvthia|LOL · KC vs MVK | Z3: K13 | AA3: =Y3&"|"&Z3
A4: LOL · KC vs MVK | B4: Canna | C4: KC | D4: Maps 1-3 Kills | E4: 9.5 | F4: =IFERROR(INDEX(CHOOSE(MATCH($Z4,{"K1","K12","K13"},0),Calc!$Y$2:$Y$11,Calc!$AA$2:$AA$11,Calc!$AC$2:$AC$11),MATCH($Y4,Calc!$A$2:$A$11,0)),"") | G4: =IFERROR(SQRT(INDEX(CHOOSE(MATCH($Z4,{"K1","K12","K13"},0),Calc!$Z$2:$Z$11,Calc!$AB$2:$AB$11,Calc!$AD$2:$AD$11),MATCH($Y4,Calc!$A$2:$A$11,0))),"") | H4: =IF(OR($E4="",$F4="",N($G4)<=0),"",1-NORMDIST(FLOOR($E4,1)+0.5,$F4,$G4,TRUE)) | I4: =IF($H4="","",NORMDIST(CEILING($E4,1)-0.5,$F4,$G4,TRUE)) | J4: =IF($H4="","",MAX(0,1-$H4-$I4)) | K4: =IF($H4="","",IF($H4>=0.5+Config!$B$8,"OVER",IF($I4>=0.5+Config!$B$8,"UNDER","—"))) | L4: =IFERROR(INDEX(CHOOSE(MATCH($Z4,{"K1","K12","K13"},0),Calc!$AE$2:$AE$11,Calc!$AF$2:$AF$11,Calc!$AG$2:$AG$11),MATCH($Y4,Calc!$A$2:$A$11,0)),"") | M4: =IF(OR($E4="",$L4="",N($G4)<=0),"",1-NORMDIST(FLOOR($E4,1)+0.5,$L4,$G4*SQRT($L4/$F4),TRUE)) | O4: =IFERROR(INDEX(Calc!$H$2:$H$11,MATCH($Y4,Calc!$A$2:$A$11,0)),"") | P4: =IFERROR(INDEX(Calc!$M$2:$M$11,MATCH($Y4,Calc!$A$2:$A$11,0)),"") | Q4: 9.2 | R4: 0.2 | S4: 0.4 | T4: 0.47 | U4: 0%/0/1 | V4: -4 | X4: =IFERROR(INDEX(Calc!$AH$2:$AH$11,MATCH($Y4,Calc!$A$2:$A$11,0)),"") | Y4: 5h8ktthuwylbro2|LOL · KC vs MVK | Z4: K13 | AA4: =Y4&"|"&Z4
A5: LOL · KC vs MVK | B5: Kyeahoo | C5: KC | D5: Maps 1-3 Kills | E5: 11.5 | F5: =IFERROR(INDEX(CHOOSE(MATCH($Z5,{"K1","K12","K13"},0),Calc!$Y$2:$Y$11,Calc!$AA$2:$AA$11,Calc!$AC$2:$AC$11),MATCH($Y5,Calc!$A$2:$A$11,0)),"") | G5: =IFERROR(SQRT(INDEX(CHOOSE(MATCH($Z5,{"K1","K12","K13"},0),Calc!$Z$2:$Z$11,Calc!$AB$2:$AB$11,Calc!$AD$2:$AD$11),MATCH($Y5,Calc!$A$2:$A$11,0))),"") | H5: =IF(OR($E5="",$F5="",N($G5)<=0),"",1-NORMDIST(FLOOR($E5,1)+0.5,$F5,$G5,TRUE)) | I5: =IF($H5="","",NORMDIST(CEILING($E5,1)-0.5,$F5,$G5,TRUE)) | J5: =IF($H5="","",MAX(0,1-$H5-$I5)) | K5: =IF($H5="","",IF($H5>=0.5+Config!$B$8,"OVER",IF($I5>=0.5+Config!$B$8,"UNDER","—"))) | L5: =IFERROR(INDEX(CHOOSE(MATCH($Z5,{"K1","K12","K13"},0),Calc!$AE$2:$AE$11,Calc!$AF$2:$AF$11,Calc!$AG$2:$AG$11),MATCH($Y5,Calc!$A$2:$A$11,0)),"") | M5: =IF(OR($E5="",$L5="",N($G5)<=0),"",1-NORMDIST(FLOOR($E5,1)+0.5,$L5,$G5*SQRT($L5/$F5),TRUE)) | O5: =IFERROR(INDEX(Calc!$H$2:$H$11,MATCH($Y5,Calc!$A$2:$A$11,0)),"") | P5: =IFERROR(INDEX(Calc!$M$2:$M$11,MATCH($Y5,Calc!$A$2:$A$11,0)),"") | Q5: 7.6 | R5: 0 | S5: 0 | T5: 0.13 | U5: 0%/0/1 | V5: -12 | X5: =IFERROR(INDEX(Calc!$AH$2:$AH$11,MATCH($Y5,Calc!$A$2:$A$11,0)),"") | Y5: cp4ibkwui10xeyj|LOL · KC vs MVK | Z5: K13 | AA5: =Y5&"|"&Z5
A6: LOL · KC vs MVK | B6: Yike | C6: KC | D6: Maps 1-3 Kills | E6: 12.5 | F6: =IFERROR(INDEX(CHOOSE(MATCH($Z6,{"K1","K12","K13"},0),Calc!$Y$2:$Y$11,Calc!$AA$2:$AA$11,Calc!$AC$2:$AC$11),MATCH($Y6,Calc!$A$2:$A$11,0)),"") | G6: =IFERROR(SQRT(INDEX(CHOOSE(MATCH($Z6,{"K1","K12","K13"},0),Calc!$Z$2:$Z$11,Calc!$AB$2:$AB$11,Calc!$AD$2:$AD$11),MATCH($Y6,Calc!$A$2:$A$11,0))),"") | H6: =IF(OR($E6="",$F6="",N($G6)<=0),"",1-NORMDIST(FLOOR($E6,1)+0.5,$F6,$G6,TRUE)) | I6: =IF($H6="","",NORMDIST(CEILING($E6,1)-0.5,$F6,$G6,TRUE)) | J6: =IF($H6="","",MAX(0,1-$H6-$I6)) | K6: =IF($H6="","",IF($H6>=0.5+Config!$B$8,"OVER",IF($I6>=0.5+Config!$B$8,"UNDER","—"))) | L6: =IFERROR(INDEX(CHOOSE(MATCH($Z6,{"K1","K12","K13"},0),Calc!$AE$2:$AE$11,Calc!$AF$2:$AF$11,Calc!$AG$2:$AG$11),MATCH($Y6,Calc!$A$2:$A$11,0)),"") | M6: =IF(OR($E6="",$L6="",N($G6)<=0),"",1-NORMDIST(FLOOR($E6,1)+0.5,$L6,$G6*SQRT($L6/$F6),TRUE)) | O6: =IFERROR(INDEX(Calc!$H$2:$H$11,MATCH($Y6,Calc!$A$2:$A$11,0)),"") | P6: =IFERROR(INDEX(Calc!$M$2:$M$11,MATCH($Y6,Calc!$A$2:$A$11,0)),"") | Q6: 9.2 | R6: 0 | S6: 0.2 | T6: 0.27 | U6: 0%/0/1 | V6: -5 | X6: =IFERROR(INDEX(Calc!$AH$2:$AH$11,MATCH($Y6,Calc!$A$2:$A$11,0)),"") | Y6: rfespsq7mcurckt|LOL · KC vs MVK | Z6: K13 | AA6: =Y6&"|"&Z6
A7: LOL · KC vs MVK | B7: Chika | C7: MVK | D7: Maps 1-3 Kills | E7: 8.5 | F7: =IFERROR(INDEX(CHOOSE(MATCH($Z7,{"K1","K12","K13"},0),Calc!$Y$2:$Y$11,Calc!$AA$2:$AA$11,Calc!$AC$2:$AC$11),MATCH($Y7,Calc!$A$2:$A$11,0)),"") | G7: =IFERROR(SQRT(INDEX(CHOOSE(MATCH($Z7,{"K1","K12","K13"},0),Calc!$Z$2:$Z$11,Calc!$AB$2:$AB$11,Calc!$AD$2:$AD$11),MATCH($Y7,Calc!$A$2:$A$11,0))),"") | H7: =IF(OR($E7="",$F7="",N($G7)<=0),"",1-NORMDIST(FLOOR($E7,1)+0.5,$F7,$G7,TRUE)) | I7: =IF($H7="","",NORMDIST(CEILING($E7,1)-0.5,$F7,$G7,TRUE)) | J7: =IF($H7="","",MAX(0,1-$H7-$I7)) | K7: =IF($H7="","",IF($H7>=0.5+Config!$B$8,"OVER",IF($I7>=0.5+Config!$B$8,"UNDER","—"))) | L7: =IFERROR(INDEX(CHOOSE(MATCH($Z7,{"K1","K12","K13"},0),Calc!$AE$2:$AE$11,Calc!$AF$2:$AF$11,Calc!$AG$2:$AG$11),MATCH($Y7,Calc!$A$2:$A$11,0)),"") | M7: =IF(OR($E7="",$L7="",N($G7)<=0),"",1-NORMDIST(FLOOR($E7,1)+0.5,$L7,$G7*SQRT($L7/$F7),TRUE)) | O7: =IFERROR(INDEX(Calc!$H$2:$H$11,MATCH($Y7,Calc!$A$2:$A$11,0)),"") | P7: =IFERROR(INDEX(Calc!$M$2:$M$11,MATCH($Y7,Calc!$A$2:$A$11,0)),"") | Q7: 11 | R7: 0.6 | S7: 0.7 | U7: 0%/0/1 | V7: -1 | X7: =IFERROR(INDEX(Calc!$AH$2:$AH$11,MATCH($Y7,Calc!$A$2:$A$11,0)),"") | Y7: r22pe1iajr6mhdp|LOL · KC vs MVK | Z7: K13 | AA7: =Y7&"|"&Z7
A8: LOL · KC vs MVK | B8: Gury | C8: MVK | D8: Maps 1-3 Kills | E8: 7 | F8: =IFERROR(INDEX(CHOOSE(MATCH($Z8,{"K1","K12","K13"},0),Calc!$Y$2:$Y$11,Calc!$AA$2:$AA$11,Calc!$AC$2:$AC$11),MATCH($Y8,Calc!$A$2:$A$11,0)),"") | G8: =IFERROR(SQRT(INDEX(CHOOSE(MATCH($Z8,{"K1","K12","K13"},0),Calc!$Z$2:$Z$11,Calc!$AB$2:$AB$11,Calc!$AD$2:$AD$11),MATCH($Y8,Calc!$A$2:$A$11,0))),"") | H8: =IF(OR($E8="",$F8="",N($G8)<=0),"",1-NORMDIST(FLOOR($E8,1)+0.5,$F8,$G8,TRUE)) | I8: =IF($H8="","",NORMDIST(CEILING($E8,1)-0.5,$F8,$G8,TRUE)) | J8: =IF($H8="","",MAX(0,1-$H8-$I8)) | K8: =IF($H8="","",IF($H8>=0.5+Config!$B$8,"OVER",IF($I8>=0.5+Config!$B$8,"UNDER","—"))) | L8: =IFERROR(INDEX(CHOOSE(MATCH($Z8,{"K1","K12","K13"},0),Calc!$AE$2:$AE$11,Calc!$AF$2:$AF$11,Calc!$AG$2:$AG$11),MATCH($Y8,Calc!$A$2:$A$11,0)),"") | M8: =IF(OR($E8="",$L8="",N($G8)<=0),"",1-NORMDIST(FLOOR($E8,1)+0.5,$L8,$G8*SQRT($L8/$F8),TRUE)) | O8: =IFERROR(INDEX(Calc!$H$2:$H$11,MATCH($Y8,Calc!$A$2:$A$11,0)),"") | P8: =IFERROR(INDEX(Calc!$M$2:$M$11,MATCH($Y8,Calc!$A$2:$A$11,0)),"") | Q8: 7.4 | R8: 0.4 | S8: 0.4 | T8: 0.4 | U8: - | V8: 1 | W8: 1 | X8: =IFERROR(INDEX(Calc!$AH$2:$AH$11,MATCH($Y8,Calc!$A$2:$A$11,0)),"") | Y8: jr80asvwieexg6m|LOL · KC vs MVK | Z8: K13 | AA8: =Y8&"|"&Z8
A9: LOL · KC vs MVK | B9: Harky | C9: MVK | D9: Maps 1-3 Kills | E9: 9.5 | F9: =IFERROR(INDEX(CHOOSE(MATCH($Z9,{"K1","K12","K13"},0),Calc!$Y$2:$Y$11,Calc!$AA$2:$AA$11,Calc!$AC$2:$AC$11),MATCH($Y9,Calc!$A$2:$A$11,0)),"") | G9: =IFERROR(SQRT(INDEX(CHOOSE(MATCH($Z9,{"K1","K12","K13"},0),Calc!$Z$2:$Z$11,Calc!$AB$2:$AB$11,Calc!$AD$2:$AD$11),MATCH($Y9,Calc!$A$2:$A$11,0))),"") | H9: =IF(OR($E9="",$F9="",N($G9)<=0),"",1-NORMDIST(FLOOR($E9,1)+0.5,$F9,$G9,TRUE)) | I9: =IF($H9="","",NORMDIST(CEILING($E9,1)-0.5,$F9,$G9,TRUE)) | J9: =IF($H9="","",MAX(0,1-$H9-$I9)) | K9: =IF($H9="","",IF($H9>=0.5+Config!$B$8,"OVER",IF($I9>=0.5+Config!$B$8,"UNDER","—"))) | L9: =IFERROR(INDEX(CHOOSE(MATCH($Z9,{"K1","K12","K13"},0),Calc!$AE$2:$AE$11,Calc!$AF$2:$AF$11,Calc!$AG$2:$AG$11),MATCH($Y9,Calc!$A$2:$A$11,0)),"") | M9: =IF(OR($E9="",$L9="",N($G9)<=0),"",1-NORMDIST(FLOOR($E9,1)+0.5,$L9,$G9*SQRT($L9/$F9),TRUE)) | O9: =IFERROR(INDEX(Calc!$H$2:$H$11,MATCH($Y9,Calc!$A$2:$A$11,0)),"") | P9: =IFERROR(INDEX(Calc!$M$2:$M$11,MATCH($Y9,Calc!$A$2:$A$11,0)),"") | Q9: 9.4 | R9: 0.4 | S9: 0.5 | T9: 0.67 | U9: 0%/0/1 | V9: -1 | X9: =IFERROR(INDEX(Calc!$AH$2:$AH$11,MATCH($Y9,Calc!$A$2:$A$11,0)),"") | Y9: tuhm132yvf0f8gg|LOL · KC vs MVK | Z9: K13 | AA9: =Y9&"|"&Z9
A10: LOL · KC vs MVK | B10: Kratos | C10: MVK | D10: Maps 1-3 Kills | E10: 6 | F10: =IFERROR(INDEX(CHOOSE(MATCH($Z10,{"K1","K12","K13"},0),Calc!$Y$2:$Y$11,Calc!$AA$2:$AA$11,Calc!$AC$2:$AC$11),MATCH($Y10,Calc!$A$2:$A$11,0)),"") | G10: =IFERROR(SQRT(INDEX(CHOOSE(MATCH($Z10,{"K1","K12","K13"},0),Calc!$Z$2:$Z$11,Calc!$AB$2:$AB$11,Calc!$AD$2:$AD$11),MATCH($Y10,Calc!$A$2:$A$11,0))),"") | H10: =IF(OR($E10="",$F10="",N($G10)<=0),"",1-NORMDIST(FLOOR($E10,1)+0.5,$F10,$G10,TRUE)) | I10: =IF($H10="","",NORMDIST(CEILING($E10,1)-0.5,$F10,$G10,TRUE)) | J10: =IF($H10="","",MAX(0,1-$H10-$I10)) | K10: =IF($H10="","",IF($H10>=0.5+Config!$B$8,"OVER",IF($I10>=0.5+Config!$B$8,"UNDER","—"))) | L10: =IFERROR(INDEX(CHOOSE(MATCH($Z10,{"K1","K12","K13"},0),Calc!$AE$2:$AE$11,Calc!$AF$2:$AF$11,Calc!$AG$2:$AG$11),MATCH($Y10,Calc!$A$2:$A$11,0)),"") | M10: =IF(OR($E10="",$L10="",N($G10)<=0),"",1-NORMDIST(FLOOR($E10,1)+0.5,$L10,$G10*SQRT($L10/$F10),TRUE)) | O10: =IFERROR(INDEX(Calc!$H$2:$H$11,MATCH($Y10,Calc!$A$2:$A$11,0)),"") | P10: =IFERROR(INDEX(Calc!$M$2:$M$11,MATCH($Y10,Calc!$A$2:$A$11,0)),"") | Q10: 7.9 | R10: 0.8 | S10: 0.8 | T10: 0.6 | U10: 0%/0/1 | V10: -1 | W10: 2 | X10: =IFERROR(INDEX(Calc!$AH$2:$AH$11,MATCH($Y10,Calc!$A$2:$A$11,0)),"") | Y10: zzsjtlvrbi44rqp|LOL · KC vs MVK | Z10: K13 | AA10: =Y10&"|"&Z10
A11: LOL · KC vs MVK | B11: Siuloong | C11: MVK | D11: Maps 1-3 Kills | E11: 1.5 | F11: =IFERROR(INDEX(CHOOSE(MATCH($Z11,{"K1","K12","K13"},0),Calc!$Y$2:$Y$11,Calc!$AA$2:$AA$11,Calc!$AC$2:$AC$11),MATCH($Y11,Calc!$A$2:$A$11,0)),"") | G11: =IFERROR(SQRT(INDEX(CHOOSE(MATCH($Z11,{"K1","K12","K13"},0),Calc!$Z$2:$Z$11,Calc!$AB$2:$AB$11,Calc!$AD$2:$AD$11),MATCH($Y11,Calc!$A$2:$A$11,0))),"") | H11: =IF(OR($E11="",$F11="",N($G11)<=0),"",1-NORMDIST(FLOOR($E11,1)+0.5,$F11,$G11,TRUE)) | I11: =IF($H11="","",NORMDIST(CEILING($E11,1)-0.5,$F11,$G11,TRUE)) | J11: =IF($H11="","",MAX(0,1-$H11-$I11)) | K11: =IF($H11="","",IF($H11>=0.5+Config!$B$8,"OVER",IF($I11>=0.5+Config!$B$8,"UNDER","—"))) | L11: =IFERROR(INDEX(CHOOSE(MATCH($Z11,{"K1","K12","K13"},0),Calc!$AE$2:$AE$11,Calc!$AF$2:$AF$11,Calc!$AG$2:$AG$11),MATCH($Y11,Calc!$A$2:$A$11,0)),"") | M11: =IF(OR($E11="",$L11="",N($G11)<=0),"",1-NORMDIST(FLOOR($E11,1)+0.5,$L11,$G11*SQRT($L11/$F11),TRUE)) | O11: =IFERROR(INDEX(Calc!$H$2:$H$11,MATCH($Y11,Calc!$A$2:$A$11,0)),"") | P11: =IFERROR(INDEX(Calc!$M$2:$M$11,MATCH($Y11,Calc!$A$2:$A$11,0)),"") | Q11: 2.6 | R11: 0.8 | S11: 0.8 | T11: 0.87 | U11: 100%/1/1 | V11: 4 | X11: =IFERROR(INDEX(Calc!$AH$2:$AH$11,MATCH($Y11,Calc!$A$2:$A$11,0)),"") | Y11: 16tiv29rhyefoti|LOL · KC vs MVK | Z11: K13 | AA11: =Y11&"|"&Z11

Sheet Calc
A1: Key | B1: Match | C1: Team | D1: Player | E1: PID | F1: Side | G1: Maps n | H1: Win rate q | I1: K avg | J1: k win | K1: k loss | L1: Env | M1: M1 p win | N1: M1 p played | O1: M1 mean | P1: M1 var | Q1: M2 p win | R1: M2 p played | S1: M2 mean | T1: M2 var | U1: M3 p win | V1: M3 p played | W1: M3 mean | X1: M3 var | Y1: K1 | Z1: K1 var | AA1: K12 | AB1: K12 var | AC1: K13 | AD1: K13 var | AE1: Naive K1 | AF1: Naive K12 | AG1: Naive K13 | AH1: Flags | AI1: Board rank | AJ1: Series code | AK1: Series proj
A2: s5zw84wcumkore8|LOL · KC vs MVK | B2: LOL · KC vs MVK | C2: KC | D2: Busio | E2: s5zw84wcumkore8 | F2: =IFERROR(IF($C2=INDEX(Matches!$S$5:$S$5,MATCH($B2,Matches!$A$5:$A$5,0)),"A",IF($C2=INDEX(Matches!$T$5:$T$5,MATCH($B2,Matches!$A$5:$A$5,0)),"B","")),"") | G2: =IFERROR(INDEX(Players!$E$2:$E$11,MATCH($E2,Players!$A$2:$A$11,0)),0) | H2: =IFERROR(INDEX(Players!$F$2:$F$11,MATCH($E2,Players!$A$2:$A$11,0)),"") | I2: =IFERROR(INDEX(Players!$G$2:$G$11,MATCH($E2,Players!$A$2:$A$11,0)),"") | J2: =IF(OR($I2="",$H2=""),"",$I2*IF(LEFT($B2,4)="DOTA",Config!$B$5,Config!$B$4)/($H2*IF(LEFT($B2,4)="DOTA",Config!$B$5,Config!$B$4)+1-$H2)) | K2: =IF(OR($I2="",$H2=""),"",$I2/($H2*IF(LEFT($B2,4)="DOTA",Config!$B$5,Config!$B$4)+1-$H2)) | L2: =IFERROR(INDEX(Matches!$R$5:$R$5,MATCH($B2,Matches!$A$5:$A$5,0)),1) | M2: =IFERROR(IF(INDEX(Matches!$M$5:$M$5,MATCH($B2,Matches!$A$5:$A$5,0))="","",IF($F2="A",INDEX(Matches!$M$5:$M$5,MATCH($B2,Matches!$A$5:$A$5,0)),1-INDEX(Matches!$M$5:$M$5,MATCH($B2,Matches!$A$5:$A$5,0)))),"") | N2: =1 | O2: =IF(OR($M2="",$J2=""),"",$L2*($M2*$J2+(1-$M2)*$K2)) | P2: =IF($O2="","",IF(LEFT($B2,4)="DOTA",Config!$B$7,Config!$B$6)*$O2+$L2^2*$M2*(1-$M2)*($J2-$K2)^2) | Q2: =IFERROR(IF(INDEX(Matches!$N$5:$N$5,MATCH($B2,Matches!$A$5:$A$5,0))="","",IF($F2="A",INDEX(Matches!$N$5:$N$5,MATCH($B2,Matches!$A$5:$A$5,0)),1-INDEX(Matches!$N$5:$N$5,MATCH($B2,Matches!$A$5:$A$5,0)))),"") | R2: =IFERROR(N(INDEX(Matches!$P$5:$P$5,MATCH($B2,Matches!$A$5:$A$5,0))),0) | S2: =IF(OR($Q2="",$J2=""),"",$L2*($Q2*$J2+(1-$Q2)*$K2)) | T2: =IF($S2="","",IF(LEFT($B2,4)="DOTA",Config!$B$7,Config!$B$6)*$S2+$L2^2*$Q2*(1-$Q2)*($J2-$K2)^2) | U2: =IFERROR(IF(INDEX(Matches!$O$5:$O$5,MATCH($B2,Matches!$A$5:$A$5,0))="","",IF($F2="A",INDEX(Matches!$O$5:$O$5,MATCH($B2,Matches!$A$5:$A$5,0)),1-INDEX(Matches!$O$5:$O$5,MATCH($B2,Matches!$A$5:$A$5,0)))),"") | V2: =IFERROR(N(INDEX(Matches!$Q$5:$Q$5,MATCH($B2,Matches!$A$5:$A$5,0))),0) | W2: =IF(OR($U2="",$J2=""),"",$L2*($U2*$J2+(1-$U2)*$K2)) | X2: =IF($W2="","",IF(LEFT($B2,4)="DOTA",Config!$B$7,Config!$B$6)*$W2+$L2^2*$U2*(1-$U2)*($J2-$K2)^2) | Y2: =IF($O2="","",$O2) | Z2: =IF($P2="","",$P2) | AA2: =IF($O2="","",N($N2)*N($O2)+N($R2)*N($S2)) | AB2: =IF($O2="","",(N($N2)*N($P2)+N($N2)*(1-N($N2))*N($O2)^2)+(N($R2)*N($T2)+N($R2)*(1-N($R2))*N($S2)^2)) | AC2: =IF($O2="","",N($N2)*N($O2)+N($R2)*N($S2)+N($V2)*N($W2)) | AD2: =IF($O2="","",(N($N2)*N($P2)+N($N2)*(1-N($N2))*N($O2)^2)+(N($R2)*N($T2)+N($R2)*(1-N($R2))*N($S2)^2)+(N($V2)*N($X2)+N($V2)*(1-N($V2))*N($W2)^2)) | AE2: =IF($I2="","",$I2*$L2) | AF2: =IF($I2="","",$I2*$L2*(1+N($R2))) | AG2: =IF($I2="","",$I2*$L2*(1+N($R2)+N($V2))) | AH2: =TRIM(IF($G2<Config!$B$9,"thin sample ("&$G2&" maps) · ","")&IF($I2="","no PickFinder stats · ","")&IFERROR(IF(INDEX(Players!$T$2:$T$11,MATCH($E2,Players!$A$2:$A$11,0))<0.5,"new roster: "&TEXT(INDEX(Players!$T$2:$T$11,MATCH($E2,Players!$A$2:$A$11,0)),"0%")&" of his recent games with these teammates",""),"")) | AI2: =IF($B2=Board!$B$2,COUNTIFS($B$2:$B$11,Board!$B$2,$Y$2:$Y$11,">"&$Y2)+COUNTIFS($B$1:$B1,Board!$B$2,$Y$1:$Y1,$Y2)+1,"") | AJ2: =IFERROR(IF(INDEX(Matches!$D$5:$D$5,MATCH($B2,Matches!$A$5:$A$5,0))=3,"K12","K13"),"K13") | AK2: =IF($AJ2="K12",$AA2,$AC2)
A3: 60n3jocjohvthia|LOL · KC vs MVK | B3: LOL · KC vs MVK | C3: KC | D3: Caliste | E3: 60n3jocjohvthia | F3: =IFERROR(IF($C3=INDEX(Matches!$S$5:$S$5,MATCH($B3,Matches!$A$5:$A$5,0)),"A",IF($C3=INDEX(Matches!$T$5:$T$5,MATCH($B3,Matches!$A$5:$A$5,0)),"B","")),"") | G3: =IFERROR(INDEX(Players!$E$2:$E$11,MATCH($E3,Players!$A$2:$A$11,0)),0) | H3: =IFERROR(INDEX(Players!$F$2:$F$11,MATCH($E3,Players!$A$2:$A$11,0)),"") | I3: =IFERROR(INDEX(Players!$G$2:$G$11,MATCH($E3,Players!$A$2:$A$11,0)),"") | J3: =IF(OR($I3="",$H3=""),"",$I3*IF(LEFT($B3,4)="DOTA",Config!$B$5,Config!$B$4)/($H3*IF(LEFT($B3,4)="DOTA",Config!$B$5,Config!$B$4)+1-$H3)) | K3: =IF(OR($I3="",$H3=""),"",$I3/($H3*IF(LEFT($B3,4)="DOTA",Config!$B$5,Config!$B$4)+1-$H3)) | L3: =IFERROR(INDEX(Matches!$R$5:$R$5,MATCH($B3,Matches!$A$5:$A$5,0)),1) | M3: =IFERROR(IF(INDEX(Matches!$M$5:$M$5,MATCH($B3,Matches!$A$5:$A$5,0))="","",IF($F3="A",INDEX(Matches!$M$5:$M$5,MATCH($B3,Matches!$A$5:$A$5,0)),1-INDEX(Matches!$M$5:$M$5,MATCH($B3,Matches!$A$5:$A$5,0)))),"") | N3: =1 | O3: =IF(OR($M3="",$J3=""),"",$L3*($M3*$J3+(1-$M3)*$K3)) | P3: =IF($O3="","",IF(LEFT($B3,4)="DOTA",Config!$B$7,Config!$B$6)*$O3+$L3^2*$M3*(1-$M3)*($J3-$K3)^2) | Q3: =IFERROR(IF(INDEX(Matches!$N$5:$N$5,MATCH($B3,Matches!$A$5:$A$5,0))="","",IF($F3="A",INDEX(Matches!$N$5:$N$5,MATCH($B3,Matches!$A$5:$A$5,0)),1-INDEX(Matches!$N$5:$N$5,MATCH($B3,Matches!$A$5:$A$5,0)))),"") | R3: =IFERROR(N(INDEX(Matches!$P$5:$P$5,MATCH($B3,Matches!$A$5:$A$5,0))),0) | S3: =IF(OR($Q3="",$J3=""),"",$L3*($Q3*$J3+(1-$Q3)*$K3)) | T3: =IF($S3="","",IF(LEFT($B3,4)="DOTA",Config!$B$7,Config!$B$6)*$S3+$L3^2*$Q3*(1-$Q3)*($J3-$K3)^2) | U3: =IFERROR(IF(INDEX(Matches!$O$5:$O$5,MATCH($B3,Matches!$A$5:$A$5,0))="","",IF($F3="A",INDEX(Matches!$O$5:$O$5,MATCH($B3,Matches!$A$5:$A$5,0)),1-INDEX(Matches!$O$5:$O$5,MATCH($B3,Matches!$A$5:$A$5,0)))),"") | V3: =IFERROR(N(INDEX(Matches!$Q$5:$Q$5,MATCH($B3,Matches!$A$5:$A$5,0))),0) | W3: =IF(OR($U3="",$J3=""),"",$L3*($U3*$J3+(1-$U3)*$K3)) | X3: =IF($W3="","",IF(LEFT($B3,4)="DOTA",Config!$B$7,Config!$B$6)*$W3+$L3^2*$U3*(1-$U3)*($J3-$K3)^2) | Y3: =IF($O3="","",$O3) | Z3: =IF($P3="","",$P3) | AA3: =IF($O3="","",N($N3)*N($O3)+N($R3)*N($S3)) | AB3: =IF($O3="","",(N($N3)*N($P3)+N($N3)*(1-N($N3))*N($O3)^2)+(N($R3)*N($T3)+N($R3)*(1-N($R3))*N($S3)^2)) | AC3: =IF($O3="","",N($N3)*N($O3)+N($R3)*N($S3)+N($V3)*N($W3)) | AD3: =IF($O3="","",(N($N3)*N($P3)+N($N3)*(1-N($N3))*N($O3)^2)+(N($R3)*N($T3)+N($R3)*(1-N($R3))*N($S3)^2)+(N($V3)*N($X3)+N($V3)*(1-N($V3))*N($W3)^2)) | AE3: =IF($I3="","",$I3*$L3) | AF3: =IF($I3="","",$I3*$L3*(1+N($R3))) | AG3: =IF($I3="","",$I3*$L3*(1+N($R3)+N($V3))) | AH3: =TRIM(IF($G3<Config!$B$9,"thin sample ("&$G3&" maps) · ","")&IF($I3="","no PickFinder stats · ","")&IFERROR(IF(INDEX(Players!$T$2:$T$11,MATCH($E3,Players!$A$2:$A$11,0))<0.5,"new roster: "&TEXT(INDEX(Players!$T$2:$T$11,MATCH($E3,Players!$A$2:$A$11,0)),"0%")&" of his recent games with these teammates",""),"")) | AI3: =IF($B3=Board!$B$2,COUNTIFS($B$2:$B$11,Board!$B$2,$Y$2:$Y$11,">"&$Y3)+COUNTIFS($B$1:$B2,Board!$B$2,$Y$1:$Y2,$Y3)+1,"") | AJ3: =IFERROR(IF(INDEX(Matches!$D$5:$D$5,MATCH($B3,Matches!$A$5:$A$5,0))=3,"K12","K13"),"K13") | AK3: =IF($AJ3="K12",$AA3,$AC3)
A4: 5h8ktthuwylbro2|LOL · KC vs MVK | B4: LOL · KC vs MVK | C4: KC | D4: Canna | E4: 5h8ktthuwylbro2 | F4: =IFERROR(IF($C4=INDEX(Matches!$S$5:$S$5,MATCH($B4,Matches!$A$5:$A$5,0)),"A",IF($C4=INDEX(Matches!$T$5:$T$5,MATCH($B4,Matches!$A$5:$A$5,0)),"B","")),"") | G4: =IFERROR(INDEX(Players!$E$2:$E$11,MATCH($E4,Players!$A$2:$A$11,0)),0) | H4: =IFERROR(INDEX(Players!$F$2:$F$11,MATCH($E4,Players!$A$2:$A$11,0)),"") | I4: =IFERROR(INDEX(Players!$G$2:$G$11,MATCH($E4,Players!$A$2:$A$11,0)),"") | J4: =IF(OR($I4="",$H4=""),"",$I4*IF(LEFT($B4,4)="DOTA",Config!$B$5,Config!$B$4)/($H4*IF(LEFT($B4,4)="DOTA",Config!$B$5,Config!$B$4)+1-$H4)) | K4: =IF(OR($I4="",$H4=""),"",$I4/($H4*IF(LEFT($B4,4)="DOTA",Config!$B$5,Config!$B$4)+1-$H4)) | L4: =IFERROR(INDEX(Matches!$R$5:$R$5,MATCH($B4,Matches!$A$5:$A$5,0)),1) | M4: =IFERROR(IF(INDEX(Matches!$M$5:$M$5,MATCH($B4,Matches!$A$5:$A$5,0))="","",IF($F4="A",INDEX(Matches!$M$5:$M$5,MATCH($B4,Matches!$A$5:$A$5,0)),1-INDEX(Matches!$M$5:$M$5,MATCH($B4,Matches!$A$5:$A$5,0)))),"") | N4: =1 | O4: =IF(OR($M4="",$J4=""),"",$L4*($M4*$J4+(1-$M4)*$K4)) | P4: =IF($O4="","",IF(LEFT($B4,4)="DOTA",Config!$B$7,Config!$B$6)*$O4+$L4^2*$M4*(1-$M4)*($J4-$K4)^2) | Q4: =IFERROR(IF(INDEX(Matches!$N$5:$N$5,MATCH($B4,Matches!$A$5:$A$5,0))="","",IF($F4="A",INDEX(Matches!$N$5:$N$5,MATCH($B4,Matches!$A$5:$A$5,0)),1-INDEX(Matches!$N$5:$N$5,MATCH($B4,Matches!$A$5:$A$5,0)))),"") | R4: =IFERROR(N(INDEX(Matches!$P$5:$P$5,MATCH($B4,Matches!$A$5:$A$5,0))),0) | S4: =IF(OR($Q4="",$J4=""),"",$L4*($Q4*$J4+(1-$Q4)*$K4)) | T4: =IF($S4="","",IF(LEFT($B4,4)="DOTA",Config!$B$7,Config!$B$6)*$S4+$L4^2*$Q4*(1-$Q4)*($J4-$K4)^2) | U4: =IFERROR(IF(INDEX(Matches!$O$5:$O$5,MATCH($B4,Matches!$A$5:$A$5,0))="","",IF($F4="A",INDEX(Matches!$O$5:$O$5,MATCH($B4,Matches!$A$5:$A$5,0)),1-INDEX(Matches!$O$5:$O$5,MATCH($B4,Matches!$A$5:$A$5,0)))),"") | V4: =IFERROR(N(INDEX(Matches!$Q$5:$Q$5,MATCH($B4,Matches!$A$5:$A$5,0))),0) | W4: =IF(OR($U4="",$J4=""),"",$L4*($U4*$J4+(1-$U4)*$K4)) | X4: =IF($W4="","",IF(LEFT($B4,4)="DOTA",Config!$B$7,Config!$B$6)*$W4+$L4^2*$U4*(1-$U4)*($J4-$K4)^2) | Y4: =IF($O4="","",$O4) | Z4: =IF($P4="","",$P4) | AA4: =IF($O4="","",N($N4)*N($O4)+N($R4)*N($S4)) | AB4: =IF($O4="","",(N($N4)*N($P4)+N($N4)*(1-N($N4))*N($O4)^2)+(N($R4)*N($T4)+N($R4)*(1-N($R4))*N($S4)^2)) | AC4: =IF($O4="","",N($N4)*N($O4)+N($R4)*N($S4)+N($V4)*N($W4)) | AD4: =IF($O4="","",(N($N4)*N($P4)+N($N4)*(1-N($N4))*N($O4)^2)+(N($R4)*N($T4)+N($R4)*(1-N($R4))*N($S4)^2)+(N($V4)*N($X4)+N($V4)*(1-N($V4))*N($W4)^2)) | AE4: =IF($I4="","",$I4*$L4) | AF4: =IF($I4="","",$I4*$L4*(1+N($R4))) | AG4: =IF($I4="","",$I4*$L4*(1+N($R4)+N($V4))) | AH4: =TRIM(IF($G4<Config!$B$9,"thin sample ("&$G4&" maps) · ","")&IF($I4="","no PickFinder stats · ","")&IFERROR(IF(INDEX(Players!$T$2:$T$11,MATCH($E4,Players!$A$2:$A$11,0))<0.5,"new roster: "&TEXT(INDEX(Players!$T$2:$T$11,MATCH($E4,Players!$A$2:$A$11,0)),"0%")&" of his recent games with these teammates",""),"")) | AI4: =IF($B4=Board!$B$2,COUNTIFS($B$2:$B$11,Board!$B$2,$Y$2:$Y$11,">"&$Y4)+COUNTIFS($B$1:$B3,Board!$B$2,$Y$1:$Y3,$Y4)+1,"") | AJ4: =IFERROR(IF(INDEX(Matches!$D$5:$D$5,MATCH($B4,Matches!$A$5:$A$5,0))=3,"K12","K13"),"K13") | AK4: =IF($AJ4="K12",$AA4,$AC4)
A5: cp4ibkwui10xeyj|LOL · KC vs MVK | B5: LOL · KC vs MVK | C5: KC | D5: Kyeahoo | E5: cp4ibkwui10xeyj | F5: =IFERROR(IF($C5=INDEX(Matches!$S$5:$S$5,MATCH($B5,Matches!$A$5:$A$5,0)),"A",IF($C5=INDEX(Matches!$T$5:$T$5,MATCH($B5,Matches!$A$5:$A$5,0)),"B","")),"") | G5: =IFERROR(INDEX(Players!$E$2:$E$11,MATCH($E5,Players!$A$2:$A$11,0)),0) | H5: =IFERROR(INDEX(Players!$F$2:$F$11,MATCH($E5,Players!$A$2:$A$11,0)),"") | I5: =IFERROR(INDEX(Players!$G$2:$G$11,MATCH($E5,Players!$A$2:$A$11,0)),"") | J5: =IF(OR($I5="",$H5=""),"",$I5*IF(LEFT($B5,4)="DOTA",Config!$B$5,Config!$B$4)/($H5*IF(LEFT($B5,4)="DOTA",Config!$B$5,Config!$B$4)+1-$H5)) | K5: =IF(OR($I5="",$H5=""),"",$I5/($H5*IF(LEFT($B5,4)="DOTA",Config!$B$5,Config!$B$4)+1-$H5)) | L5: =IFERROR(INDEX(Matches!$R$5:$R$5,MATCH($B5,Matches!$A$5:$A$5,0)),1) | M5: =IFERROR(IF(INDEX(Matches!$M$5:$M$5,MATCH($B5,Matches!$A$5:$A$5,0))="","",IF($F5="A",INDEX(Matches!$M$5:$M$5,MATCH($B5,Matches!$A$5:$A$5,0)),1-INDEX(Matches!$M$5:$M$5,MATCH($B5,Matches!$A$5:$A$5,0)))),"") | N5: =1 | O5: =IF(OR($M5="",$J5=""),"",$L5*($M5*$J5+(1-$M5)*$K5)) | P5: =IF($O5="","",IF(LEFT($B5,4)="DOTA",Config!$B$7,Config!$B$6)*$O5+$L5^2*$M5*(1-$M5)*($J5-$K5)^2) | Q5: =IFERROR(IF(INDEX(Matches!$N$5:$N$5,MATCH($B5,Matches!$A$5:$A$5,0))="","",IF($F5="A",INDEX(Matches!$N$5:$N$5,MATCH($B5,Matches!$A$5:$A$5,0)),1-INDEX(Matches!$N$5:$N$5,MATCH($B5,Matches!$A$5:$A$5,0)))),"") | R5: =IFERROR(N(INDEX(Matches!$P$5:$P$5,MATCH($B5,Matches!$A$5:$A$5,0))),0) | S5: =IF(OR($Q5="",$J5=""),"",$L5*($Q5*$J5+(1-$Q5)*$K5)) | T5: =IF($S5="","",IF(LEFT($B5,4)="DOTA",Config!$B$7,Config!$B$6)*$S5+$L5^2*$Q5*(1-$Q5)*($J5-$K5)^2) | U5: =IFERROR(IF(INDEX(Matches!$O$5:$O$5,MATCH($B5,Matches!$A$5:$A$5,0))="","",IF($F5="A",INDEX(Matches!$O$5:$O$5,MATCH($B5,Matches!$A$5:$A$5,0)),1-INDEX(Matches!$O$5:$O$5,MATCH($B5,Matches!$A$5:$A$5,0)))),"") | V5: =IFERROR(N(INDEX(Matches!$Q$5:$Q$5,MATCH($B5,Matches!$A$5:$A$5,0))),0) | W5: =IF(OR($U5="",$J5=""),"",$L5*($U5*$J5+(1-$U5)*$K5)) | X5: =IF($W5="","",IF(LEFT($B5,4)="DOTA",Config!$B$7,Config!$B$6)*$W5+$L5^2*$U5*(1-$U5)*($J5-$K5)^2) | Y5: =IF($O5="","",$O5) | Z5: =IF($P5="","",$P5) | AA5: =IF($O5="","",N($N5)*N($O5)+N($R5)*N($S5)) | AB5: =IF($O5="","",(N($N5)*N($P5)+N($N5)*(1-N($N5))*N($O5)^2)+(N($R5)*N($T5)+N($R5)*(1-N($R5))*N($S5)^2)) | AC5: =IF($O5="","",N($N5)*N($O5)+N($R5)*N($S5)+N($V5)*N($W5)) | AD5: =IF($O5="","",(N($N5)*N($P5)+N($N5)*(1-N($N5))*N($O5)^2)+(N($R5)*N($T5)+N($R5)*(1-N($R5))*N($S5)^2)+(N($V5)*N($X5)+N($V5)*(1-N($V5))*N($W5)^2)) | AE5: =IF($I5="","",$I5*$L5) | AF5: =IF($I5="","",$I5*$L5*(1+N($R5))) | AG5: =IF($I5="","",$I5*$L5*(1+N($R5)+N($V5))) | AH5: =TRIM(IF($G5<Config!$B$9,"thin sample ("&$G5&" maps) · ","")&IF($I5="","no PickFinder stats · ","")&IFERROR(IF(INDEX(Players!$T$2:$T$11,MATCH($E5,Players!$A$2:$A$11,0))<0.5,"new roster: "&TEXT(INDEX(Players!$T$2:$T$11,MATCH($E5,Players!$A$2:$A$11,0)),"0%")&" of his recent games with these teammates",""),"")) | AI5: =IF($B5=Board!$B$2,COUNTIFS($B$2:$B$11,Board!$B$2,$Y$2:$Y$11,">"&$Y5)+COUNTIFS($B$1:$B4,Board!$B$2,$Y$1:$Y4,$Y5)+1,"") | AJ5: =IFERROR(IF(INDEX(Matches!$D$5:$D$5,MATCH($B5,Matches!$A$5:$A$5,0))=3,"K12","K13"),"K13") | AK5: =IF($AJ5="K12",$AA5,$AC5)
A6: rfespsq7mcurckt|LOL · KC vs MVK | B6: LOL · KC vs MVK | C6: KC | D6: Yike | E6: rfespsq7mcurckt | F6: =IFERROR(IF($C6=INDEX(Matches!$S$5:$S$5,MATCH($B6,Matches!$A$5:$A$5,0)),"A",IF($C6=INDEX(Matches!$T$5:$T$5,MATCH($B6,Matches!$A$5:$A$5,0)),"B","")),"") | G6: =IFERROR(INDEX(Players!$E$2:$E$11,MATCH($E6,Players!$A$2:$A$11,0)),0) | H6: =IFERROR(INDEX(Players!$F$2:$F$11,MATCH($E6,Players!$A$2:$A$11,0)),"") | I6: =IFERROR(INDEX(Players!$G$2:$G$11,MATCH($E6,Players!$A$2:$A$11,0)),"") | J6: =IF(OR($I6="",$H6=""),"",$I6*IF(LEFT($B6,4)="DOTA",Config!$B$5,Config!$B$4)/($H6*IF(LEFT($B6,4)="DOTA",Config!$B$5,Config!$B$4)+1-$H6)) | K6: =IF(OR($I6="",$H6=""),"",$I6/($H6*IF(LEFT($B6,4)="DOTA",Config!$B$5,Config!$B$4)+1-$H6)) | L6: =IFERROR(INDEX(Matches!$R$5:$R$5,MATCH($B6,Matches!$A$5:$A$5,0)),1) | M6: =IFERROR(IF(INDEX(Matches!$M$5:$M$5,MATCH($B6,Matches!$A$5:$A$5,0))="","",IF($F6="A",INDEX(Matches!$M$5:$M$5,MATCH($B6,Matches!$A$5:$A$5,0)),1-INDEX(Matches!$M$5:$M$5,MATCH($B6,Matches!$A$5:$A$5,0)))),"") | N6: =1 | O6: =IF(OR($M6="",$J6=""),"",$L6*($M6*$J6+(1-$M6)*$K6)) | P6: =IF($O6="","",IF(LEFT($B6,4)="DOTA",Config!$B$7,Config!$B$6)*$O6+$L6^2*$M6*(1-$M6)*($J6-$K6)^2) | Q6: =IFERROR(IF(INDEX(Matches!$N$5:$N$5,MATCH($B6,Matches!$A$5:$A$5,0))="","",IF($F6="A",INDEX(Matches!$N$5:$N$5,MATCH($B6,Matches!$A$5:$A$5,0)),1-INDEX(Matches!$N$5:$N$5,MATCH($B6,Matches!$A$5:$A$5,0)))),"") | R6: =IFERROR(N(INDEX(Matches!$P$5:$P$5,MATCH($B6,Matches!$A$5:$A$5,0))),0) | S6: =IF(OR($Q6="",$J6=""),"",$L6*($Q6*$J6+(1-$Q6)*$K6)) | T6: =IF($S6="","",IF(LEFT($B6,4)="DOTA",Config!$B$7,Config!$B$6)*$S6+$L6^2*$Q6*(1-$Q6)*($J6-$K6)^2) | U6: =IFERROR(IF(INDEX(Matches!$O$5:$O$5,MATCH($B6,Matches!$A$5:$A$5,0))="","",IF($F6="A",INDEX(Matches!$O$5:$O$5,MATCH($B6,Matches!$A$5:$A$5,0)),1-INDEX(Matches!$O$5:$O$5,MATCH($B6,Matches!$A$5:$A$5,0)))),"") | V6: =IFERROR(N(INDEX(Matches!$Q$5:$Q$5,MATCH($B6,Matches!$A$5:$A$5,0))),0) | W6: =IF(OR($U6="",$J6=""),"",$L6*($U6*$J6+(1-$U6)*$K6)) | X6: =IF($W6="","",IF(LEFT($B6,4)="DOTA",Config!$B$7,Config!$B$6)*$W6+$L6^2*$U6*(1-$U6)*($J6-$K6)^2) | Y6: =IF($O6="","",$O6) | Z6: =IF($P6="","",$P6) | AA6: =IF($O6="","",N($N6)*N($O6)+N($R6)*N($S6)) | AB6: =IF($O6="","",(N($N6)*N($P6)+N($N6)*(1-N($N6))*N($O6)^2)+(N($R6)*N($T6)+N($R6)*(1-N($R6))*N($S6)^2)) | AC6: =IF($O6="","",N($N6)*N($O6)+N($R6)*N($S6)+N($V6)*N($W6)) | AD6: =IF($O6="","",(N($N6)*N($P6)+N($N6)*(1-N($N6))*N($O6)^2)+(N($R6)*N($T6)+N($R6)*(1-N($R6))*N($S6)^2)+(N($V6)*N($X6)+N($V6)*(1-N($V6))*N($W6)^2)) | AE6: =IF($I6="","",$I6*$L6) | AF6: =IF($I6="","",$I6*$L6*(1+N($R6))) | AG6: =IF($I6="","",$I6*$L6*(1+N($R6)+N($V6))) | AH6: =TRIM(IF($G6<Config!$B$9,"thin sample ("&$G6&" maps) · ","")&IF($I6="","no PickFinder stats · ","")&IFERROR(IF(INDEX(Players!$T$2:$T$11,MATCH($E6,Players!$A$2:$A$11,0))<0.5,"new roster: "&TEXT(INDEX(Players!$T$2:$T$11,MATCH($E6,Players!$A$2:$A$11,0)),"0%")&" of his recent games with these teammates",""),"")) | AI6: =IF($B6=Board!$B$2,COUNTIFS($B$2:$B$11,Board!$B$2,$Y$2:$Y$11,">"&$Y6)+COUNTIFS($B$1:$B5,Board!$B$2,$Y$1:$Y5,$Y6)+1,"") | AJ6: =IFERROR(IF(INDEX(Matches!$D$5:$D$5,MATCH($B6,Matches!$A$5:$A$5,0))=3,"K12","K13"),"K13") | AK6: =IF($AJ6="K12",$AA6,$AC6)
