Workbook

Sheet README
A1: FPS Player Model — CS2 + Valorant
A2: Kills and headshot projections built map by map: per-map KPR × the rounds you expect on that map.
A3: Slate 2026-10-20 · 194 board legs · 13 matches
A5: HOW TO USE
A6: 1. Matches tab: every match on the slate, one row each. The shaded columns are yours — Map 1, Map 2, Map 3 (dropdowns) and Rounds M1/M2/M3. They arrive prefilled: maps from PickFinder's Map Picks, rounds from Thunderpick's Total Rounds ladder for that map. Change any of them and every projection for that match recalculates.
A7: 2. Board tab: pick a match in the shaded cell B2. Both rosters load, ranked by projected Maps 1-2 kills, with the PrizePicks line, the model's P(over), Thunderpick's own kill-line median and PickFinder's L10 beside it.
A8: 3. Projections tab: every leg on the board (Maps 1-2, Map 1, Map 2 — kills and HS), filterable.
A9: 4. Log tab: the same projections frozen as values at default settings when the sheet was built. Type the result in Actual after settlement; Result fills itself. This is the forward record the model does not yet have.
A11: THE MODEL, IN FOUR LINES
A12: Per-map KPR = (n × map KPR + SHRINK_MAPS × overall KPR) ÷ (n + SHRINK_MAPS), n = maps the player has on that map in PickFinder's sample. A map he has never played uses his overall KPR.
A13: Kills on map k = per-map KPR × rounds on map k. Maps 1-2 = map 1 + map 2. Maps 1-3 = maps 1-2 + P(map 3) × map 3.
A14: HS on map k = kills on map k × per-map HS%, shrunk the same way. (CS2 only — PickFinder posts no Valorant HS%.)
... A36: Each slate is rebuilt from fresh captures and imported over this file (File → Import → Replace spreadsheet), so the link stays the same. Your shaded edits are per slate and are replaced on the next import.

Sheet Match_Intel
A1: Match Intel — 2026-10-20
A2: Recent form, margins, ranks, pistols, map pools and recent vetoes per match. Windows: HLTV 3 months to the day before the slate; vlr last 10 series. Bucket probabilities are the frozen v2 model (PAPER, not a pick). Margins are rounds: + won by, − lost by.
A4: CS2 [NO MARKET] · AE vs RA | 05:00 UTC | Bo3
A5: No HLTV intel captured for this match.
A7: CS2 · PRIV vs ALL | 09:00 UTC | Bo3 | Win: PRIV 38% – ALL 62% | 2-0 18% · 2-1 20% · 1-2 29% · 0-2 32%
B8: Private (PRIV) | C8: Alliance (ALL)
A9: Rank | B9: HLTV: #63 · VRS: #80 | C9: HLTV: #29 · VRS: #36
A10: Last 10 maps (newest first) | B10: 5-5 L L W W W W L L W L | C10: 2-8 L L L L L L W L W L
A11: Last 10 maps, avg margin | B11: +0.3 | C11: -3.4
A12: 3 months: maps W-L | B12: 17-10 (63%) | C12: 9-17 (35%)
A13: Avg margin in wins / losses | B13: +6.2 / -4.5 | C13: +3.1 / -5.9
A14: Stomps for / against (8+) | B14: 4 / 2 | C14: 0 / 6
A15: Pistols (3 months) | B15: not captured | C15: not captured
A16: Kill share (last 6 series, all maps) | B16: 6 series · 14 maps · team 79.6 kills/map sowalio 21.4% (17.1/map) z1k4 21.3% (17.0/map) H4SAN4TOR 20.9% (16.6/map) 1eeR 18.6% (14.8/map) sh1nejezzz 17.8% (14.1/map) | C16: 6 series · 14 maps · team 67.1 kills/map eraa 23.9% (16.1/map) bobeksde 22.3% (15.0/map) avid 18.0% (12.1/map) upE 17.9% (12.0/map) twist 17.9% (12.0/map)
A17: Last 5 series | B17: 0 - 2 PRIVATE vs BIG 2 - 0 PRIVATE vs UPGRADE 2 - 1 PRIVATE vs Honvéd 1 - 2 PRIVATE vs Johnny Speeds 13 - 8 PRIVATE vs BET-M | C17: 0 - 2 Alliance vs The MongolZ 0 - 2 Alliance vs fnatic 0 - 2 Alliance vs Nemiga 2 - 1 Alliance vs Astralis 0 - 2 Alliance vs 3DMAX
A18: Recent vetoes (last 5) | B18: First ban: Inferno×5 First pick: Mirage×2, Dust2×1 19th of Octo PRIVATE vs BIG: opp ban Dust2 · us ban Inferno · opp pick Cache · us pick Mirage · us ban Nuke · opp ban Anubis · left Ancient 16th of Octo PRIVATE vs UPGRADE: us ban Inferno · opp ban Mirage · us pick Dust2 · opp pick Anubis · us ban Cache · opp ban Ancient · left Nuke 15th of Octo PRIVATE vs Honvéd: opp ban Nuke · us ban Inferno · opp pick Cache · us pick Ancient · opp ban Mirage · us ban Anubis · left Dust2 12th of Octo PRIVATE vs Johnny Speeds: opp ban Anubis · us ban Inferno · opp pick Cache · us pick Mirage · us ban Dust2 · opp ban Ancient · left Nuke 11th of Octo PRIVATE vs BET-M: opp ban Cache · opp ban Mirage · us ban Inferno · us ban Anubis · us ban Nuke · opp ban Ancient · left Dust2 | C18: First ban: Mirage×3, Cache×2 First pick: Inferno×4, Ancient×1 19th of Octo Alliance vs The MongolZ: us ban Cache · opp ban Anubis · us pick Inferno · opp pick Dust2 · opp ban Nuke · us ban Mirage · left Ancient 3rd of Octob Alliance vs fnatic: opp ban Nuke · us ban Mirage · opp pick Cache · us pick Inferno · us ban Anubis · opp ban Ancient · left Dust2 2nd of Octob Alliance vs Nemiga: opp ban Inferno · us ban Mirage · opp pick Cache · us pick Ancient · us ban Dust2 · opp ban Nuke · left Anubis 1st of Octob Alliance vs Astralis: us ban Mirage · opp ban Dust2 · us pick Inferno · opp pick Cache · opp ban Anubis · us ban Ancient · left Nuke 26th of Sept Alliance vs 3DMAX: opp ban Mirage · us ban Cache · opp pick Dust2 · us pick Inferno · us ban Anubis · opp ban Nuke · left Ancient
A19: Map | B19: PF pick % | C19: A maps | D19: A W-L | E19: A avg ± | F19: A CT % | G19: A T % | H19: A pistol | I19: B maps | J19: B W-L | K19: B avg ± | L19: B CT % | M19: B T % | N19: B pistol | O19: A 8+ | A 3-7 | close/OT | B 3-7 | B 8+ | P19: E rounds
A20: Ancient | B20: 30% | C20: 5 | D20: 5-0 | E20: +5.6 | F20: 56.0% | G20: 67.2% | H20: 4/10 | I20: 5 | J20: 3-2 | K20: -0.8 | L20: 56.7% | M20: 38.9% | N20: 3/10 | O20: 11% | 39% | 29% | 19% | 3% | P20: 22.3
A21: Dust2 | B21: 20% | C21: 5 | D21: 4-1 | E21: +4.4 | F21: 60.6% | G21: 58.0% | H21: 7/10 | I21: 5 | J21: 0-5 | K21: -4.8 | L21: 48.3% | M21: 26.1% | N21: 3/10 | O21: 14% | 43% | 26% | 14% | 2% | P21: 22.0
A22: Inferno | B22: 18% | C22: 0 | I22: 10 | J22: 4-6 | K22: -2.3 | L22: 44.6% | M22: 44.7% | N22: 8/20 | O22: 8% | 34% | 30% | 23% | 4% | P22: 22.5
A23: Nuke | B23: 8% | C23: 3 | D23: 1-2 | E23: -1.0 | F23: 52.8% | G23: 41.4% | H23: 4/6 | I23: 2 | J23: 2-0 | K23: +2.5 | L23: 65.2% | M23: 45.8% | N23: 2/4 | O23: 5% | 25% | 30% | 32% | 8% | P23: 22.5
A24: Cache | B24: 8% | C24: 5 | D24: 0-5 | E24: -5.2 | F24: 52.7% | G24: 23.6% | H24: 5/10 | I24: 4 | J24: 0-4 | K24: -6.8 | L24: 39.6% | M24: 20.7% | N24: 3/8 | O24: 7% | 31% | 31% | 26% | 5% | P24: 22.5
A25: Mirage | B25: 8% | C25: 6 | D25: 5-1 | E25: +5.2 | F25: 66.7% | G25: 58.5% | H25: 7/12 | I25: 0 | O25: 10% | 38% | 29% | 19% | 3% | P25: 22.3
A26: Anubis | C26: 3 | D26: 2-1 | E26: +2.7 | F26: 72.7% | G26: 47.2% | H26: 3/6 | I26: 0 | O26: 8% | 33% | 30% | 24% | 5% | P26: 22.5
A28: CS2 [NO MARKET] · MZP vs ex-RUSTEC | 09:00 UTC | Bo3
A29: No HLTV intel captured for this match.
A31: CS2 · BBL vs BCG | 11:00 UTC | Bo3 | Win: BBL 39% – BCG 61% | 2-0 20% · 2-1 19% · 1-2 26% · 0-2 35%
B32: BBL Esports (BBL) | C32: BC.Game (BCG)
A33: Rank | B33: HLTV: #48 · VRS: #35 | C33: HLTV: #51 · VRS: #41
A34: Last 10 maps (newest first) | B34: 6-4 W L W W W L W W L L | C34: 5-5 W W L W L L L W L W
A35: Last 10 maps, avg margin | B35: +2.3 | C35: -0.6
A36: 3 months: maps W-L | B36: 31-32 (49%) | C36: 26-13 (67%)
A37: Avg margin in wins / losses | B37: +6.1 / -5.1 | C37: +6.0 / -4.2
A38: Stomps for / against (8+) | B38: 12 / 7 | C38: 8 / 2
A39: Pistols (3 months) | B39: not captured | C39: not captured
A40: Kill share (last 6 series, all maps) | B40: 6 series · 16 maps · team 76.0 kills/map leakz 22.0% (16.7/map) NickyB 21.6% (16.4/map) salazar 20.8% (15.8/map) IceBerg 17.4% (13.2/map) MistR 16.0% (13.9/map) Boye 2.1% (13.0/map) (sub) | C40: 6 series · 13 maps · team 69.5 kills/map s1mple 24.3% (16.8/map) mzinho 21.6% (15.0/map) Senzu 20.2% (14.0/map) Magisk 18.1% (12.5/map) asap 15.9% (11.1/map)
A41: Last 5 series | B41: 2 - 1 BBL vs Betclic 2 - 1 BBL vs ex-RUSTEC 2 - 0 BBL vs EYEBALLERS 1 - 2 BBL vs JiJieHao 1 - 2 BBL vs Liquid | C41: 13 - 10 BC.Game vs WBT 13 - 8 BC.Game vs Drama 1 - 2 BC.Game vs MIBR 0 - 2 BC.Game vs HEROIC 2 - 1 BC.Game vs MIBR
A42: Recent vetoes (last 5) | B42: First ban: Dust2×5 First pick: Nuke×3, Cache×1 19th of Octo BBL vs Betclic: opp ban Inferno · us ban Dust2 · opp pick Cache · us pick Nuke · us ban Anubis · opp ban Ancient · left Mirage 17th of Octo BBL vs ex-RUSTEC: opp ban Cache · us ban Dust2 · opp pick Anubis · us pick Nuke · us ban Mirage · opp ban Inferno · left Ancient 16th of Octo BBL vs EYEBALLERS: opp ban Nuke · us ban Dust2 · opp pick Anubis · us pick Cache · us ban Mirage · opp ban Ancient · left Inferno 13th of Octo BBL vs JiJieHao: us ban Dust2 · opp ban Nuke · us pick Inferno · opp pick Mirage · us ban Anubis · opp ban Ancient · left Cache 13th of Octo BBL vs Liquid: us ban Dust2 · opp ban Ancient · us pick Nuke · opp pick Mirage · us ban Anubis · opp ban Inferno · left Cache | C42: First ban: Ancient×2, Anubis×2 First pick: Cache×2, Mirage×1 19th of Octo BC.Game vs WBT: opp ban Inferno · opp ban Cache · us ban Ancient · us ban Anubis · us ban Mirage · opp ban Nuke · left Dust2 19th of Octo BC.Game vs Drama: opp ban Dust2 · opp ban Cache · us ban Ancient · us ban Anubis · us ban Inferno · opp ban Nuke · left Mirage 15th of Octo BC.Game vs MIBR: us ban Anubis · opp ban Dust2 · us pick Mirage · opp pick Ancient · us ban Nuke · opp ban Cache · left Inferno 15th of Octo BC.Game vs HEROIC: us ban Inferno · opp ban Anubis · us pick Cache · opp pick Nuke · us ban Ancient · opp ban Dust2 · left Mirage 15th of Octo BC.Game vs MIBR: us ban Anubis · opp ban Dust2 · us pick Cache · opp pick Ancient · us ban Inferno · opp ban Mirage · left Nuke
A43: Map | B43: PF pick % | C43: A maps | D43: A W-L | E43: A avg ± | F43: A CT % | G43: A T % | H43: A pistol | I43: B maps | J43: B W-L | K43: B avg ± | L43: B CT % | M43: B T % | N43: B pistol | O43: A 8+ | A 3-7 | close/OT | B 3-7 | B 8+ | P43: E rounds
A44: Cache | B44: 38% | C44: 12 | D44: 4-8 | E44: -0.7 | F44: 45.2% | G44: 51.8% | H44: 15/24 | I44: 9 | J44: 8-1 | K44: +4.2 | L44: 63.5% | M44: 57.3% | N44: 8/18 | O44: 3% | 17% | 28% | 40% | 12% | P44: 22.2
...

Sheet Board
A1: Board
A2: Match: | B2: CS2 [NO MARKET] · AE vs RA
A4: Teams | B4: =IFERROR(IF(INDEX(Matches!$E$5:$E$17,MATCH($B$2,Matches!$A$5:$A$17,0))="","",INDEX(Matches!$E$5:$E$17,MATCH($B$2,Matches!$A$5:$A$17,0))),"")&" vs "&IFERROR(IF(INDEX(Matches!$F$5:$F$17,MATCH($B$2,Matches!$A$5:$A$17,0))="","",INDEX(Matches!$F$5:$F$17,MATCH($B$2,Matches!$A$5:$A$17,0))),"") -> AE (AE) vs RA (RA) | D4: Start (CT) | E4: =IFERROR(IF(INDEX(Matches!$C$5:$C$17,MATCH($B$2,Matches!$A$5:$A$17,0))="","",INDEX(Matches!$C$5:$C$17,MATCH($B$2,Matches!$A$5:$A$17,0))),"") -> Tue 00:00 | G4: Bo | H4: =IFERROR(IF(INDEX(Matches!$D$5:$D$17,MATCH($B$2,Matches!$A$5:$A$17,0))="","",INDEX(Matches!$D$5:$D$17,MATCH($B$2,Matches!$A$5:$A$17,0))),"") -> 3
A5: P(A wins) | B5: =IFERROR(IF(INDEX(Matches!$G$5:$G$17,MATCH($B$2,Matches!$A$5:$A$17,0))="","",INDEX(Matches!$G$5:$G$17,MATCH($B$2,Matches!$A$5:$A$17,0))),"") | D5: P(A 2-0) | E5: =IFERROR(IF(INDEX(Matches!$H$5:$H$17,MATCH($B$2,Matches!$A$5:$A$17,0))="","",INDEX(Matches!$H$5:$H$17,MATCH($B$2,Matches!$A$5:$A$17,0))),"") | G5: P(B 2-0) | H5: =IFERROR(IF(INDEX(Matches!$I$5:$I$17,MATCH($B$2,Matches!$A$5:$A$17,0))="","",INDEX(Matches!$I$5:$I$17,MATCH($B$2,Matches!$A$5:$A$17,0))),"")
A6: P(3 maps) | B6: =IFERROR(IF(INDEX(Matches!$J$5:$J$17,MATCH($B$2,Matches!$A$5:$A$17,0))="","",INDEX(Matches!$J$5:$J$17,MATCH($B$2,Matches!$A$5:$A$17,0))),"") | D6: Map pick #1 | E6: =IFERROR(IF(INDEX(Matches!$K$5:$K$17,MATCH($B$2,Matches!$A$5:$A$17,0))="","",INDEX(Matches!$K$5:$K$17,MATCH($B$2,Matches!$A$5:$A$17,0))),"") -> Dust2 53% | G6: Map pick #2 | H6: =IFERROR(IF(INDEX(Matches!$L$5:$L$17,MATCH($B$2,Matches!$A$5:$A$17,0))="","",INDEX(Matches!$L$5:$L$17,MATCH($B$2,Matches!$A$5:$A$17,0))),"") -> Cache 26%
A7: TP rounds M1 | B7: =IFERROR(IF(INDEX(Matches!$O$5:$O$17,MATCH($B$2,Matches!$A$5:$A$17,0))="","",INDEX(Matches!$O$5:$O$17,MATCH($B$2,Matches!$A$5:$A$17,0))),"") | D7: TP rounds M2 | E7: =IFERROR(IF(INDEX(Matches!$P$5:$P$17,MATCH($B$2,Matches!$A$5:$A$17,0))="","",INDEX(Matches!$P$5:$P$17,MATCH($B$2,Matches!$A$5:$A$17,0))),"") | G7: P(OT) M1 | H7: =IFERROR(IF(INDEX(Matches!$R$5:$R$17,MATCH($B$2,Matches!$A$5:$A$17,0))="","",INDEX(Matches!$R$5:$R$17,MATCH($B$2,Matches!$A$5:$A$17,0))),"")
A8: A margin M1 | B8: =IFERROR(IF(INDEX(Matches!$S$5:$S$17,MATCH($B$2,Matches!$A$5:$A$17,0))="","",INDEX(Matches!$S$5:$S$17,MATCH($B$2,Matches!$A$5:$A$17,0))),"") | D8: A rounds M1 | E8: =IFERROR(IF(INDEX(Matches!$T$5:$T$17,MATCH($B$2,Matches!$A$5:$A$17,0))="","",INDEX(Matches!$T$5:$T$17,MATCH($B$2,Matches!$A$5:$A$17,0))),"") | G8: B rounds M1 | H8: =IFERROR(IF(INDEX(Matches!$U$5:$U$17,MATCH($B$2,Matches!$A$5:$A$17,0))="","",INDEX(Matches!$U$5:$U$17,MATCH($B$2,Matches!$A$5:$A$17,0))),"")
A9: HLTV rounds M1 | B9: =IFERROR(IF(INDEX(Matches!$AN$5:$AN$17,MATCH($B$2,Matches!$A$5:$A$17,0))="","",INDEX(Matches!$AN$5:$AN$17,MATCH($B$2,Matches!$A$5:$A$17,0))),"") | D9: HLTV A margin M1 | E9: =IFERROR(IF(INDEX(Matches!$AO$5:$AO$17,MATCH($B$2,Matches!$A$5:$A$17,0))="","",INDEX(Matches!$AO$5:$AO$17,MATCH($B$2,Matches!$A$5:$A$17,0))),"") | G9: Hist share A / B | H9: =IF(IFERROR(IF(INDEX(Matches!$AI$5:$AI$17,MATCH($B$2,Matches!$A$5:$A$17,0))="","",INDEX(Matches!$AI$5:$AI$17,MATCH($B$2,Matches!$A$5:$A$17,0))),"")="","",TEXT(IFERROR(IF(INDEX(Matches!$AI$5:$AI$17,MATCH($B$2,Matches!$A$5:$A$17,0))="","",INDEX(Matches!$AI$5:$AI$17,MATCH($B$2,Matches!$A$5:$A$17,0))),""),"0%")&" / "&TEXT(IFERROR(IF(INDEX(Matches!$AJ$5:$AJ$17,MATCH($B$2,Matches!$A$5:$A$17,0))="","",INDEX(Matches!$AJ$5:$AJ$17,MATCH($B$2,Matches!$A$5:$A$17,0))),""),"0%")) -> 56% / 54%
A10: IN USE | B10: ="Map 1: "&IFERROR(IF(INDEX(Matches!$W$5:$W$17,MATCH($B$2,Matches!$A$5:$A$17,0))="","",INDEX(Matches!$W$5:$W$17,MATCH($B$2,Matches!$A$5:$A$17,0))),"")&" · Map 2: "&IFERROR(IF(INDEX(Matches!$X$5:$X$17,MATCH($B$2,Matches!$A$5:$A$17,0))="","",INDEX(Matches!$X$5:$X$17,MATCH($B$2,Matches!$A$5:$A$17,0))),"")&IF(IFERROR(IF(INDEX(Matches!$Y$5:$Y$17,MATCH($B$2,Matches!$A$5:$A$17,0))="","",INDEX(Matches!$Y$5:$Y$17,MATCH($B$2,Matches!$A$5:$A$17,0))),"")="",""," · Map 3: "&IFERROR(IF(INDEX(Matches!$Y$5:$Y$17,MATCH($B$2,Matches!$A$5:$A$17,0))="","",INDEX(Matches!$Y$5:$Y$17,MATCH($B$2,Matches!$A$5:$A$17,0))),"")) -> Map 1: Dust2 · Map 2: Cache · Map 3: Ancient
B11: ="Rounds: "&TEXT(IFERROR(IF(INDEX(Matches!$Z$5:$Z$17,MATCH($B$2,Matches!$A$5:$A$17,0))="","",INDEX(Matches!$Z$5:$Z$17,MATCH($B$2,Matches!$A$5:$A$17,0))),""),"0.0")&" / "&TEXT(IFERROR(IF(INDEX(Matches!$AA$5:$AA$17,MATCH($B$2,Matches!$A$5:$A$17,0))="","",INDEX(Matches!$AA$5:$AA$17,MATCH($B$2,Matches!$A$5:$A$17,0))),""),"0.0")&IF(IFERROR(IF(INDEX(Matches!$AB$5:$AB$17,MATCH($B$2,Matches!$A$5:$A$17,0))="","",INDEX(Matches!$AB$5:$AB$17,MATCH($B$2,Matches!$A$5:$A$17,0))),"")="",""," / "&TEXT(IFERROR(IF(INDEX(Matches!$AB$5:$AB$17,MATCH($B$2,Matches!$A$5:$A$17,0))="","",INDEX(Matches!$AB$5:$AB$17,MATCH($B$2,Matches!$A$5:$A$17,0))),""),"0.0"))&" · P(map 3) "&TEXT(IFERROR(IF(INDEX(Matches!$AC$5:$AC$17,MATCH($B$2,Matches!$A$5:$A$17,0))="","",INDEX(Matches!$AC$5:$AC$17,MATCH($B$2,Matches!$A$5:$A$17,0))),""),"0%") -> Rounds: 21.5 / 21.5 / 21.5 · P(map 3) 0%
B12: ="Change maps or rounds on the Matches tab, row "&(MATCH($B$2,Matches!$A$5:$A$17,0)+4)&" (shaded cells)." -> Change maps or rounds on the Matches tab, row 5 (shaded cells).
A14: Team | B14: Player | C14: KPR M1 | D14: KPR M2 | E14: Kills M1 | F14: Kills M2 | G14: Kills 1-2 | H14: Diff mult | I14: Adj K 1-2 | J14: PP line | K14: P(over) | L14: Adj P(over) | M14: TP book | N14: PF L10 | O14: HS% 1-2 | P14: HS 1-2 | Q14: PP HS line | R14: P(over) HS | S14: Sample | T14: Flags | V14: row
A15: =IF($V15="","",INDEX(Calc!$D$2:$D$105,$V15)) -> RA | B15: =IF($V15="","",INDEX(Calc!$E$2:$E$105,$V15)) -> ChildKing | C15: =IF($V15="","",INDEX(Calc!$T$2:$T$105,$V15)) -> 0.81444444 | D15: =IF($V15="","",INDEX(Calc!$AA$2:$AA$105,$V15)) -> 0.8175 | E15: =IF($V15="","",INDEX(Calc!$V$2:$V$105,$V15)) -> 17.510556 | F15: =IF($V15="","",INDEX(Calc!$AC$2:$AC$105,$V15)) -> 17.57625 | G15: =IF($V15="","",INDEX(Calc!$AL$2:$AL$105,$V15)) -> 35.086806 | H15: =IF($V15="","",INDEX(Calc!$BK$2:$BK$105,$V15)) -> 1 | I15: =IF($V15="","",INDEX(Calc!$BD$2:$BD$105,$V15)) -> 35.086806 | J15: =IF($V15="","",IFERROR(INDEX(Projections!$F$2:$F$195,MATCH(INDEX(Calc!$A$2:$A$105,$V15)&"|K12",Projections!$Y$2:$Y$195,0)),"")) -> 32.5 | K15: =IF($V15="","",IFERROR(INDEX(Projections!$I$2:$I$195,MATCH(INDEX(Calc!$A$2:$A$105,$V15)&"|K12",Projections!$Y$2:$Y$195,0)),"")) -> 0.64396828 | L15: =IF($V15="","",IFERROR(INDEX(Projections!$AB$2:$AB$195,MATCH(INDEX(Calc!$A$2:$A$105,$V15)&"|K12",Projections!$Y$2:$Y$195,0)),"")) -> 0.64396828 | M15: =IF($V15="","",IFERROR(INDEX(Projections!$M$2:$M$195,MATCH(INDEX(Calc!$A$2:$A$105,$V15)&"|K12",Projections!$Y$2:$Y$195,0)),"")) -> 0 | N15: =IF($V15="","",IFERROR(INDEX(Projections!$P$2:$P$195,MATCH(INDEX(Calc!$A$2:$A$105,$V15)&"|K12",Projections!$Y$2:$Y$195,0)),"")) -> 0.5 | O15: =IF($V15="","",INDEX(Calc!$AP$2:$AP$105,$V15)) -> 0.63466455 | P15: =IF($V15="","",INDEX(Calc!$AN$2:$AN$105,$V15)) -> 22.268352 | Q15: =IF($V15="","",IFERROR(INDEX(Projections!$F$2:$F$195,MATCH(INDEX(Calc!$A$2:$A$105,$V15)&"|H12",Projections!$Y$2:$Y$195,0)),"")) -> 20.5 | R15: =IF($V15="","",IFERROR(INDEX(Projections!$I$2:$I$195,MATCH(INDEX(Calc!$A$2:$A$105,$V15)&"|H12",Projections!$Y$2:$Y$195,0)),"")) -> 0.63105784 | S15: =IF($V15="","",INDEX(Calc!$N$2:$N$105,$V15)) -> 39 | T15: =IF($V15="","",INDEX(Calc!$AQ$2:$AQ$105,$V15)) | V15: =IFERROR(MATCH(1,Calc!$AR$2:$AR$105,0),"") -> 2
A16: =IF($V16="","",INDEX(Calc!$D$2:$D$105,$V16)) -> RA | B16: =IF($V16="","",INDEX(Calc!$E$2:$E$105,$V16)) -> Kaze | C16: =IF($V16="","",INDEX(Calc!$T$2:$T$105,$V16)) -> 0.76421053 | D16: =IF($V16="","",INDEX(Calc!$AA$2:$AA$105,$V16)) -> 0.7 | E16: =IF($V16="","",INDEX(Calc!$V$2:$V$105,$V16)) -> 16.430526 | F16: =IF($V16="","",INDEX(Calc!$AC$2:$AC$105,$V16)) -> 15.05 | G16: =IF($V16="","",INDEX(Calc!$AL$2:$AL$105,$V16)) -> 31.480526 | H16: =IF($V16="","",INDEX(Calc!$BK$2:$BK$105,$V16)) -> 1 | I16: =IF($V16="","",INDEX(Calc!$BD$2:$BD$105,$V16)) -> 31.480526 | J16: =IF($V16="","",IFERROR(INDEX(Projections!$F$2:$F$195,MATCH(INDEX(Calc!$A$2:$A$105,$V16)&"|K12",Projections!$Y$2:$Y$195,0)),"")) -> 30.5 | K16: =IF($V16="","",IFERROR(INDEX(Projections!$I$2:$I$195,MATCH(INDEX(Calc!$A$2:$A$105,$V16)&"|K12",Projections!$Y$2:$Y$195,0)),"")) -> 0.5587094 | L16: =IF($V16="","",IFERROR(INDEX(Projections!$AB$2:$AB$195,MATCH(INDEX(Calc!$A$2:$A$105,$V16)&"|K12",Projections!$Y$2:$Y$195,0)),"")) -> 0.5587094 | M16: =IF($V16="","",IFERROR(INDEX(Projections!$M$2:$M$195,MATCH(INDEX(Calc!$A$2:$A$105,$V16)&"|K12",Projections!$Y$2:$Y$195,0)),"")) -> 0 | N16: =IF($V16="","",IFERROR(INDEX(Projections!$P$2:$P$195,MATCH(INDEX(Calc!$A$2:$A$105,$V16)&"|K12",Projections!$Y$2:$Y$195,0)),"")) -> 0.5 | O16: =IF($V16="","",INDEX(Calc!$AP$2:$AP$105,$V16)) -> 0.42617388 | P16: =IF($V16="","",INDEX(Calc!$AN$2:$AN$105,$V16)) -> 13.416178 | Q16: =IF($V16="","",IFERROR(INDEX(Projections!$F$2:$F$195,MATCH(INDEX(Calc!$A$2:$A$105,$V16)&"|H12",Projections!$Y$2:$Y$195,0)),"")) -> 10.5 | R16: =IF($V16="","",IFERROR(INDEX(Projections!$I$2:$I$195,MATCH(INDEX(Calc!$A$2:$A$105,$V16)&"|H12",Projections!$Y$2:$Y$195,0)),"")) -> 0.76910462 | S16: =IF($V16="","",INDEX(Calc!$N$2:$N$105,$V16)) -> 37 | T16: =IF($V16="","",INDEX(Calc!$AQ$2:$AQ$105,$V16)) | V16: =IFERROR(MATCH(2,Calc!$AR$2:$AR$105,0),"") -> 3
A17: =IF($V17="","",INDEX(Calc!$D$2:$D$105,$V17)) -> RA | B17: =IF($V17="","",INDEX(Calc!$E$2:$E$105,$V17)) -> L1haNg | C17: =IF($V17="","",INDEX(Calc!$T$2:$T$105,$V17)) -> 0.71 | D17: =IF($V17="","",INDEX(Calc!$AA$2:$AA$105,$V17)) -> 0.73333333 | E17: =IF($V17="","",INDEX(Calc!$V$2:$V$105,$V17)) -> 15.265 | F17: =IF($V17="","",INDEX(Calc!$AC$2:$AC$105,$V17)) -> 15.766667 | G17: =IF($V17="","",INDEX(Calc!$AL$2:$AL$105,$V17)) -> 31.031667 | H17: =IF($V17="","",INDEX(Calc!$BK$2:$BK$105,$V17)) -> 1 | I17: =IF($V17="","",INDEX(Calc!$BD$2:$BD$105,$V17)) -> 31.031667 | J17: =IF($V17="","",IFERROR(INDEX(Projections!$F$2:$F$195,MATCH(INDEX(Calc!$A$2:$A$105,$V17)&"|K12",Projections!$Y$2:$Y$195,0)),"")) -> 31.5 | K17: =IF($V17="","",IFERROR(INDEX(Projections!$I$2:$I$195,MATCH(INDEX(Calc!$A$2:$A$105,$V17)&"|K12",Projections!$Y$2:$Y$195,0)),"")) -> 0.47167739 | L17: =IF($V17="","",IFERROR(INDEX(Projections!$AB$2:$AB$195,MATCH(INDEX(Calc!$A$2:$A$105,$V17)&"|K12",Projections!$Y$2:$Y$195,0)),"")) -> 0.47167739 | M17: =IF($V17="","",IFERROR(INDEX(Projections!$M$2:$M$195,MATCH(INDEX(Calc!$A$2:$A$105,$V17)&"|K12",Projections!$Y$2:$Y$195,0)),"")) -> 0 | N17: =IF($V17="","",IFERROR(INDEX(Projections!$P$2:$P$195,MATCH(INDEX(Calc!$A$2:$A$105,$V17)&"|K12",Projections!$Y$2:$Y$195,0)),"")) -> 0.4 | O17: =IF($V17="","",INDEX(Calc!$AP$2:$AP$105,$V17)) -> 0.59125712 | P17: =IF($V17="","",INDEX(Calc!$AN$2:$AN$105,$V17)) -> 18.347694 | Q17: =IF($V17="","",IFERROR(INDEX(Projections!$F$2:$F$195,MATCH(INDEX(Calc!$A$2:$A$105,$V17)&"|H12",Projections!$Y$2:$Y$195,0)),"")) -> 17.5 | R17: =IF($V17="","",IFERROR(INDEX(Projections!$I$2:$I$195,MATCH(INDEX(Calc!$A$2:$A$105,$V17)&"|H12",Projections!$Y$2:$Y$195,0)),"")) -> 0.57062737 | S17: =IF($V17="","",INDEX(Calc!$N$2:$N$105,$V17)) -> 39 | T17: =IF($V17="","",INDEX(Calc!$AQ$2:$AQ$105,$V17)) | V17: =IFERROR(MATCH(3,Calc!$AR$2:$AR$105,0),"") -> 4
A18: =IF($V18="","",INDEX(Calc!$D$2:$D$105,$V18)) -> RA | B18: =IF($V18="","",INDEX(Calc!$E$2:$E$105,$V18)) -> 3gl | C18: =IF($V18="","",INDEX(Calc!$T$2:$T$105,$V18)) -> 0.59222222 | D18: =IF($V18="","",INDEX(Calc!$AA$2:$AA$105,$V18)) -> 0.685 | E18: =IF($V18="","",INDEX(Calc!$V$2:$V$105,$V18)) -> 12.732778 | F18: =IF($V18="","",INDEX(Calc!$AC$2:$AC$105,$V18)) -> 14.7275 | G18: =IF($V18="","",INDEX(Calc!$AL$2:$AL$105,$V18)) -> 27.460278 | H18: =IF($V18="","",INDEX(Calc!$BK$2:$BK$105,$V18)) -> 1 | I18: =IF($V18="","",INDEX(Calc!$BD$2:$BD$105,$V18)) -> 27.460278 | J18: =IF($V18="","",IFERROR(INDEX(Projections!$F$2:$F$195,MATCH(INDEX(Calc!$A$2:$A$105,$V18)&"|K12",Projections!$Y$2:$Y$195,0)),"")) -> 27 | K18: =IF($V18="","",IFERROR(INDEX(Projections!$I$2:$I$195,MATCH(INDEX(Calc!$A$2:$A$105,$V18)&"|K12",Projections!$Y$2:$Y$195,0)),"")) -> 0.49744422 | L18: =IF($V18="","",IFERROR(INDEX(Projections!$AB$2:$AB$195,MATCH(INDEX(Calc!$A$2:$A$105,$V18)&"|K12",Projections!$Y$2:$Y$195,0)),"")) -> 0.49744422 | M18: =IF($V18="","",IFERROR(INDEX(Projections!$M$2:$M$195,MATCH(INDEX(Calc!$A$2:$A$105,$V18)&"|K12",Projections!$Y$2:$Y$195,0)),"")) -> 0 | N18: =IF($V18="","",IFERROR(INDEX(Projections!$P$2:$P$195,MATCH(INDEX(Calc!$A$2:$A$105,$V18)&"|K12",Projections!$Y$2:$Y$195,0)),"")) -> 0.5 | O18: =IF($V18="","",INDEX(Calc!$AP$2:$AP$105,$V18)) -> 0.44639051 | P18: =IF($V18="","",INDEX(Calc!$AN$2:$AN$105,$V18)) -> 12.258007 | Q18: =IF($V18="","",IFERROR(INDEX(Projections!$F$2:$F$195,MATCH(INDEX(Calc!$A$2:$A$105,$V18)&"|H12",Projections!$Y$2:$Y$195,0)),"")) | R18: =IF($V18="","",IFERROR(INDEX(Projections!$I$2:$I$195,MATCH(INDEX(Calc!$A$2:$A$105,$V18)&"|H12",Projections!$Y$2:$Y$195,0)),"")) | S18: =IF($V18="","",INDEX(Calc!$N$2:$N$105,$V18)) -> 39 | T18: =IF($V18="","",INDEX(Calc!$AQ$2:$AQ$105,$V18)) | V18: =IFERROR(MATCH(4,Calc!$AR$2:$AR$105,0),"") -> 1
A19: =IF($V19="","",INDEX(Calc!$D$2:$D$105,$V19)) -> RA | B19: =IF($V19="","",INDEX(Calc!$E$2:$E$105,$V19)) -> Summer | C19: =IF($V19="","",INDEX(Calc!$T$2:$T$105,$V19)) -> 0.61166667 | D19: =IF($V19="","",INDEX(Calc!$AA$2:$AA$105,$V19)) -> 0.63083333 | E19: =IF($V19="","",INDEX(Calc!$V$2:$V$105,$V19)) -> 13.150833 | F19: =IF($V19="","",INDEX(Calc!$AC$2:$AC$105,$V19)) -> 13.562917 | G19: =IF($V19="","",INDEX(Calc!$AL$2:$AL$105,$V19)) -> 26.71375 | H19: =IF($V19="","",INDEX(Calc!$BK$2:$BK$105,$V19)) -> 1 | I19: =IF($V19="","",INDEX(Calc!$BD$2:$BD$105,$V19)) -> 26.71375 | J19: =IF($V19="","",IFERROR(INDEX(Projections!$F$2:$F$195,MATCH(INDEX(Calc!$A$2:$A$105,$V19)&"|K12",Projections!$Y$2:$Y$195,0)),"")) -> 27 | K19: =IF($V19="","",IFERROR(INDEX(Projections!$I$2:$I$195,MATCH(INDEX(Calc!$A$2:$A$105,$V19)&"|K12",Projections!$Y$2:$Y$195,0)),"")) -> 0.44885017 | L19: =IF($V19="","",IFERROR(INDEX(Projections!$AB$2:$AB$195,MATCH(INDEX(Calc!$A$2:$A$105,$V19)&"|K12",Projections!$Y$2:$Y$195,0)),"")) -> 0.44885017 | M19: =IF($V19="","",IFERROR(INDEX(Projections!$M$2:$M$195,MATCH(INDEX(Calc!$A$2:$A$105,$V19)&"|K12",Projections!$Y$2:$Y$195,0)),"")) -> 0 | N19: =IF($V19="","",IFERROR(INDEX(Projections!$P$2:$P$195,MATCH(INDEX(Calc!$A$2:$A$105,$V19)&"|K12",Projections!$Y$2:$Y$195,0)),"")) -> 0.4 | O19: =IF($V19="","",INDEX(Calc!$AP$2:$AP$105,$V19)) -> 0.62653018 | P19: =IF($V19="","",INDEX(Calc!$AN$2:$AN$105,$V19)) -> 16.736971 | Q19: =IF($V19="","",IFERROR(INDEX(Projections!$F$2:$F$195,MATCH(INDEX(Calc!$A$2:$A$105,$V19)&"|H12",Projections!$Y$2:$Y$195,0)),"")) -> 15.5 | R19: =IF($V19="","",IFERROR(INDEX(Projections!$I$2:$I$195,MATCH(INDEX(Calc!$A$2:$A$105,$V19)&"|H12",Projections!$Y$2:$Y$195,0)),"")) -> 0.60656247 | S19: =IF($V19="","",INDEX(Calc!$N$2:$N$105,$V19)) -> 39 | T19: =IF($V19="","",INDEX(Calc!$AQ$2:$AQ$105,$V19)) | V19: =IFERROR(MATCH(5,Calc!$AR$2:$AR$105,0),"") -> 5
A20: =IF($V20="","",INDEX(Calc!$D$2:$D$105,$V20)) | B20: =IF($V20="","",INDEX(Calc!$E$2:$E$105,$V20)) | C20: =IF($V20="","",INDEX(Calc!$T$2:$T$105,$V20)) | D20: =IF($V20="","",INDEX(Calc!$AA$2:$AA$105,$V20)) | E20: =IF($V20="","",INDEX(Calc!$V$2:$V$105,$V20)) | F20: =IF($V20="","",INDEX(Calc!$AC$2:$AC$105,$V20)) | G20: =IF($V20="","",INDEX(Calc!$AL$2:$AL$105,$V20)) | H20: =IF($V20="","",INDEX(Calc!$BK$2:$BK$105,$V20)) | I20: =IF($V20="","",INDEX(Calc!$BD$2:$BD$105,$V20)) | J20: =IF($V20="","",IFERROR(INDEX(Projections!$F$2:$F$195,MATCH(INDEX(Calc!$A$2:$A$105,$V20)&"|K12",Projections!$Y$2:$Y$195,0)),"")) | K20: =IF($V20="","",IFERROR(INDEX(Projections!$I$2:$I$195,MATCH(INDEX(Calc!$A$2:$A$105,$V20)&"|K12",Projections!$Y$2:$Y$195,0)),"")) | L20: =IF($V20="","",IFERROR(INDEX(Projections!$AB$2:$AB$195,MATCH(INDEX(Calc!$A$2:$A$105,$V20)&"|K12",Projections!$Y$2:$Y$195,0)),"")) | M20: =IF($V20="","",IFERROR(INDEX(Projections!$M$2:$M$195,MATCH(INDEX(Calc!$A$2:$A$105,$V20)&"|K12",Projections!$Y$2:$Y$195,0)),"")) | N20: =IF($V20="","",IFERROR(INDEX(Projections!$P$2:$P$195,MATCH(INDEX(Calc!$A$2:$A$105,$V20)&"|K12",Projections!$Y$2:$Y$195,0)),"")) | O20: =IF($V20="","",INDEX(Calc!$AP$2:$AP$105,$V20)) | P20: =IF($V20="","",INDEX(Calc!$AN$2:$AN$105,$V20)) | Q20: =IF($V20="","",IFERROR(INDEX(Projections!$F$2:$F$195,MATCH(INDEX(Calc!$A$2:$A$105,$V20)&"|H12",Projections!$Y$2:$Y$195,0)),"")) | R20: =IF($V20="","",IFERROR(INDEX(Projections!$I$2:$I$195,MATCH(INDEX(Calc!$A$2:$A$105,$V20)&"|H12",Projections!$Y$2:$Y$195,0)),"")) | S20: =IF($V20="","",INDEX(Calc!$N$2:$N$105,$V20)) | T20: =IF($V20="","",INDEX(Calc!$AQ$2:$AQ$105,$V20)) | V20: =IFERROR(MATCH(6,Calc!$AR$2:$AR$105,0),"")
A21: =IF($V21="","",INDEX(Calc!$D$2:$D$105,$V21)) | B21: =IF($V21="","",INDEX(Calc!$E$2:$E$105,$V21)) | C21: =IF($V21="","",INDEX(Calc!$T$2:$T$105,$V21)) | D21: =IF($V21="","",INDEX(Calc!$AA$2:$AA$105,$V21)) | E21: =IF($V21="","",INDEX(Calc!$V$2:$V$105,$V21)) | F21: =IF($V21="","",INDEX(Calc!$AC$2:$AC$105,$V21)) | G21: =IF($V21="","",INDEX(Calc!$AL$2:$AL$105,$V21)) | H21: =IF($V21="","",INDEX(Calc!$BK$2:$BK$105,$V21)) | I21: =IF($V21="","",INDEX(Calc!$BD$2:$BD$105,$V21)) | J21: =IF($V21="","",IFERROR(INDEX(Projections!$F$2:$F$195,MATCH(INDEX(Calc!$A$2:$A$105,$V21)&"|K12",Projections!$Y$2:$Y$195,0)),"")) | K21: =IF($V21="","",IFERROR(INDEX(Projections!$I$2:$I$195,MATCH(INDEX(Calc!$A$2:$A$105,$V21)&"|K12",Projections!$Y$2:$Y$195,0)),"")) | L21: =IF($V21="","",IFERROR(INDEX(Projections!$AB$2:$AB$195,MATCH(INDEX(Calc!$A$2:$A$105,$V21)&"|K12",Projections!$Y$2:$Y$195,0)),"")) | M21: =IF($V21="","",IFERROR(INDEX(Projections!$M$2:$M$195,MATCH(INDEX(Calc!$A$2:$A$105,$V21)&"|K12",Projections!$Y$2:$Y$195,0)),"")) | N21: =IF($V21="","",IFERROR(INDEX(Projections!$P$2:$P$195,MATCH(INDEX(Calc!$A$2:$A$105,$V21)&"|K12",Projections!$Y$2:$Y$195,0)),"")) | O21: =IF($V21="","",INDEX(Calc!$AP$2:$AP$105,$V21)) | P21: =IF($V21="","",INDEX(Calc!$AN$2:$AN$105,$V21)) | Q21: =IF($V21="","",IFERROR(INDEX(Projections!$F$2:$F$195,MATCH(INDEX(Calc!$A$2:$A$105,$V21)&"|H12",Projections!$Y$2:$Y$195,0)),"")) | R21: =IF($V21="","",IFERROR(INDEX(Projections!$I$2:$I$195,MATCH(INDEX(Calc!$A$2:$A$105,$V21)&"|H12",Projections!$Y$2:$Y$195,0)),"")) | S21: =IF($V21="","",INDEX(Calc!$N$2:$N$105,$V21)) | T21: =IF($V21="","",INDEX(Calc!$AQ$2:$AQ$105,$V21)) | V21: =IFERROR(MATCH(7,Calc!$AR$2:$AR$105,0),"")
A22: =IF($V22="","",INDEX(Calc!$D$2:$D$105,$V22)) | B22: =IF($V22="","",INDEX(Calc!$E$2:$E$105,$V22)) | C22: =IF($V22="","",INDEX(Calc!$T$2:$T$105,$V22)) | D22: =IF($V22="","",INDEX(Calc!$AA$2:$AA$105,$V22)) | E22: =IF($V22="","",INDEX(Calc!$V$2:$V$105,$V22)) | F22: =IF($V22="","",INDEX(Calc!$AC$2:$AC$105,$V22)) | G22: =IF($V22="","",INDEX(Calc!$AL$2:$AL$105,$V22)) | H22: =IF($V22="","",INDEX(Calc!$BK$2:$BK$105,$V22)) | I22: =IF($V22="","",INDEX(Calc!$BD$2:$BD$105,$V22)) | J22: =IF($V22="","",IFERROR(INDEX(Projections!$F$2:$F$195,MATCH(INDEX(Calc!$A$2:$A$105,$V22)&"|K12",Projections!$Y$2:$Y$195,0)),"")) | K22: =IF($V22="","",IFERROR(INDEX(Projections!$I$2:$I$195,MATCH(INDEX(Calc!$A$2:$A$105,$V22)&"|K12",Projections!$Y$2:$Y$195,0)),"")) | L22: =IF($V22="","",IFERROR(INDEX(Projections!$AB$2:$AB$195,MATCH(INDEX(Calc!$A$2:$A$105,$V22)&"|K12",Projections!$Y$2:$Y$195,0)),"")) | M22: =IF($V22="","",IFERROR(INDEX(Projections!$M$2:$M$195,MATCH(INDEX(Calc!$A$2:$A$105,$V22)&"|K12",Projections!$Y$2:$Y$195,0)),"")) | N22: =IF($V22="","",IFERROR(INDEX(Projections!$P$2:$P$195,MATCH(INDEX(Calc!$A$2:$A$105,$V22)&"|K12",Projections!$Y$2:$Y$195,0)),"")) | O22: =IF($V22="","",INDEX(Calc!$AP$2:$AP$105,$V22)) | P22: =IF($V22="","",INDEX(Calc!$AN$2:$AN$105,$V22)) | Q22: =IF($V22="","",IFERROR(INDEX(Projections!$F$2:$F$195,MATCH(INDEX(Calc!$A$2:$A$105,$V22)&"|H12",Projections!$Y$2:$Y$195,0)),"")) | R22: =IF($V22="","",IFERROR(INDEX(Projections!$I$2:$I$195,MATCH(INDEX(Calc!$A$2:$A$105,$V22)&"|H12",Projections!$Y$2:$Y$195,0)),"")) | S22: =IF($V22="","",INDEX(Calc!$N$2:$N$105,$V22)) | T22: =IF($V22="","",INDEX(Calc!$AQ$2:$AQ$105,$V22)) | V22: =IFERROR(MATCH(8,Calc!$AR$2:$AR$105,0),"")
A23: =IF($V23="","",INDEX(Calc!$D$2:$D$105,$V23)) | B23: =IF($V23="","",INDEX(Calc!$E$2:$E$105,$V23)) | C23: =IF($V23="","",INDEX(Calc!$T$2:$T$105,$V23)) | D23: =IF($V23="","",INDEX(Calc!$AA$2:$AA$105,$V23)) | E23: =IF($V23="","",INDEX(Calc!$V$2:$V$105,$V23)) | F23: =IF($V23="","",INDEX(Calc!$AC$2:$AC$105,$V23)) | G23: =IF($V23="","",INDEX(Calc!$AL$2:$AL$105,$V23)) | H23: =IF($V23="","",INDEX(Calc!$BK$2:$BK$105,$V23)) | I23: =IF($V23="","",INDEX(Calc!$BD$2:$BD$105,$V23)) | J23: =IF($V23="","",IFERROR(INDEX(Projections!$F$2:$F$195,MATCH(INDEX(Calc!$A$2:$A$105,$V23)&"|K12",Projections!$Y$2:$Y$195,0)),"")) | K23: =IF($V23="","",IFERROR(INDEX(Projections!$I$2:$I$195,MATCH(INDEX(Calc!$A$2:$A$105,$V23)&"|K12",Projections!$Y$2:$Y$195,0)),"")) | L23: =IF($V23="","",IFERROR(INDEX(Projections!$AB$2:$AB$195,MATCH(INDEX(Calc!$A$2:$A$105,$V23)&"|K12",Projections!$Y$2:$Y$195,0)),"")) | M23: =IF($V23="","",IFERROR(INDEX(Projections!$M$2:$M$195,MATCH(INDEX(Calc!$A$2:$A$105,$V23)&"|K12",Projections!$Y$2:$Y$195,0)),"")) | N23: =IF($V23="","",IFERROR(INDEX(Projections!$P$2:$P$195,MATCH(INDEX(Calc!$A$2:$A$105,$V23)&"|K12",Projections!$Y$2:$Y$195,0)),"")) | O23: =IF($V23="","",INDEX(Calc!$AP$2:$AP$105,$V23)) | P23: =IF($V23="","",INDEX(Calc!$AN$2:$AN$105,$V23)) | Q23: =IF($V23="","",IFERROR(INDEX(Projections!$F$2:$F$195,MATCH(INDEX(Calc!$A$2:$A$105,$V23)&"|H12",Projections!$Y$2:$Y$195,0)),"")) | R23: =IF($V23="","",IFERROR(INDEX(Projections!$I$2:$I$195,MATCH(INDEX(Calc!$A$2:$A$105,$V23)&"|H12",Projections!$Y$2:$Y$195,0)),"")) | S23: =IF($V23="","",INDEX(Calc!$N$2:$N$105,$V23)) | T23: =IF($V23="","",INDEX(Calc!$AQ$2:$AQ$105,$V23)) | V23: =IFERROR(MATCH(9,Calc!$AR$2:$AR$105,0),"")
A24: =IF($V24="","",INDEX(Calc!$D$2:$D$105,$V24)) | B24: =IF($V24="","",INDEX(Calc!$E$2:$E$105,$V24)) | C24: =IF($V24="","",INDEX(Calc!$T$2:$T$105,$V24)) | D24: =IF($V24="","",INDEX(Calc!$AA$2:$AA$105,$V24)) | E24: =IF($V24="","",INDEX(Calc!$V$2:$V$105,$V24)) | F24: =IF($V24="","",INDEX(Calc!$AC$2:$AC$105,$V24)) | G24: =IF($V24="","",INDEX(Calc!$AL$2:$AL$105,$V24)) | H24: =IF($V24="","",INDEX(Calc!$BK$2:$BK$105,$V24)) | I24: =IF($V24="","",INDEX(Calc!$BD$2:$BD$105,$V24)) | J24: =IF($V24="","",IFERROR(INDEX(Projections!$F$2:$F$195,MATCH(INDEX(Calc!$A$2:$A$105,$V24)&"|K12",Projections!$Y$2:$Y$195,0)),"")) | K24: =IF($V24="","",IFERROR(INDEX(Projections!$I$2:$I$195,MATCH(INDEX(Calc!$A$2:$A$105,$V24)&"|K12",Projections!$Y$2:$Y$195,0)),"")) | L24: =IF($V24="","",IFERROR(INDEX(Projections!$AB$2:$AB$195,MATCH(INDEX(Calc!$A$2:$A$105,$V24)&"|K12",Projections!$Y$2:$Y$195,0)),"")) | M24: =IF($V24="","",IFERROR(INDEX(Projections!$M$2:$M$195,MATCH(INDEX(Calc!$A$2:$A$105,$V24)&"|K12",Projections!$Y$2:$Y$195,0)),"")) | N24: =IF($V24="","",IFERROR(INDEX(Projections!$P$2:$P$195,MATCH(INDEX(Calc!$A$2:$A$105,$V24)&"|K12",Projections!$Y$2:$Y$195,0)),"")) | O24: =IF($V24="","",INDEX(Calc!$AP$2:$AP$105,$V24)) | P24: =IF($V24="","",INDEX(Calc!$AN$2:$AN$105,$V24)) | Q24: =IF($V24="","",IFERROR(INDEX(Projections!$F$2:$F$195,MATCH(INDEX(Calc!$A$2:$A$105,$V24)&"|H12",Projections!$Y$2:$Y$195,0)),"")) | R24: =IF($V24="","",IFERROR(INDEX(Projections!$I$2:$I$195,MATCH(INDEX(Calc!$A$2:$A$105,$V24)&"|H12",Projections!$Y$2:$Y$195,0)),"")) | S24: =IF($V24="","",INDEX(Calc!$N$2:$N$105,$V24)) | T24: =IF($V24="","",INDEX(Calc!$AQ$2:$AQ$105,$V24)) | V24: =IFERROR(MATCH(10,Calc!$AR$2:$AR$105,0),"")
A25: =IF($V25="","",INDEX(Calc!$D$2:$D$105,$V25)) | B25: =IF($V25="","",INDEX(Calc!$E$2:$E$105,$V25)) | C25: =IF($V25="","",INDEX(Calc!$T$2:$T$105,$V25)) | D25: =IF($V25="","",INDEX(Calc!$AA$2:$AA$105,$V25)) | E25: =IF($V25="","",INDEX(Calc!$V$2:$V$105,$V25)) | F25: =IF($V25="","",INDEX(Calc!$AC$2:$AC$105,$V25)) | G25: =IF($V25="","",INDEX(Calc!$AL$2:$AL$105,$V25)) | H25: =IF($V25="","",INDEX(Calc!$BK$2:$BK$105,$V25)) | I25: =IF($V25="","",INDEX(Calc!$BD$2:$BD$105,$V25)) | J25: =IF($V25="","",IFERROR(INDEX(Projections!$F$2:$F$195,MATCH(INDEX(Calc!$A$2:$A$105,$V25)&"|K12",Projections!$Y$2:$Y$195,0)),"")) | K25: =IF($V25="","",IFERROR(INDEX(Projections!$I$2:$I$195,MATCH(INDEX(Calc!$A$2:$A$105,$V25)&"|K12",Projections!$Y$2:$Y$195,0)),"")) | L25: =IF($V25="","",IFERROR(INDEX(Projections!$AB$2:$AB$195,MATCH(INDEX(Calc!$A$2:$A$105,$V25)&"|K12",Projections!$Y$2:$Y$195,0)),"")) | M25: =IF($V25="","",IFERROR(INDEX(Projections!$M$2:$M$195,MATCH(INDEX(Calc!$A$2:$A$105,$V25)&"|K12",Projections!$Y$2:$Y$195,0)),"")) | N25: =IF($V25="","",IFERROR(INDEX(Projections!$P$2:$P$195,MATCH(INDEX(Calc!$A$2:$A$105,$V25)&"|K12",Projections!$Y$2:$Y$195,0)),"")) | O25: =IF($V25="","",INDEX(Calc!$AP$2:$AP$105,$V25)) | P25: =IF($V25="","",INDEX(Calc!$AN$2:$AN$105,$V25)) | Q25: =IF($V25="","",IFERROR(INDEX(Projections!$F$2:$F$195,MATCH(INDEX(Calc!$A$2:$A$105,$V25)&"|H12",Projections!$Y$2:$Y$195,0)),"")) | R25: =IF($V25="","",IFERROR(INDEX(Projections!$I$2:$I$195,MATCH(INDEX(Calc!$A$2:$A$105,$V25)&"|H12",Projections!$Y$2:$Y$195,0)),"")) | S25: =IF($V25="","",INDEX(Calc!$N$2:$N$105,$V25)) | T25: =IF($V25="","",INDEX(Calc!$AQ$2:$AQ$105,$V25)) | V25: =IFERROR(MATCH(11,Calc!$AR$2:$AR$105,0),"")
A26: =IF($V26="","",INDEX(Calc!$D$2:$D$105,$V26)) | B26: =IF($V26="","",INDEX(Calc!$E$2:$E$105,$V26)) | C26: =IF($V26="","",INDEX(Calc!$T$2:$T$105,$V26)) | D26: =IF($V26="","",INDEX(Calc!$AA$2:$AA$105,$V26)) | E26: =IF($V26="","",INDEX(Calc!$V$2:$V$105,$V26)) | F26: =IF($V26="","",INDEX(Calc!$AC$2:$AC$105,$V26)) | G26: =IF($V26="","",INDEX(Calc!$AL$2:$AL$105,$V26)) | H26: =IF($V26="","",INDEX(Calc!$BK$2:$BK$105,$V26)) | I26: =IF($V26="","",INDEX(Calc!$BD$2:$BD$105,$V26)) | J26: =IF($V26="","",IFERROR(INDEX(Projections!$F$2:$F$195,MATCH(INDEX(Calc!$A$2:$A$105,$V26)&"|K12",Projections!$Y$2:$Y$195,0)),"")) | K26: =IF($V26="","",IFERROR(INDEX(Projections!$I$2:$I$195,MATCH(INDEX(Calc!$A$2:$A$105,$V26)&"|K12",Projections!$Y$2:$Y$195,0)),"")) | L26: =IF($V26="","",IFERROR(INDEX(Projections!$AB$2:$AB$195,MATCH(INDEX(Calc!$A$2:$A$105,$V26)&"|K12",Projections!$Y$2:$Y$195,0)),"")) | M26: =IF($V26="","",IFERROR(INDEX(Projections!$M$2:$M$195,MATCH(INDEX(Calc!$A$2:$A$105,$V26)&"|K12",Projections!$Y$2:$Y$195,0)),"")) | N26: =IF($V26="","",IFERROR(INDEX(Projections!$P$2:$P$195,MATCH(INDEX(Calc!$A$2:$A$105,$V26)&"|K12",Projections!$Y$2:$Y$195,0)),"")) | O26: =IF($V26="","",INDEX(Calc!$AP$2:$AP$105,$V26)) | P26: =IF($V26="","",INDEX(Calc!$AN$2:$AN$105,$V26)) | Q26: =IF($V26="","",IFERROR(INDEX(Projections!$F$2:$F$195,MATCH(INDEX(Calc!$A$2:$A$105,$V26)&"|H12",Projections!$Y$2:$Y$195,0)),"")) | R26: =IF($V26="","",IFERROR(INDEX(Projections!$I$2:$I$195,MATCH(INDEX(Calc!$A$2:$A$105,$V26)&"|H12",Projections!$Y$2:$Y$195,0)),"")) | S26: =IF($V26="","",INDEX(Calc!$N$2:$N$105,$V26)) | T26: =IF($V26="","",INDEX(Calc!$AQ$2:$AQ$105,$V26)) | V26: =IFERROR(MATCH(12,Calc!$AR$2:$AR$105,0),"")
A28: Kills = Σ over the chosen maps of (per-map KPR, shrunk toward the player's overall KPR by SHRINK_MAPS) × rounds. HS = kills × per-map HS%, shrunk the same way. P(over) is a normal approximation with variance = KILLS_DISPERSION × projection.
A29: Adj = the round-differential layer (CS2): each map's kills × (a·s + b·(1−s)) ÷ (a·s_hist + b·(1−s_hist)), s = the team's expected round share on that map from HLTV conditional margins and Thunderpick map odds, s_hist = its round share over HLTV's 3-month sample. PAPER: neither column has a forward record.

Sheet Matches
A1: Matches — pick the maps and rounds for every match in the shaded columns
A2: Prefilled: maps from PickFinder Map Picks (#1, #2, #3), rounds from Thunderpick "Total Rounds - Map k" (devigged 50% crossing). Overwrite any shaded cell; Calc, Projections and Board follow instantly.
A4: Match | B4: Title | C4: Start (CT) | D4: Bo | E4: Team A | F4: Team B | G4: P(A wins) | H4: P(A 2-0) | I4: P(B 2-0) | J4: P(3 maps) | K4: Map pick #1 | L4: Map pick #2 | M4: Map pick #3 | N4: Picks from | O4: TP rounds M1 | P4: TP rounds M2 | Q4: TP rounds M3 | R4: P(OT) M1 | S4: A margin M1 | T4: A rounds M1 | U4: B rounds M1 | V4: TP markets | W4: Map 1 | X4: Map 2 | Y4: Map 3 | Z4: Rounds M1 | AA4: Rounds M2 | AB4: Rounds M3 | AC4: P(map 3) used | AD4: Tag A | AE4: Tag B | AF4: P(A map 1) | AG4: P(A map 2) | AH4: P(A map 3) | AI4: A hist share | AJ4: B hist share | AK4: HLTV cA M1 | AL4: HLTV cB M1 | AM4: HLTV src M1 | AN4: HLTV rounds M1 | AO4: HLTV A margin M1 | AP4: HLTV A share M1 | AQ4: HLTV cA M2 | AR4: HLTV cB M2 | AS4: HLTV src M2 | AT4: HLTV rounds M2 | AU4: HLTV A margin M2 | AV4: HLTV A share M2 | AW4: HLTV cA M3 | AX4: HLTV cB M3 | AY4: HLTV src M3 | AZ4: HLTV rounds M3 | BA4: HLTV A margin M3 | BB4: HLTV A share M3
A5: CS2 [NO MARKET] · AE vs RA | B5: CS2 | C5: Tue 00:00 | D5: 3 | E5: AE (AE) | F5: RA (RA) | K5: Dust2 53% | L5: Cache 26% | M5: Ancient 6% | N5: PF Map Picks | V5: 0 | W5: Dust2 | X5: Cache | Y5: Ancient | Z5: =Config!$B$7 -> 21.5 | AA5: =Config!$B$7 -> 21.5 | AB5: =Config!$B$7 -> 21.5 | AC5: 0 | AD5: AE | AE5: RA | AI5: =IFERROR(INDEX(HLTV_Teams!$N$2:$N$25,MATCH($A5&"|A",HLTV_Teams!$A$2:$A$25,0)),"") -> 0.56289828 | AJ5: =IFERROR(INDEX(HLTV_Teams!$N$2:$N$25,MATCH($A5&"|B",HLTV_Teams!$A$2:$A$25,0)),"") -> 0.54083384 | AK5: =IF($W5="","",IFERROR((SUMIFS(HLTV_Long!$B$2:$B$337,HLTV_Long!$A$2:$A$337,$A5&"|A|"&$W5&"|lw")+SUMIFS(HLTV_Long!$B$2:$B$337,HLTV_Long!$A$2:$A$337,$A5&"|B|"&$W5&"|wl"))/(COUNTIFS(HLTV_Long!$A$2:$A$337,$A5&"|A|"&$W5&"|lw")+COUNTIFS(HLTV_Long!$A$2:$A$337,$A5&"|B|"&$W5&"|wl")),IFERROR((SUMIFS(HLTV_Long!$B$2:$B$337,HLTV_Long!$A$2:$A$337,$A5&"|A|"&"ALL"&"|lw")+SUMIFS(HLTV_Long!$B$2:$B$337,HLTV_Long!$A$2:$A$337,$A5&"|B|"&"ALL"&"|wl"))/(COUNTIFS(HLTV_Long!$A$2:$A$337,$A5&"|A|"&"ALL"&"|lw")+COUNTIFS(HLTV_Long!$A$2:$A$337,$A5&"|B|"&"ALL"&"|wl")),""))) -> 7.89 | AL5: =IF($W5="","",IFERROR((SUMIFS(HLTV_Long!$B$2:$B$337,HLTV_Long!$A$2:$A$337,$A5&"|B|"&$W5&"|lw")+SUMIFS(HLTV_Long!$B$2:$B$337,HLTV_Long!$A$2:$A$337,$A5&"|A|"&$W5&"|wl"))/(COUNTIFS(HLTV_Long!$A$2:$A$337,$A5&"|B|"&$W5&"|lw")+COUNTIFS(HLTV_Long!$A$2:$A$337,$A5&"|A|"&$W5&"|wl")),IFERROR((SUMIFS(HLTV_Long!$B$2:$B$337,HLTV_Long!$A$2:$A$337,$A5&"|B|"&"ALL"&"|lw")+SUMIFS(HLTV_Long!$B$2:$B$337,HLTV_Long!$A$2:$A$337,$A5&"|A|"&"ALL"&"|wl"))/(COUNTIFS(HLTV_Long!$A$2:$A$337,$A5&"|B|"&"ALL"&"|lw")+COUNTIFS(HLTV_Long!$A$2:$A$337,$A5&"|A|"&"ALL"&"|wl")),""))) -> 8.23 | AM5: =IF($W5="","",COUNTIFS(HLTV_Long!$A$2:$A$337,$A5&"|A|"&$W5&"|lw")+COUNTIFS(HLTV_Long!$A$2:$A$337,$A5&"|B|"&$W5&"|wl")+COUNTIFS(HLTV_Long!$A$2:$A$337,$A5&"|B|"&$W5&"|lw")+COUNTIFS(HLTV_Long!$A$2:$A$337,$A5&"|A|"&$W5&"|wl")) -> 4 | AN5: =IF(OR($AK5="",$AL5="",$AF5=""),"",13+$AF5*$AK5+(1-$AF5)*$AL5) | AO5: =IF($AN5="","",$AF5*(13-$AK5)-(1-$AF5)*(13-$AL5)) | AP5: =IF($AN5="","",($AF5*13+(1-$AF5)*$AL5)/$AN5) | AQ5: =IF($X5="","",IFERROR((SUMIFS(HLTV_Long!$B$2:$B$337,HLTV_Long!$A$2:$A$337,$A5&"|A|"&$X5&"|lw")+SUMIFS(HLTV_Long!$B$2:$B$337,HLTV_Long!$A$2:$A$337,$A5&"|B|"&$X5&"|wl"))/(COUNTIFS(HLTV_Long!$A$2:$A$337,$A5&"|A|"&$X5&"|lw")+COUNTIFS(HLTV_Long!$A$2:$A$337,$A5&"|B|"&$X5&"|wl")),IFERROR((SUMIFS(HLTV_Long!$B$2:$B$337,HLTV_Long!$A$2:$A$337,$A5&"|A|"&"ALL"&"|lw")+SUMIFS(HLTV_Long!$B$2:$B$337,HLTV_Long!$A$2:$A$337,$A5&"|B|"&"ALL"&"|wl"))/(COUNTIFS(HLTV_Long!$A$2:$A$337,$A5&"|A|"&"ALL"&"|lw")+COUNTIFS(HLTV_Long!$A$2:$A$337,$A5&"|B|"&"ALL"&"|wl")),""))) -> 8.915 | AR5: =IF($X5="","",IFERROR((SUMIFS(HLTV_Long!$B$2:$B$337,HLTV_Long!$A$2:$A$337,$A5&"|B|"&$X5&"|lw")+SUMIFS(HLTV_Long!$B$2:$B$337,HLTV_Long!$A$2:$A$337,$A5&"|A|"&$X5&"|wl"))/(COUNTIFS(HLTV_Long!$A$2:$A$337,$A5&"|B|"&$X5&"|lw")+COUNTIFS(HLTV_Long!$A$2:$A$337,$A5&"|A|"&$X5&"|wl")),IFERROR((SUMIFS(HLTV_Long!$B$2:$B$337,HLTV_Long!$A$2:$A$337,$A5&"|B|"&"ALL"&"|lw")+SUMIFS(HLTV_Long!$B$2:$B$337,HLTV_Long!$A$2:$A$337,$A5&"|A|"&"ALL"&"|wl"))/(COUNTIFS(HLTV_Long!$A$2:$A$337,$A5&"|B|"&"ALL"&"|lw")+COUNTIFS(HLTV_Long!$A$2:$A$337,$A5&"|A|"&"ALL"&"|wl")),""))) -> 8.4 | AS5: =IF($X5="","",COUNTIFS(HLTV_Long!$A$2:$A$337,$A5&"|A|"&$X5&"|lw")+COUNTIFS(HLTV_Long!$A$2:$A$337,$A5&"|B|"&$X5&"|wl")+COUNTIFS(HLTV_Long!$A$2:$A$337,$A5&"|B|"&$X5&"|lw")+COUNTIFS(HLTV_Long!$A$2:$A$337,$A5&"|A|"&$X5&"|wl")) -> 4 | AT5: =IF(OR($AQ5="",$AR5="",$AG5=""),"",13+$AG5*$AQ5+(1-$AG5)*$AR5) | AU5: =IF($AT5="","",$AG5*(13-$AQ5)-(1-$AG5)*(13-$AR5)) | AV5: =IF($AT5="","",($AG5*13+(1-$AG5)*$AR5)/$AT5) | AW5: =IF($Y5="","",IFERROR((SUMIFS(HLTV_Long!$B$2:$B$337,HLTV_Long!$A$2:$A$337,$A5&"|A|"&$Y5&"|lw")+SUMIFS(HLTV_Long!$B$2:$B$337,HLTV_Long!$A$2:$A$337,$A5&"|B|"&$Y5&"|wl"))/(COUNTIFS(HLTV_Long!$A$2:$A$337,$A5&"|A|"&$Y5&"|lw")+COUNTIFS(HLTV_Long!$A$2:$A$337,$A5&"|B|"&$Y5&"|wl")),IFERROR((SUMIFS(HLTV_Long!$B$2:$B$337,HLTV_Long!$A$2:$A$337,$A5&"|A|"&"ALL"&"|lw")+SUMIFS(HLTV_Long!$B$2:$B$337,HLTV_Long!$A$2:$A$337,$A5&"|B|"&"ALL"&"|wl"))/(COUNTIFS(HLTV_Long!$A$2:$A$337,$A5&"|A|"&"ALL"&"|lw")+COUNTIFS(HLTV_Long!$A$2:$A$337,$A5&"|B|"&"ALL"&"|wl")),""))) -> 6.95 | AX5: =IF($Y5="","",IFERROR((SUMIFS(HLTV_Long!$B$2:$B$337,HLTV_Long!$A$2:$A$337,$A5&"|B|"&$Y5&"|lw")+SUMIFS(HLTV_Long!$B$2:$B$337,HLTV_Long!$A$2:$A$337,$A5&"|A|"&$Y5&"|wl"))/(COUNTIFS(HLTV_Long!$A$2:$A$337,$A5&"|B|"&$Y5&"|lw")+COUNTIFS(HLTV_Long!$A$2:$A$337,$A5&"|A|"&$Y5&"|wl")),IFERROR((SUMIFS(HLTV_Long!$B$2:$B$337,HLTV_Long!$A$2:$A$337,$A5&"|B|"&"ALL"&"|lw")+SUMIFS(HLTV_Long!$B$2:$B$337,HLTV_Long!$A$2:$A$337,$A5&"|A|"&"ALL"&"|wl"))/(COUNTIFS(HLTV_Long!$A$2:$A$337,$A5&"|B|"&"ALL"&"|lw")+COUNTIFS(HLTV_Long!$A$2:$A$337,$A5&"|A|"&"ALL"&"|wl")),""))) -> 7.665 | AY5: =IF($Y5="","",COUNTIFS(HLTV_Long!$A$2:$A$337,$A5&"|A|"&$Y5&"|lw")+COUNTIFS(HLTV_Long!$A$2:$A$337,$A5&"|B|"&$Y5&"|wl")+COUNTIFS(HLTV_Long!$A$2:$A$337,$A5&"|B|"&$Y5&"|lw")+COUNTIFS(HLTV_Long!$A$2:$A$337,$A5&"|A|"&$Y5&"|wl")) -> 4 | AZ5: =IF(OR($AW5="",$AX5="",$AH5=""),"",13+$AH5*$AW5+(1-$AH5)*$AX5) | BA5: =IF($AZ5="","",$AH5*(13-$AW5)-(1-$AH5)*(13-$AX5)) | BB5: =IF($AZ5="","",($AH5*13+(1-$AH5)*$AX5)/$AZ5)
A6: CS2 · PRIV vs ALL | B6: CS2 | C6: Tue 04:00 | D6: 3 | E6: Private (PRIV) | F6: Alliance (ALL) | G6: 0.38461538 | H6: 0.18095732 | I6: 0.32170191 | J6: 0.49734077 | K6: Ancient 30% | L6: Dust2 20% | M6: Inferno 18% | N6: PF Map Picks | O6: 21.5 | P6: 21.358533 | Q6: 21.423154 | R6: 0.15942029 | S6: -0.996875 | T6: 12.5 | V6: 229 | W6: Ancient | X6: Dust2 | Y6: Inferno | Z6: 21.5 | AA6: 21.36 | AB6: 21.42 | AC6: 0.4973 | AD6: PRIV | AE6: ALL | AF6: 0.4624 | AG6: 0.3846 | AH6: 0.418 | AI6: =IFERROR(INDEX(HLTV_Teams!$N$2:$N$25,MATCH($A6&"|A",HLTV_Teams!$A$2:$A$25,0)),"") -> 0.51594443 | AJ6: =IFERROR(INDEX(HLTV_Teams!$N$2:$N$25,MATCH($A6&"|B",HLTV_Teams!$A$2:$A$25,0)),"") -> 0.42855368 | AK6: =IF($W6="","",IFERROR((SUMIFS(HLTV_Long!$B$2:$B$337,HLTV_Long!$A$2:$A$337,$A6&"|A|"&$W6&"|lw")+SUMIFS(HLTV_Long!$B$2:$B$337,HLTV_Long!$A$2:$A$337,$A6&"|B|"&$W6&"|wl"))/(COUNTIFS(HLTV_Long!$A$2:$A$337,$A6&"|A|"&$W6&"|lw")+COUNTIFS(HLTV_Long!$A$2:$A$337,$A6&"|B|"&$W6&"|wl")),IFERROR((SUMIFS(HLTV_Long!$B$2:$B$337,HLTV_Long!$A$2:$A$337,$A6&"|A|"&"ALL"&"|lw")+SUMIFS(HLTV_Long!$B$2:$B$337,HLTV_Long!$A$2:$A$337,$A6&"|B|"&"ALL"&"|wl"))/(COUNTIFS(HLTV_Long!$A$2:$A$337,$A6&"|A|"&"ALL"&"|lw")+COUNTIFS(HLTV_Long!$A$2:$A$337,$A6&"|B|"&"ALL"&"|wl")),""))) -> 7.36 | AL6: =IF($W6="","",IFERROR((SUMIFS(HLTV_Long!$B$2:$B$337,HLTV_Long!$A$2:$A$337,$A6&"|B|"&$W6&"|lw")+SUMIFS(HLTV_Long!$B$2:$B$337,HLTV_Long!$A$2:$A$337,$A6&"|A|"&$W6&"|wl"))/(COUNTIFS(HLTV_Long!$A$2:$A$337,$A6&"|B|"&$W6&"|lw")+COUNTIFS(HLTV_Long!$A$2:$A$337,$A6&"|A|"&$W6&"|wl")),IFERROR((SUMIFS(HLTV_Long!$B$2:$B$337,HLTV_Long!$A$2:$A$337,$A6&"|B|"&"ALL"&"|lw")+SUMIFS(HLTV_Long!$B$2:$B$337,HLTV_Long!$A$2:$A$337,$A6&"|A|"&"ALL"&"|wl"))/(COUNTIFS(HLTV_Long!$A$2:$A$337,$A6&"|B|"&"ALL"&"|lw")+COUNTIFS(HLTV_Long!$A$2:$A$337,$A6&"|A|"&"ALL"&"|wl")),""))) -> 9.125 | AM6: =IF($W6="","",COUNTIFS(HLTV_Long!$A$2:$A$337,$A6&"|A|"&$W6&"|lw")+COUNTIFS(HLTV_Long!$A$2:$A$337,$A6&"|B|"&$W6&"|wl")+COUNTIFS(HLTV_Long!$A$2:$A$337,$A6&"|B|"&$W6&"|lw")+COUNTIFS(HLTV_Long!$A$2:$A$337,$A6&"|A|"&$W6&"|wl")) -> 4 | AN6: =IF(OR($AK6="",$AL6="",$AF6=""),"",13+$AF6*$AK6+(1-$AF6)*$AL6) -> 21.308864 | AO6: =IF($AN6="","",$AF6*(13-$AK6)-(1-$AF6)*(13-$AL6)) -> 0.524736 | AP6: =IF($AN6="","",($AF6*13+(1-$AF6)*$AL6)/$AN6) -> 0.51231262 | AQ6: =IF($X6="","",IFERROR((SUMIFS(HLTV_Long!$B$2:$B$337,HLTV_Long!$A$2:$A$337,$A6&"|A|"&$X6&"|lw")+SUMIFS(HLTV_Long!$B$2:$B$337,HLTV_Long!$A$2:$A$337,$A6&"|B|"&$X6&"|wl"))/(COUNTIFS(HLTV_Long!$A$2:$A$337,$A6&"|A|"&$X6&"|lw")+COUNTIFS(HLTV_Long!$A$2:$A$337,$A6&"|B|"&$X6&"|wl")),IFERROR((SUMIFS(HLTV_Long!$B$2:$B$337,HLTV_Long!$A$2:$A$337,$A6&"|A|"&"ALL"&"|lw")+SUMIFS(HLTV_Long!$B$2:$B$337,HLTV_Long!$A$2:$A$337,$A6&"|B|"&"ALL"&"|wl"))/(COUNTIFS(HLTV_Long!$A$2:$A$337,$A6&"|A|"&"ALL"&"|lw")+COUNTIFS(HLTV_Long!$A$2:$A$337,$A6&"|B|"&"ALL"&"|wl")),""))) -> 8.655 | AR6: =IF($X6="","",IFERROR((SUMIFS(HLTV_Long!$B$2:$B$337,HLTV_Long!$A$2:$A$337,$A6&"|B|"&$X6&"|lw")+SUMIFS(HLTV_Long!$B$2:$B$337,HLTV_Long!$A$2:$A$337,$A6&"|A|"&$X6&"|wl"))/(COUNTIFS(HLTV_Long!$A$2:$A$337,$A6&"|B|"&$X6&"|lw")+COUNTIFS(HLTV_Long!$A$2:$A$337,$A6&"|A|"&$X6&"|wl")),IFERROR((SUMIFS(HLTV_Long!$B$2:$B$337,HLTV_Long!$A$2:$A$337,$A6&"|B|"&"ALL"&"|lw")+SUMIFS(HLTV_Long!$B$2:$B$337,HLTV_Long!$A$2:$A$337,$A6&"|A|"&"ALL"&"|wl"))/(COUNTIFS(HLTV_Long!$A$2:$A$337,$A6&"|B|"&"ALL"&"|lw")+COUNTIFS(HLTV_Long!$A$2:$A$337,$A6&"|A|"&"ALL"&"|wl")),""))) -> 9.75 | AS6: =IF($X6="","",COUNTIFS(HLTV_Long!$A$2:$A$337,$A6&"|A|"&$X6&"|lw")+COUNTIFS(HLTV_Long!$A$2:$A$337,$A6&"|B|"&$X6&"|wl")+COUNTIFS(HLTV_Long!$A$2:$A$337,$A6&"|B|"&$X6&"|lw")+COUNTIFS(HLTV_Long!$A$2:$A$337,$A6&"|A|"&$X6&"|wl")) -> 3 | AT6: =IF(OR($AQ6="",$AR6="",$AG6=""),"",13+$AG6*$AQ6+(1-$AG6)*$AR6) -> 22.328863 | AU6: =IF($AT6="","",$AG6*(13-$AQ6)-(1-$AG6)*(13-$AR6)) -> -0.328963 | AV6: =IF($AT6="","",($AG6*13+(1-$AG6)*$AR6)/$AT6) -> 0.49263368 | AW6: =IF($Y6="","",IFERROR((SUMIFS(HLTV_Long!$B$2:$B$337,HLTV_Long!$A$2:$A$337,$A6&"|A|"&$Y6&"|lw")+SUMIFS(HLTV_Long!$B$2:$B$337,HLTV_Long!$A$2:$A$337,$A6&"|B|"&$Y6&"|wl"))/(COUNTIFS(HLTV_Long!$A$2:$A$337,$A6&"|A|"&$Y6&"|lw")+COUNTIFS(HLTV_Long!$A$2:$A$337,$A6&"|B|"&$Y6&"|wl")),IFERROR((SUMIFS(HLTV_Long!$B$2:$B$337,HLTV_Long!$A$2:$A$337,$A6&"|A|"&"ALL"&"|lw")+SUMIFS(HLTV_Long!$B$2:$B$337,HLTV_Long!$A$2:$A$337,$A6&"|B|"&"ALL"&"|wl"))/(COUNTIFS(HLTV_Long!$A$2:$A$337,$A6&"|A|"&"ALL"&"|lw")+COUNTIFS(HLTV_Long!$A$2:$A$337,$A6&"|B|"&"ALL"&"|wl")),""))) -> 6.83 | AX6: =IF($Y6="","",IFERROR((SUMIFS(HLTV_Long!$B$2:$B$337,HLTV_Long!$A$2:$A$337,$A6&"|B|"&$Y6&"|lw")+SUMIFS(HLTV_Long!$B$2:$B$337,HLTV_Long!$A$2:$A$337,$A6&"|A|"&$Y6&"|wl"))/(COUNTIFS(HLTV_Long!$A$2:$A$337,$A6&"|B|"&$Y6&"|lw")+COUNTIFS(HLTV_Long!$A$2:$A$337,$A6&"|A|"&$Y6&"|wl")),IFERROR((SUMIFS(HLTV_Long!$B$2:$B$337,HLTV_Long!$A$2:$A$337,$A6&"|B|"&"ALL"&"|lw")+SUMIFS(HLTV_Long!$B$2:$B$337,HLTV_Long!$A$2:$A$337,$A6&"|A|"&"ALL"&"|wl"))/(COUNTIFS(HLTV_Long!$A$2:$A$337,$A6&"|B|"&"ALL"&"|lw")+COUNTIFS(HLTV_Long!$A$2:$A$337,$A6&"|A|"&"ALL"&"|wl")),""))) -> 10.25 | AY6: =IF($Y6="","",COUNTIFS(HLTV_Long!$A$2:$A$337,$A6&"|A|"&$Y6&"|lw")+COUNTIFS(HLTV_Long!$A$2:$A$337,$A6&"|B|"&$Y6&"|wl")+COUNTIFS(HLTV_Long!$A$2:$A$337,$A6&"|B|"&$Y6&"|lw")+COUNTIFS(HLTV_Long!$A$2:$A$337,$A6&"|A|"&$Y6&"|wl")) -> 2 | AZ6: =IF(OR($AW6="",$AX6="",$AH6=""),"",13+$AH6*$AW6+(1-$AH6)*$AX6) -> 21.82044 | BA6: =IF($AZ6="","",$AH6*(13-$AW6)-(1-$AH6)*(13-$AX6)) -> 0.97856 | BB6: =IF($AZ6="","",($AH6*13+(1-$AH6)*$AX6)/$AZ6) -> 0.52242301
A7: CS2 [NO MARKET] · MZP vs ex-RUSTEC | B7: CS2 | C7: Tue 04:00 | D7: 3 | E7: MZP (MZP) | F7: ex-RUSTEC (ex-RUSTEC) | K7: Nuke 70% | L7: Inferno 8% | M7: Mirage 7% | N7: PF Map Picks | V7: 0 | W7: Nuke | X7: Inferno | Y7: Mirage | Z7: =Config!$B$7 -> 21.5 | AA7: =Config!$B$7 -> 21.5 | AB7: =Config!$B$7 -> 21.5 | AC7: 0 | AD7: MZP | AE7: ex-RUSTEC | AI7: =IFERROR(INDEX(HLTV_Teams!$N$2:$N$25,MATCH($A7&"|A",HLTV_Teams!$A$2:$A$25,0)),"") -> 0.5206652 | AJ7: =IFERROR(INDEX(HLTV_Teams!$N$2:$N$25,MATCH($A7&"|B",HLTV_Teams!$A$2:$A$25,0)),"") -> 0.53267656 | AK7: =IF($W7="","",IFERROR((SUMIFS(HLTV_Long!$B$2:$B$337,HLTV_Long!$A$2:$A$337,$A7&"|A|"&$W7&"|lw")+SUMIFS(HLTV_Long!$B$2:$B$337,HLTV_Long!$A$2:$A$337,$A7&"|B|"&$W7&"|wl"))/(COUNTIFS(HLTV_Long!$A$2:$A$337,$A7&"|A|"&$W7&"|lw")+COUNTIFS(HLTV_Long!$A$2:$A$337,$A7&"|B|"&$W7&"|wl")),IFERROR((SUMIFS(HLTV_Long!$B$2:$B$337,HLTV_Long!$A$2:$A$337,$A7&"|A|"&"ALL"&"|lw")+SUMIFS(HLTV_Long!$B$2:$B$337,HLTV_Long!$A$2:$A$337,$A7&"|B|"&"ALL"&"|wl"))/(COUNTIFS(HLTV_Long!$A$2:$A$337,$A7&"|A|"&"ALL"&"|lw")+COUNTIFS(HLTV_Long!$A$2:$A$337,$A7&"|B|"&"ALL"&"|wl")),""))) -> 9.315 | AL7: =IF($W7="","",IFERROR((SUMIFS(HLTV_Long!$B$2:$B$337,HLTV_Long!$A$2:$A$337,$A7&"|B|"&$W7&"|lw")+SUMIFS(HLTV_Long!$B$2:$B$337,HLTV_Long!$A$2:$A$337,$A7&"|A|"&$W7&"|wl"))/(COUNTIFS(HLTV_Long!$A$2:$A$337,$A7&"|B|"&$W7&"|lw")+COUNTIFS(HLTV_Long!$A$2:$A$337,$A7&"|A|"&$W7&"|wl")),IFERROR((SUMIFS(HLTV_Long!$B$2:$B$337,HLTV_Long!$A$2:$A$337,$A7&"|B|"&"ALL"&"|lw")+SUMIFS(HLTV_Long!$B$2:$B$337,HLTV_Long!$A$2:$A$337,$A7&"|A|"&"ALL"&"|wl"))/(COUNTIFS(HLTV_Long!$A$2:$A$337,$A7&"|B|"&"ALL"&"|lw")+COUNTIFS(HLTV_Long!$A$2:$A$337,$A7&"|A|"&"ALL"&"|wl")),""))) -> 9.225 | AM7: =IF($W7="","",COUNTIFS(HLTV_Long!$A$2:$A$337,$A7&"|A|"&$W7&"|lw")+COUNTIFS(HLTV_Long!$A$2:$A$337,$A7&"|B|"&$W7&"|wl")+COUNTIFS(HLTV_Long!$A$2:$A$337,$A7&"|B|"&$W7&"|lw")+COUNTIFS(HLTV_Long!$A$2:$A$337,$A7&"|A|"&$W7&"|wl")) -> 4 | AN7: =IF(OR($AK7="",$AL7="",$AF7=""),"",13+$AF7*$AK7+(1-$AF7)*$AL7) | AO7: =IF($AN7="","",$AF7*(13-$AK7)-(1-$AF7)*(13-$AL7)) | AP7: =IF($AN7="","",($AF7*13+(1-$AF7)*$AL7)/$AN7) | AQ7: =IF($X7="","",IFERROR((SUMIFS(HLTV_Long!$B$2:$B$337,HLTV_Long!$A$2:$A$337,$A7&"|A|"&$X7&"|lw")+SUMIFS(HLTV_Long!$B$2:$B$337,HLTV_Long!$A$2:$A$337,$A7&"|B|"&$X7&"|wl"))/(COUNTIFS(HLTV_Long!$A$2:$A$337,$A7&"|A|"&$X7&"|lw")+COUNTIFS(HLTV_Long!$A$2:$A$337,$A7&"|B|"&$X7&"|wl")),IFERROR((SUMIFS(HLTV_Long!$B$2:$B$337,HLTV_Long!$A$2:$A$337,$A7&"|A|"&"ALL"&"|lw")+SUMIFS(HLTV_Long!$B$2:$B$337,HLTV_Long!$A$2:$A$337,$A7&"|B|"&"ALL"&"|wl"))/(COUNTIFS(HLTV_Long!$A$2:$A$337,$A7&"|A|"&"ALL"&"|lw")+COUNTIFS(HLTV_Long!$A$2:$A$337,$A7&"|B|"&"ALL"&"|wl")),""))) -> 8.53 | AR7: =IF($X7="","",IFERROR((SUMIFS(HLTV_Long!$B$2:$B$337,HLTV_Long!$A$2:$A$337,$A7&"|B|"&$X7&"|lw")+SUMIFS(HLTV_Long!$B$2:$B$337,HLTV_Long!$A$2:$A$337,$A7&"|A|"&$X7&"|wl"))/(COUNTIFS(HLTV_Long!$A$2:$A$337,$A7&"|B|"&$X7&"|lw")+COUNTIFS(HLTV_Long!$A$2:$A$337,$A7&"|A|"&$X7&"|wl")),IFERROR((SUMIFS(HLTV_Long!$B$2:$B$337,HLTV_Long!$A$2:$A$337,$A7&"|B|"&"ALL"&"|lw")+SUMIFS(HLTV_Long!$B$2:$B$337,HLTV_Long!$A$2:$A$337,$A7&"|A|"&"ALL"&"|wl"))/(COUNTIFS(HLTV_Long!$A$2:$A$337,$A7&"|B|"&"ALL"&"|lw")+COUNTIFS(HLTV_Long!$A$2:$A$337,$A7&"|A|"&"ALL"&"|wl")),""))) -> 6.965 | AS7: =IF($X7="","",COUNTIFS(HLTV_Long!$A$2:$A$337,$A7&"|A|"&$X7&"|lw")+COUNTIFS(HLTV_Long!$A$2:$A$337,$A7&"|B|"&$X7&"|wl")+COUNTIFS(HLTV_Long!$A$2:$A$337,$A7&"|B|"&$X7&"|lw")+COUNTIFS(HLTV_Long!$A$2:$A$337,$A7&"|A|"&$X7&"|wl")) -> 4 | AT7: =IF(OR($AQ7="",$AR7="",$AG7=""),"",13+$AG7*$AQ7+(1-$AG7)*$AR7) | AU7: =IF($AT7="","",$AG7*(13-$AQ7)-(1-$AG7)*(13-$AR7)) | AV7: =IF($AT7="","",($AG7*13+(1-$AG7)*$AR7)/$AT7) | AW7: =IF($Y7="","",IFERROR((SUMIFS(HLTV_Long!$B$2:$B$337,HLTV_Long!$A$2:$A$337,$A7&"|A|"&$Y7&"|lw")+SUMIFS(HLTV_Long!$B$2:$B$337,HLTV_Long!$A$2:$A$337,$A7&"|B|"&$Y7&"|wl"))/(COUNTIFS(HLTV_Long!$A$2:$A$337,$A7&"|A|"&$Y7&"|lw")+COUNTIFS(HLTV_Long!$A$2:$A$337,$A7&"|B|"&$Y7&"|wl")),IFERROR((SUMIFS(HLTV_Long!$B$2:$B$337,HLTV_Long!$A$2:$A$337,$A7&"|A|"&"ALL"&"|lw")+SUMIFS(HLTV_Long!$B$2:$B$337,HLTV_Long!$A$2:$A$337,$A7&"|B|"&"ALL"&"|wl"))/(COUNTIFS(HLTV_Long!$A$2:$A$337,$A7&"|A|"&"ALL"&"|lw")+COUNTIFS(HLTV_Long!$A$2:$A$337,$A7&"|B|"&"ALL"&"|wl")),""))) -> 9.375 | AX7: =IF($Y7="","",IFERROR((SUMIFS(HLTV_Long!$B$2:$B$337,HLTV_Long!$A$2:$A$337,$A7&"|B|"&$Y7&"|lw")+SUMIFS(HLTV_Long!$B$2:$B$337,HLTV_Long!$A$2:$A$337,$A7&"|A|"&$Y7&"|wl"))/(COUNTIFS(HLTV_Long!$A$2:$A$337,$A7&"|B|"&$Y7&"|lw")+COUNTIFS(HLTV_Long!$A$2:$A$337,$A7&"|A|"&$Y7&"|wl")),IFERROR((SUMIFS(HLTV_Long!$B$2:$B$337,HLTV_Long!$A$2:$A$337,$A7&"|B|"&"ALL"&"|lw")+SUMIFS(HLTV_Long!$B$2:$B$337,HLTV_Long!$A$2:$A$337,$A7&"|A|"&"ALL"&"|wl"))/(COUNTIFS(HLTV_Long!$A$2:$A$337,$A7&"|B|"&"ALL"&"|lw")+COUNTIFS(HLTV_Long!$A$2:$A$337,$A7&"|A|"&"ALL"&"|wl")),""))) -> 8.09 | AY7: =IF($Y7="","",COUNTIFS(HLTV_Long!$A$2:$A$337,$A7&"|A|"&$Y7&"|lw")+COUNTIFS(HLTV_Long!$A$2:$A$337,$A7&"|B|"&$Y7&"|wl")+COUNTIFS(HLTV_Long!$A$2:$A$337,$A7&"|B|"&$Y7&"|lw")+COUNTIFS(HLTV_Long!$A$2:$A$337,$A7&"|A|"&$Y7&"|wl")) -> 4 | AZ7: =IF(OR($AW7="",$AX7="",$AH7=""),"",13+$AH7*$AW7+(1-$AH7)*$AX7) | BA7: =IF($AZ7="","",$AH7*(13-$AW7)-(1-$AH7)*(13-$AX7)) | BB7: =IF($AZ7="","",($AH7*13+(1-$AH7)*$AX7)/$AZ7)
A8: CS2 · BBL vs BCG | B8: CS2 | C8: Tue 06:00 | D8: 3 | E8: BBL Esports (BBL) | F8: BC.Game (BCG) | G8: 0.39285714 | H8: 0.19863159 | I8: 0.34879707 | J8: 0.45257133 | K8: Cache 38% | L8: Nuke 23% | M8: Ancient 9% | N8: PF Map Picks | O8: 21.14229 | P8: 21.121494 | R8: 0.14864865 | S8: -2.4557493 | T8: 11.095238 | V8: 275 | W8: Cache | X8: Nuke | Y8: Ancient | Z8: 21.14 | AA8: 21.12 | AB8: =Config!$B$7 -> 21.5 | AC8: 0.4526 | AD8: BBL | AE8: BCG | AF8: 0.4193 | AG8: 0.4193 | AH8: 0.3929 | AI8: =IFERROR(INDEX(HLTV_Teams!$N$2:$N$25,MATCH($A8&"|A",HLTV_Teams!$A$2:$A$25,0)),"") -> 0.50848994 | AJ8: =IFERROR(INDEX(HLTV_Teams!$N$2:$N$25,MATCH($A8&"|B",HLTV_Teams!$A$2:$A$25,0)),"") -> 0.53645454 | AK8: =IF($W8="","",IFERROR((SUMIFS(HLTV_Long!$B$2:$B$337,HLTV_Long!$A$2:$A$337,$A8&"|A|"&$W8&"|lw")+SUMIFS(HLTV_Long!$B$2:$B$337,HLTV_Long!$A$2:$A$337,$A8&"|B|"&$W8&"|wl"))/(COUNTIFS(HLTV_Long!$A$2:$A$337,$A8&"|A|"&$W8&"|lw")+COUNTIFS(HLTV_Long!$A$2:$A$337,$A8&"|B|"&$W8&"|wl")),IFERROR((SUMIFS(HLTV_Long!$B$2:$B$337,HLTV_Long!$A$2:$A$337,$A8&"|A|"&"ALL"&"|lw")+SUMIFS(HLTV_Long!$B$2:$B$337,HLTV_Long!$A$2:$A$337,$A8&"|B|"&"ALL"&"|wl"))/(COUNTIFS(HLTV_Long!$A$2:$A$337,$A8&"|A|"&"ALL"&"|lw")+COUNTIFS(HLTV_Long!$A$2:$A$337,$A8&"|B|"&"ALL"&"|wl")),""))) -> 6.335 | AL8: =IF($W8="","",IFERROR((SUMIFS(HLTV_Long!$B$2:$B$337,HLTV_Long!$A$2:$A$337,$A8&"|B|"&$W8&"|lw")+SUMIFS(HLTV_Long!$B$2:$B$337,HLTV_Long!$A$2:$A$337,$A8&"|A|"&$W8&"|wl"))/(COUNTIFS(HLTV_Long!$A$2:$A$337,$A8&"|B|"&$W8&"|lw")+COUNTIFS(HLTV_Long!$A$2:$A$337,$A8&"|A|"&$W8&"|wl")),IFERROR((SUMIFS(HLTV_Long!$B$2:$B$337,HLTV_Long!$A$2:$A$337,$A8&"|B|"&"ALL"&"|lw")+SUMIFS(HLTV_Long!$B$2:$B$337,HLTV_Long!$A$2:$A$337,$A8&"|A|"&"ALL"&"|wl"))/(COUNTIFS(HLTV_Long!$A$2:$A$337,$A8&"|B|"&"ALL"&"|lw")+COUNTIFS(HLTV_Long!$A$2:$A$337,$A8&"|A|"&"ALL"&"|wl")),""))) -> 9.4 | AM8: =IF($W8="","",COUNTIFS(HLTV_Long!$A$2:$A$337,$A8&"|A|"&$W8&"|lw")+COUNTIFS(HLTV_Long!$A$2:$A$337,$A8&"|B|"&$W8&"|wl")+COUNTIFS(HLTV_Long!$A$2:$A$337,$A8&"|B|"&$W8&"|lw")+COUNTIFS(HLTV_Long!$A$2:$A$337,$A8&"|A|"&$W8&"|wl")) -> 4 | AN8: =IF(OR($AK8="",$AL8="",$AF8=""),"",13+$AF8*$AK8+(1-$AF8)*$AL8) -> 21.114846 | AO8: =IF($AN8="","",$AF8*(13-$AK8)-(1-$AF8)*(13-$AL8)) -> 0.7041145 | AP8: =IF($AN8="","",($AF8*13+(1-$AF8)*$AL8)/$AN8) -> 0.51667345 | AQ8: =IF($X8="","",IFERROR((SUMIFS(HLTV_Long!$B$2:$B$337,HLTV_Long!$A$2:$A$337,$A8&"|A|"&$X8&"|lw")+SUMIFS(HLTV_Long!$B$2:$B$337,HLTV_Long!$A$2:$A$337,$A8&"|B|"&$X8&"|wl"))/(COUNTIFS(HLTV_Long!$A$2:$A$337,$A8&"|A|"&$X8&"|lw")+COUNTIFS(HLTV_Long!$A$2:$A$337,$A8&"|B|"&$X8&"|wl")),IFERROR((SUMIFS(HLTV_Long!$B$2:$B$337,HLTV_Long!$A$2:$A$337,$A8&"|A|"&"ALL"&"|lw")+SUMIFS(HLTV_Long!$B$2:$B$337,HLTV_Long!$A$2:$A$337,$A8&"|B|"&"ALL"&"|wl"))/(COUNTIFS(HLTV_Long!$A$2:$A$337,$A8&"|A|"&"ALL"&"|lw")+COUNTIFS(HLTV_Long!$A$2:$A$337,$A8&"|B|"&"ALL"&"|wl")),""))) -> 9.42 | AR8: =IF($X8="","",IFERROR((SUMIFS(HLTV_Long!$B$2:$B$337,HLTV_Long!$A$2:$A$337,$A8&"|B|"&$X8&"|lw")+SUMIFS(HLTV_Long!$B$2:$B$337,HLTV_Long!$A$2:$A$337,$A8&"|A|"&$X8&"|wl"))/(COUNTIFS(HLTV_Long!$A$2:$A$337,$A8&"|B|"&$X8&"|lw")+COUNTIFS(HLTV_Long!$A$2:$A$337,$A8&"|A|"&$X8&"|wl")),IFERROR((SUMIFS(HLTV_Long!$B$2:$B$337,HLTV_Long!$A$2:$A$337,$A8&"|B|"&"ALL"&"|lw")+SUMIFS(HLTV_Long!$B$2:$B$337,HLTV_Long!$A$2:$A$337,$A8&"|A|"&"ALL"&"|wl"))/(COUNTIFS(HLTV_Long!$A$2:$A$337,$A8&"|B|"&"ALL"&"|lw")+COUNTIFS(HLTV_Long!$A$2:$A$337,$A8&"|A|"&"ALL"&"|wl")),""))) -> 8.2 | AS8: =IF($X8="","",COUNTIFS(HLTV_Long!$A$2:$A$337,$A8&"|A|"&$X8&"|lw")+COUNTIFS(HLTV_Long!$A$2:$A$337,$A8&"|B|"&$X8&"|wl")+COUNTIFS(HLTV_Long!$A$2:$A$337,$A8&"|B|"&$X8&"|lw")+COUNTIFS(HLTV_Long!$A$2:$A$337,$A8&"|A|"&$X8&"|wl")) -> 4 | AT8: =IF(OR($AQ8="",$AR8="",$AG8=""),"",13+$AG8*$AQ8+(1-$AG8)*$AR8) -> 21.711546 | AU8: =IF($AT8="","",$AG8*(13-$AQ8)-(1-$AG8)*(13-$AR8)) -> -1.286266 | AV8: =IF($AT8="","",($AG8*13+(1-$AG8)*$AR8)/$AT8) -> 0.4703783 | AW8: =IF($Y8="","",IFERROR((SUMIFS(HLTV_Long!$B$2:$B$337,HLTV_Long!$A$2:$A$337,$A8&"|A|"&$Y8&"|lw")+SUMIFS(HLTV_Long!$B$2:$B$337,HLTV_Long!$A$2:$A$337,$A8&"|B|"&$Y8&"|wl"))/(COUNTIFS(HLTV_Long!$A$2:$A$337,$A8&"|A|"&$Y8&"|lw")+COUNTIFS(HLTV_Long!$A$2:$A$337,$A8&"|B|"&$Y8&"|wl")),IFERROR((SUMIFS(HLTV_Long!$B$2:$B$337,HLTV_Long!$A$2:$A$337,$A8&"|A|"&"ALL"&"|lw")+SUMIFS(HLTV_Long!$B$2:$B$337,HLTV_Long!$A$2:$A$337,$A8&"|B|"&"ALL"&"|wl"))/(COUNTIFS(HLTV_Long!$A$2:$A$337,$A8&"|A|"&"ALL"&"|lw")+COUNTIFS(HLTV_Long!$A$2:$A$337,$A8&"|B|"&"ALL"&"|wl")),""))) -> 5.915 | AX8: =IF($Y8="","",IFERROR((SUMIFS(HLTV_Long!$B$2:$B$337,HLTV_Long!$A$2:$A$337,$A8&"|B|"&$Y8&"|lw")+SUMIFS(HLTV_Long!$B$2:$B$337,HLTV_Long!$A$2:$A$337,$A8&"|A|"&$Y8&"|wl"))/(COUNTIFS(HLTV_Long!$A$2:$A$337,$A8&"|B|"&$Y8&"|lw")+COUNTIFS(HLTV_Long!$A$2:$A$337,$A8&"|A|"&$Y8&"|wl")),IFERROR((SUMIFS(HLTV_Long!$B$2:$B$337,HLTV_Long!$A$2:$A$337,$A8&"|B|"&"ALL"&"|lw")+SUMIFS(HLTV_Long!$B$2:$B$337,HLTV_Long!$A$2:$A$337,$A8&"|A|"&"ALL"&"|wl"))/(COUNTIFS(HLTV_Long!$A$2:$A$337,$A8&"|B|"&"ALL"&"|lw")+COUNTIFS(HLTV_Long!$A$2:$A$337,$A8&"|A|"&"ALL"&"|wl")),""))) -> 8.125 | AY8: =IF($Y8="","",COUNTIFS(HLTV_Long!$A$2:$A$337,$A8&"|A|"&$Y8&"|lw")+COUNTIFS(HLTV_Long!$A$2:$A$337,$A8&"|B|"&$Y8&"|wl")+COUNTIFS(HLTV_Long!$A$2:$A$337,$A8&"|B|"&$Y8&"|lw")+COUNTIFS(HLTV_Long!$A$2:$A$337,$A8&"|A|"&$Y8&"|wl")) -> 4 | AZ8: =IF(OR($AW8="",$AX8="",$AH8=""),"",13+$AH8*$AW8+(1-$AH8)*$AX8) -> 20.256691 | BA8: =IF($AZ8="","",$AH8*(13-$AW8)-(1-$AH8)*(13-$AX8)) -> -0.175916 | BB8: =IF($AZ8="","",($AH8*13+(1-$AH8)*$AX8)/$AZ8) -> 0.49565783
